Workbook
Name ___RM2: [1]PAG19!$J$3:$P$39
Name __RM1: [1]PAG19!$B$3:$I$39
Name __RM2: [2]PAG19!$J$3:$P$39
Name _BancosData_: [3]InputBancos!$B$12:$EL$20
Name _colaentregadopenfdo1_: [3]SaldosBancos!$AD$10
Name _colaentregadopenfdo2_: [3]SaldosBancos!$AD$11
Name _colaentregadopenfdo3_: [3]SaldosBancos!$AD$12
Name _CP_: [3]ModData!$N$5
Name _EmisorLinea_: '[3]Margen Legal'!$D$2
Name _fechaCajaLim_: [3]ModData!$R$9
Name _FechaCarteraReal_: [3]ModData!$D$12
Name _fechalim_: [3]ModData!$C$2
Name _NomInputBancos_: [3]ModData!$F$23
Name _OpeCantSigno_: [3]Operaciones!#REF!
Name _OpeFondoSBS_: [3]Operaciones!#REF!
Name _OpeInstrAntiguos_: [3]Operaciones!#REF!
Name _OpeInstrNuevos_: [3]Operaciones!#REF!
Name _OpeNuevas_: [3]Operaciones!#REF!
Name _OpeNuevoSBS_: [3]Operaciones!#REF!
Name _PatFechaFin_: [3]Patrimonio!$C$15
Name _PatFechaIni_: [3]Patrimonio!$C$14
Name _RegHisOpeFX_: '[3]50'!$D$21
Name _RM1: [2]PAG19!$B$3:$I$39
Name _RM2: [2]PAG19!$J$3:$P$39
Name _TcFechaIni_: [3]TC!$C$4
Name _VectFechIni_: [3]Vector!$C$4
Name a: #REF!
Name ABRE_EMISOR: [5]Parametros!$C$3:$C$14
Name Alternativos_Estrategia: [6]Apoyo!#REF!
Name Alternativos_Estructura_Vehiculo: [6]Apoyo!#REF!
Name Alternativos_Tipo_Activos: [6]Apoyo!#REF!
Name Alternativos_Tipo_Vehiculo: [6]Apoyo!#REF!
Name Aportes: '[7]Ing-Egresos'!$I$166:$IV$171
Name Aportes1: '[7]Ing-Egresos'!$H$166:$IV$171
Name aportexcot: '[8]Aporte x cot'!$10:$16
Name Area_1: '[9]LImites Javier'!$B$2:$Y$94
Name Area_2: '[9]LImites Javier'!$B$96:$Y$138
Name b: #REF!
Name Banco_Central_de_Reserva_del_Perú: [7]Concen!$C$10:$IV$10
Name Banco_Continental: [7]Concen!$C$15:$IV$15
Name Banco_de_Crédito_del_Perú: [7]Concen!$C$13:$IV$13
Name Banco_Internacional_del_Perú_S.A.A.: [7]Concen!$C$18:$IV$18
Name Banco_Santander_Central_Hispano___Perú: [7]Concen!$C$25:$IV$25
Name Banco_Wiese_Sudameris_S.A.: [7]Concen!$C$21:$IV$21
Name BankBoston__N.A.__Sucursal_del_Perú: [7]Concen!$C$22:$IV$22
Name CARTERA_ADMINISTRADA_SPP: [7]Intru!$247:$247
Name Cartera_AFP: '[10]Montos Set'!$A$1:$K$80
Name CartxInstru: [11]Intru!$5:$353
Name Cementos_Lima_S.A.: [7]Concen!$C$11:$IV$11
Name Cía._De_Minas_Buenaventura_S.A.A.: [7]Concen!$C$6:$IV$6
Name Comparación: '[10]Montos Set'!$P$1:$Z$69
Name Comparativo: '[10]Montos Set'!$O$1:$Y$97
Name Credicorp_Ltd.: [7]Concen!$C$7:$IV$7
Name cuadro1: [12]Hoja1!$B$1:$K$67
Name cuadro2: [12]Hoja1!$B$68:$K$136
Name cuadro3: [12]Hoja1!$B$138:$J$207
Name cuadro4: [12]Hoja1!$B$208:$J$239
Name Cuadro5: [12]Hoja3!$B$5:$K$111
Name data: OFFSET([3]CarteraEstimada!$B$8,0,0,MAX([3]CarteraEstimada!$A:$A)+1,37)
Name DStandard: [11]VC_Shar!$L$196:$Q$207

Sheet Valorización de Instrumentos
A1: Fecha Valoración | B1: 20251231
A3: FechaValoracion | B3: TIPO_TITULO | C3: PORTAFOLIO | D3: GRUPO | E3: CODIGO_SBS | F3: CODIGO_ISIN | G3: TITULO | H3: EMISOR | I3: Moneda | J3: VALOR_UNITARIO | K3: VALOR_VECTOR_LOCAL | L3: VALOR_VECTOR_ORIGEN | M3: CANTIDAD | N3: FECHA_VENCIMIENTO | O3: DIAS_VENTIMIENTO | P3: TIPO_CAMBIO | Q3: TIPO_RENTA | R3: VALOR_VECTOR_LOCAL_T-1 | S3: VALOR_VECTOR_ORIGEN_T-1 | T3: GRUPO_ECONOMICO | U3: ACTIVO_DEL_EMISOR | V3: PASIVO_DEL_EMISOR | W3: PASTRIMONIO_DEL_EMISOR | X3: DIFERENCIA | Y3: Column1 | Z3: ID_POS | AA3: Clasificación ERR | AB3: Clasificación General | AC3: Posición Nominal | AD3: Emisor2 | AE3: Nombre (G&P)
A4: 31/12/2025 | B4: 01 | C4: IN-FONDO1 | D4: BGC | E4: 011000112F55 | F4: PEP01000C4S2 | G4: SB12FEB55 | H4: 1000 | I4: 1 | J4: 1000 | K4: 47670526 | L4: 47670526 | M4: 42700 | N4: 56657 | O4: 10635 | P4: 1 | Q4: RENTA FIJA | R4: 47662749 | S4: 47662749 | U4: 0 | V4: 0 | W4: 0 | X4: 0.1821469 | Y4: =+MID(Tabla_Consulta_desde_Reporte_de_Valorización_de_Instrumentos6[[#This Row],[CODIGO_SBS]],7,1) -> 1 | Z4: =Tabla_Consulta_desde_Reporte_de_Valorización_de_Instrumentos6[[#This Row],[CODIGO_SBS]]&"-"&RIGHT(Tabla_Consulta_desde_Reporte_de_Valorización_de_Instrumentos6[[#This Row],[PORTAFOLIO]],1) -> 011000112F55-1 | AA4: Deuda soberana - Local | AB4: Deuda | AC4: =Tabla_Consulta_desde_Reporte_de_Valorización_de_Instrumentos6[[#This Row],[VALOR_UNITARIO]]*Tabla_Consulta_desde_Reporte_de_Valorización_de_Instrumentos6[[#This Row],[CANTIDAD]] -> 42700000 | AD4: Gobierno Central | AE4: =_xlfn.IFNA(_xlfn.XLOOKUP(Tabla_Consulta_desde_Reporte_de_Valorización_de_Instrumentos6[[#This Row],[Emisor2]],'Parametria 2'!G:G,'Parametria 2'!F:F,_xlfn.XLOOKUP(Tabla_Consulta_desde_Reporte_de_Valorización_de_Instrumentos6[[#This Row],[Emisor2]],'Valorización de Instrumentos_of'!H:H,'Valorización de Instrumentos_of'!H:H)),_xlfn.XLOOKUP(Tabla_Consulta_desde_Reporte_de_Valorización_de_Instrumentos6[[#This Row],[TITULO]],'Parametria 2'!K:K,'Parametria 2'!L:L)) -> Gobierno Central
A5: 31/12/2025 | B5: 01 | C5: IN-FONDO2 | D5: BGC | E5: 011000112F55 | F5: PEP01000C4S2 | G5: SB12FEB55 | H5: 1000 | I5: 1 | J5: 1000 | K5: 1.2615385e+08 | L5: 1.2615385e+08 | M5: 113000 | N5: 56657 | O5: 10635 | P5: 1 | Q5: RENTA FIJA | R5: 1.2613327e+08 | S5: 1.2613327e+08 | U5: 0 | V5: 0 | W5: 0 | X5: 0.1821469 | Y5: =+MID(Tabla_Consulta_desde_Reporte_de_Valorización_de_Instrumentos6[[#This Row],[CODIGO_SBS]],7,1) -> 1 | Z5: =Tabla_Consulta_desde_Reporte_de_Valorización_de_Instrumentos6[[#This Row],[CODIGO_SBS]]&"-"&RIGHT(Tabla_Consulta_desde_Reporte_de_Valorización_de_Instrumentos6[[#This Row],[PORTAFOLIO]],1) -> 011000112F55-2 | AA5: Deuda soberana - Local | AB5: Deuda | AC5: =Tabla_Consulta_desde_Reporte_de_Valorización_de_Instrumentos6[[#This Row],[VALOR_UNITARIO]]*Tabla_Consulta_desde_Reporte_de_Valorización_de_Instrumentos6[[#This Row],[CANTIDAD]] -> 113000000 | AD5: Gobierno Central | AE5: =_xlfn.IFNA(_xlfn.XLOOKUP(Tabla_Consulta_desde_Reporte_de_Valorización_de_Instrumentos6[[#This Row],[Emisor2]],'Parametria 2'!G:G,'Parametria 2'!F:F,_xlfn.XLOOKUP(Tabla_Consulta_desde_Reporte_de_Valorización_de_Instrumentos6[[#This Row],[Emisor2]],'Valorización de Instrumentos_of'!H:H,'Valorización de Instrumentos_of'!H:H)),_xlfn.XLOOKUP(Tabla_Consulta_desde_Reporte_de_Valorización_de_Instrumentos6[[#This Row],[TITULO]],'Parametria 2'!K:K,'Parametria 2'!L:L)) -> Gobierno Central
A6: 31/12/2025 | B6: 01 | C6: IN-FONDO1 | D6: BGC | E6: 011000112G37 | F6: PEP01000C2Z1 | G6: SOBAGO2037 | H6: 1000 | I6: 1 | J6: 1000 | K6: 5.2060934e+08 | L6: 5.2060934e+08 | M6: 485359 | N6: 50264 | O6: 4242 | P6: 1 | Q6: RENTA FIJA | R6: 5.1813911e+08 | S6: 5.1813911e+08 | U6: 0 | V6: 0 | W6: 0 | X6: 5.0895012 | Y6: =+MID(Tabla_Consulta_desde_Reporte_de_Valorización_de_Instrumentos6[[#This Row],[CODIGO_SBS]],7,1) -> 1 | Z6: =Tabla_Consulta_desde_Reporte_de_Valorización_de_Instrumentos6[[#This Row],[CODIGO_SBS]]&"-"&RIGHT(Tabla_Consulta_desde_Reporte_de_Valorización_de_Instrumentos6[[#This Row],[PORTAFOLIO]],1) -> 011000112G37-1 | AA6: Deuda soberana - Local | AB6: Deuda | AC6: =Tabla_Consulta_desde_Reporte_de_Valorización_de_Instrumentos6[[#This Row],[VALOR_UNITARIO]]*Tabla_Consulta_desde_Reporte_de_Valorización_de_Instrumentos6[[#This Row],[CANTIDAD]] -> 485359000 | AD6: Gobierno Central | AE6: =_xlfn.IFNA(_xlfn.XLOOKUP(Tabla_Consulta_desde_Reporte_de_Valorización_de_Instrumentos6[[#This Row],[Emisor2]],'Parametria 2'!G:G,'Parametria 2'!F:F,_xlfn.XLOOKUP(Tabla_Consulta_desde_Reporte_de_Valorización_de_Instrumentos6[[#This Row],[Emisor2]],'Valorización de Instrumentos_of'!H:H,'Valorización de Instrumentos_of'!H:H)),_xlfn.XLOOKUP(Tabla_Consulta_desde_Reporte_de_Valorización_de_Instrumentos6[[#This Row],[TITULO]],'Parametria 2'!K:K,'Parametria 2'!L:L)) -> Gobierno Central
A7: 31/12/2025 | B7: 01 | C7: IN-FONDO2 | D7: BGC | E7: 011000112G37 | F7: PEP01000C2Z1 | G7: SOBAGO2037 | H7: 1000 | I7: 1 | J7: 1000 | K7: 1.7105274e+09 | L7: 1.7105274e+09 | M7: 1594708 | N7: 50264 | O7: 4242 | P7: 1 | Q7: RENTA FIJA | R7: 1.7024112e+09 | S7: 1.7024112e+09 | U7: 0 | V7: 0 | W7: 0 | X7: 5.0895012 | Y7: =+MID(Tabla_Consulta_desde_Reporte_de_Valorización_de_Instrumentos6[[#This Row],[CODIGO_SBS]],7,1) -> 1 | Z7: =Tabla_Consulta_desde_Reporte_de_Valorización_de_Instrumentos6[[#This Row],[CODIGO_SBS]]&"-"&RIGHT(Tabla_Consulta_desde_Reporte_de_Valorización_de_Instrumentos6[[#This Row],[PORTAFOLIO]],1) -> 011000112G37-2 | AA7: Deuda soberana - Local | AB7: Deuda | AC7: =Tabla_Consulta_desde_Reporte_de_Valorización_de_Instrumentos6[[#This Row],[VALOR_UNITARIO]]*Tabla_Consulta_desde_Reporte_de_Valorización_de_Instrumentos6[[#This Row],[CANTIDAD]] -> 1594708000 | AD7: Gobierno Central | AE7: =_xlfn.IFNA(_xlfn.XLOOKUP(Tabla_Consulta_desde_Reporte_de_Valorización_de_Instrumentos6[[#This Row],[Emisor2]],'Parametria 2'!G:G,'Parametria 2'!F:F,_xlfn.XLOOKUP(Tabla_Consulta_desde_Reporte_de_Valorización_de_Instrumentos6[[#This Row],[Emisor2]],'Valorización de Instrumentos_of'!H:H,'Valorización de Instrumentos_of'!H:H)),_xlfn.XLOOKUP(Tabla_Consulta_desde_Reporte_de_Valorización_de_Instrumentos6[[#This Row],[TITULO]],'Parametria 2'!K:K,'Parametria 2'!L:L)) -> Gobierno Central
A8: 31/12/2025 | B8: 01 | C8: IN-FONDO1 | D8: BGC | E8: 011000112G39 | F8: PEP01000C5J8 | G8: SB12G39 | H8: 1000 | I8: 1 | J8: 1000 | K8: 8.0004694e+08 | L8: 8.0004694e+08 | M8: 713081 | N8: 50994 | O8: 4972 | P8: 1 | Q8: RENTA FIJA | R8: 7.9692161e+08 | S8: 7.9692161e+08 | U8: 0 | V8: 0 | W8: 0 | X8: 4.3828539 | Y8: =+MID(Tabla_Consulta_desde_Reporte_de_Valorización_de_Instrumentos6[[#This Row],[CODIGO_SBS]],7,1) -> 1 | Z8: =Tabla_Consulta_desde_Reporte_de_Valorización_de_Instrumentos6[[#This Row],[CODIGO_SBS]]&"-"&RIGHT(Tabla_Consulta_desde_Reporte_de_Valorización_de_Instrumentos6[[#This Row],[PORTAFOLIO]],1) -> 011000112G39-1 | AA8: Deuda soberana - Local | AB8: Deuda | AC8: =Tabla_Consulta_desde_Reporte_de_Valorización_de_Instrumentos6[[#This Row],[VALOR_UNITARIO]]*Tabla_Consulta_desde_Reporte_de_Valorización_de_Instrumentos6[[#This Row],[CANTIDAD]] -> 713081000 | AD8: Gobierno Central | AE8: =_xlfn.IFNA(_xlfn.XLOOKUP(Tabla_Consulta_desde_Reporte_de_Valorización_de_Instrumentos6[[#This Row],[Emisor2]],'Parametria 2'!G:G,'Parametria 2'!F:F,_xlfn.XLOOKUP(Tabla_Consulta_desde_Reporte_de_Valorización_de_Instrumentos6[[#This Row],[Emisor2]],'Valorización de Instrumentos_of'!H:H,'Valorización de Instrumentos_of'!H:H)),_xlfn.XLOOKUP(Tabla_Consulta_desde_Reporte_de_Valorización_de_Instrumentos6[[#This Row],[TITULO]],'Parametria 2'!K:K,'Parametria 2'!L:L)) -> Gobierno Central
A9: 31/12/2025 | B9: 01 | C9: IN-FONDO2 | D9: BGC | E9: 011000112G39 | F9: PEP01000C5J8 | G9: SB12G39 | H9: 1000 | I9: 1 | J9: 1000 | K9: 2.0210548e+09 | L9: 2.0210548e+09 | M9: 1801364 | N9: 50994 | O9: 4972 | P9: 1 | Q9: RENTA FIJA | R9: 1.7538822e+09 | S9: 1.7538822e+09 | U9: 0 | V9: 0 | W9: 0 | X9: 4.3828539 | Y9: =+MID(Tabla_Consulta_desde_Reporte_de_Valorización_de_Instrumentos6[[#This Row],[CODIGO_SBS]],7,1) -> 1 | Z9: =Tabla_Consulta_desde_Reporte_de_Valorización_de_Instrumentos6[[#This Row],[CODIGO_SBS]]&"-"&RIGHT(Tabla_Consulta_desde_Reporte_de_Valorización_de_Instrumentos6[[#This Row],[PORTAFOLIO]],1) -> 011000112G39-2 | AA9: Deuda soberana - Local | AB9: Deuda | AC9: =Tabla_Consulta_desde_Reporte_de_Valorización_de_Instrumentos6[[#This Row],[VALOR_UNITARIO]]*Tabla_Consulta_desde_Reporte_de_Valorización_de_Instrumentos6[[#This Row],[CANTIDAD]] -> 1801364000 | AD9: Gobierno Central | AE9: =_xlfn.IFNA(_xlfn.XLOOKUP(Tabla_Consulta_desde_Reporte_de_Valorización_de_Instrumentos6[[#This Row],[Emisor2]],'Parametria 2'!G:G,'Parametria 2'!F:F,_xlfn.XLOOKUP(Tabla_Consulta_desde_Reporte_de_Valorización_de_Instrumentos6[[#This Row],[Emisor2]],'Valorización de Instrumentos_of'!H:H,'Valorización de Instrumentos_of'!H:H)),_xlfn.XLOOKUP(Tabla_Consulta_desde_Reporte_de_Valorización_de_Instrumentos6[[#This Row],[TITULO]],'Parametria 2'!K:K,'Parametria 2'!L:L)) -> Gobierno Central
A10: 31/12/2025 | B10: 01 | C10: IN-FONDO1 | D10: BGC | E10: 011000112G33 | F10: PEP01000C5I0 | G10: SB12AGO33 | H10: 1000 | I10: 1 | J10: 1000 | K10: 1.7522759e+08 | L10: 1.7522759e+08 | M10: 149758 | N10: 48803 | O10: 2781 | P10: 1 | Q10: RENTA FIJA | R10: 1.7480285e+08 | S10: 1.7480285e+08 | U10: 0 | V10: 0 | W10: 0 | X10: 2.8362001 | Y10: =+MID(Tabla_Consulta_desde_Reporte_de_Valorización_de_Instrumentos6[[#This Row],[CODIGO_SBS]],7,1) -> 1 | Z10: =Tabla_Consulta_desde_Reporte_de_Valorización_de_Instrumentos6[[#This Row],[CODIGO_SBS]]&"-"&RIGHT(Tabla_Consulta_desde_Reporte_de_Valorización_de_Instrumentos6[[#This Row],[PORTAFOLIO]],1) -> 011000112G33-1 | AA10: Deuda soberana - Local | AB10: Deuda | AC10: =Tabla_Consulta_desde_Reporte_de_Valorización_de_Instrumentos6[[#This Row],[VALOR_UNITARIO]]*Tabla_Consulta_desde_Reporte_de_Valorización_de_Instrumentos6[[#This Row],[CANTIDAD]] -> 149758000 | AD10: Gobierno Central | AE10: =_xlfn.IFNA(_xlfn.XLOOKUP(Tabla_Consulta_desde_Reporte_de_Valorización_de_Instrumentos6[[#This Row],[Emisor2]],'Parametria 2'!G:G,'Parametria 2'!F:F,_xlfn.XLOOKUP(Tabla_Consulta_desde_Reporte_de_Valorización_de_Instrumentos6[[#This Row],[Emisor2]],'Valorización de Instrumentos_of'!H:H,'Valorización de Instrumentos_of'!H:H)),_xlfn.XLOOKUP(Tabla_Consulta_desde_Reporte_de_Valorización_de_Instrumentos6[[#This Row],[TITULO]],'Parametria 2'!K:K,'Parametria 2'!L:L)) -> Gobierno Central
A11: 31/12/2025 | B11: 01 | C11: IN-FONDO2 | D11: BGC | E11: 011000112G33 | F11: PEP01000C5I0 | G11: SB12AGO33 | H11: 1000 | I11: 1 | J11: 1000 | K11: 1.3456725e+09 | L11: 1.3456725e+09 | M11: 1150077 | N11: 48803 | O11: 2781 | P11: 1 | Q11: RENTA FIJA | R11: 1.3424106e+09 | S11: 1.3424106e+09 | U11: 0 | V11: 0 | W11: 0 | X11: 2.8362001 | Y11: =+MID(Tabla_Consulta_desde_Reporte_de_Valorización_de_Instrumentos6[[#This Row],[CODIGO_SBS]],7,1) -> 1 | Z11: =Tabla_Consulta_desde_Reporte_de_Valorización_de_Instrumentos6[[#This Row],[CODIGO_SBS]]&"-"&RIGHT(Tabla_Consulta_desde_Reporte_de_Valorización_de_Instrumentos6[[#This Row],[PORTAFOLIO]],1) -> 011000112G33-2 | AA11: Deuda soberana - Local | AB11: Deuda | AC11: =Tabla_Consulta_desde_Reporte_de_Valorización_de_Instrumentos6[[#This Row],[VALOR_UNITARIO]]*Tabla_Consulta_desde_Reporte_de_Valorización_de_Instrumentos6[[#This Row],[CANTIDAD]] -> 1150077000 | AD11: Gobierno Central | AE11: =_xlfn.IFNA(_xlfn.XLOOKUP(Tabla_Consulta_desde_Reporte_de_Valorización_de_Instrumentos6[[#This Row],[Emisor2]],'Parametria 2'!G:G,'Parametria 2'!F:F,_xlfn.XLOOKUP(Tabla_Consulta_desde_Reporte_de_Valorización_de_Instrumentos6[[#This Row],[Emisor2]],'Valorización de Instrumentos_of'!H:H,'Valorización de Instrumentos_of'!H:H)),_xlfn.XLOOKUP(Tabla_Consulta_desde_Reporte_de_Valorización_de_Instrumentos6[[#This Row],[TITULO]],'Parametria 2'!K:K,'Parametria 2'!L:L)) -> Gobierno Central
A12: 31/12/2025 | B12: 01 | C12: IN-FONDO1 | D12: BGC | E12: 011000112G40 | F12: PEP01000C5H2 | G12: SB12AGO40 | H12: 1000 | I12: 1 | J12: 1000 | K12: 2.3012165e+08 | L12: 2.3012165e+08 | M12: 252870 | N12: 51360 | O12: 5338 | P12: 1 | Q12: RENTA FIJA | R12: 2.2973463e+08 | S12: 2.2973463e+08 | U12: 0 | V12: 0 | W12: 0 | X12: 1.5305237 | Y12: =+MID(Tabla_Consulta_desde_Reporte_de_Valorización_de_Instrumentos6[[#This Row],[CODIGO_SBS]],7,1) -> 1 | Z12: =Tabla_Consulta_desde_Reporte_de_Valorización_de_Instrumentos6[[#This Row],[CODIGO_SBS]]&"-"&RIGHT(Tabla_Consulta_desde_Reporte_de_Valorización_de_Instrumentos6[[#This Row],[PORTAFOLIO]],1) -> 011000112G40-1 | AA12: Deuda soberana - Local | AB12: Deuda | AC12: =Tabla_Consulta_desde_Reporte_de_Valorización_de_Instrumentos6[[#This Row],[VALOR_UNITARIO]]*Tabla_Consulta_desde_Reporte_de_Valorización_de_Instrumentos6[[#This Row],[CANTIDAD]] -> 252870000 | AD12: Gobierno Central | AE12: =_xlfn.IFNA(_xlfn.XLOOKUP(Tabla_Consulta_desde_Reporte_de_Valorización_de_Instrumentos6[[#This Row],[Emisor2]],'Parametria 2'!G:G,'Parametria 2'!F:F,_xlfn.XLOOKUP(Tabla_Consulta_desde_Reporte_de_Valorización_de_Instrumentos6[[#This Row],[Emisor2]],'Valorización de Instrumentos_of'!H:H,'Valorización de Instrumentos_of'!H:H)),_xlfn.XLOOKUP(Tabla_Consulta_desde_Reporte_de_Valorización_de_Instrumentos6[[#This Row],[TITULO]],'Parametria 2'!K:K,'Parametria 2'!L:L)) -> Gobierno Central
A13: 31/12/2025 | B13: 01 | C13: IN-FONDO2 | D13: BGC | E13: 011000112G40 | F13: PEP01000C5H2 | G13: SB12AGO40 | H13: 1000 | I13: 1 | J13: 1000 | K13: 2.2746707e+08 | L13: 2.2746707e+08 | M13: 249953 | N13: 51360 | O13: 5338 | P13: 1 | Q13: RENTA FIJA | R13: 2.2708451e+08 | S13: 2.2708451e+08 | U13: 0 | V13: 0 | W13: 0 | X13: 1.5305237 | Y13: =+MID(Tabla_Consulta_desde_Reporte_de_Valorización_de_Instrumentos6[[#This Row],[CODIGO_SBS]],7,1) -> 1 | Z13: =Tabla_Consulta_desde_Reporte_de_Valorización_de_Instrumentos6[[#This Row],[CODIGO_SBS]]&"-"&RIGHT(Tabla_Consulta_desde_Reporte_de_Valorización_de_Instrumentos6[[#This Row],[PORTAFOLIO]],1) -> 011000112G40-2 | AA13: Deuda soberana - Local | AB13: Deuda | AC13: =Tabla_Consulta_desde_Reporte_de_Valorización_de_Instrumentos6[[#This Row],[VALOR_UNITARIO]]*Tabla_Consulta_desde_Reporte_de_Valorización_de_Instrumentos6[[#This Row],[CANTIDAD]] -> 249953000 | AD13: Gobierno Central | AE13: =_xlfn.IFNA(_xlfn.XLOOKUP(Tabla_Consulta_desde_Reporte_de_Valorización_de_Instrumentos6[[#This Row],[Emisor2]],'Parametria 2'!G:G,'Parametria 2'!F:F,_xlfn.XLOOKUP(Tabla_Consulta_desde_Reporte_de_Valorización_de_Instrumentos6[[#This Row],[Emisor2]],'Valorización de Instrumentos_of'!H:H,'Valorización de Instrumentos_of'!H:H)),_xlfn.XLOOKUP(Tabla_Consulta_desde_Reporte_de_Valorización_de_Instrumentos6[[#This Row],[TITULO]],'Parametria 2'!K:K,'Parametria 2'!L:L)) -> Gobierno Central
A14: 31/12/2025 | B14: 01 | C14: IN-FONDO1 | D14: BGC | E14: 011000112G32 | F14: PEP01000C5E9 | G14: SB12AGO32 | H14: 1000 | I14: 1 | J14: 1000 | K14: 73619932 | L14: 73619932 | M14: 66706 | N14: 48438 | O14: 2416 | P14: 1 | Q14: RENTA FIJA | R14: 73512435 | S14: 73512435 | U14: 0 | V14: 0 | W14: 0 | X14: 1.6115024 | Y14: =+MID(Tabla_Consulta_desde_Reporte_de_Valorización_de_Instrumentos6[[#This Row],[CODIGO_SBS]],7,1) -> 1 | Z14: =Tabla_Consulta_desde_Reporte_de_Valorización_de_Instrumentos6[[#This Row],[CODIGO_SBS]]&"-"&RIGHT(Tabla_Consulta_desde_Reporte_de_Valorización_de_Instrumentos6[[#This Row],[PORTAFOLIO]],1) -> 011000112G32-1 | AA14: Deuda soberana - Local | AB14: Deuda | AC14: =Tabla_Consulta_desde_Reporte_de_Valorización_de_Instrumentos6[[#This Row],[VALOR_UNITARIO]]*Tabla_Consulta_desde_Reporte_de_Valorización_de_Instrumentos6[[#This Row],[CANTIDAD]] -> 66706000 | AD14: Gobierno Central | AE14: =_xlfn.IFNA(_xlfn.XLOOKUP(Tabla_Consulta_desde_Reporte_de_Valorización_de_Instrumentos6[[#This Row],[Emisor2]],'Parametria 2'!G:G,'Parametria 2'!F:F,_xlfn.XLOOKUP(Tabla_Consulta_desde_Reporte_de_Valorización_de_Instrumentos6[[#This Row],[Emisor2]],'Valorización de Instrumentos_of'!H:H,'Valorización de Instrumentos_of'!H:H)),_xlfn.XLOOKUP(Tabla_Consulta_desde_Reporte_de_Valorización_de_Instrumentos6[[#This Row],[TITULO]],'Parametria 2'!K:K,'Parametria 2'!L:L)) -> Gobierno Central
A15: 31/12/2025 | B15: 01 | C15: IN-FONDO2 | D15: BGC | E15: 011000112G32 | F15: PEP01000C5E9 | G15: SB12AGO32 | H15: 1000 | I15: 1 | J15: 1000 | K15: 611420.9 | L15: 611420.9 | M15: 554 | N15: 48438 | O15: 2416 | P15: 1 | Q15: RENTA FIJA | R15: 610528.12 | S15: 610528.12 | U15: 0 | V15: 0 | W15: 0 | X15: 1.6115024 | Y15: =+MID(Tabla_Consulta_desde_Reporte_de_Valorización_de_Instrumentos6[[#This Row],[CODIGO_SBS]],7,1) -> 1 | Z15: =Tabla_Consulta_desde_Reporte_de_Valorización_de_Instrumentos6[[#This Row],[CODIGO_SBS]]&"-"&RIGHT(Tabla_Consulta_desde_Reporte_de_Valorización_de_Instrumentos6[[#This Row],[PORTAFOLIO]],1) -> 011000112G32-2 | AA15: Deuda soberana - Local | AB15: Deuda | AC15: =Tabla_Consulta_desde_Reporte_de_Valorización_de_Instrumentos6[[#This Row],[VALOR_UNITARIO]]*Tabla_Consulta_desde_Reporte_de_Valorización_de_Instrumentos6[[#This Row],[CANTIDAD]] -> 554000 | AD15: Gobierno Central | AE15: =_xlfn.IFNA(_xlfn.XLOOKUP(Tabla_Consulta_desde_Reporte_de_Valorización_de_Instrumentos6[[#This Row],[Emisor2]],'Parametria 2'!G:G,'Parametria 2'!F:F,_xlfn.XLOOKUP(Tabla_Consulta_desde_Reporte_de_Valorización_de_Instrumentos6[[#This Row],[Emisor2]],'Valorización de Instrumentos_of'!H:H,'Valorización de Instrumentos_of'!H:H)),_xlfn.XLOOKUP(Tabla_Consulta_desde_Reporte_de_Valorización_de_Instrumentos6[[#This Row],[TITULO]],'Parametria 2'!K:K,'Parametria 2'!L:L)) -> Gobierno Central
... A38: 31/12/2025 | B38: 15 | C38: IN-FONDO2 | D38: OSX | E38: 1551192MAD04 | F38: USP1400MAD04 | G38: BANORT 8 3/8 PE | H38: 5119 | I38: 2 | J38: 1000 | K38: 65150544 | L38: 19384851 | M38: 18270 | N38: 54928 | O38: 8906 | P38: 3.3609 | Q38: RENTA FIJA | R38: 65231708 | S38: 19399188 | U38: 2191378000000 | V38: 1948764000000 | W38: 242614000000 | X38: -0.784723 | Y38: =+MID(Tabla_Consulta_desde_Reporte_de_Valorización_de_Instrumentos6[[#This Row],[CODIGO_SBS]],7,1) -> 2 | Z38: =Tabla_Consulta_desde_Reporte_de_Valorización_de_Instrumentos6[[#This Row],[CODIGO_SBS]]&"-"&RIGHT(Tabla_Consulta_desde_Reporte_de_Valorización_de_Instrumentos6[[#This Row],[PORTAFOLIO]],1) -> 1551192MAD04-2 | AA38: Deuda corporativa directa - Internacional | AB38: Deuda | AC38: =Tabla_Consulta_desde_Reporte_de_Valorización_de_Instrumentos6[[#This Row],[VALOR_UNITARIO]]*Tabla_Consulta_desde_Reporte_de_Valorización_de_Instrumentos6[[#This Row],[CANTIDAD]] -> 18270000 | AD38: Grupo Financiero Banorte | AE38: =_xlfn.IFNA(_xlfn.XLOOKUP(Tabla_Consulta_desde_Reporte_de_Valorización_de_Instrumentos6[[#This Row],[Emisor2]],'Parametria 2'!G:G,'Parametria 2'!F:F,_xlfn.XLOOKUP(Tabla_Consulta_desde_Reporte_de_Valorización_de_Instrumentos6[[#This Row],[Emisor2]],'Valorización de Instrumentos_of'!H:H,'Valorización de Instrumentos_of'!H:H)),_xlfn.XLOOKUP(Tabla_Consulta_desde_Reporte_de_Valorización_de_Instrumentos6[[#This Row],[TITULO]],'Parametria 2'!K:K,'Parametria 2'!L:L)) -> #N/A
A39: 31/12/2025 | B39: 15 | C39: IN-FONDO1 | D39: OSX | E39: 1552782GAA15 | F39: USP2000GAA15 | G39: BBVASM 2035 | H39: 5278 | I39: 2 | J39: 1000 | K39: 5456578.7 | L39: 1623546.9 | M39: 1500 | N39: 49351 | O39: 3329 | P39: 3.3609 | Q39: RENTA FIJA | R39: 5469811.8 | S39: 1626661.5 | T39: GBBV | U39: 2808249000000 | V39: 2500434000000 | W39: 307815000000 | X39: -2.076389 | Y39: =+MID(Tabla_Consulta_desde_Reporte_de_Valorización_de_Instrumentos6[[#This Row],[CODIGO_SBS]],7,1) -> 2 | Z39: =Tabla_Consulta_desde_Reporte_de_Valorización_de_Instrumentos6[[#This Row],[CODIGO_SBS]]&"-"&RIGHT(Tabla_Consulta_desde_Reporte_de_Valorización_de_Instrumentos6[[#This Row],[PORTAFOLIO]],1) -> 1552782GAA15-1 | AA39: Deuda corporativa directa - Internacional | AB39: Deuda | AC39: =Tabla_Consulta_desde_Reporte_de_Valorización_de_Instrumentos6[[#This Row],[VALOR_UNITARIO]]*Tabla_Consulta_desde_Reporte_de_Valorización_de_Instrumentos6[[#This Row],[CANTIDAD]] -> 1500000 | AD39: BBVA Bancomer | AE39: =_xlfn.IFNA(_xlfn.XLOOKUP(Tabla_Consulta_desde_Reporte_de_Valorización_de_Instrumentos6[[#This Row],[Emisor2]],'Parametria 2'!G:G,'Parametria 2'!F:F,_xlfn.XLOOKUP(Tabla_Consulta_desde_Reporte_de_Valorización_de_Instrumentos6[[#This Row],[Emisor2]],'Valorización de Instrumentos_of'!H:H,'Valorización de Instrumentos_of'!H:H)),_xlfn.XLOOKUP(Tabla_Consulta_desde_Reporte_de_Valorización_de_Instrumentos6[[#This Row],[TITULO]],'Parametria 2'!K:K,'Parametria 2'!L:L)) -> BBVA Bancomer
A40: 31/12/2025 | B40: 15 | C40: IN-FONDO1 | D40: OSX | E40: 1552782BAB48 | F40: USP1S81BAB48 | G40: BBVASM 2039 | H40: 5278 | I40: 2 | J40: 1000 | K40: 48322572 | L40: 14377867 | M40: 12800 | N40: 50778 | O40: 4756 | P40: 3.3609 | Q40: RENTA FIJA | R40: 48303082 | S40: 14364802 | T40: GBBV | U40: 2808249000000 | V40: 2500434000000 | W40: 307815000000 | X40: 1.020707 | Y40: =+MID(Tabla_Consulta_desde_Reporte_de_Valorización_de_Instrumentos6[[#This Row],[CODIGO_SBS]],7,1) -> 2 | Z40: =Tabla_Consulta_desde_Reporte_de_Valorización_de_Instrumentos6[[#This Row],[CODIGO_SBS]]&"-"&RIGHT(Tabla_Consulta_desde_Reporte_de_Valorización_de_Instrumentos6[[#This Row],[PORTAFOLIO]],1) -> 1552782BAB48-1 | AA40: Deuda corporativa directa - Internacional | AB40: Deuda | AC40: =Tabla_Consulta_desde_Reporte_de_Valorización_de_Instrumentos6[[#This Row],[VALOR_UNITARIO]]*Tabla_Consulta_desde_Reporte_de_Valorización_de_Instrumentos6[[#This Row],[CANTIDAD]] -> 12800000 | AD40: BBVA Bancomer | AE40: =_xlfn.IFNA(_xlfn.XLOOKUP(Tabla_Consulta_desde_Reporte_de_Valorización_de_Instrumentos6[[#This Row],[Emisor2]],'Parametria 2'!G:G,'Parametria 2'!F:F,_xlfn.XLOOKUP(Tabla_Consulta_desde_Reporte_de_Valorización_de_Instrumentos6[[#This Row],[Emisor2]],'Valorización de Instrumentos_of'!H:H,'Valorización de Instrumentos_of'!H:H)),_xlfn.XLOOKUP(Tabla_Consulta_desde_Reporte_de_Valorización_de_Instrumentos6[[#This Row],[TITULO]],'Parametria 2'!K:K,'Parametria 2'!L:L)) -> BBVA Bancomer
A41: 31/12/2025 | B41: 15 | C41: IN-FONDO2 | D41: OSX | E41: 1552782BAB48 | F41: USP1S81BAB48 | G41: BBVASM 2039 | H41: 5278 | I41: 2 | J41: 1000 | K41: 43414811 | L41: 12917615 | M41: 11500 | N41: 50778 | O41: 4756 | P41: 3.3609 | Q41: RENTA FIJA | R41: 43397300 | S41: 12905876 | T41: GBBV | U41: 2808249000000 | V41: 2500434000000 | W41: 307815000000 | X41: 1.020707 | Y41: =+MID(Tabla_Consulta_desde_Reporte_de_Valorización_de_Instrumentos6[[#This Row],[CODIGO_SBS]],7,1) -> 2 | Z41: =Tabla_Consulta_desde_Reporte_de_Valorización_de_Instrumentos6[[#This Row],[CODIGO_SBS]]&"-"&RIGHT(Tabla_Consulta_desde_Reporte_de_Valorización_de_Instrumentos6[[#This Row],[PORTAFOLIO]],1) -> 1552782BAB48-2 | AA41: Deuda corporativa directa - Internacional | AB41: Deuda | AC41: =Tabla_Consulta_desde_Reporte_de_Valorización_de_Instrumentos6[[#This Row],[VALOR_UNITARIO]]*Tabla_Consulta_desde_Reporte_de_Valorización_de_Instrumentos6[[#This Row],[CANTIDAD]] -> 11500000 | AD41: BBVA Bancomer | AE41: =_xlfn.IFNA(_xlfn.XLOOKUP(Tabla_Consulta_desde_Reporte_de_Valorización_de_Instrumentos6[[#This Row],[Emisor2]],'Parametria 2'!G:G,'Parametria 2'!F:F,_xlfn.XLOOKUP(Tabla_Consulta_desde_Reporte_de_Valorización_de_Instrumentos6[[#This Row],[Emisor2]],'Valorización de Instrumentos_of'!H:H,'Valorización de Instrumentos_of'!H:H)),_xlfn.XLOOKUP(Tabla_Consulta_desde_Reporte_de_Valorización_de_Instrumentos6[[#This Row],[TITULO]],'Parametria 2'!K:K,'Parametria 2'!L:L)) -> BBVA Bancomer
A42: 31/12/2025 | B42: 15 | C42: IN-FONDO1 | D42: OSX | E42: 1552782BAA64 | F42: USP1S81BAA64 | G42: BBVASM 2038 | H42: 5278 | I42: 2 | J42: 1000 | K42: 30555199 | L42: 9091374.2 | M42: 8200 | N42: 50585 | O42: 4563 | P42: 3.3609 | Q42: RENTA FIJA | R42: 30559802 | S42: 9088146.6 | T42: GBBV | U42: 2808249000000 | V42: 2500434000000 | W42: 307815000000 | X42: 0.393611 | Y42: =+MID(Tabla_Consulta_desde_Reporte_de_Valorización_de_Instrumentos6[[#This Row],[CODIGO_SBS]],7,1) -> 2 | Z42: =Tabla_Consulta_desde_Reporte_de_Valorización_de_Instrumentos6[[#This Row],[CODIGO_SBS]]&"-"&RIGHT(Tabla_Consulta_desde_Reporte_de_Valorización_de_Instrumentos6[[#This Row],[PORTAFOLIO]],1) -> 1552782BAA64-1 | AA42: Deuda corporativa directa - Internacional | AB42: Deuda | AC42: =Tabla_Consulta_desde_Reporte_de_Valorización_de_Instrumentos6[[#This Row],[VALOR_UNITARIO]]*Tabla_Consulta_desde_Reporte_de_Valorización_de_Instrumentos6[[#This Row],[CANTIDAD]] -> 8200000 | AD42: BBVA Bancomer | AE42: =_xlfn.IFNA(_xlfn.XLOOKUP(Tabla_Consulta_desde_Reporte_de_Valorización_de_Instrumentos6[[#This Row],[Emisor2]],'Parametria 2'!G:G,'Parametria 2'!F:F,_xlfn.XLOOKUP(Tabla_Consulta_desde_Reporte_de_Valorización_de_Instrumentos6[[#This Row],[Emisor2]],'Valorización de Instrumentos_of'!H:H,'Valorización de Instrumentos_of'!H:H)),_xlfn.XLOOKUP(Tabla_Consulta_desde_Reporte_de_Valorización_de_Instrumentos6[[#This Row],[TITULO]],'Parametria 2'!K:K,'Parametria 2'!L:L)) -> BBVA Bancomer
A43: 31/12/2025 | B43: 15 | C43: IN-FONDO2 | D43: OSX | E43: 1552782BAA64 | F43: USP1S81BAA64 | G43: BBVASM 2038 | H43: 5278 | I43: 2 | J43: 1000 | K43: 24965834 | L43: 7428317.9 | M43: 6700 | N43: 50585 | O43: 4563 | P43: 3.3609 | Q43: RENTA FIJA | R43: 24969594 | S43: 7425680.7 | T43: GBBV | U43: 2808249000000 | V43: 2500434000000 | W43: 307815000000 | X43: 0.393611 | Y43: =+MID(Tabla_Consulta_desde_Reporte_de_Valorización_de_Instrumentos6[[#This Row],[CODIGO_SBS]],7,1) -> 2 | Z43: =Tabla_Consulta_desde_Reporte_de_Valorización_de_Instrumentos6[[#This Row],[CODIGO_SBS]]&"-"&RIGHT(Tabla_Consulta_desde_Reporte_de_Valorización_de_Instrumentos6[[#This Row],[PORTAFOLIO]],1) -> 1552782BAA64-2 | AA43: Deuda corporativa directa - Internacional | AB43: Deuda | AC43: =Tabla_Consulta_desde_Reporte_de_Valorización_de_Instrumentos6[[#This Row],[VALOR_UNITARIO]]*Tabla_Consulta_desde_Reporte_de_Valorización_de_Instrumentos6[[#This Row],[CANTIDAD]] -> 6700000 | AD43: BBVA Bancomer | AE43: =_xlfn.IFNA(_xlfn.XLOOKUP(Tabla_Consulta_desde_Reporte_de_Valorización_de_Instrumentos6[[#This Row],[Emisor2]],'Parametria 2'!G:G,'Parametria 2'!F:F,_xlfn.XLOOKUP(Tabla_Consulta_desde_Reporte_de_Valorización_de_Instrumentos6[[#This Row],[Emisor2]],'Valorización de Instrumentos_of'!H:H,'Valorización de Instrumentos_of'!H:H)),_xlfn.XLOOKUP(Tabla_Consulta_desde_Reporte_de_Valorización_de_Instrumentos6[[#This Row],[TITULO]],'Parametria 2'!K:K,'Parametria 2'!L:L)) -> BBVA Bancomer
A44: 31/12/2025 | B44: 15 | C44: IN-FONDO2 | D44: OSX | E44: 15527829AM84 | F44: USP16259AM84 | G44: BBVA 2033 | H44: 5278 | I44: 2 | J44: 1000 | K44: 8467700 | L44: 2519474 | M44: 2500 | N44: 48597 | O44: 2575 | P44: 3.3609 | Q44: RENTA FIJA | R44: 8454457.9 | S44: 2514262.2 | T44: GBBV | U44: 2808249000000 | V44: 2500434000000 | W44: 307815000000 | X44: 2.084722 | Y44: =+MID(Tabla_Consulta_desde_Reporte_de_Valorización_de_Instrumentos6[[#This Row],[CODIGO_SBS]],7,1) -> 2 | Z44: =Tabla_Consulta_desde_Reporte_de_Valorización_de_Instrumentos6[[#This Row],[CODIGO_SBS]]&"-"&RIGHT(Tabla_Consulta_desde_Reporte_de_Valorización_de_Instrumentos6[[#This Row],[PORTAFOLIO]],1) -> 15527829AM84-2 | AA44: Deuda corporativa directa - Internacional | AB44: Deuda | AC44: =Tabla_Consulta_desde_Reporte_de_Valorización_de_Instrumentos6[[#This Row],[VALOR_UNITARIO]]*Tabla_Consulta_desde_Reporte_de_Valorización_de_Instrumentos6[[#This Row],[CANTIDAD]] -> 2500000 | AD44: BBVA Bancomer | AE44: =_xlfn.IFNA(_xlfn.XLOOKUP(Tabla_Consulta_desde_Reporte_de_Valorización_de_Instrumentos6[[#This Row],[Emisor2]],'Parametria 2'!G:G,'Parametria 2'!F:F,_xlfn.XLOOKUP(Tabla_Consulta_desde_Reporte_de_Valorización_de_Instrumentos6[[#This Row],[Emisor2]],'Valorización de Instrumentos_of'!H:H,'Valorización de Instrumentos_of'!H:H)),_xlfn.XLOOKUP(Tabla_Consulta_desde_Reporte_de_Valorización_de_Instrumentos6[[#This Row],[TITULO]],'Parametria 2'!K:K,'Parametria 2'!L:L)) -> BBVA Bancomer
A45: 31/12/2025 | B45: 15 | C45: IN-FONDO1 | D45: OSX | E45: 15527829AN67 | F45: USP16259AN67 | G45: BBVA 2034 | H45: 5278 | I45: 2 | J45: 1000 | K45: 16416058 | L45: 4884423.3 | M45: 4800 | N45: 49200 | O45: 3178 | P45: 3.3609 | Q45: RENTA FIJA | R45: 16381971 | S45: 4871816.7 | T45: GBBV | U45: 2808249000000 | V45: 2500434000000 | W45: 307815000000 | X45: 2.626388 | Y45: =+MID(Tabla_Consulta_desde_Reporte_de_Valorización_de_Instrumentos6[[#This Row],[CODIGO_SBS]],7,1) -> 2 | Z45: =Tabla_Consulta_desde_Reporte_de_Valorización_de_Instrumentos6[[#This Row],[CODIGO_SBS]]&"-"&RIGHT(Tabla_Consulta_desde_Reporte_de_Valorización_de_Instrumentos6[[#This Row],[PORTAFOLIO]],1) -> 15527829AN67-1 | AA45: Deuda corporativa directa - Internacional | AB45: Deuda | AC45: =Tabla_Consulta_desde_Reporte_de_Valorización_de_Instrumentos6[[#This Row],[VALOR_UNITARIO]]*Tabla_Consulta_desde_Reporte_de_Valorización_de_Instrumentos6[[#This Row],[CANTIDAD]] -> 4800000 | AD45: BBVA Bancomer | AE45: =_xlfn.IFNA(_xlfn.XLOOKUP(Tabla_Consulta_desde_Reporte_de_Valorización_de_Instrumentos6[[#This Row],[Emisor2]],'Parametria 2'!G:G,'Parametria 2'!F:F,_xlfn.XLOOKUP(Tabla_Consulta_desde_Reporte_de_Valorización_de_Instrumentos6[[#This Row],[Emisor2]],'Valorización de Instrumentos_of'!H:H,'Valorización de Instrumentos_of'!H:H)),_xlfn.XLOOKUP(Tabla_Consulta_desde_Reporte_de_Valorización_de_Instrumentos6[[#This Row],[TITULO]],'Parametria 2'!K:K,'Parametria 2'!L:L)) -> BBVA Bancomer
A46: 31/12/2025 | B46: 15 | C46: IN-FONDO2 | D46: OSX | E46: 15527829AN67 | F46: USP16259AN67 | G46: BBVA 2034 | H46: 5278 | I46: 2 | J46: 1000 | K46: 20520073 | L46: 6105529.2 | M46: 6000 | N46: 49200 | O46: 3178 | P46: 3.3609 | Q46: RENTA FIJA | R46: 20477463 | S46: 6089770.8 | T46: GBBV | U46: 2808249000000 | V46: 2500434000000 | W46: 307815000000 | X46: 2.626388 | Y46: =+MID(Tabla_Consulta_desde_Reporte_de_Valorización_de_Instrumentos6[[#This Row],[CODIGO_SBS]],7,1) -> 2 | Z46: =Tabla_Consulta_desde_Reporte_de_Valorización_de_Instrumentos6[[#This Row],[CODIGO_SBS]]&"-"&RIGHT(Tabla_Consulta_desde_Reporte_de_Valorización_de_Instrumentos6[[#This Row],[PORTAFOLIO]],1) -> 15527829AN67-2 | AA46: Deuda corporativa directa - Internacional | AB46: Deuda | AC46: =Tabla_Consulta_desde_Reporte_de_Valorización_de_Instrumentos6[[#This Row],[VALOR_UNITARIO]]*Tabla_Consulta_desde_Reporte_de_Valorización_de_Instrumentos6[[#This Row],[CANTIDAD]] -> 6000000 | AD46: BBVA Bancomer | AE46: =_xlfn.IFNA(_xlfn.XLOOKUP(Tabla_Consulta_desde_Reporte_de_Valorización_de_Instrumentos6[[#This Row],[Emisor2]],'Parametria 2'!G:G,'Parametria 2'!F:F,_xlfn.XLOOKUP(Tabla_Consulta_desde_Reporte_de_Valorización_de_Instrumentos6[[#This Row],[Emisor2]],'Valorización de Instrumentos_of'!H:H,'Valorización de Instrumentos_of'!H:H)),_xlfn.XLOOKUP(Tabla_Consulta_desde_Reporte_de_Valorización_de_Instrumentos6[[#This Row],[TITULO]],'Parametria 2'!K:K,'Parametria 2'!L:L)) -> BBVA Bancomer
A47: 31/12/2025 | B47: 15 | C47: IN-FONDO2 | D47: OSX | E47: 15528725AC15 | F47: USG42045AC15 | G47: AVALCB 4 3/8 02 | H47: 5287 | I47: 2 | J47: 1000 | K47: 3807145.4 | L47: 1132775.6 | M47: 1184 | N47: 47518 | O47: 1496 | P47: 3.3609 | Q47: RENTA FIJA | R47: 3808533.4 | S47: 1132615.7 | T47: GAVA | U47: 316615576000000 | V47: 284936353000000 | W47: 3.1679223e+13 | X47: 0.135055 | Y47: =+MID(Tabla_Consulta_desde_Reporte_de_Valorización_de_Instrumentos6[[#This Row],[CODIGO_SBS]],7,1) -> 2 | Z47: =Tabla_Consulta_desde_Reporte_de_Valorización_de_Instrumentos6[[#This Row],[CODIGO_SBS]]&"-"&RIGHT(Tabla_Consulta_desde_Reporte_de_Valorización_de_Instrumentos6[[#This Row],[PORTAFOLIO]],1) -> 15528725AC15-2 | AA47: Deuda corporativa directa - Internacional | AB47: Deuda | AC47: =Tabla_Consulta_desde_Reporte_de_Valorización_de_Instrumentos6[[#This Row],[VALOR_UNITARIO]]*Tabla_Consulta_desde_Reporte_de_Valorización_de_Instrumentos6[[#This Row],[CANTIDAD]] -> 1184000 | AD47: Grupo Aval Acciones y Valores | AE47: =_xlfn.IFNA(_xlfn.XLOOKUP(Tabla_Consulta_desde_Reporte_de_Valorización_de_Instrumentos6[[#This Row],[Emisor2]],'Parametria 2'!G:G,'Parametria 2'!F:F,_xlfn.XLOOKUP(Tabla_Consulta_desde_Reporte_de_Valorización_de_Instrumentos6[[#This Row],[Emisor2]],'Valorización de Instrumentos_of'!H:H,'Valorización de Instrumentos_of'!H:H)),_xlfn.XLOOKUP(Tabla_Consulta_desde_Reporte_de_Valorización_de_Instrumentos6[[#This Row],[TITULO]],'Parametria 2'!K:K,'Parametria 2'!L:L)) -> #N/A
A48: 31/12/2025 | B48: 15 | C48: IN-FONDO1 | D48: OSX | E48: 15532427PD99 | F48: USP0R137PD99 | G48: DAVIVI2035 | H48: 5324 | I48: 2 | J48: 1000 | K48: 41207481 | L48: 12260847 | M48: 11753 | N48: 48397 | O48: 2375 | P48: 3.3609 | Q48: RENTA FIJA | R48: 42836589 | S48: 12739127 | U48: 177149615000000 | V48: 161267686000000 | W48: 15881929000000 | X48: -40.694306 | Y48: =+MID(Tabla_Consulta_desde_Reporte_de_Valorización_de_Instrumentos6[[#This Row],[CODIGO_SBS]],7,1) -> 2 | Z48: =Tabla_Consulta_desde_Reporte_de_Valorización_de_Instrumentos6[[#This Row],[CODIGO_SBS]]&"-"&RIGHT(Tabla_Consulta_desde_Reporte_de_Valorización_de_Instrumentos6[[#This Row],[PORTAFOLIO]],1) -> 15532427PD99-1 | AA48: Deuda corporativa directa - Internacional | AB48: Deuda | AC48: =Tabla_Consulta_desde_Reporte_de_Valorización_de_Instrumentos6[[#This Row],[VALOR_UNITARIO]]*Tabla_Consulta_desde_Reporte_de_Valorización_de_Instrumentos6[[#This Row],[CANTIDAD]] -> 11753000 | AD48: Banco Davivienda S.A. | AE48: =_xlfn.IFNA(_xlfn.XLOOKUP(Tabla_Consulta_desde_Reporte_de_Valorización_de_Instrumentos6[[#This Row],[Emisor2]],'Parametria 2'!G:G,'Parametria 2'!F:F,_xlfn.XLOOKUP(Tabla_Consulta_desde_Reporte_de_Valorización_de_Instrumentos6[[#This Row],[Emisor2]],'Valorización de Instrumentos_of'!H:H,'Valorización de Instrumentos_of'!H:H)),_xlfn.XLOOKUP(Tabla_Consulta_desde_Reporte_de_Valorización_de_Instrumentos6[[#This Row],[TITULO]],'Parametria 2'!K:K,'Parametria 2'!L:L)) -> Banco Davivienda S.A.
A49: 31/12/2025 | B49: 15 | C49: IN-FONDO2 | D49: OSX | E49: 15532427PD99 | F49: USP0R137PD99 | G49: DAVIVI2035 | H49: 5324 | I49: 2 | J49: 1000 | K49: 24307961 | L49: 7232574.9 | M49: 6933 | N49: 48397 | O49: 2375 | P49: 3.3609 | Q49: RENTA FIJA | R49: 25268959 | S49: 7514708.6 | U49: 177149615000000 | V49: 161267686000000 | W49: 15881929000000 | X49: -40.694306 | Y49: =+MID(Tabla_Consulta_desde_Reporte_de_Valorización_de_Instrumentos6[[#This Row],[CODIGO_SBS]],7,1) -> 2 | Z49: =Tabla_Consulta_desde_Reporte_de_Valorización_de_Instrumentos6[[#This Row],[CODIGO_SBS]]&"-"&RIGHT(Tabla_Consulta_desde_Reporte_de_Valorización_de_Instrumentos6[[#This Row],[PORTAFOLIO]],1) -> 15532427PD99-2 | AA49: Deuda corporativa directa - Internacional | AB49: Deuda | AC49: =Tabla_Consulta_desde_Reporte_de_Valorización_de_Instrumentos6[[#This Row],[VALOR_UNITARIO]]*Tabla_Consulta_desde_Reporte_de_Valorización_de_Instrumentos6[[#This Row],[CANTIDAD]] -> 6933000 | AD49: Banco Davivienda S.A. | AE49: =_xlfn.IFNA(_xlfn.XLOOKUP(Tabla_Consulta_desde_Reporte_de_Valorización_de_Instrumentos6[[#This Row],[Emisor2]],'Parametria 2'!G:G,'Parametria 2'!F:F,_xlfn.XLOOKUP(Tabla_Consulta_desde_Reporte_de_Valorización_de_Instrumentos6[[#This Row],[Emisor2]],'Valorización de Instrumentos_of'!H:H,'Valorización de Instrumentos_of'!H:H)),_xlfn.XLOOKUP(Tabla_Consulta_desde_Reporte_de_Valorización_de_Instrumentos6[[#This Row],[TITULO]],'Parametria 2'!K:K,'Parametria 2'!L:L)) -> Banco Davivienda S.A.
A50: 31/12/2025 | B50: 15 | C50: IN-FONDO1 | D50: OSX | E50: 15515123CH47 | F50: USP32133CH47 | G50: BCICI 7 1/2 PE | H50: 5151 | I50: 2 | J50: 1000 | K50: 17937711 | L50: 5337175 | M50: 4920 | N50: 73121 | O50: 27099 | P50: 3.3609 | Q50: RENTA FIJA | R50: 17939891 | S50: 5335125 | U50: 0 | V50: 0 | W50: 0 | X50: 0.416667 | Y50: =+MID(Tabla_Consulta_desde_Reporte_de_Valorización_de_Instrumentos6[[#This Row],[CODIGO_SBS]],7,1) -> 2 | Z50: =Tabla_Consulta_desde_Reporte_de_Valorización_de_Instrumentos6[[#This Row],[CODIGO_SBS]]&"-"&RIGHT(Tabla_Consulta_desde_Reporte_de_Valorización_de_Instrumentos6[[#This Row],[PORTAFOLIO]],1) -> 15515123CH47-1 | AA50: Deuda corporativa directa - Internacional | AB50: Deuda | AC50: =Tabla_Consulta_desde_Reporte_de_Valorización_de_Instrumentos6[[#This Row],[VALOR_UNITARIO]]*Tabla_Consulta_desde_Reporte_de_Valorización_de_Instrumentos6[[#This Row],[CANTIDAD]] -> 4920000 | AD50: Banco de Crédito e Inversiones | AE50: =_xlfn.IFNA(_xlfn.XLOOKUP(Tabla_Consulta_desde_Reporte_de_Valorización_de_Instrumentos6[[#This Row],[Emisor2]],'Parametria 2'!G:G,'Parametria 2'!F:F,_xlfn.XLOOKUP(Tabla_Consulta_desde_Reporte_de_Valorización_de_Instrumentos6[[#This Row],[Emisor2]],'Valorización de Instrumentos_of'!H:H,'Valorización de Instrumentos_of'!H:H)),_xlfn.XLOOKUP(Tabla_Consulta_desde_Reporte_de_Valorización_de_Instrumentos6[[#This Row],[TITULO]],'Parametria 2'!K:K,'Parametria 2'!L:L)) -> Banco de Crédito e Inversiones
A51: 31/12/2025 | B51: 15 | C51: IN-FONDO1 | D51: OSX | E51: 1551112LAN29 | F51: US05968LAN29 | G51: BCOLO 2034 | H51: 5111 | I51: 2 | J51: 1000 | K51: 60957859 | L51: 18137362 | M51: 16900 | N51: 49302 | O51: 3280 | P51: 3.3609 | Q51: RENTA FIJA | R51: 60992718 | S51: 18138559 | U51: 338596669000000 | V51: 301098538000000 | W51: 37498131000000 | X51: -0.070833 | Y51: =+MID(Tabla_Consulta_desde_Reporte_de_Valorización_de_Instrumentos6[[#This Row],[CODIGO_SBS]],7,1) -> 2 | Z51: =Tabla_Consulta_desde_Reporte_de_Valorización_de_Instrumentos6[[#This Row],[CODIGO_SBS]]&"-"&RIGHT(Tabla_Consulta_desde_Reporte_de_Valorización_de_Instrumentos6[[#This Row],[PORTAFOLIO]],1) -> 1551112LAN29-1 | AA51: Deuda corporativa directa - Internacional | AB51: Deuda | AC51: =Tabla_Consulta_desde_Reporte_de_Valorización_de_Instrumentos6[[#This Row],[VALOR_UNITARIO]]*Tabla_Consulta_desde_Reporte_de_Valorización_de_Instrumentos6[[#This Row],[CANTIDAD]] -> 16900000 | AD51: Banco de Colombia | AE51: =_xlfn.IFNA(_xlfn.XLOOKUP(Tabla_Consulta_desde_Reporte_de_Valorización_de_Instrumentos6[[#This Row],[Emisor2]],'Parametria 2'!G:G,'Parametria 2'!F:F,_xlfn.XLOOKUP(Tabla_Consulta_desde_Reporte_de_Valorización_de_Instrumentos6[[#This Row],[Emisor2]],'Valorización de Instrumentos_of'!H:H,'Valorización de Instrumentos_of'!H:H)),_xlfn.XLOOKUP(Tabla_Consulta_desde_Reporte_de_Valorización_de_Instrumentos6[[#This Row],[TITULO]],'Parametria 2'!K:K,'Parametria 2'!L:L)) -> #N/A
A52: 31/12/2025 | B52: 15 | C52: IN-FONDO2 | D52: OSX | E52: 1551112LAN29 | F52: US05968LAN29 | G52: BCOLO 2034 | H52: 5111 | I52: 2 | J52: 1000 | K52: 48614794 | L52: 14464814 | M52: 13478 | N52: 49302 | O52: 3280 | P52: 3.3609 | Q52: RENTA FIJA | R52: 48642595 | S52: 14465769 | U52: 338596669000000 | V52: 301098538000000 | W52: 37498131000000 | X52: -0.070833 | Y52: =+MID(Tabla_Consulta_desde_Reporte_de_Valorización_de_Instrumentos6[[#This Row],[CODIGO_SBS]],7,1) -> 2 | Z52: =Tabla_Consulta_desde_Reporte_de_Valorización_de_Instrumentos6[[#This Row],[CODIGO_SBS]]&"-"&RIGHT(Tabla_Consulta_desde_Reporte_de_Valorización_de_Instrumentos6[[#This Row],[PORTAFOLIO]],1) -> 1551112LAN29-2 | AA52: Deuda corporativa directa - Internacional | AB52: Deuda | AC52: =Tabla_Consulta_desde_Reporte_de_Valorización_de_Instrumentos6[[#This Row],[VALOR_UNITARIO]]*Tabla_Consulta_desde_Reporte_de_Valorización_de_Instrumentos6[[#This Row],[CANTIDAD]] -> 13478000 | AD52: Banco de Colombia | AE52: =_xlfn.IFNA(_xlfn.XLOOKUP(Tabla_Consulta_desde_Reporte_de_Valorización_de_Instrumentos6[[#This Row],[Emisor2]],'Parametria 2'!G:G,'Parametria 2'!F:F,_xlfn.XLOOKUP(Tabla_Consulta_desde_Reporte_de_Valorización_de_Instrumentos6[[#This Row],[Emisor2]],'Valorización de Instrumentos_of'!H:H,'Valorización de Instrumentos_of'!H:H)),_xlfn.XLOOKUP(Tabla_Consulta_desde_Reporte_de_Valorización_de_Instrumentos6[[#This Row],[TITULO]],'Parametria 2'!K:K,'Parametria 2'!L:L)) -> #N/A
A53: 31/12/2025 | B53: 18 | C53: IN-FONDO1 | D53: BNP | E53: 182096345816 | F53: XS0799645816 | G53: IVPRB 6.45 06/3 | H53: 2096 | I53: 3 | J53: 1000 | K53: 21246157 | L53: 21246157 | M53: 18557 | N53: 50221 | O53: 4199 | P53: 1 | Q53: RENTA FIJA | R53: 21210902 | S53: 21210902 | U53: 4252869000 | V53: 3246804000 | W53: 1006065000 | X53: 1.899852 | Y53: =+MID(Tabla_Consulta_desde_Reporte_de_Valorización_de_Instrumentos6[[#This Row],[CODIGO_SBS]],7,1) -> 3 | Z53: =Tabla_Consulta_desde_Reporte_de_Valorización_de_Instrumentos6[[#This Row],[CODIGO_SBS]]&"-"&RIGHT(Tabla_Consulta_desde_Reporte_de_Valorización_de_Instrumentos6[[#This Row],[PORTAFOLIO]],1) -> 182096345816-1 | AA53: Titularización - Renta fija - Internacional | AB53: Deuda | AC53: =Tabla_Consulta_desde_Reporte_de_Valorización_de_Instrumentos6[[#This Row],[VALOR_UNITARIO]]*Tabla_Consulta_desde_Reporte_de_Valorización_de_Instrumentos6[[#This Row],[CANTIDAD]] -> 18557000 | AD53: Línea Amarilla S.A.C. | AE53: =_xlfn.IFNA(_xlfn.XLOOKUP(Tabla_Consulta_desde_Reporte_de_Valorización_de_Instrumentos6[[#This Row],[Emisor2]],'Parametria 2'!G:G,'Parametria 2'!F:F,_xlfn.XLOOKUP(Tabla_Consulta_desde_Reporte_de_Valorización_de_Instrumentos6[[#This Row],[Emisor2]],'Valorización de Instrumentos_of'!H:H,'Valorización de Instrumentos_of'!H:H)),_xlfn.XLOOKUP(Tabla_Consulta_desde_Reporte_de_Valorización_de_Instrumentos6[[#This Row],[TITULO]],'Parametria 2'!K:K,'Parametria 2'!L:L)) -> Lima Expresa
A54: 31/12/2025 | B54: 18 | C54: IN-FONDO2 | D54: BNP | E54: 182096345816 | F54: XS0799645816 | G54: IVPRB 6.45 06/3 | H54: 2096 | I54: 3 | J54: 1000 | K54: 2.4281781e+08 | L54: 2.4281781e+08 | M54: 212084 | N54: 50221 | O54: 4199 | P54: 1 | Q54: RENTA FIJA | R54: 2.4241488e+08 | S54: 2.4241488e+08 | U54: 4252869000 | V54: 3246804000 | W54: 1006065000 | X54: 1.899852 | Y54: =+MID(Tabla_Consulta_desde_Reporte_de_Valorización_de_Instrumentos6[[#This Row],[CODIGO_SBS]],7,1) -> 3 | Z54: =Tabla_Consulta_desde_Reporte_de_Valorización_de_Instrumentos6[[#This Row],[CODIGO_SBS]]&"-"&RIGHT(Tabla_Consulta_desde_Reporte_de_Valorización_de_Instrumentos6[[#This Row],[PORTAFOLIO]],1) -> 182096345816-2 | AA54: Titularización - Renta fija - Internacional | AB54: Deuda | AC54: =Tabla_Consulta_desde_Reporte_de_Valorización_de_Instrumentos6[[#This Row],[VALOR_UNITARIO]]*Tabla_Consulta_desde_Reporte_de_Valorización_de_Instrumentos6[[#This Row],[CANTIDAD]] -> 212084000 | AD54: Línea Amarilla S.A.C. | AE54: =_xlfn.IFNA(_xlfn.XLOOKUP(Tabla_Consulta_desde_Reporte_de_Valorización_de_Instrumentos6[[#This Row],[Emisor2]],'Parametria 2'!G:G,'Parametria 2'!F:F,_xlfn.XLOOKUP(Tabla_Consulta_desde_Reporte_de_Valorización_de_Instrumentos6[[#This Row],[Emisor2]],'Valorización de Instrumentos_of'!H:H,'Valorización de Instrumentos_of'!H:H)),_xlfn.XLOOKUP(Tabla_Consulta_desde_Reporte_de_Valorización_de_Instrumentos6[[#This Row],[TITULO]],'Parametria 2'!K:K,'Parametria 2'!L:L)) -> Lima Expresa
A55: 31/12/2025 | B55: 21 | C55: IN-FONDO1 | D55: BSF | E55: 21003811902A | F55: PEP12100D292 | G55: BIF3BS2A | H55: 0038 | I55: 1 | J55: 1000 | K55: 20536162 | L55: 20536162 | M55: 20000 | N55: 47177 | O55: 1155 | P55: 1 | Q55: RENTA FIJA | R55: 20535736 | S55: 20535736 | T55: GFIE | U55: 22149047000 | V55: 20355021000 | W55: 1794026000 | X55: 0.0212816 | Y55: =+MID(Tabla_Consulta_desde_Reporte_de_Valorización_de_Instrumentos6[[#This Row],[CODIGO_SBS]],7,1) -> 1 | Z55: =Tabla_Consulta_desde_Reporte_de_Valorización_de_Instrumentos6[[#This Row],[CODIGO_SBS]]&"-"&RIGHT(Tabla_Consulta_desde_Reporte_de_Valorización_de_Instrumentos6[[#This Row],[PORTAFOLIO]],1) -> 21003811902A-1 | AA55: Deuda corporativa directa - Local | AB55: Deuda | AC55: =Tabla_Consulta_desde_Reporte_de_Valorización_de_Instrumentos6[[#This Row],[VALOR_UNITARIO]]*Tabla_Consulta_desde_Reporte_de_Valorización_de_Instrumentos6[[#This Row],[CANTIDAD]] -> 20000000 | AD55: Banco Interamericano de Finanzas | AE55: =_xlfn.IFNA(_xlfn.XLOOKUP(Tabla_Consulta_desde_Reporte_de_Valorización_de_Instrumentos6[[#This Row],[Emisor2]],'Parametria 2'!G:G,'Parametria 2'!F:F,_xlfn.XLOOKUP(Tabla_Consulta_desde_Reporte_de_Valorización_de_Instrumentos6[[#This Row],[Emisor2]],'Valorización de Instrumentos_of'!H:H,'Valorización de Instrumentos_of'!H:H)),_xlfn.XLOOKUP(Tabla_Consulta_desde_Reporte_de_Valorización_de_Instrumentos6[[#This Row],[TITULO]],'Parametria 2'!K:K,'Parametria 2'!L:L)) -> Banbif
A56: 31/12/2025 | B56: 21 | C56: IN-FONDO2 | D56: BSF | E56: 21003811902A | F56: PEP12100D292 | G56: BIF3BS2A | H56: 0038 | I56: 1 | J56: 1000 | K56: 5134040.5 | L56: 5134040.5 | M56: 5000 | N56: 47177 | O56: 1155 | P56: 1 | Q56: RENTA FIJA | R56: 5133934 | S56: 5133934 | T56: GFIE | U56: 22149047000 | V56: 20355021000 | W56: 1794026000 | X56: 0.0212816 | Y56: =+MID(Tabla_Consulta_desde_Reporte_de_Valorización_de_Instrumentos6[[#This Row],[CODIGO_SBS]],7,1) -> 1 | Z56: =Tabla_Consulta_desde_Reporte_de_Valorización_de_Instrumentos6[[#This Row],[CODIGO_SBS]]&"-"&RIGHT(Tabla_Consulta_desde_Reporte_de_Valorización_de_Instrumentos6[[#This Row],[PORTAFOLIO]],1) -> 21003811902A-2 | AA56: Deuda corporativa directa - Local | AB56: Deuda | AC56: =Tabla_Consulta_desde_Reporte_de_Valorización_de_Instrumentos6[[#This Row],[VALOR_UNITARIO]]*Tabla_Consulta_desde_Reporte_de_Valorización_de_Instrumentos6[[#This Row],[CANTIDAD]] -> 5000000 | AD56: Banco Interamericano de Finanzas | AE56: =_xlfn.IFNA(_xlfn.XLOOKUP(Tabla_Consulta_desde_Reporte_de_Valorización_de_Instrumentos6[[#This Row],[Emisor2]],'Parametria 2'!G:G,'Parametria 2'!F:F,_xlfn.XLOOKUP(Tabla_Consulta_desde_Reporte_de_Valorización_de_Instrumentos6[[#This Row],[Emisor2]],'Valorización de Instrumentos_of'!H:H,'Valorización de Instrumentos_of'!H:H)),_xlfn.XLOOKUP(Tabla_Consulta_desde_Reporte_de_Valorización_de_Instrumentos6[[#This Row],[TITULO]],'Parametria 2'!K:K,'Parametria 2'!L:L)) -> Banbif
A57: 31/12/2025 | B57: 21 | C57: IN-FONDO2 | D57: BSF | E57: 21001811601A | F57: PEP12030D010 | G57: BN1BS1A | H57: 0018 | I57: 1 | J57: 1000 | K57: 5479726.5 | L57: 5479726.5 | M57: 5176 | N57: 48182 | O57: 2160 | P57: 1 | Q57: RENTA FIJA | R57: 5482093.3 | S57: 5482093.3 | U57: 47334882000 | V57: 43945418000 | W57: 3389464000 | X57: -0.4572594 | Y57: =+MID(Tabla_Consulta_desde_Reporte_de_Valorización_de_Instrumentos6[[#This Row],[CODIGO_SBS]],7,1) -> 1 | Z57: =Tabla_Consulta_desde_Reporte_de_Valorización_de_Instrumentos6[[#This Row],[CODIGO_SBS]]&"-"&RIGHT(Tabla_Consulta_desde_Reporte_de_Valorización_de_Instrumentos6[[#This Row],[PORTAFOLIO]],1) -> 21001811601A-2 | AA57: Deuda corporativa directa - Local | AB57: Deuda | AC57: =Tabla_Consulta_desde_Reporte_de_Valorización_de_Instrumentos6[[#This Row],[VALOR_UNITARIO]]*Tabla_Consulta_desde_Reporte_de_Valorización_de_Instrumentos6[[#This Row],[CANTIDAD]] -> 5176000 | AD57: Banco de la Nación | AE57: =_xlfn.IFNA(_xlfn.XLOOKUP(Tabla_Consulta_desde_Reporte_de_Valorización_de_Instrumentos6[[#This Row],[Emisor2]],'Parametria 2'!G:G,'Parametria 2'!F:F,_xlfn.XLOOKUP(Tabla_Consulta_desde_Reporte_de_Valorización_de_Instrumentos6[[#This Row],[Emisor2]],'Valorización de Instrumentos_of'!H:H,'Valorización de Instrumentos_of'!H:H)),_xlfn.XLOOKUP(Tabla_Consulta_desde_Reporte_de_Valorización_de_Instrumentos6[[#This Row],[TITULO]],'Parametria 2'!K:K,'Parametria 2'!L:L)) -> Banco de la Nación
A58: 31/12/2025 | B58: 21 | C58: IN-FONDO1 | D58: BSF | E58: 2100022V2H78 | F58: US05971V2H78 | G58: BCP 5.8 03/10/2 | H58: 0002 | I58: 2 | J58: 1000 | K58: 50270495 | L58: 14957451 | M58: 14479 | N58: 49378 | O58: 3356 | P58: 3.3609 | Q58: RENTA FIJA | R58: 50280235 | S58: 14952785 | T58: CCOR | U58: 187469765000 | V58: 164938084000 | W58: 22531681000 | X58: 0.322222 | Y58: =+MID(Tabla_Consulta_desde_Reporte_de_Valorización_de_Instrumentos6[[#This Row],[CODIGO_SBS]],7,1) -> 2 | Z58: =Tabla_Consulta_desde_Reporte_de_Valorización_de_Instrumentos6[[#This Row],[CODIGO_SBS]]&"-"&RIGHT(Tabla_Consulta_desde_Reporte_de_Valorización_de_Instrumentos6[[#This Row],[PORTAFOLIO]],1) -> 2100022V2H78-1 | AA58: Deuda corporativa directa - Internacional | AB58: Deuda | AC58: =Tabla_Consulta_desde_Reporte_de_Valorización_de_Instrumentos6[[#This Row],[VALOR_UNITARIO]]*Tabla_Consulta_desde_Reporte_de_Valorización_de_Instrumentos6[[#This Row],[CANTIDAD]] -> 14479000 | AD58: Banco de Crédito del Perú | AE58: =_xlfn.IFNA(_xlfn.XLOOKUP(Tabla_Consulta_desde_Reporte_de_Valorización_de_Instrumentos6[[#This Row],[Emisor2]],'Parametria 2'!G:G,'Parametria 2'!F:F,_xlfn.XLOOKUP(Tabla_Consulta_desde_Reporte_de_Valorización_de_Instrumentos6[[#This Row],[Emisor2]],'Valorización de Instrumentos_of'!H:H,'Valorización de Instrumentos_of'!H:H)),_xlfn.XLOOKUP(Tabla_Consulta_desde_Reporte_de_Valorización_de_Instrumentos6[[#This Row],[TITULO]],'Parametria 2'!K:K,'Parametria 2'!L:L)) -> Banco de Crédito del Perú
A59: 31/12/2025 | B59: 21 | C59: IN-FONDO2 | D59: BSF | E59: 2100022V2H78 | F59: US05971V2H78 | G59: BCP 5.8 03/10/2 | H59: 0002 | I59: 2 | J59: 1000 | K59: 1.0032226e+08 | L59: 29849819 | M59: 28895 | N59: 49378 | O59: 3356 | P59: 3.3609 | Q59: RENTA FIJA | R59: 1.0034169e+08 | S59: 29840509 | T59: CCOR | U59: 187469765000 | V59: 164938084000 | W59: 22531681000 | X59: 0.322222 | Y59: =+MID(Tabla_Consulta_desde_Reporte_de_Valorización_de_Instrumentos6[[#This Row],[CODIGO_SBS]],7,1) -> 2 | Z59: =Tabla_Consulta_desde_Reporte_de_Valorización_de_Instrumentos6[[#This Row],[CODIGO_SBS]]&"-"&RIGHT(Tabla_Consulta_desde_Reporte_de_Valorización_de_Instrumentos6[[#This Row],[PORTAFOLIO]],1) -> 2100022V2H78-2 | AA59: Deuda corporativa directa - Internacional | AB59: Deuda | AC59: =Tabla_Consulta_desde_Reporte_de_Valorización_de_Instrumentos6[[#This Row],[VALOR_UNITARIO]]*Tabla_Consulta_desde_Reporte_de_Valorización_de_Instrumentos6[[#This Row],[CANTIDAD]] -> 28895000 | AD59: Banco de Crédito del Perú | AE59: =_xlfn.IFNA(_xlfn.XLOOKUP(Tabla_Consulta_desde_Reporte_de_Valorización_de_Instrumentos6[[#This Row],[Emisor2]],'Parametria 2'!G:G,'Parametria 2'!F:F,_xlfn.XLOOKUP(Tabla_Consulta_desde_Reporte_de_Valorización_de_Instrumentos6[[#This Row],[Emisor2]],'Valorización de Instrumentos_of'!H:H,'Valorización de Instrumentos_of'!H:H)),_xlfn.XLOOKUP(Tabla_Consulta_desde_Reporte_de_Valorización_de_Instrumentos6[[#This Row],[TITULO]],'Parametria 2'!K:K,'Parametria 2'!L:L)) -> Banco de Crédito del Perú
A60: 31/12/2025 | B60: 21 | C60: IN-FONDO1 | D60: BSF | E60: 2100022V2J35 | F60: US05971V2J35 | G60: BCP2035 | H60: 0002 | I60: 2 | J60: 1000 | K60: 6913698 | L60: 2057097.2 | M60: 1923 | N60: 49520 | O60: 3498 | P60: 3.3609 | Q60: RENTA FIJA | R60: 6914878 | S60: 2056408.1 | T60: CCOR | U60: 187469765000 | V60: 164938084000 | W60: 22531681000 | X60: 0.358333 | Y60: =+MID(Tabla_Consulta_desde_Reporte_de_Valorización_de_Instrumentos6[[#This Row],[CODIGO_SBS]],7,1) -> 2 | Z60: =Tabla_Consulta_desde_Reporte_de_Valorización_de_Instrumentos6[[#This Row],[CODIGO_SBS]]&"-"&RIGHT(Tabla_Consulta_desde_Reporte_de_Valorización_de_Instrumentos6[[#This Row],[PORTAFOLIO]],1) -> 2100022V2J35-1 | AA60: Deuda corporativa directa - Internacional | AB60: Deuda | AC60: =Tabla_Consulta_desde_Reporte_de_Valorización_de_Instrumentos6[[#This Row],[VALOR_UNITARIO]]*Tabla_Consulta_desde_Reporte_de_Valorización_de_Instrumentos6[[#This Row],[CANTIDAD]] -> 1923000 | AD60: Banco de Crédito del Perú | AE60: =_xlfn.IFNA(_xlfn.XLOOKUP(Tabla_Consulta_desde_Reporte_de_Valorización_de_Instrumentos6[[#This Row],[Emisor2]],'Parametria 2'!G:G,'Parametria 2'!F:F,_xlfn.XLOOKUP(Tabla_Consulta_desde_Reporte_de_Valorización_de_Instrumentos6[[#This Row],[Emisor2]],'Valorización de Instrumentos_of'!H:H,'Valorización de Instrumentos_of'!H:H)),_xlfn.XLOOKUP(Tabla_Consulta_desde_Reporte_de_Valorización_de_Instrumentos6[[#This Row],[TITULO]],'Parametria 2'!K:K,'Parametria 2'!L:L)) -> Banco de Crédito del Perú
A61: 31/12/2025 | B61: 21 | C61: IN-FONDO2 | D61: BSF | E61: 2100022V2J35 | F61: US05971V2J35 | G61: BCP2035 | H61: 0002 | I61: 2 | J61: 1000 | K61: 26964501 | L61: 8023000 | M61: 7500 | N61: 49520 | O61: 3498 | P61: 3.3609 | Q61: RENTA FIJA | R61: 26969103 | S61: 8020312.5 | T61: CCOR | U61: 187469765000 | V61: 164938084000 | W61: 22531681000 | X61: 0.358333 | Y61: =+MID(Tabla_Consulta_desde_Reporte_de_Valorización_de_Instrumentos6[[#This Row],[CODIGO_SBS]],7,1) -> 2 | Z61: =Tabla_Consulta_desde_Reporte_de_Valorización_de_Instrumentos6[[#This Row],[CODIGO_SBS]]&"-"&RIGHT(Tabla_Consulta_desde_Reporte_de_Valorización_de_Instrumentos6[[#This Row],[PORTAFOLIO]],1) -> 2100022V2J35-2 | AA61: Deuda corporativa directa - Internacional | AB61: Deuda | AC61: =Tabla_Consulta_desde_Reporte_de_Valorización_de_Instrumentos6[[#This Row],[VALOR_UNITARIO]]*Tabla_Consulta_desde_Reporte_de_Valorización_de_Instrumentos6[[#This Row],[CANTIDAD]] -> 7500000 | AD61: Banco de Crédito del Perú | AE61: =_xlfn.IFNA(_xlfn.XLOOKUP(Tabla_Consulta_desde_Reporte_de_Valorización_de_Instrumentos6[[#This Row],[Emisor2]],'Parametria 2'!G:G,'Parametria 2'!F:F,_xlfn.XLOOKUP(Tabla_Consulta_desde_Reporte_de_Valorización_de_Instrumentos6[[#This Row],[Emisor2]],'Valorización de Instrumentos_of'!H:H,'Valorización de Instrumentos_of'!H:H)),_xlfn.XLOOKUP(Tabla_Consulta_desde_Reporte_de_Valorización_de_Instrumentos6[[#This Row],[TITULO]],'Parametria 2'!K:K,'Parametria 2'!L:L)) -> Banco de Crédito del Perú
A62: 31/12/2025 | B62: 27 | C62: IN-FONDO1 | D62: TCDC | E62: 2721181IRC1U | F62: CVL80070P015 | G62: INRT4.90 | H62: 2118 | I62: 1 | J62: 10000 | K62: 42788373 | L62: 42788373 | M62: 4300 | N62: 46827 | O62: 805 | P62: 1 | Q62: RENTA FIJA | R62: 42794239 | S62: 42794239 | T62: GITC | U62: 15587660000 | V62: 12914429000 | W62: 2673231000 | X62: -1.3640716 | Y62: =+MID(Tabla_Consulta_desde_Reporte_de_Valorización_de_Instrumentos6[[#This Row],[CODIGO_SBS]],7,1) -> 1 | Z62: =Tabla_Consulta_desde_Reporte_de_Valorización_de_Instrumentos6[[#This Row],[CODIGO_SBS]]&"-"&RIGHT(Tabla_Consulta_desde_Reporte_de_Valorización_de_Instrumentos6[[#This Row],[PORTAFOLIO]],1) -> 2721181IRC1U-1 | AA62: Titularización - Renta fija - Internacional | AB62: Deuda | AC62: =Tabla_Consulta_desde_Reporte_de_Valorización_de_Instrumentos6[[#This Row],[VALOR_UNITARIO]]*Tabla_Consulta_desde_Reporte_de_Valorización_de_Instrumentos6[[#This Row],[CANTIDAD]] -> 43000000 | AD62: SINT1INR1U - InRetail | AE62: =_xlfn.IFNA(_xlfn.XLOOKUP(Tabla_Consulta_desde_Reporte_de_Valorización_de_Instrumentos6[[#This Row],[Emisor2]],'Parametria 2'!G:G,'Parametria 2'!F:F,_xlfn.XLOOKUP(Tabla_Consulta_desde_Reporte_de_Valorización_de_Instrumentos6[[#This Row],[Emisor2]],'Valorización de Instrumentos_of'!H:H,'Valorización de Instrumentos_of'!H:H)),_xlfn.XLOOKUP(Tabla_Consulta_desde_Reporte_de_Valorización_de_Instrumentos6[[#This Row],[TITULO]],'Parametria 2'!K:K,'Parametria 2'!L:L)) -> InRetail Consumer
A63: 31/12/2025 | B63: 27 | C63: IN-FONDO2 | D63: TCDC | E63: 2721181IRC1U | F63: CVL80070P015 | G63: INRT4.90 | H63: 2118 | I63: 1 | J63: 10000 | K63: 1.2637496e+08 | L63: 1.2637496e+08 | M63: 12700 | N63: 46827 | O63: 805 | P63: 1 | Q63: RENTA FIJA | R63: 1.2639229e+08 | S63: 1.2639229e+08 | T63: GITC | U63: 15587660000 | V63: 12914429000 | W63: 2673231000 | X63: -1.3640716 | Y63: =+MID(Tabla_Consulta_desde_Reporte_de_Valorización_de_Instrumentos6[[#This Row],[CODIGO_SBS]],7,1) -> 1 | Z63: =Tabla_Consulta_desde_Reporte_de_Valorización_de_Instrumentos6[[#This Row],[CODIGO_SBS]]&"-"&RIGHT(Tabla_Consulta_desde_Reporte_de_Valorización_de_Instrumentos6[[#This Row],[PORTAFOLIO]],1) -> 2721181IRC1U-2 | AA63: Titularización - Renta fija - Internacional | AB63: Deuda | AC63: =Tabla_Consulta_desde_Reporte_de_Valorización_de_Instrumentos6[[#This Row],[VALOR_UNITARIO]]*Tabla_Consulta_desde_Reporte_de_Valorización_de_Instrumentos6[[#This Row],[CANTIDAD]] -> 127000000 | AD63: SINT1INR1U - InRetail | AE63: =_xlfn.IFNA(_xlfn.XLOOKUP(Tabla_Consulta_desde_Reporte_de_Valorización_de_Instrumentos6[[#This Row],[Emisor2]],'Parametria 2'!G:G,'Parametria 2'!F:F,_xlfn.XLOOKUP(Tabla_Consulta_desde_Reporte_de_Valorización_de_Instrumentos6[[#This Row],[Emisor2]],'Valorización de Instrumentos_of'!H:H,'Valorización de Instrumentos_of'!H:H)),_xlfn.XLOOKUP(Tabla_Consulta_desde_Reporte_de_Valorización_de_Instrumentos6[[#This Row],[TITULO]],'Parametria 2'!K:K,'Parametria 2'!L:L)) -> InRetail Consumer
...

Sheet Parametria 2
A1: Emisor2 | C1: Nombre (G&P) | F1: Nombre (G&P) | G1: Emisor2 | O1: Emisor | P1: AUM
A2: Gobierno Central | C2: Gobierno Central | F2: Aenza | G2: Graña y Montero S.A.A. | K2: MIBAN5CD1A | L2: MiBanco | O2: Banbif | P2: =SUMIF('Valorización de Instrumentos'!AE:AE,'Parametria 2'!O2,'Valorización de Instrumentos'!K:K) -> 1.442558e+08
A3: Gobierno de Chile | C3: Carlyle Peru | F3: Alicorp | G3: Alicorp S.A. | K3: COMPA3CD3B | L3: Compartamos Banco | O3: Banco de la Nación | P3: =SUMIF('Valorización de Instrumentos'!AE:AE,'Parametria 2'!O3,'Valorización de Instrumentos'!K:K) -> 5479726.5
A4: Gobierno de Brasil | C4: Macro Infraestructura | F4: Alicorp | G4: Alicorp | K4: COMPF3CD3A | L4: Compartamos Banco | O4: Jockey Plaza | P4: =SUMIF('Valorización de Instrumentos'!AE:AE,'Parametria 2'!O4,'Valorización de Instrumentos'!K:K) -> 57157116
A5: Gobierno de Colombia | C5: BD Senior Loans | F5: Auna | G5: AUNA SA | K5: INTER2CD1E | L5: Interbank | O5: Primax | P5: =SUMIF('Valorización de Instrumentos'!AE:AE,'Parametria 2'!O5,'Valorización de Instrumentos'!K:K) -> 51254539
A6: Gobierno de México | C6: Sigma - Leasing Operativo | F6: BBVA | G6: Banco Continental | K6: INTER2CD1D | L6: Interbank | O6: Hermes | P6: =SUMIF('Valorización de Instrumentos'!AE:AE,'Parametria 2'!O6,'Valorización de Instrumentos'!K:K) -> 6957636.3
