Workbook
Name IQ_CH: 110000
Name IQ_CQ: 5000
Name IQ_CY: 10000
Name IQ_DAILY: 500000
Name IQ_FH: 100000
Name IQ_FQ: 500
Name IQ_FY: 1000
Name IQ_LTM: 2000
Name IQ_MONTH: 15000
Name IQ_NTM: 6000
Name IQ_WEEK: 50000
Name IQ_YTD: 3000

Sheet LEEME
A1: BASE DE DATOS HISTORICA DE JUNTAS DE ACCIONISTAS - AFP Integra
A3: Este archivo es el historico consolidado de TODOS los anios. Nunca se reemplaza ni se versiona por anio.
A4: Ubicacion: Z:\Mesa de Inversiones\Bottom-Up\0 Juntas de Accionistas\Dashboard Python
A6: QUIEN ESCRIBE QUE
A7: Los analistas NO escriben aqui. Escriben en el archivo del anio (Propuestas_JGA_AAAA.xlsx).
A8: El script etl_juntas.py trae esa data a este archivo. Se puede correr las veces que haga falta.
A9: El responsable de la BD (Bottom-Up) completa a mano lo que el ETL no puede saber:
A10: Director, Independencia, Especialidad_1 y Especialidad_2. El ETL NUNCA pisa esas 4 columnas.
A12: HOJAS
A13: Juntas 1 fila por junta. Datos logisticos: fecha, hora, medio, acta, responsable.
A14: Registro 1 fila por punto de agenda votado. Es la tabla que alimenta los charts.
A15: Parametria Empresas del universo. Aqui se corrige el Sector cuando el ETL marca POR CLASIFICAR.
... A34: 6. Publicado el reporte, marcar Estado = Cerrado en esas filas.

Sheet Juntas
A1: Junta_ID | B1: Empresa | C1: Tipo_Junta | D1: Fecha | E1: Hora | F1: Medio | G1: Estado_Acta | H1: Responsable | I1: Asistencia | J1: Observaciones | K1: Sector | L1: Anio | M1: Trimestre | N1: Origen | O1: Cargado_El | P1: Estado | Q1: Editado_A_Mano
A2: VOLCAN|20260326|JOA | B2: Volcan | C2: JOA | D2: 46107 | E2: 10:00 | F2: Virtual | G2: Pendiente | H2: RMN | I2: Asistimos | J2: EJEMPLO - borrar | K2: =IF($B2="","",IFERROR(INDEX(Parametria!$C$4:$C$400,MATCH($B2,Parametria!$A$4:$A$400,0)),"SIN SECTOR")) -> Metales y Mineria | L2: =IF($D2="","",YEAR($D2)) -> 2026 | M2: =IF($D2="","","T"&ROUNDUP(MONTH($D2)/3,0)) -> T1 | N2: MANUAL | P2: Borrador | Q2: NO
A3: VOLCAN|20260610|JGA | B3: Volcan | C3: JGA | D3: 46183 | E3: 10:00 | F3: Virtual | G3: Pendiente | H3: RMN | I3: Asistimos | J3: EJEMPLO - borrar | K3: =IF($B3="","",IFERROR(INDEX(Parametria!$C$4:$C$400,MATCH($B3,Parametria!$A$4:$A$400,0)),"SIN SECTOR")) -> Metales y Mineria | L3: =IF($D3="","",YEAR($D3)) -> 2026 | M3: =IF($D3="","","T"&ROUNDUP(MONTH($D3)/3,0)) -> T2 | N3: ETL | O3: 2026-07-20 14:43 | P3: Borrador | Q3: NO
A4: BVN|20260326|JOA | B4: Cia. de Minas Buenaventura | C4: JOA | D4: 46107 | E4: 10:00 | F4: Virtual | G4: Pendiente | H4: RMN | I4: Asistimos | J4: EJEMPLO - borrar | K4: =IF($B4="","",IFERROR(INDEX(Parametria!$C$4:$C$400,MATCH($B4,Parametria!$A$4:$A$400,0)),"SIN SECTOR")) -> Metales y Mineria | L4: =IF($D4="","",YEAR($D4)) -> 2026 | M4: =IF($D4="","","T"&ROUNDUP(MONTH($D4)/3,0)) -> T1 | N4: ETL | O4: 2026-07-20 14:43 | P4: Borrador
K5: =IF($B5="","",IFERROR(INDEX(Parametria!$C$4:$C$400,MATCH($B5,Parametria!$A$4:$A$400,0)),"SIN SECTOR")) | L5: =IF($D5="","",YEAR($D5)) | M5: =IF($D5="","","T"&ROUNDUP(MONTH($D5)/3,0))
K6: =IF($B6="","",IFERROR(INDEX(Parametria!$C$4:$C$400,MATCH($B6,Parametria!$A$4:$A$400,0)),"SIN SECTOR")) | L6: =IF($D6="","",YEAR($D6)) | M6: =IF($D6="","","T"&ROUNDUP(MONTH($D6)/3,0))
K7: =IF($B7="","",IFERROR(INDEX(Parametria!$C$4:$C$400,MATCH($B7,Parametria!$A$4:$A$400,0)),"SIN SECTOR")) | L7: =IF($D7="","",YEAR($D7)) | M7: =IF($D7="","","T"&ROUNDUP(MONTH($D7)/3,0))
K8: =IF($B8="","",IFERROR(INDEX(Parametria!$C$4:$C$400,MATCH($B8,Parametria!$A$4:$A$400,0)),"SIN SECTOR")) | L8: =IF($D8="","",YEAR($D8)) | M8: =IF($D8="","","T"&ROUNDUP(MONTH($D8)/3,0))
K9: =IF($B9="","",IFERROR(INDEX(Parametria!$C$4:$C$400,MATCH($B9,Parametria!$A$4:$A$400,0)),"SIN SECTOR")) | L9: =IF($D9="","",YEAR($D9)) | M9: =IF($D9="","","T"&ROUNDUP(MONTH($D9)/3,0))
K10: =IF($B10="","",IFERROR(INDEX(Parametria!$C$4:$C$400,MATCH($B10,Parametria!$A$4:$A$400,0)),"SIN SECTOR")) | L10: =IF($D10="","",YEAR($D10)) | M10: =IF($D10="","","T"&ROUNDUP(MONTH($D10)/3,0))
K11: =IF($B11="","",IFERROR(INDEX(Parametria!$C$4:$C$400,MATCH($B11,Parametria!$A$4:$A$400,0)),"SIN SECTOR")) | L11: =IF($D11="","",YEAR($D11)) | M11: =IF($D11="","","T"&ROUNDUP(MONTH($D11)/3,0))
K12: =IF($B12="","",IFERROR(INDEX(Parametria!$C$4:$C$400,MATCH($B12,Parametria!$A$4:$A$400,0)),"SIN SECTOR")) | L12: =IF($D12="","",YEAR($D12)) | M12: =IF($D12="","","T"&ROUNDUP(MONTH($D12)/3,0))
K13: =IF($B13="","",IFERROR(INDEX(Parametria!$C$4:$C$400,MATCH($B13,Parametria!$A$4:$A$400,0)),"SIN SECTOR")) | L13: =IF($D13="","",YEAR($D13)) | M13: =IF($D13="","","T"&ROUNDUP(MONTH($D13)/3,0))
K14: =IF($B14="","",IFERROR(INDEX(Parametria!$C$4:$C$400,MATCH($B14,Parametria!$A$4:$A$400,0)),"SIN SECTOR")) | L14: =IF($D14="","",YEAR($D14)) | M14: =IF($D14="","","T"&ROUNDUP(MONTH($D14)/3,0))
K15: =IF($B15="","",IFERROR(INDEX(Parametria!$C$4:$C$400,MATCH($B15,Parametria!$A$4:$A$400,0)),"SIN SECTOR")) | L15: =IF($D15="","",YEAR($D15)) | M15: =IF($D15="","","T"&ROUNDUP(MONTH($D15)/3,0))
K16: =IF($B16="","",IFERROR(INDEX(Parametria!$C$4:$C$400,MATCH($B16,Parametria!$A$4:$A$400,0)),"SIN SECTOR")) | L16: =IF($D16="","",YEAR($D16)) | M16: =IF($D16="","","T"&ROUNDUP(MONTH($D16)/3,0))
... K5000: =IF($B5000="","",IFERROR(INDEX(Parametria!$C$4:$C$400,MATCH($B5000,Parametria!$A$4:$A$400,0)),"SIN SECTOR")) | L5000: =IF($D5000="","",YEAR($D5000)) | M5000: =IF($D5000="","","T"&ROUNDUP(MONTH($D5000)/3,0))

Sheet Registro
A1: Empresa | B1: Tipo_Junta | C1: Fecha | D1: Punto | E1: Texto_Agenda | F1: Tema | G1: Decision | H1: Motivo_Contra | I1: Justificacion | J1: Director | K1: Independencia | L1: Especialidad_1 | M1: Especialidad_2 | N1: Firma_Auditora | O1: Pct_Aprobacion | P1: Responsable | Q1: Comentario | R1: Junta_ID | S1: Punto_UID | T1: Sector | U1: Anio | V1: Trimestre | W1: Es_Director | X1: Origen | Y1: Cargado_El | Z1: Estado | AA1: Editado_A_Mano
A2: Union Andina de Cementos | B2: JOA | C2: 45747 | D2: 01 | E2: Reporte Integrado, que contiene la Memoria del Directorio del Ejercicio 2024; y Estados Financieros Auditados del Ejercicio 2024. | F2: Gestion Social (EEFF, Memoria) | G2: A Favor | R2: =IF($A2="","",IFERROR(INDEX(Parametria!$B$4:$B$400,MATCH($A2,Parametria!$A$4:$A$400,0)),"?")&"|"&TEXT($C2,"yyyymmdd")&"|"&$B2) -> UNACEM|20250331|JOA | S2: =IF($A2="","",$R2&"|"&$D2) -> UNACEM|20250331|JOA|01 | T2: =IF($A2="","",IFERROR(INDEX(Parametria!$C$4:$C$400,MATCH($A2,Parametria!$A$4:$A$400,0)),"SIN SECTOR")) -> Industriales y Construccion | U2: =IF($C2="","",YEAR($C2)) -> 2025 | V2: =IF($C2="","","T"&ROUNDUP(MONTH($C2)/3,0)) -> T1 | W2: =IF($A2="","",IF($J2="","NO","SI")) -> NO | X2: MIGRACION | Y2: 2026-07-20 19:54 | Z2: Revisado | AA2: NO
A3: Union Andina de Cementos | B3: JOA | C3: 45747 | D3: 02 | E3: Reporte de los Avances en Sostenibilidad del Grupo UNACEM. | F3: ASG | G3: Informativo | R3: =IF($A3="","",IFERROR(INDEX(Parametria!$B$4:$B$400,MATCH($A3,Parametria!$A$4:$A$400,0)),"?")&"|"&TEXT($C3,"yyyymmdd")&"|"&$B3) -> UNACEM|20250331|JOA | S3: =IF($A3="","",$R3&"|"&$D3) -> UNACEM|20250331|JOA|02 | T3: =IF($A3="","",IFERROR(INDEX(Parametria!$C$4:$C$400,MATCH($A3,Parametria!$A$4:$A$400,0)),"SIN SECTOR")) -> Industriales y Construccion | U3: =IF($C3="","",YEAR($C3)) -> 2025 | V3: =IF($C3="","","T"&ROUNDUP(MONTH($C3)/3,0)) -> T1 | W3: =IF($A3="","",IF($J3="","NO","SI")) -> NO | X3: MIGRACION | Y3: 2026-07-20 19:54 | Z3: Revisado | AA3: NO
A4: Union Andina de Cementos | B4: JOA | C4: 45747 | D4: 03 | E4: Delegación en el Directorio de Auditores Externos. | F4: Designacion Auditores | G4: En Contra | I4: De acuerdo a la política interna de Sura (Auditores Externos deberían ser escogidos en la JGA) | R4: =IF($A4="","",IFERROR(INDEX(Parametria!$B$4:$B$400,MATCH($A4,Parametria!$A$4:$A$400,0)),"?")&"|"&TEXT($C4,"yyyymmdd")&"|"&$B4) -> UNACEM|20250331|JOA | S4: =IF($A4="","",$R4&"|"&$D4) -> UNACEM|20250331|JOA|03 | T4: =IF($A4="","",IFERROR(INDEX(Parametria!$C$4:$C$400,MATCH($A4,Parametria!$A$4:$A$400,0)),"SIN SECTOR")) -> Industriales y Construccion | U4: =IF($C4="","",YEAR($C4)) -> 2025 | V4: =IF($C4="","","T"&ROUNDUP(MONTH($C4)/3,0)) -> T1 | W4: =IF($A4="","",IF($J4="","NO","SI")) -> NO | X4: MIGRACION | Y4: 2026-07-20 19:54 | Z4: Revisado | AA4: NO
A5: Alicorp | B5: JOA | C5: 45743 | D5: 01 | E5: Elección o Remoción de Directores | F5: Eleccion y Numero de Directores | G5: Informativo | R5: =IF($A5="","",IFERROR(INDEX(Parametria!$B$4:$B$400,MATCH($A5,Parametria!$A$4:$A$400,0)),"?")&"|"&TEXT($C5,"yyyymmdd")&"|"&$B5) -> ALICORP|20250327|JOA | S5: =IF($A5="","",$R5&"|"&$D5) -> ALICORP|20250327|JOA|01 | T5: =IF($A5="","",IFERROR(INDEX(Parametria!$C$4:$C$400,MATCH($A5,Parametria!$A$4:$A$400,0)),"SIN SECTOR")) -> Consumo | U5: =IF($C5="","",YEAR($C5)) -> 2025 | V5: =IF($C5="","","T"&ROUNDUP(MONTH($C5)/3,0)) -> T1 | W5: =IF($A5="","",IF($J5="","NO","SI")) -> NO | X5: MIGRACION | Y5: 2026-07-20 19:54 | Z5: Revisado | AA5: NO
A6: Alicorp | B6: JOA | C6: 45743 | D6: 02 | E6: Aprobación de la Gestión Social (EEFF y Memoria) | F6: Gestion Social (EEFF, Memoria) | G6: A Favor | R6: =IF($A6="","",IFERROR(INDEX(Parametria!$B$4:$B$400,MATCH($A6,Parametria!$A$4:$A$400,0)),"?")&"|"&TEXT($C6,"yyyymmdd")&"|"&$B6) -> ALICORP|20250327|JOA | S6: =IF($A6="","",$R6&"|"&$D6) -> ALICORP|20250327|JOA|02 | T6: =IF($A6="","",IFERROR(INDEX(Parametria!$C$4:$C$400,MATCH($A6,Parametria!$A$4:$A$400,0)),"SIN SECTOR")) -> Consumo | U6: =IF($C6="","",YEAR($C6)) -> 2025 | V6: =IF($C6="","","T"&ROUNDUP(MONTH($C6)/3,0)) -> T1 | W6: =IF($A6="","",IF($J6="","NO","SI")) -> NO | X6: MIGRACION | Y6: 2026-07-20 19:54 | Z6: Revisado | AA6: NO
A7: Alicorp | B7: JOA | C7: 45743 | D7: 03 | E7: Distribución o Aplicación de Utilidades | F7: Aplicacion de Utilidades (Distribucion de Dividendos) | G7: A Favor | R7: =IF($A7="","",IFERROR(INDEX(Parametria!$B$4:$B$400,MATCH($A7,Parametria!$A$4:$A$400,0)),"?")&"|"&TEXT($C7,"yyyymmdd")&"|"&$B7) -> ALICORP|20250327|JOA | S7: =IF($A7="","",$R7&"|"&$D7) -> ALICORP|20250327|JOA|03 | T7: =IF($A7="","",IFERROR(INDEX(Parametria!$C$4:$C$400,MATCH($A7,Parametria!$A$4:$A$400,0)),"SIN SECTOR")) -> Consumo | U7: =IF($C7="","",YEAR($C7)) -> 2025 | V7: =IF($C7="","","T"&ROUNDUP(MONTH($C7)/3,0)) -> T1 | W7: =IF($A7="","",IF($J7="","NO","SI")) -> NO | X7: MIGRACION | Y7: 2026-07-20 19:54 | Z7: Revisado | AA7: NO
A8: Alicorp | B8: JOA | C8: 45743 | D8: 04 | E8: Retribución de los miembros del Directorio y miembros de Comités del Directorio | F8: Remuneracion de Directores | G8: A Favor | R8: =IF($A8="","",IFERROR(INDEX(Parametria!$B$4:$B$400,MATCH($A8,Parametria!$A$4:$A$400,0)),"?")&"|"&TEXT($C8,"yyyymmdd")&"|"&$B8) -> ALICORP|20250327|JOA | S8: =IF($A8="","",$R8&"|"&$D8) -> ALICORP|20250327|JOA|04 | T8: =IF($A8="","",IFERROR(INDEX(Parametria!$C$4:$C$400,MATCH($A8,Parametria!$A$4:$A$400,0)),"SIN SECTOR")) -> Consumo | U8: =IF($C8="","",YEAR($C8)) -> 2025 | V8: =IF($C8="","","T"&ROUNDUP(MONTH($C8)/3,0)) -> T1 | W8: =IF($A8="","",IF($J8="","NO","SI")) -> NO | X8: MIGRACION | Y8: 2026-07-20 19:54 | Z8: Revisado | AA8: NO
A9: Alicorp | B9: JOA | C9: 45743 | D9: 05 | E9: Designación de los Auditores Externos para el ejercicio 2025 | F9: Designacion Auditores | G9: A Favor | R9: =IF($A9="","",IFERROR(INDEX(Parametria!$B$4:$B$400,MATCH($A9,Parametria!$A$4:$A$400,0)),"?")&"|"&TEXT($C9,"yyyymmdd")&"|"&$B9) -> ALICORP|20250327|JOA | S9: =IF($A9="","",$R9&"|"&$D9) -> ALICORP|20250327|JOA|05 | T9: =IF($A9="","",IFERROR(INDEX(Parametria!$C$4:$C$400,MATCH($A9,Parametria!$A$4:$A$400,0)),"SIN SECTOR")) -> Consumo | U9: =IF($C9="","",YEAR($C9)) -> 2025 | V9: =IF($C9="","","T"&ROUNDUP(MONTH($C9)/3,0)) -> T1 | W9: =IF($A9="","",IF($J9="","NO","SI")) -> NO | X9: MIGRACION | Y9: 2026-07-20 19:54 | Z9: Revisado | AA9: NO
A10: Alicorp | B10: JOA | C10: 45743 | D10: 06 | E10: Aprobación de un financiamiento a través del Mercado de Capitales para la reestructuración de los pasivos | F10: Otros | G10: A Favor | R10: =IF($A10="","",IFERROR(INDEX(Parametria!$B$4:$B$400,MATCH($A10,Parametria!$A$4:$A$400,0)),"?")&"|"&TEXT($C10,"yyyymmdd")&"|"&$B10) -> ALICORP|20250327|JOA | S10: =IF($A10="","",$R10&"|"&$D10) -> ALICORP|20250327|JOA|06 | T10: =IF($A10="","",IFERROR(INDEX(Parametria!$C$4:$C$400,MATCH($A10,Parametria!$A$4:$A$400,0)),"SIN SECTOR")) -> Consumo | U10: =IF($C10="","",YEAR($C10)) -> 2025 | V10: =IF($C10="","","T"&ROUNDUP(MONTH($C10)/3,0)) -> T1 | W10: =IF($A10="","",IF($J10="","NO","SI")) -> NO | X10: MIGRACION | Y10: 2026-07-20 19:54 | Z10: Revisado | AA10: NO
A11: Alicorp | B11: JOA | C11: 45743 | D11: 07 | E11: Informe ASG | F11: ASG | G11: Informativo | R11: =IF($A11="","",IFERROR(INDEX(Parametria!$B$4:$B$400,MATCH($A11,Parametria!$A$4:$A$400,0)),"?")&"|"&TEXT($C11,"yyyymmdd")&"|"&$B11) -> ALICORP|20250327|JOA | S11: =IF($A11="","",$R11&"|"&$D11) -> ALICORP|20250327|JOA|07 | T11: =IF($A11="","",IFERROR(INDEX(Parametria!$C$4:$C$400,MATCH($A11,Parametria!$A$4:$A$400,0)),"SIN SECTOR")) -> Consumo | U11: =IF($C11="","",YEAR($C11)) -> 2025 | V11: =IF($C11="","","T"&ROUNDUP(MONTH($C11)/3,0)) -> T1 | W11: =IF($A11="","",IF($J11="","NO","SI")) -> NO | X11: MIGRACION | Y11: 2026-07-20 19:54 | Z11: Revisado | AA11: NO
A12: Aenza | B12: JOA | C12: 45743 | D12: 01 | E12: Aprobación de los Estados Financieros Separados y Consolidados Auditados, Memoria Anual, Informe Anual de Gobierno Corporativo del Ejercicio 2024 | F12: Gestion Social (EEFF, Memoria) | G12: A Favor | R12: =IF($A12="","",IFERROR(INDEX(Parametria!$B$4:$B$400,MATCH($A12,Parametria!$A$4:$A$400,0)),"?")&"|"&TEXT($C12,"yyyymmdd")&"|"&$B12) -> AENZA|20250327|JOA | S12: =IF($A12="","",$R12&"|"&$D12) -> AENZA|20250327|JOA|01 | T12: =IF($A12="","",IFERROR(INDEX(Parametria!$C$4:$C$400,MATCH($A12,Parametria!$A$4:$A$400,0)),"SIN SECTOR")) -> Industriales y Construccion | U12: =IF($C12="","",YEAR($C12)) -> 2025 | V12: =IF($C12="","","T"&ROUNDUP(MONTH($C12)/3,0)) -> T1 | W12: =IF($A12="","",IF($J12="","NO","SI")) -> NO | X12: MIGRACION | Y12: 2026-07-20 19:54 | Z12: Revisado | AA12: NO
A13: Aenza | B13: JOA | C13: 45743 | D13: 02 | E13: Aplicación de Resultados del Ejercicio 2024 | F13: Aplicacion de Utilidades (Distribucion de Dividendos) | G13: A Favor | R13: =IF($A13="","",IFERROR(INDEX(Parametria!$B$4:$B$400,MATCH($A13,Parametria!$A$4:$A$400,0)),"?")&"|"&TEXT($C13,"yyyymmdd")&"|"&$B13) -> AENZA|20250327|JOA | S13: =IF($A13="","",$R13&"|"&$D13) -> AENZA|20250327|JOA|02 | T13: =IF($A13="","",IFERROR(INDEX(Parametria!$C$4:$C$400,MATCH($A13,Parametria!$A$4:$A$400,0)),"SIN SECTOR")) -> Industriales y Construccion | U13: =IF($C13="","",YEAR($C13)) -> 2025 | V13: =IF($C13="","","T"&ROUNDUP(MONTH($C13)/3,0)) -> T1 | W13: =IF($A13="","",IF($J13="","NO","SI")) -> NO | X13: MIGRACION | Y13: 2026-07-20 19:54 | Z13: Revisado | AA13: NO
A14: Aenza | B14: JOA | C14: 45743 | D14: 03 | E14: Designación de los auditores externos para el periodo 2025-2027 | F14: Designacion Auditores | G14: Informativo | R14: =IF($A14="","",IFERROR(INDEX(Parametria!$B$4:$B$400,MATCH($A14,Parametria!$A$4:$A$400,0)),"?")&"|"&TEXT($C14,"yyyymmdd")&"|"&$B14) -> AENZA|20250327|JOA | S14: =IF($A14="","",$R14&"|"&$D14) -> AENZA|20250327|JOA|03 | T14: =IF($A14="","",IFERROR(INDEX(Parametria!$C$4:$C$400,MATCH($A14,Parametria!$A$4:$A$400,0)),"SIN SECTOR")) -> Industriales y Construccion | U14: =IF($C14="","",YEAR($C14)) -> 2025 | V14: =IF($C14="","","T"&ROUNDUP(MONTH($C14)/3,0)) -> T1 | W14: =IF($A14="","",IF($J14="","NO","SI")) -> NO | X14: MIGRACION | Y14: 2026-07-20 19:54 | Z14: Revisado | AA14: NO
A15: Aenza | B15: JOA | C15: 45743 | D15: 04 | E15: Delegación de Facultades para formalizar acuerdos | F15: Formalizacion Acuerdos | G15: A Favor | R15: =IF($A15="","",IFERROR(INDEX(Parametria!$B$4:$B$400,MATCH($A15,Parametria!$A$4:$A$400,0)),"?")&"|"&TEXT($C15,"yyyymmdd")&"|"&$B15) -> AENZA|20250327|JOA | S15: =IF($A15="","",$R15&"|"&$D15) -> AENZA|20250327|JOA|04 | T15: =IF($A15="","",IFERROR(INDEX(Parametria!$C$4:$C$400,MATCH($A15,Parametria!$A$4:$A$400,0)),"SIN SECTOR")) -> Industriales y Construccion | U15: =IF($C15="","",YEAR($C15)) -> 2025 | V15: =IF($C15="","","T"&ROUNDUP(MONTH($C15)/3,0)) -> T1 | W15: =IF($A15="","",IF($J15="","NO","SI")) -> NO | X15: MIGRACION | Y15: 2026-07-20 19:54 | Z15: Revisado | AA15: NO
A16: Aenza | B16: JOA | C16: 45743 | D16: 05 | E16: Aprobación de Informe de Sostenibilidad del ejercicio 2024 | F16: ASG | G16: A Favor | R16: =IF($A16="","",IFERROR(INDEX(Parametria!$B$4:$B$400,MATCH($A16,Parametria!$A$4:$A$400,0)),"?")&"|"&TEXT($C16,"yyyymmdd")&"|"&$B16) -> AENZA|20250327|JOA | S16: =IF($A16="","",$R16&"|"&$D16) -> AENZA|20250327|JOA|05 | T16: =IF($A16="","",IFERROR(INDEX(Parametria!$C$4:$C$400,MATCH($A16,Parametria!$A$4:$A$400,0)),"SIN SECTOR")) -> Industriales y Construccion | U16: =IF($C16="","",YEAR($C16)) -> 2025 | V16: =IF($C16="","","T"&ROUNDUP(MONTH($C16)/3,0)) -> T1 | W16: =IF($A16="","",IF($J16="","NO","SI")) -> NO | X16: MIGRACION | Y16: 2026-07-20 19:54 | Z16: Revisado | AA16: NO
... A56: Cia. de Minas Buenaventura | B56: JOA | C56: 45744 | D56: 02 | E56: Retribución al directorio – ejercicio 2024 | F56: Remuneracion de Directores | G56: Informativo | R56: =IF($A56="","",IFERROR(INDEX(Parametria!$B$4:$B$400,MATCH($A56,Parametria!$A$4:$A$400,0)),"?")&"|"&TEXT($C56,"yyyymmdd")&"|"&$B56) -> BVN|20250328|JOA | S56: =IF($A56="","",$R56&"|"&$D56) -> BVN|20250328|JOA|02 | T56: =IF($A56="","",IFERROR(INDEX(Parametria!$C$4:$C$400,MATCH($A56,Parametria!$A$4:$A$400,0)),"SIN SECTOR")) -> Metales y Mineria | U56: =IF($C56="","",YEAR($C56)) -> 2025 | V56: =IF($C56="","","T"&ROUNDUP(MONTH($C56)/3,0)) -> T1 | W56: =IF($A56="","",IF($J56="","NO","SI")) -> NO | X56: MIGRACION | Y56: 2026-07-20 19:54 | Z56: Revisado | AA56: NO
A57: Cia. de Minas Buenaventura | B57: JOA | C57: 45744 | D57: 03 | E57: Designación de auditores externos para el ejercicio 2025 | F57: Designacion Auditores | G57: En Contra | I57: Se propone a Ernst and Young (Tanaka, Valdivia y Asociados). EY ha sido la firma auditora por más de 10 años. | R57: =IF($A57="","",IFERROR(INDEX(Parametria!$B$4:$B$400,MATCH($A57,Parametria!$A$4:$A$400,0)),"?")&"|"&TEXT($C57,"yyyymmdd")&"|"&$B57) -> BVN|20250328|JOA | S57: =IF($A57="","",$R57&"|"&$D57) -> BVN|20250328|JOA|03 | T57: =IF($A57="","",IFERROR(INDEX(Parametria!$C$4:$C$400,MATCH($A57,Parametria!$A$4:$A$400,0)),"SIN SECTOR")) -> Metales y Mineria | U57: =IF($C57="","",YEAR($C57)) -> 2025 | V57: =IF($C57="","","T"&ROUNDUP(MONTH($C57)/3,0)) -> T1 | W57: =IF($A57="","",IF($J57="","NO","SI")) -> NO | X57: MIGRACION | Y57: 2026-07-20 19:54 | Z57: Revisado | AA57: NO
A58: Cia. de Minas Buenaventura | B58: JOA | C58: 45744 | D58: 04 | E58: Distribución de dividendos | F58: Aplicacion de Utilidades (Distribucion de Dividendos) | G58: A Favor | R58: =IF($A58="","",IFERROR(INDEX(Parametria!$B$4:$B$400,MATCH($A58,Parametria!$A$4:$A$400,0)),"?")&"|"&TEXT($C58,"yyyymmdd")&"|"&$B58) -> BVN|20250328|JOA | S58: =IF($A58="","",$R58&"|"&$D58) -> BVN|20250328|JOA|04 | T58: =IF($A58="","",IFERROR(INDEX(Parametria!$C$4:$C$400,MATCH($A58,Parametria!$A$4:$A$400,0)),"SIN SECTOR")) -> Metales y Mineria | U58: =IF($C58="","",YEAR($C58)) -> 2025 | V58: =IF($C58="","","T"&ROUNDUP(MONTH($C58)/3,0)) -> T1 | W58: =IF($A58="","",IF($J58="","NO","SI")) -> NO | X58: MIGRACION | Y58: 2026-07-20 19:54 | Z58: Revisado | AA58: NO
A59: Volcan | B59: JOA | C59: 45743 | D59: 01 | E59: Aprobación de la Gestión Social (EEFF Y Memoria) | F59: Gestion Social (EEFF, Memoria) | G59: A Favor | R59: =IF($A59="","",IFERROR(INDEX(Parametria!$B$4:$B$400,MATCH($A59,Parametria!$A$4:$A$400,0)),"?")&"|"&TEXT($C59,"yyyymmdd")&"|"&$B59) -> VOLCAN|20250327|JOA | S59: =IF($A59="","",$R59&"|"&$D59) -> VOLCAN|20250327|JOA|01 | T59: =IF($A59="","",IFERROR(INDEX(Parametria!$C$4:$C$400,MATCH($A59,Parametria!$A$4:$A$400,0)),"SIN SECTOR")) -> Metales y Mineria | U59: =IF($C59="","",YEAR($C59)) -> 2025 | V59: =IF($C59="","","T"&ROUNDUP(MONTH($C59)/3,0)) -> T1 | W59: =IF($A59="","",IF($J59="","NO","SI")) -> NO | X59: MIGRACION | Y59: 2026-07-20 19:54 | Z59: Revisado | AA59: NO
A60: Volcan | B60: JOA | C60: 45743 | D60: 02 | E60: Aplicación de resultados del ejercicio 2024 | F60: Otros | G60: Cabecera | R60: =IF($A60="","",IFERROR(INDEX(Parametria!$B$4:$B$400,MATCH($A60,Parametria!$A$4:$A$400,0)),"?")&"|"&TEXT($C60,"yyyymmdd")&"|"&$B60) -> VOLCAN|20250327|JOA | S60: =IF($A60="","",$R60&"|"&$D60) -> VOLCAN|20250327|JOA|02 | T60: =IF($A60="","",IFERROR(INDEX(Parametria!$C$4:$C$400,MATCH($A60,Parametria!$A$4:$A$400,0)),"SIN SECTOR")) -> Metales y Mineria | U60: =IF($C60="","",YEAR($C60)) -> 2025 | V60: =IF($C60="","","T"&ROUNDUP(MONTH($C60)/3,0)) -> T1 | W60: =IF($A60="","",IF($J60="","NO","SI")) -> NO | X60: MIGRACION | Y60: 2026-07-20 19:54 | Z60: Revisado | AA60: NO
A61: Volcan | B61: JOA | C61: 45743 | D61: 02.1 | E61: Aumentar Reserva Legal | F61: Aplicacion de Utilidades (Incremento de Reserva Legal) | G61: A Favor | R61: =IF($A61="","",IFERROR(INDEX(Parametria!$B$4:$B$400,MATCH($A61,Parametria!$A$4:$A$400,0)),"?")&"|"&TEXT($C61,"yyyymmdd")&"|"&$B61) -> VOLCAN|20250327|JOA | S61: =IF($A61="","",$R61&"|"&$D61) -> VOLCAN|20250327|JOA|02.1 | T61: =IF($A61="","",IFERROR(INDEX(Parametria!$C$4:$C$400,MATCH($A61,Parametria!$A$4:$A$400,0)),"SIN SECTOR")) -> Metales y Mineria | U61: =IF($C61="","",YEAR($C61)) -> 2025 | V61: =IF($C61="","","T"&ROUNDUP(MONTH($C61)/3,0)) -> T1 | W61: =IF($A61="","",IF($J61="","NO","SI")) -> NO | X61: MIGRACION | Y61: 2026-07-20 19:54 | Z61: Revisado | AA61: NO
A62: Volcan | B62: JOA | C62: 45743 | D62: 02.2 | E62: Saldo a Resultados Acumulados | F62: Aplicacion de Utilidades (Saldo a Resultados Acumulados) | G62: A Favor | R62: =IF($A62="","",IFERROR(INDEX(Parametria!$B$4:$B$400,MATCH($A62,Parametria!$A$4:$A$400,0)),"?")&"|"&TEXT($C62,"yyyymmdd")&"|"&$B62) -> VOLCAN|20250327|JOA | S62: =IF($A62="","",$R62&"|"&$D62) -> VOLCAN|20250327|JOA|02.2 | T62: =IF($A62="","",IFERROR(INDEX(Parametria!$C$4:$C$400,MATCH($A62,Parametria!$A$4:$A$400,0)),"SIN SECTOR")) -> Metales y Mineria | U62: =IF($C62="","",YEAR($C62)) -> 2025 | V62: =IF($C62="","","T"&ROUNDUP(MONTH($C62)/3,0)) -> T1 | W62: =IF($A62="","",IF($J62="","NO","SI")) -> NO | X62: MIGRACION | Y62: 2026-07-20 19:54 | Z62: Revisado | AA62: NO
A63: Volcan | B63: JOA | C63: 45743 | D63: 03 | E63: Designar o delegar en el directorio la designación de los auditores externos | F63: Designacion Auditores | G63: Informativo | R63: =IF($A63="","",IFERROR(INDEX(Parametria!$B$4:$B$400,MATCH($A63,Parametria!$A$4:$A$400,0)),"?")&"|"&TEXT($C63,"yyyymmdd")&"|"&$B63) -> VOLCAN|20250327|JOA | S63: =IF($A63="","",$R63&"|"&$D63) -> VOLCAN|20250327|JOA|03 | T63: =IF($A63="","",IFERROR(INDEX(Parametria!$C$4:$C$400,MATCH($A63,Parametria!$A$4:$A$400,0)),"SIN SECTOR")) -> Metales y Mineria | U63: =IF($C63="","",YEAR($C63)) -> 2025 | V63: =IF($C63="","","T"&ROUNDUP(MONTH($C63)/3,0)) -> T1 | W63: =IF($A63="","",IF($J63="","NO","SI")) -> NO | X63: MIGRACION | Y63: 2026-07-20 19:54 | Z63: Revisado | AA63: NO
A64: Volcan | B64: JOA | C64: 45743 | D64: 04 | E64: Otorgamiento de facultades para formalizar los acuerdos adoptados en la junta | F64: Formalizacion Acuerdos | G64: A Favor | R64: =IF($A64="","",IFERROR(INDEX(Parametria!$B$4:$B$400,MATCH($A64,Parametria!$A$4:$A$400,0)),"?")&"|"&TEXT($C64,"yyyymmdd")&"|"&$B64) -> VOLCAN|20250327|JOA | S64: =IF($A64="","",$R64&"|"&$D64) -> VOLCAN|20250327|JOA|04 | T64: =IF($A64="","",IFERROR(INDEX(Parametria!$C$4:$C$400,MATCH($A64,Parametria!$A$4:$A$400,0)),"SIN SECTOR")) -> Metales y Mineria | U64: =IF($C64="","",YEAR($C64)) -> 2025 | V64: =IF($C64="","","T"&ROUNDUP(MONTH($C64)/3,0)) -> T1 | W64: =IF($A64="","",IF($J64="","NO","SI")) -> NO | X64: MIGRACION | Y64: 2026-07-20 19:54 | Z64: Revisado | AA64: NO
A65: BBVA Peru | B65: JOA | C65: 45743 | D65: 01 | E65: Lectura del dictamen e informe de los auditores externos correspondiente al ejercicio 2024. Aprobación de los estados financieros separados y consolidados, memoria anual y gestión social correspondiente al ejercicio 2024 | F65: Gestion Social (EEFF, Memoria) | G65: A Favor | R65: =IF($A65="","",IFERROR(INDEX(Parametria!$B$4:$B$400,MATCH($A65,Parametria!$A$4:$A$400,0)),"?")&"|"&TEXT($C65,"yyyymmdd")&"|"&$B65) -> BBVA|20250327|JOA | S65: =IF($A65="","",$R65&"|"&$D65) -> BBVA|20250327|JOA|01 | T65: =IF($A65="","",IFERROR(INDEX(Parametria!$C$4:$C$400,MATCH($A65,Parametria!$A$4:$A$400,0)),"SIN SECTOR")) -> Sistema Financiero | U65: =IF($C65="","",YEAR($C65)) -> 2025 | V65: =IF($C65="","","T"&ROUNDUP(MONTH($C65)/3,0)) -> T1 | W65: =IF($A65="","",IF($J65="","NO","SI")) -> NO | X65: MIGRACION | Y65: 2026-07-20 19:54 | Z65: Revisado | AA65: NO
A66: BBVA Peru | B66: JOA | C66: 45743 | D66: 02 | E66: Informe sobre la gestión social y de avances en la gestión de factores ambientales, sociales, de gobierno corporativo y riesgo climático (ASG). | F66: ASG | G66: Informativo | R66: =IF($A66="","",IFERROR(INDEX(Parametria!$B$4:$B$400,MATCH($A66,Parametria!$A$4:$A$400,0)),"?")&"|"&TEXT($C66,"yyyymmdd")&"|"&$B66) -> BBVA|20250327|JOA | S66: =IF($A66="","",$R66&"|"&$D66) -> BBVA|20250327|JOA|02 | T66: =IF($A66="","",IFERROR(INDEX(Parametria!$C$4:$C$400,MATCH($A66,Parametria!$A$4:$A$400,0)),"SIN SECTOR")) -> Sistema Financiero | U66: =IF($C66="","",YEAR($C66)) -> 2025 | V66: =IF($C66="","","T"&ROUNDUP(MONTH($C66)/3,0)) -> T1 | W66: =IF($A66="","",IF($J66="","NO","SI")) -> NO | X66: MIGRACION | Y66: 2026-07-20 19:54 | Z66: Revisado | AA66: NO
A67: BBVA Peru | B67: JOA | C67: 45743 | D67: 03 | E67: Designación de los auditores externos para el ejercicio 2025 | F67: Designacion Auditores | G67: A Favor | R67: =IF($A67="","",IFERROR(INDEX(Parametria!$B$4:$B$400,MATCH($A67,Parametria!$A$4:$A$400,0)),"?")&"|"&TEXT($C67,"yyyymmdd")&"|"&$B67) -> BBVA|20250327|JOA | S67: =IF($A67="","",$R67&"|"&$D67) -> BBVA|20250327|JOA|03 | T67: =IF($A67="","",IFERROR(INDEX(Parametria!$C$4:$C$400,MATCH($A67,Parametria!$A$4:$A$400,0)),"SIN SECTOR")) -> Sistema Financiero | U67: =IF($C67="","",YEAR($C67)) -> 2025 | V67: =IF($C67="","","T"&ROUNDUP(MONTH($C67)/3,0)) -> T1 | W67: =IF($A67="","",IF($J67="","NO","SI")) -> NO | X67: MIGRACION | Y67: 2026-07-20 19:54 | Z67: Revisado | AA67: NO
A68: BBVA Peru | B68: JOA | C68: 45743 | D68: 04 | E68: Propuesta de aplicación de utilidades. | F68: Otros | G68: Cabecera | R68: =IF($A68="","",IFERROR(INDEX(Parametria!$B$4:$B$400,MATCH($A68,Parametria!$A$4:$A$400,0)),"?")&"|"&TEXT($C68,"yyyymmdd")&"|"&$B68) -> BBVA|20250327|JOA | S68: =IF($A68="","",$R68&"|"&$D68) -> BBVA|20250327|JOA|04 | T68: =IF($A68="","",IFERROR(INDEX(Parametria!$C$4:$C$400,MATCH($A68,Parametria!$A$4:$A$400,0)),"SIN SECTOR")) -> Sistema Financiero | U68: =IF($C68="","",YEAR($C68)) -> 2025 | V68: =IF($C68="","","T"&ROUNDUP(MONTH($C68)/3,0)) -> T1 | W68: =IF($A68="","",IF($J68="","NO","SI")) -> NO | X68: MIGRACION | Y68: 2026-07-20 19:54 | Z68: Revisado | AA68: NO
A69: BBVA Peru | B69: JOA | C69: 45743 | D69: 04.1 | E69: PEN 188’640,459.53, se destinarán a incrementar la reserva legal | F69: Aplicacion de Utilidades (Incremento de Reserva Legal) | G69: A Favor | R69: =IF($A69="","",IFERROR(INDEX(Parametria!$B$4:$B$400,MATCH($A69,Parametria!$A$4:$A$400,0)),"?")&"|"&TEXT($C69,"yyyymmdd")&"|"&$B69) -> BBVA|20250327|JOA | S69: =IF($A69="","",$R69&"|"&$D69) -> BBVA|20250327|JOA|04.1 | T69: =IF($A69="","",IFERROR(INDEX(Parametria!$C$4:$C$400,MATCH($A69,Parametria!$A$4:$A$400,0)),"SIN SECTOR")) -> Sistema Financiero | U69: =IF($C69="","",YEAR($C69)) -> 2025 | V69: =IF($C69="","","T"&ROUNDUP(MONTH($C69)/3,0)) -> T1 | W69: =IF($A69="","",IF($J69="","NO","SI")) -> NO | X69: MIGRACION | Y69: 2026-07-20 19:54 | Z69: Revisado | AA69: NO
... A98: Cerro Verde | B98: JOA | C98: 45740 | D98: 02 | E98: Destino de los resultados económicos obtenidos en el año 2024 | F98: Otros | G98: Cabecera | R98: =IF($A98="","",IFERROR(INDEX(Parametria!$B$4:$B$400,MATCH($A98,Parametria!$A$4:$A$400,0)),"?")&"|"&TEXT($C98,"yyyymmdd")&"|"&$B98) -> CVERDE|20250324|JOA | S98: =IF($A98="","",$R98&"|"&$D98) -> CVERDE|20250324|JOA|02 | T98: =IF($A98="","",IFERROR(INDEX(Parametria!$C$4:$C$400,MATCH($A98,Parametria!$A$4:$A$400,0)),"SIN SECTOR")) -> Metales y Mineria | U98: =IF($C98="","",YEAR($C98)) -> 2025 | V98: =IF($C98="","","T"&ROUNDUP(MONTH($C98)/3,0)) -> T1 | W98: =IF($A98="","",IF($J98="","NO","SI")) -> NO | X98: MIGRACION | Y98: 2026-07-20 19:54 | Z98: Revisado | AA98: NO
A99: Cerro Verde | B99: JOA | C99: 45740 | D99: 03 | E99: Ratificación de los miembros del Directorio | F99: Eleccion y Numero de Directores | G99: En Contra | I99: No cuentan con directores independientes | R99: =IF($A99="","",IFERROR(INDEX(Parametria!$B$4:$B$400,MATCH($A99,Parametria!$A$4:$A$400,0)),"?")&"|"&TEXT($C99,"yyyymmdd")&"|"&$B99) -> CVERDE|20250324|JOA | S99: =IF($A99="","",$R99&"|"&$D99) -> CVERDE|20250324|JOA|03 | T99: =IF($A99="","",IFERROR(INDEX(Parametria!$C$4:$C$400,MATCH($A99,Parametria!$A$4:$A$400,0)),"SIN SECTOR")) -> Metales y Mineria | U99: =IF($C99="","",YEAR($C99)) -> 2025 | V99: =IF($C99="","","T"&ROUNDUP(MONTH($C99)/3,0)) -> T1 | W99: =IF($A99="","",IF($J99="","NO","SI")) -> NO | X99: MIGRACION | Y99: 2026-07-20 19:54 | Z99: Revisado | AA99: NO
A100: Cerro Verde | B100: JOA | C100: 45740 | D100: 04 | E100: Delegación al Directorio de la designación de los auditores externos | F100: Designacion Auditores | G100: En Contra | R100: =IF($A100="","",IFERROR(INDEX(Parametria!$B$4:$B$400,MATCH($A100,Parametria!$A$4:$A$400,0)),"?")&"|"&TEXT($C100,"yyyymmdd")&"|"&$B100) -> CVERDE|20250324|JOA | S100: =IF($A100="","",$R100&"|"&$D100) -> CVERDE|20250324|JOA|04 | T100: =IF($A100="","",IFERROR(INDEX(Parametria!$C$4:$C$400,MATCH($A100,Parametria!$A$4:$A$400,0)),"SIN SECTOR")) -> Metales y Mineria | U100: =IF($C100="","",YEAR($C100)) -> 2025 | V100: =IF($C100="","","T"&ROUNDUP(MONTH($C100)/3,0)) -> T1 | W100: =IF($A100="","",IF($J100="","NO","SI")) -> NO | X100: MIGRACION | Y100: 2026-07-20 19:54 | Z100: Revisado | AA100: NO
A101: Engie Energia Peru | B101: JOA | C101: 45736 | D101: 01 | E101: Aprobación de la gestión social expresada en el Reporte Integrado, que contiene la Memoria Anual 2024 y los estados financieros auditados | F101: Gestion Social (EEFF, Memoria) | G101: A Favor | R101: =IF($A101="","",IFERROR(INDEX(Parametria!$B$4:$B$400,MATCH($A101,Parametria!$A$4:$A$400,0)),"?")&"|"&TEXT($C101,"yyyymmdd")&"|"&$B101) -> ENGIE|20250320|JOA | S101: =IF($A101="","",$R101&"|"&$D101) -> ENGIE|20250320|JOA|01 | T101: =IF($A101="","",IFERROR(INDEX(Parametria!$C$4:$C$400,MATCH($A101,Parametria!$A$4:$A$400,0)),"SIN SECTOR")) -> Servicios Publicos | U101: =IF($C101="","",YEAR($C101)) -> 2025 | V101: =IF($C101="","","T"&ROUNDUP(MONTH($C101)/3,0)) -> T1 | W101: =IF($A101="","",IF($J101="","NO","SI")) -> NO | X101: MIGRACION | Y101: 2026-07-20 19:54 | Z101: Revisado | AA101: NO
A102: Engie Energia Peru | B102: JOA | C102: 45736 | D102: 02 | E102: Distribución o Aplicación de Utilidades | F102: Aplicacion de Utilidades (Distribucion de Dividendos) | G102: A Favor | R102: =IF($A102="","",IFERROR(INDEX(Parametria!$B$4:$B$400,MATCH($A102,Parametria!$A$4:$A$400,0)),"?")&"|"&TEXT($C102,"yyyymmdd")&"|"&$B102) -> ENGIE|20250320|JOA | S102: =IF($A102="","",$R102&"|"&$D102) -> ENGIE|20250320|JOA|02 | T102: =IF($A102="","",IFERROR(INDEX(Parametria!$C$4:$C$400,MATCH($A102,Parametria!$A$4:$A$400,0)),"SIN SECTOR")) -> Servicios Publicos | U102: =IF($C102="","",YEAR($C102)) -> 2025 | V102: =IF($C102="","","T"&ROUNDUP(MONTH($C102)/3,0)) -> T1 | W102: =IF($A102="","",IF($J102="","NO","SI")) -> NO | X102: MIGRACION | Y102: 2026-07-20 19:54 | Z102: Revisado | AA102: NO
A103: Engie Energia Peru | B103: JOA | C103: 45736 | D103: 03 | E103: Determinación de la Fecha de Registro y Fecha de Entrega de Dividendos | F103: Politica de Dividendos | G103: A Favor | R103: =IF($A103="","",IFERROR(INDEX(Parametria!$B$4:$B$400,MATCH($A103,Parametria!$A$4:$A$400,0)),"?")&"|"&TEXT($C103,"yyyymmdd")&"|"&$B103) -> ENGIE|20250320|JOA | S103: =IF($A103="","",$R103&"|"&$D103) -> ENGIE|20250320|JOA|03 | T103: =IF($A103="","",IFERROR(INDEX(Parametria!$C$4:$C$400,MATCH($A103,Parametria!$A$4:$A$400,0)),"SIN SECTOR")) -> Servicios Publicos | U103: =IF($C103="","",YEAR($C103)) -> 2025 | V103: =IF($C103="","","T"&ROUNDUP(MONTH($C103)/3,0)) -> T1 | W103: =IF($A103="","",IF($J103="","NO","SI")) -> NO | X103: MIGRACION | Y103: 2026-07-20 19:54 | Z103: Revisado | AA103: NO
A104: Engie Energia Peru | B104: JOA | C104: 45736 | D104: 04 | E104: Designación de Auditores | F104: Designacion Auditores | G104: A Favor | R104: =IF($A104="","",IFERROR(INDEX(Parametria!$B$4:$B$400,MATCH($A104,Parametria!$A$4:$A$400,0)),"?")&"|"&TEXT($C104,"yyyymmdd")&"|"&$B104) -> ENGIE|20250320|JOA | S104: =IF($A104="","",$R104&"|"&$D104) -> ENGIE|20250320|JOA|04 | T104: =IF($A104="","",IFERROR(INDEX(Parametria!$C$4:$C$400,MATCH($A104,Parametria!$A$4:$A$400,0)),"SIN SECTOR")) -> Servicios Publicos | U104: =IF($C104="","",YEAR($C104)) -> 2025 | V104: =IF($C104="","","T"&ROUNDUP(MONTH($C104)/3,0)) -> T1 | W104: =IF($A104="","",IF($J104="","NO","SI")) -> NO | X104: MIGRACION | Y104: 2026-07-20 19:54 | Z104: Revisado | AA104: NO
A105: Engie Energia Peru | B105: JOA | C105: 45736 | D105: 05 | E105: Informar a la Junta Obligatoria Anual de Accionistas sobre los aspectos Ambientales, Sociales y Gobierno Corporativo | F105: ASG | G105: Informativo | R105: =IF($A105="","",IFERROR(INDEX(Parametria!$B$4:$B$400,MATCH($A105,Parametria!$A$4:$A$400,0)),"?")&"|"&TEXT($C105,"yyyymmdd")&"|"&$B105) -> ENGIE|20250320|JOA | S105: =IF($A105="","",$R105&"|"&$D105) -> ENGIE|20250320|JOA|05 | T105: =IF($A105="","",IFERROR(INDEX(Parametria!$C$4:$C$400,MATCH($A105,Parametria!$A$4:$A$400,0)),"SIN SECTOR")) -> Servicios Publicos | U105: =IF($C105="","",YEAR($C105)) -> 2025 | V105: =IF($C105="","","T"&ROUNDUP(MONTH($C105)/3,0)) -> T1 | W105: =IF($A105="","",IF($J105="","NO","SI")) -> NO | X105: MIGRACION | Y105: 2026-07-20 19:54 | Z105: Revisado | AA105: NO
A106: Engie Energia Peru | B106: JOA | C106: 45736 | D106: 06 | E106: Designación de los miembros del Directorio y fijación de su retribución | F106: Eleccion y Numero de Directores | G106: Informativo | R106: =IF($A106="","",IFERROR(INDEX(Parametria!$B$4:$B$400,MATCH($A106,Parametria!$A$4:$A$400,0)),"?")&"|"&TEXT($C106,"yyyymmdd")&"|"&$B106) -> ENGIE|20250320|JOA | S106: =IF($A106="","",$R106&"|"&$D106) -> ENGIE|20250320|JOA|06 | T106: =IF($A106="","",IFERROR(INDEX(Parametria!$C$4:$C$400,MATCH($A106,Parametria!$A$4:$A$400,0)),"SIN SECTOR")) -> Servicios Publicos | U106: =IF($C106="","",YEAR($C106)) -> 2025 | V106: =IF($C106="","","T"&ROUNDUP(MONTH($C106)/3,0)) -> T1 | W106: =IF($A106="","",IF($J106="","NO","SI")) -> NO | X106: MIGRACION | Y106: 2026-07-20 19:54 | Z106: Revisado | AA106: NO
A107: Engie Energia Peru | B107: JOA | C107: 45736 | D107: 07 | E107: Adaptación de ENGIE a sociedad anónima abierta según lo dispuesto en la Ley General de Sociedades y modificación de estatutos. | F107: Modificacion de Estatutos | G107: A Favor | R107: =IF($A107="","",IFERROR(INDEX(Parametria!$B$4:$B$400,MATCH($A107,Parametria!$A$4:$A$400,0)),"?")&"|"&TEXT($C107,"yyyymmdd")&"|"&$B107) -> ENGIE|20250320|JOA | S107: =IF($A107="","",$R107&"|"&$D107) -> ENGIE|20250320|JOA|07 | T107: =IF($A107="","",IFERROR(INDEX(Parametria!$C$4:$C$400,MATCH($A107,Parametria!$A$4:$A$400,0)),"SIN SECTOR")) -> Servicios Publicos | U107: =IF($C107="","",YEAR($C107)) -> 2025 | V107: =IF($C107="","","T"&ROUNDUP(MONTH($C107)/3,0)) -> T1 | W107: =IF($A107="","",IF($J107="","NO","SI")) -> NO | X107: MIGRACION | Y107: 2026-07-20 19:54 | Z107: Revisado | AA107: NO
...

Sheet Parametria
A1: PARAMETRIA DE EMPRESAS - editable. Si el ETL crea una empresa con Sector = POR CLASIFICAR, corregirla en la columna C.
A2: Cod_SBS_Emisor sale de la hoja 'Matriz de Eventos' del Oficio SBS 24409-2018.
A3: Empresa | B3: Abrev | C3: Sector | D3: Ticker | E3: ISIN | F3: Cod_SBS_Emisor | G3: Activo | H3: Notas
A4: BBVA Peru | B4: BBVA | C4: Sistema Financiero | D4: BBVAC1 PE | E4: PEP116001004 | F4: 300011100001 | G4: SI
A5: Credicorp | B5: BAP | C5: Sistema Financiero | D5: BAP US | E5: BMG2519Y1084 | F5: 302012200001 | G5: SI
A6: Intergroup | B6: IFS | C6: Sistema Financiero | D6: IFS TOTAL | E6: PAL2400671A3 | G6: SI
A7: Scotiabank Peru | B7: SCOTIA | C7: Sistema Financiero | D7: SCOTIAC1 PE | E7: PEP140001004 | G7: NO
A8: Union Andina de Cementos | B8: UNACEM | C8: Industriales y Construccion | D8: UNACEMC1 PE | E8: PEP761001002 | G8: SI
A9: Cementos Pacasmayo | B9: PACAS | C9: Industriales y Construccion | D9: CPACAS TOTAL | E9: PEP239501005 | F9: 302051100001 | G9: SI
A10: Aenza | B10: AENZA | C10: Industriales y Construccion | D10: AENZA TOTAL | E10: PEP736581005 | G10: SI
A11: Ferreycorp | B11: FERREY | C11: Industriales y Construccion | D11: FERREYC1 PE | G11: SI
A12: Corporacion Aceros Arequipa | B12: CORAREI | C12: Industriales y Construccion | D12: CORAREI1 PE | E12: PEP206015005 | G12: SI
A13: Cumbra | B13: CUMBRA | C13: Industriales y Construccion | G13: SI
A14: Volcan | B14: VOLCAN | C14: Metales y Mineria | D14: VOLCABC1 PE | G14: SI | H14: Suele tener JOA y JGA el mismo año
A15: Cia. de Minas Buenaventura | B15: BVN | C15: Metales y Mineria | D15: BUENAVC1 PE | F15: 302008100002 | G15: SI
A16: Cerro Verde | B16: CVERDE | C16: Metales y Mineria | D16: CVERDEC1 PE | G16: SI
A17: Nexa Resources | B17: NEXA | C17: Metales y Mineria | D17: NEXA US | G17: SI
A18: Nexa Peru | B18: NEXAPE | C18: Metales y Mineria | D18: NEXAPEC1 PE | G18: SI
A19: Nexa Resources Atacocha | B19: ATACOCHA | C19: Metales y Mineria | D19: ATACOAC1 PE | F19: 302048100001 | G19: SI
A20: Hudbay Minerals | B20: HUDBAY | C20: Metales y Mineria | D20: HBM CN | G20: SI | H20: Vota via Proxy Edge
A21: Hochschild Mining | B21: HOC | C21: Metales y Mineria | D21: HOC LN | G21: SI
A22: Alicorp | B22: ALICORP | C22: Consumo | D22: ALICORC1 PE | F22: 302011100001 | G22: SI
A23: InRetail | B23: INRETAIL | C23: Consumo | D23: INRETC1 PE | G23: SI
A24: Engie Energia Peru | B24: ENGIE | C24: Servicios Publicos | D24: ENGIEC1 PE | G24: SI
A25: Orygen | B25: ORYGEN | C25: Servicios Publicos | G25: SI
A26: Pluz Energia | B26: PLUZ | C26: Servicios Publicos | G26: SI
A27: Auna | B27: AUNA | C27: Salud | D27: AUNA US | G27: SI | H27: Vota via Proxy Edge
A28: Chancay | B28: CHANCAY | C28: Otros | G28: SI

Sheet Catalogos
A1: CATALOGOS - todo editable. Agregar una fila alcanza; los desplegables y los charts se actualizan solos.
A3: Tema | B3: Cod_SBS | C3: Orden | E3: Decision | F3: Cuenta_en_Charts | G3: Color | I3: Tipo_Junta | J3: Etiqueta_Reporte | K3: Orden | M3: Motivo_Contra | N3: Aplica_a_Tema | P3: Independencia | R3: Especialidad | S3: Orden | U3: Sector | V3: Color | W3: Orden | Y3: Responsable | Z3: DOI | AA3: Tipo_Rep | AC3: Medio | AE3: Estado_Acta | AG3: Asistencia | AI3: Estado_Registro
A4: Eleccion y Numero de Directores | B4: 1006 | C4: 1 | E4: A Favor | F4: SI | G4: 00AECB | I4: JOA | J4: Juntas Obligatorias Anuales (JOAs) | K4: 1 | M4: No se cuenta con directores independientes | N4: Eleccion y Numero de Directores | P4: Independiente | R4: Finanzas e Inversiones | S4: 1 | U4: Metales y Mineria | V4: 1E2E6E | W4: 1 | Y4: GFC | AA4: T | AC4: Virtual | AE4: Pendiente | AG4: Asistimos | AI4: Borrador
A5: Gestion Social (EEFF, Memoria) | B5: 1017 | C5: 2 | E5: En Contra | F5: SI | G5: E3E829 | I5: JGA | J5: Juntas Generales de Accionistas (JGAs) | K5: 2 | M5: Directores alternos o suplentes | N5: Eleccion y Numero de Directores | P5: Dependiente | R5: Industrial y Materiales | S5: 2 | U5: Industriales y Construccion | V5: 00AECB | W5: 2 | Y5: CHUCK | AA5: T | AC5: Presencial | AE5: Falta el envio | AG5: No asistimos | AI5: Revisado
A6: Designacion Auditores | B6: 1015 | C6: 3 | E6: Abstencion | F6: SI | G6: 1E2E6E | I6: JGO | J6: Juntas Generales de Obligacionistas (JGOs) | K6: 3 | M6: Numero de directores suplentes | N6: Eleccion y Numero de Directores | P6: No aplica | R6: Banca | S6: 3 | U6: Sistema Financiero | V6: 5B6DAE | W6: 3 | Y6: LA | AA6: T | AC6: Hibrido | AE6: Falta la firma | AI6: Cerrado
A7: Formalizacion Acuerdos | B7: 1013 | C7: 4 | E7: Informativo | F7: SI | G7: 5B6DAE | M7: Se delega la eleccion de la firma auditora al directorio | N7: Designacion Auditores | R7: Mineria | S7: 4 | U7: Servicios Publicos | V7: 3E9FBF | W7: 4 | Y7: RMN | AA7: T | AC7: Proxy Edge | AE7: Firmada
A8: ASG | B8: 1030 | C8: 5 | E8: No Asistimos | F8: NO | G8: BFBFBF | M8: La firma auditora supera 10 anios de servicio | N8: Designacion Auditores | R8: Legal y Auditoria | S8: 5 | U8: Consumo | V8: 7FC9DB | W8: 5 | Y8: DJ | AA8: T | AE8: OK | AI8: Cerrado = reporte ya publicado. El ETL nunca reescribe esas filas.
A9: Aplicacion de Utilidades (Distribucion de Dividendos) | B9: 1003 | C9: 6 | E9: Cabecera | F9: NO | G9: FFFFFF | M9: Aceptacion de renuncias futuras de directores | N9: Otros | R9: Planificacion y Desarrollo | S9: 6 | U9: Salud | V9: A9BCE0 | W9: 6 | Y9: RS | AA9: T
A10: Aplicacion de Utilidades (Saldo a Resultados Acumulados) | B10: 1003 | C10: 7 | M10: No es una practica acorde al estandar de mercado | N10: Otros | R10: Innovacion y trans. digital | S10: 7 | U10: Otros | V10: BFBFBF | W10: 7
A11: Aplicacion de Utilidades (Incremento de Reserva Legal) | B11: 1003 | C11: 8 | E11: Cuenta_en_Charts=NO excluye la fila de los conteos. | M11: Falta de informacion | N11: Otros | R11: Ciberseguridad | S11: 8 | U11: POR CLASIFICAR | V11: FF6B6B | W11: 99 | Y11: DOI y Tipo_Rep alimentan el Anexo 1 del Oficio SBS.
A12: Politica de Dividendos | B12: 1003 | C12: 9 | R12: Contabilidad | S12: 9
A13: Remuneracion de Directores | B13: 1006 | C13: 10 | M13: Aplica_a_Tema aisla el chart de motivos de directores. | R13: Quimica | S13: 10 | U13: POR CLASIFICAR lo crea el ETL; corregirlo en Parametria columna C.
A14: Modificacion de Estatutos | B14: 1019 | C14: 11 | R14: Retail | S14: 11
A15: Cambios en Patrimonio | B15: 1005 | C15: 12 | R15: Negocios Internacionales | S15: 12
A16: Emision de Instrumentos | B16: 1024 | C16: 13 | R16: Otros | S16: 13
A17: Modificacion de Reglamento de Junta General de Accionistas | B17: 1019 | C17: 14
A18: Recompra de Acciones | B18: 1005 | C18: 15 | R18: Se asigna a mano por director.
A19: M&A | B19: 1004 | C19: 16
A20: Otros | B20: 1035 | C20: 17
A22: Orden controla el eje del chart de barras.
A24: CONFIGURACION
A25: Color_Primario | B25: 1E2E6E
A26: Color_Secundario | B26: 00AECB
A27: Color_Acento | B27: E3E829
A28: Color_Texto | B28: 1E2E6E
A29: Nombre_Institucion | B29: AFP Integra
A30: Titulo_Reporte | B30: REPORTE DE JUNTAS DE ACCIONISTAS
A31: Pie_Pagina | B31: Contact Center: (01) 513-5050 o 0800-40110 - www.afpintegra.pe
A32: Min_Puntos_Para_Chart | B32: 1

Sheet Textos
A1: PLANTILLAS DEL WORDING DEL WORD - editable. Lo que va entre llaves lo reemplaza Python.
A2: No borrar la columna Clave. El texto se puede reescribir libremente.
A3: Clave | B3: Plantilla | C3: Variables disponibles
A4: intro | B4: {institucion} tiene como objetivo principal la gestion de fondos de pensiones en representacion de nuestros afiliados, con quienes mantenemos el deber fiduciario de buscar la mejor rentabilidad ajustada por riesgo para sus recursos. El presente documento comparte informacion sobre el sentido de nuestros votos en las juntas de accionistas a las que hemos asistido durante el {periodo}. | C4: {institucion} {periodo}
A5: sector | B5: Durante el {periodo}, participamos en {n_juntas} {junta_larga} de {n_empresas} empresas. La mayor parte de dichas juntas ({pct_top}) corresponden a los sectores {sectores_top}, dada la mayor cantidad de empresas de estos sectores en nuestra cartera de renta variable. | C5: {n_juntas} {n_empresas} {pct_top} {sectores_top} {junta_larga}
A6: temas | B6: Durante este periodo votamos respecto a {n_puntos} puntos de agenda, los cuales incluyeron temas recurrentes, asi como temas no recurrentes como {temas_raros}. | C6: {n_puntos} {temas_raros} {tema_top}
A7: contras | B7: Emitimos {n_contra} votos en contra durante este periodo siguiendo las mejores practicas de mercado y la Politica de Votacion de los Fondos de Pensiones de {institucion}. Los temas donde concentramos los votos en contra fueron {temas_contra}. | C7: {n_contra} {temas_contra} {institucion}
A8: contras_dir | B8: Emitimos {n_contra_dir} votos en contra en esta categoria siguiendo los lineamientos de la Politica de Votacion. La mayor parte de los votos en contra se emitieron por: {motivo_top}. | C8: {n_contra_dir} {motivo_top} {motivos_lista}
A9: independencia | B9: Votamos a favor de {n_dir} directores, {frase_indep}. | C9: {n_dir} {n_indep} {pct_indep} {frase_indep}
A10: experiencia | B10: Votamos a favor de {n_dir} directores, los cuales tenian experiencia en distintas industrias y especialidades. La mayoria de estos directores presentaban experiencia en {esp_top} ({pct_esp_top}). | C10: {n_dir} {esp_top} {pct_esp_top}
A11: sin_datos | B11: No se registraron juntas de este tipo durante el periodo.

Sheet Log
A1: BITACORA - la escribe etl_juntas.py. No editar a mano.
A3: Corrida | B3: Archivo_Origen | C3: Anio | D3: Juntas_Nuevas | E3: Juntas_Actualizadas | F3: Puntos_Nuevos | G3: Puntos_Actualizados | H3: Puntos_Ignorados_Cerrados | I3: Rechazados | J3: Empresas_Nuevas | K3: Alertas_SBS | L3: Detalle
A4: 2026-07-20 14:43 | B4: Propuestas de JGA 2026.xlsx | C4: 2026 | D4: 1 | E4: 1 | F4: 3 | G4: 0 | H4: 0 | I4: 0 | J4: - | K4: No se encontro el Oficio SBS del periodo (cruce omitido) | L4: -
