Workbook
Name IQ_CH: 110000
Name IQ_CQ: 5000
Name IQ_CY: 10000
Name IQ_DAILY: 500000
Name IQ_FH: 100000
Name IQ_FQ: 500
Name IQ_FY: 1000
Name IQ_LTM: 2000
Name IQ_MONTH: 15000
Name IQ_NTM: 6000
Name IQ_WEEK: 50000
Name IQ_YTD: 3000
Name repCO2: '[1]Manual Ant'!#REF!

Sheet ANALISIS BD
A1: Cod. OriginadorBU | B1: SBS | C1: ISIN | D1: Weight | E1: Fondo | F1: assetclass | G1: Strategy | H1: Afp | I1: AUM | J1: Tipo | K1: Q | L1: Nombre | M1: Fecha | N1: codEmisor | O1: Precio | P1: Inversión | Q1: Sector | R1: País | S1: ISSUER_CNTRY_DOMICILE | T1: IVA_INDUSTRY | U1: RATING | V1: IVA_RATING_TREND | W1: E | X1: S | Y1: G | Z1: EW | AA1: SW | AB1: GW | AC1: CONTROVERSIES | AD1: CO2 Tn | AE1: CO2/Sales | AF1: CARBON_EMISSIONS_SCORE | AG1: CARBON_EMISSIONS_EXP_SCORE | AH1: CORP_GOVERNANCE_SCORE | AI1: FUND_ESG_COVERAGE | AJ1: FUND_ESG_LEADERS_PCT | AK1: FUND_ESG_AVERAGE_PCT | AL1: FUND_ESG_LAGGARDS_PCT | AM1: FUND_ESG_QUALITY_SCORE | AN1: FUND_CARBON_SCOPE_12_INTEN_3Y_TREND_M_IMPROV | AO1: FUND_CARBON_SCOPE_12_INTEN_3Y_TREND_M_WORSE | AP1: GOVERNANCE_PILLAR_QUARTILE | AQ1: GOVERNANCE_PCTL_GLOBAL | AR1: INDUSTRY_ADJUSTED_SCORE | AS1: CO2/EVIC | AT1: FUND_ESG_QUALITY_SCORE_PCTL_GLOBAL | AU1: FUND_GOV_GLOBAL_LEADERS_PCT | AV1: FUND_GOV_GLOBAL_AVERAGE_PCT | AW1: FUND_GOV_GLOBAL_LAGGARDS_PCT | AX1: FUND_FINANCED_CARBON_EMISSIONS | AY1: ITR | AZ1: Cobertura | BA1: Weight_Ingresado | BB1: Weight_Cubierto | BC1: Weight_N | BD1: trend*Wn | BE1: E*Wn | BF1: S*Wn | BG1: G*Wn | BH1: ESG*Wn | BI1: Controversia*Wn | BJ1: CO2/Sales*Wn | BK1: CO2/EVIC*Wn | BL1: CO2*Wn | BM1: Gov*Wn
B2: 12535622BA92 | C2: USP58072BA92 | D2: 0.0013603332 | E2: Multifondos | F2: RFIC | G2: BU | H2: Ex_Integra | I2: 7.7424621e+10 | J2: 3.4075 | K2: 31330 | M2: 46174 | N2: 5356 | O2: 986.57053 | P2: 1.0532329e+08 | AI2: rt | AJ2: rt | AK2: rt | AL2: rt | AM2: rt | AN2: rt | AO2: rt | AT2: rt | AU2: rt | AV2: rt | AW2: rt | AX2: rt | AZ2: NoCov | BA2: 0.62163188 | BB2: 0.14542962 | BC2: 0.0093538937
B3: 15515123CH47 | C3: USP32133CH47 | D3: 0.0012602963 | E3: F1 | F3: RFIC | G3: BU | H3: Ex_Integra | I3: 1.3660104e+10 | J3: 3.4075 | K3: 4675.0074 | M3: 46174 | N3: 5151 | O3: 1080.7083 | P3: 17215779 | AI3: rt | AJ3: rt | AK3: rt | AL3: rt | AM3: rt | AN3: rt | AO3: rt | AT3: rt | AU3: rt | AV3: rt | AW3: rt | AX3: rt | AZ3: NoCov | BA3: 0.57964491 | BB3: 0.30151641 | BC3: 0.0041798599
B4: 2100022V2H78 | C4: US05971V2H78 | D4: 0.00084844162 | E4: Multifondos | F4: RFLC | G4: BU | H4: Habitat | I4: 2.2785495e+10 | J4: 3.4075 | K4: 5532.97 | M4: 46174 | N4: 0002 | O4: 1025.3833 | P4: 19332162 | AI4: rt | AJ4: rt | AK4: rt | AL4: rt | AM4: rt | AN4: rt | AO4: rt | AT4: rt | AU4: rt | AV4: rt | AW4: rt | AX4: rt | AZ4: NoCov | BA4: 0.65823103 | BB4: 0.11726488 | BC4: 0.0072352577
A5: 509401 | B5: 59509428AJ82 | C5: US279158AJ82 | D5: 0.00096096238 | E5: F1 | F5: RFIC | G5: BU | H5: Habitat | I5: 1.8939189e+09 | J5: 3.4075 | K5: 644.13118 | L5: Ecopetrol S.A. | M5: 46174 | N5: 5094 | O5: 829.19671 | P5: 1819984.8 | Q5: Energy | R5: Colombia | S5: CO | T5: Integrated Oil & Gas | U5: A | V5: 1 | W5: 4.9145451 | X5: 8.1681979 | Y5: 4.609375 | Z5: 41 | AA5: 26 | AB5: 33 | AC5: 4 | AD5: 12677105 | AE5: 418.89 | AF5: 5.9190111 | AG5: 7.4017041 | AH5: 5.9 | AI5: rt | AJ5: rt | AK5: rt | AL5: rt | AM5: rt | AN5: rt | AO5: rt | AP5: 2 | AQ5: 39 | AR5: 6.51 | AS5: 226.35 | AT5: rt | AU5: rt | AV5: rt | AW5: rt | AX5: rt | AY5: Strongly Misaligned | AZ5: Cov | BA5: 0.63778762 | BB5: 0.36085898 | BC5: 0.0026629859 | BD5: 0.0026629859 | BE5: 0.013087364 | BF5: 0.021751796 | BG5: 0.0122747 | BH5: 0.017336038 | BI5: 0.010651943 | BJ5: 1.1154982 | BK5: 0.60276685 | BL5: 33758.951 | BM5: 0.0053259717
B6: 1254342KAB22 | C6: USP4R21KAB22 | D6: 0.0023538246 | E6: Multifondos | F6: RFIC | G6: BU | H6: Ex_Integra | I6: 7.7424621e+10 | J6: 3.4075 | K6: 47705 | M6: 46174 | N6: 5434 | O6: 1121.1234 | P6: 1.8224398e+08 | AI6: rt | AJ6: rt | AK6: rt | AL6: rt | AM6: rt | AN6: rt | AO6: rt | AT6: rt | AU6: rt | AV6: rt | AW6: rt | AX6: rt | AZ6: NoCov | BA6: 0.62163188 | BB6: 0.14542962 | BC6: 0.016185317
B7: 12535622BA92 | C7: USP58072BA92 | D7: 0.0032170875 | E7: Multifondos | F7: RFIC | G7: BU | H7: Prima | I7: 3.2738708e+10 | J7: 3.4075 | K7: 31330 | M7: 46174 | N7: 5356 | O7: 986.57053 | P7: 1.0532329e+08 | AI7: rt | AJ7: rt | AK7: rt | AL7: rt | AM7: rt | AN7: rt | AO7: rt | AT7: rt | AU7: rt | AV7: rt | AW7: rt | AX7: rt | AZ7: NoCov | BA7: 0.62127201 | BB7: 0.1558531 | BC7: 0.020641794
B8: 1551192MAD04 | C8: USP1400MAD04 | D8: 0.0024271404 | E8: Multifondos | F8: RFIC | G8: BU | H8: Profuturo | I8: 2.1900418e+10 | J8: 3.4075 | K8: 15093.95 | M8: 46174 | N8: 5119 | O8: 1033.4953 | P8: 53155388 | AI8: rt | AJ8: rt | AK8: rt | AL8: rt | AM8: rt | AN8: rt | AO8: rt | AT8: rt | AU8: rt | AV8: rt | AW8: rt | AX8: rt | AZ8: NoCov | BA8: 0.58409167 | BB8: 0.15915074 | BC8: 0.015250576
B9: 1551112LAN29 | C9: US05968LAN29 | D9: 0.00034459576 | E9: Multifondos | F9: RFIC | G9: BU | H9: Ex_Integra | I9: 7.7424621e+10 | J9: 3.4075 | K9: 7319 | M9: 46174 | N9: 5111 | O9: 1069.7971 | P9: 26680196 | AI9: rt | AJ9: rt | AK9: rt | AL9: rt | AM9: rt | AN9: rt | AO9: rt | AT9: rt | AU9: rt | AV9: rt | AW9: rt | AX9: rt | AZ9: NoCov | BA9: 0.62163188 | BB9: 0.14542962 | BC9: 0.0023695019
B10: 15515123CH47 | C10: USP32133CH47 | D10: 0.00354492 | E10: F1 | F10: RFIC | G10: BU | H10: Profuturo | I10: 4.856457e+09 | J10: 3.4075 | K10: 4675 | M10: 46174 | N10: 5151 | O10: 1080.7083 | P10: 17215751 | AI10: rt | AJ10: rt | AK10: rt | AL10: rt | AM10: rt | AN10: rt | AO10: rt | AT10: rt | AU10: rt | AV10: rt | AW10: rt | AX10: rt | AZ10: NoCov | BA10: 0.58036121 | BB10: 0.33866066 | BC10: 0.010467469
B11: 1551512PAC05 | C11: US05890PAC05 | D11: 0.0038776307 | E11: F1 | F11: RFIC | G11: BU | H11: Ex_Integra | I11: 1.3660104e+10 | J11: 3.4075 | K11: 14039 | M11: 46174 | N11: 5151 | O11: 1107.2569 | P11: 52968839 | AI11: rt | AJ11: rt | AK11: rt | AL11: rt | AM11: rt | AN11: rt | AO11: rt | AT11: rt | AU11: rt | AV11: rt | AW11: rt | AX11: rt | AZ11: NoCov | BA11: 0.57964491 | BB11: 0.30151641 | BC11: 0.01286043
B12: 15515123CH47 | C12: USP32133CH47 | D12: 3.9640842e-09 | E12: F1 | F12: RFIC | G12: BU | H12: Prima | I12: 6.909728e+09 | J12: 3.4075 | K12: 0.0074380562 | M12: 46174 | N12: 5151 | O12: 1080.7083 | P12: 27.390743 | AI12: rt | AJ12: rt | AK12: rt | AL12: rt | AM12: rt | AN12: rt | AO12: rt | AT12: rt | AU12: rt | AV12: rt | AW12: rt | AX12: rt | AZ12: NoCov | BA12: 0.56320494 | BB12: 0.28214925 | BC12: 1.40496e-08
B13: 2100022V2J35 | C13: US05971V2J35 | D13: 0.00092579384 | E13: Multifondos | F13: RFLC | G13: BU | H13: Habitat | I13: 2.2785495e+10 | J13: 3.4075 | K13: 5839.83 | M13: 46174 | N13: 0002 | O13: 1060.0752 | P13: 21094671 | AI13: rt | AJ13: rt | AK13: rt | AL13: rt | AM13: rt | AN13: rt | AO13: rt | AT13: rt | AU13: rt | AV13: rt | AW13: rt | AX13: rt | AZ13: NoCov | BA13: 0.65823103 | BB13: 0.11726488 | BC13: 0.0078948945
B14: 1551192MAD04 | C14: USP1400MAD04 | D14: 0.0028494034 | E14: Multifondos | F14: RFIC | G14: BU | H14: Ex_Integra | I14: 7.7424621e+10 | J14: 3.4075 | K14: 62645.32 | M14: 46174 | N14: 5119 | O14: 1033.4953 | P14: 2.2061397e+08 | AI14: rt | AJ14: rt | AK14: rt | AL14: rt | AM14: rt | AN14: rt | AO14: rt | AT14: rt | AU14: rt | AV14: rt | AW14: rt | AX14: rt | AZ14: NoCov | BA14: 0.62163188 | BB14: 0.14542962 | BC14: 0.019593005
B15: 15515123CH47 | C15: USP32133CH47 | D15: 0.00022235535 | E15: Multifondos | F15: RFIC | G15: BU | H15: Ex_Integra | I15: 7.7424621e+10 | J15: 3.4075 | K15: 4675.0074 | M15: 46174 | N15: 5151 | O15: 1080.7083 | P15: 17215779 | AI15: rt | AJ15: rt | AK15: rt | AL15: rt | AM15: rt | AN15: rt | AO15: rt | AT15: rt | AU15: rt | AV15: rt | AW15: rt | AX15: rt | AZ15: NoCov | BA15: 0.62163188 | BB15: 0.14542962 | BC15: 0.001528955
B16: 1254342KAB22 | C16: USP4R21KAB22 | D16: 0.005566621 | E16: Multifondos | F16: RFIC | G16: BU | H16: Prima | I16: 3.2738708e+10 | J16: 3.4075 | K16: 47705 | M16: 46174 | N16: 5434 | O16: 1121.1234 | P16: 1.8224398e+08 | AI16: rt | AJ16: rt | AK16: rt | AL16: rt | AM16: rt | AN16: rt | AO16: rt | AT16: rt | AU16: rt | AV16: rt | AW16: rt | AX16: rt | AZ16: NoCov | BA16: 0.62127201 | BB16: 0.1558531 | BC16: 0.035717102
B17: 1551192MAD04 | C17: USP1400MAD04 | D17: 0.0086965016 | E17: F1 | F17: RFIC | G17: BU | H17: Ex_Integra | I17: 1.3660104e+10 | J17: 3.4075 | K17: 33732.94 | M17: 46174 | N17: 5119 | O17: 1033.4953 | P17: 1.1879511e+08 | AI17: rt | AJ17: rt | AK17: rt | AL17: rt | AM17: rt | AN17: rt | AO17: rt | AT17: rt | AU17: rt | AV17: rt | AW17: rt | AX17: rt | AZ17: NoCov | BA17: 0.57964491 | BB17: 0.30151641 | BC17: 0.028842549
... B20: 1254342KAB22 | C20: USP4R21KAB22 | D20: 0.002263091 | E20: Multifondos | F20: RFIC | G20: BU | H20: Integra | I20: 3.9311487e+10 | J20: 3.4075 | K20: 23288 | M20: 46174 | N20: 5434 | O20: 1121.1234 | P20: 88965470 | AI20: rt | AJ20: rt | AK20: rt | AL20: rt | AM20: rt | AN20: rt | AO20: rt | AT20: rt | AU20: rt | AV20: rt | AW20: rt | AX20: rt | AZ20: NoCov | BA20: 0.59538531 | BB20: 0.13474712 | BC20: 0.016795097
A21: 527801 | B21: 15527829AM84 | C21: USP16259AM84 | D21: 0.00060143115 | E21: Multifondos | F21: RFIC | G21: BU | H21: Ex_Integra | I21: 7.7424621e+10 | J21: 3.4075 | K21: 13622 | L21: BBVA Mexico, S.A., Institucion de Banca Multiple, Grupo Financiero BBVA Mexico | M21: 46174 | N21: 5278 | O21: 1003.2017 | P21: 46565578 | Q21: Financials | R21: Mexico | S21: MX | T21: Banks | U21: AA | V21: 0 | W21: 8.4489927 | X21: 5.8658712 | Y21: 4.8984375 | Z21: 13 | AA21: 54 | AB21: 33 | AC21: 4 | AD21: 249742 | AE21: 2.68 | AF21: 10 | AG21: 2.085084 | AH21: 7.5 | AI21: rt | AJ21: rt | AK21: rt | AL21: rt | AM21: rt | AN21: rt | AO21: rt | AP21: 4 | AQ21: 75 | AR21: 8.27 | AS21: 0.77 | AT21: rt | AU21: rt | AV21: rt | AW21: rt | AX21: rt | AY21: 1.5°C Aligned | AZ21: Cov | BA21: 0.62163188 | BB21: 0.47620225 | BC21: 0.0012629742 | BD21: 0 | BE21: 0.01067086 | BF21: 0.0074084437 | BG21: 0.0061866 | BH21: 0.010444796 | BI21: 0.0050518967 | BJ21: 0.0033847708 | BK21: 0.00097249011 | BL21: 315.41769 | BM21: 0.0050518967
B22: 1551192MAD04 | C22: USP1400MAD04 | D22: 0.0020033656 | E22: F2 | F22: RFIC | G22: BU | H22: Ex_Integra | I22: 5.0823903e+10 | J22: 3.4075 | K22: 28912.38 | M22: 46174 | N22: 5119 | O22: 1033.4953 | P22: 1.0181886e+08 | AI22: rt | AJ22: rt | AK22: rt | AL22: rt | AM22: rt | AN22: rt | AO22: rt | AT22: rt | AU22: rt | AV22: rt | AW22: rt | AX22: rt | AZ22: NoCov | BA22: 0.60589742 | BB22: 0.14204353 | BC22: 0.014103885
B23: 2100022V2K08 | C23: US05971V2K08 | D23: 0.0012592095 | E23: Multifondos | F23: RFLC | G23: BU | H23: Habitat | I23: 2.2785495e+10 | J23: 3.4075 | K23: 8157.37 | M23: 46174 | N23: 0002 | O23: 1032.2156 | P23: 28691712 | AI23: rt | AJ23: rt | AK23: rt | AL23: rt | AM23: rt | AN23: rt | AO23: rt | AT23: rt | AU23: rt | AV23: rt | AW23: rt | AX23: rt | AZ23: NoCov | BA23: 0.65823103 | BB23: 0.11726488 | BC23: 0.010738164
A24: 527801 | B24: 15527829AN67 | C24: USP16259AN67 | D24: 0.0011411929 | E24: Multifondos | F24: RFIC | G24: BU | H24: Ex_Integra | I24: 7.7424621e+10 | J24: 3.4075 | K24: 25841.48 | L24: BBVA Mexico, S.A., Institucion de Banca Multiple, Grupo Financiero BBVA Mexico | M24: 46174 | N24: 5278 | O24: 1003.425 | P24: 88356431 | Q24: Financials | R24: Mexico | S24: MX | T24: Banks | U24: AA | V24: 0 | W24: 8.4489927 | X24: 5.8658712 | Y24: 4.8984375 | Z24: 13 | AA24: 54 | AB24: 33 | AC24: 4 | AD24: 249742 | AE24: 2.68 | AF24: 10 | AG24: 2.085084 | AH24: 7.5 | AI24: rt | AJ24: rt | AK24: rt | AL24: rt | AM24: rt | AN24: rt | AO24: rt | AP24: 4 | AQ24: 75 | AR24: 8.27 | AS24: 0.77 | AT24: rt | AU24: rt | AV24: rt | AW24: rt | AX24: rt | AY24: 1.5°C Aligned | AZ24: Cov | BA24: 0.62163188 | BB24: 0.47620225 | BC24: 0.0023964459 | BD24: 0 | BE24: 0.020247554 | BF24: 0.014057243 | BG24: 0.011738841 | BH24: 0.019818608 | BI24: 0.0095857837 | BJ24: 0.0064224751 | BK24: 0.0018452634 | BL24: 598.4932 | BM24: 0.0095857837
B25: 1552782BAB48 | C25: USP1S81BAB48 | D25: 0.00072717208 | E25: Multifondos | F25: RFIC | G25: BU | H25: Profuturo | I25: 2.1900418e+10 | J25: 3.4075 | K25: 4217.9 | M25: 46174 | N25: 5278 | O25: 1108.0451 | P25: 15925372 | AI25: rt | AJ25: rt | AK25: rt | AL25: rt | AM25: rt | AN25: rt | AO25: rt | AT25: rt | AU25: rt | AV25: rt | AW25: rt | AX25: rt | AZ25: NoCov | BA25: 0.58409167 | BB25: 0.15915074 | BC25: 0.0045690776
B26: 1552782GAA15 | C26: USP2000GAA15 | D26: 0.00085934127 | E26: F1 | F26: RFIC | G26: BU | H26: Ex_Integra | I26: 1.3660104e+10 | J26: 3.4075 | K26: 3233 | M26: 46174 | N26: 5278 | O26: 1065.5605 | P26: 11738691 | AI26: rt | AJ26: rt | AK26: rt | AL26: rt | AM26: rt | AN26: rt | AO26: rt | AT26: rt | AU26: rt | AV26: rt | AW26: rt | AX26: rt | AZ26: NoCov | BA26: 0.57964491 | BB26: 0.30151641 | BC26: 0.0028500647
A27: 527801 | B27: 1552782BAA64 | C27: USP1S81BAA64 | D27: 0.00016144479 | E27: Multifondos | F27: RFIC | G27: BU | H27: Ex_Integra | I27: 7.7424621e+10 | J27: 3.4075 | K27: 3398 | L27: BBVA Mexico, S.A., Institucion de Banca Multiple, Grupo Financiero BBVA Mexico | M27: 46174 | N27: 5278 | O27: 1079.5528 | P27: 12499802 | Q27: Financials | R27: Mexico | S27: MX | T27: Banks | U27: AA | V27: 0 | W27: 8.4489927 | X27: 5.8658712 | Y27: 4.8984375 | Z27: 13 | AA27: 54 | AB27: 33 | AC27: 4 | AD27: 249742 | AE27: 2.68 | AF27: 10 | AG27: 2.085084 | AH27: 7.5 | AI27: rt | AJ27: rt | AK27: rt | AL27: rt | AM27: rt | AN27: rt | AO27: rt | AP27: 4 | AQ27: 75 | AR27: 8.27 | AS27: 0.77 | AT27: rt | AU27: rt | AV27: rt | AW27: rt | AX27: rt | AY27: 1.5°C Aligned | AZ27: Cov | BA27: 0.62163188 | BB27: 0.47620225 | BC27: 0.00033902567 | BD27: 0 | BE27: 0.0028644254 | BF27: 0.0019886809 | BG27: 0.0016606961 | BH27: 0.0028037423 | BI27: 0.0013561027 | BJ27: 0.0009085888 | BK27: 0.00026104977 | BL27: 84.668949 | BM27: 0.0013561027
B28: 1552782BAB48 | C28: USP1S81BAB48 | D28: 0.001226819 | E28: Multifondos | F28: RFIC | G28: BU | H28: Ex_Integra | I28: 7.7424621e+10 | J28: 3.4075 | K28: 25157.43 | M28: 46174 | N28: 5278 | O28: 1108.0451 | P28: 94985998 | AI28: rt | AJ28: rt | AK28: rt | AL28: rt | AM28: rt | AN28: rt | AO28: rt | AT28: rt | AU28: rt | AV28: rt | AW28: rt | AX28: rt | AZ28: NoCov | BA28: 0.62163188 | BB28: 0.14542962 | BC28: 0.0084358262
B29: 1551112LAN29 | C29: US05968LAN29 | D29: 0.00081494348 | E29: Multifondos | F29: RFIC | G29: BU | H29: Prima | I29: 3.2738708e+10 | J29: 3.4075 | K29: 7319 | M29: 46174 | N29: 5111 | O29: 1069.7971 | P29: 26680196 | AI29: rt | AJ29: rt | AK29: rt | AL29: rt | AM29: rt | AN29: rt | AO29: rt | AT29: rt | AU29: rt | AV29: rt | AW29: rt | AX29: rt | AZ29: NoCov | BA29: 0.62127201 | BB29: 0.1558531 | BC29: 0.0052289207
B30: 1552782GAA15 | C30: USP2000GAA15 | D30: 0.00033919805 | E30: Multifondos | F30: RFIC | G30: BU | H30: Ex_Integra | I30: 7.7424621e+10 | J30: 3.4075 | K30: 7233 | M30: 46174 | N30: 5278 | O30: 1065.5605 | P30: 26262280 | AI30: rt | AJ30: rt | AK30: rt | AL30: rt | AM30: rt | AN30: rt | AO30: rt | AT30: rt | AU30: rt | AV30: rt | AW30: rt | AX30: rt | AZ30: NoCov | BA30: 0.62163188 | BB30: 0.14542962 | BC30: 0.0023323862
B31: 1551112LAN29 | C31: US05968LAN29 | D31: 0.0027798442 | E31: Multifondos | F31: RFIC | G31: BU | H31: Integra | I31: 3.9311487e+10 | J31: 3.4075 | K31: 29978 | M31: 46174 | N31: 5111 | O31: 1069.7971 | P31: 1.0927981e+08 | AI31: rt | AJ31: rt | AK31: rt | AL31: rt | AM31: rt | AN31: rt | AO31: rt | AT31: rt | AU31: rt | AV31: rt | AW31: rt | AX31: rt | AZ31: NoCov | BA31: 0.59538531 | BB31: 0.13474712 | BC31: 0.020630082
B32: 1551512PAC05 | C32: US05890PAC05 | D32: 0.0076658356 | E32: F1 | F32: RFIC | G32: BU | H32: Prima | I32: 6.909728e+09 | J32: 3.4075 | K32: 14039 | M32: 46174 | N32: 5151 | O32: 1107.2569 | P32: 52968839 | AI32: rt | AJ32: rt | AK32: rt | AL32: rt | AM32: rt | AN32: rt | AO32: rt | AT32: rt | AU32: rt | AV32: rt | AW32: rt | AX32: rt | AZ32: NoCov | BA32: 0.56320494 | BB32: 0.28214925 | BC32: 0.027169434
B33: 1551192MAD04 | C33: USP1400MAD04 | D33: 0.005115003 | E33: Multifondos | F33: RFIC | G33: BU | H33: Prima | I33: 3.2738708e+10 | J33: 3.4075 | K33: 47551.37 | M33: 46174 | N33: 5119 | O33: 1033.4953 | P33: 1.6745859e+08 | AI33: rt | AJ33: rt | AK33: rt | AL33: rt | AM33: rt | AN33: rt | AO33: rt | AT33: rt | AU33: rt | AV33: rt | AW33: rt | AX33: rt | AZ33: NoCov | BA33: 0.62127201 | BB33: 0.1558531 | BC33: 0.032819386
B34: 1552782GAA15 | C34: USP2000GAA15 | D34: 0.0011223262 | E34: F3 | F34: RFIC | G34: BU | H34: Ex_Integra | I34: 1.2940613e+10 | J34: 3.4075 | K34: 4000 | M34: 46174 | N34: 5278 | O34: 1065.5605 | P34: 14523589 | AI34: rt | AJ34: rt | AK34: rt | AL34: rt | AM34: rt | AN34: rt | AO34: rt | AT34: rt | AU34: rt | AV34: rt | AW34: rt | AX34: rt | AZ34: NoCov | BA34: 0.8040057 | BB34: 0.070219065 | BC34: 0.015983212
B35: 15532427PD99 | C35: USP0R137PD99 | D35: 0.0035958357 | E35: Multifondos | F35: RFIC | G35: BU | H35: Ex_Integra | I35: 7.7424621e+10 | J35: 3.4075 | K35: 75813.31 | M35: 46174 | N35: 5324 | O35: 1077.6993 | P35: 2.7840621e+08 | AI35: rt | AJ35: rt | AK35: rt | AL35: rt | AM35: rt | AN35: rt | AO35: rt | AT35: rt | AU35: rt | AV35: rt | AW35: rt | AX35: rt | AZ35: NoCov | BA35: 0.62163188 | BB35: 0.14542962 | BC35: 0.024725607
B36: 21000325AF20 | C36: USP13435AF20 | D36: 2.7940878e-05 | E36: Multifondos | F36: RFLC | G36: BU | H36: Habitat | I36: 2.2785495e+10 | J36: 3.4075 | K36: 172.01 | M36: 46174 | N36: 0003 | O36: 1086.1979 | P36: 636646.75 | AI36: rt | AJ36: rt | AK36: rt | AL36: rt | AM36: rt | AN36: rt | AO36: rt | AT36: rt | AU36: rt | AV36: rt | AW36: rt | AX36: rt | AZ36: NoCov | BA36: 0.65823103 | BB36: 0.11726488 | BC36: 0.0002382715
A37: 509401 | B37: 59509428AJ82 | C37: US279158AJ82 | D37: 0.00064020052 | E37: F2 | F37: RFIC | G37: BU | H37: Habitat | I37: 1.4820338e+10 | J37: 3.4075 | K37: 3358 | L37: Ecopetrol S.A. | M37: 46174 | N37: 5094 | O37: 829.19671 | P37: 9487988 | Q37: Energy | R37: Colombia | S37: CO | T37: Integrated Oil & Gas | U37: A | V37: 1 | W37: 4.9145451 | X37: 8.1681979 | Y37: 4.609375 | Z37: 41 | AA37: 26 | AB37: 33 | AC37: 4 | AD37: 12677105 | AE37: 418.89 | AF37: 5.9190111 | AG37: 7.4017041 | AH37: 5.9 | AI37: rt | AJ37: rt | AK37: rt | AL37: rt | AM37: rt | AN37: rt | AO37: rt | AP37: 2 | AQ37: 39 | AR37: 6.51 | AS37: 226.35 | AT37: rt | AU37: rt | AV37: rt | AW37: rt | AX37: rt | AY37: Strongly Misaligned | AZ37: Cov | BA37: 0.61054168 | BB37: 0.49055401 | BC37: 0.0013050561 | BD37: 0.0013050561 | BE37: 0.0064137571 | BF37: 0.010659957 | BG37: 0.0060154931 | BH37: 0.0084959154 | BI37: 0.0052202245 | BJ37: 0.54667496 | BK37: 0.29539945 | BL37: 16544.334 | BM37: 0.0026101122
A38: 209601 | B38: 182096345816 | C38: XS0799645816 | D38: 0.0046054666 | E38: Multifondos | F38: RFLC | G38: BU | H38: Ex_Integra | I38: 7.7424621e+10 | J38: 1 | K38: 303359 | M38: 46174 | N38: 2096 | O38: 1175.4275 | P38: 3.5657651e+08 | Q38: Industrials | R38: Peru | AI38: rt | AJ38: rt | AK38: rt | AL38: rt | AM38: rt | AN38: rt | AO38: rt | AT38: rt | AU38: rt | AV38: rt | AW38: rt | AX38: rt | AZ38: NoCov | BA38: 0.62163188 | BB38: 0.14542962 | BC38: 0.031668009
A39: 527801 | B39: 15527829AM84 | C39: USP16259AM84 | D39: 0.00091621412 | E39: F2 | F39: RFIC | G39: BU | H39: Ex_Integra | I39: 5.0823903e+10 | J39: 3.4075 | K39: 13622 | L39: BBVA Mexico, S.A., Institucion de Banca Multiple, Grupo Financiero BBVA Mexico | M39: 46174 | N39: 5278 | O39: 1003.2017 | P39: 46565578 | Q39: Financials | R39: Mexico | S39: MX | T39: Banks | U39: AA | V39: 0 | W39: 8.4489927 | X39: 5.8658712 | Y39: 4.8984375 | Z39: 13 | AA39: 54 | AB39: 33 | AC39: 4 | AD39: 249742 | AE39: 2.68 | AF39: 10 | AG39: 2.085084 | AH39: 7.5 | AI39: rt | AJ39: rt | AK39: rt | AL39: rt | AM39: rt | AN39: rt | AO39: rt | AP39: 4 | AQ39: 75 | AR39: 8.27 | AS39: 0.77 | AT39: rt | AU39: rt | AV39: rt | AW39: rt | AX39: rt | AY39: 1.5°C Aligned | AZ39: Cov | BA39: 0.60589742 | BB39: 0.46385389 | BC39: 0.0019752214 | BD39: 0 | BE39: 0.016688631 | BF39: 0.011586394 | BG39: 0.0096754984 | BH39: 0.016335081 | BI39: 0.0079008855 | BJ39: 0.0052935933 | BK39: 0.0015209205 | BL39: 493.29574 | BM39: 0.0079008855
A40: 209601 | B40: 182096345816 | C40: XS0799645816 | D40: 0.0075675691 | E40: Multifondos | F40: RFLC | G40: BU | H40: Profuturo | I40: 2.1900418e+10 | J40: 1 | K40: 140998 | M40: 46174 | N40: 2096 | O40: 1175.4275 | P40: 1.6573292e+08 | Q40: Industrials | R40: Peru | AI40: rt | AJ40: rt | AK40: rt | AL40: rt | AM40: rt | AN40: rt | AO40: rt | AT40: rt | AU40: rt | AV40: rt | AW40: rt | AX40: rt | AZ40: NoCov | BA40: 0.58409167 | BB40: 0.15915074 | BC40: 0.047549695
B41: 1551192MAD04 | C41: USP1400MAD04 | D41: 0.010945302 | E41: F1 | F41: RFIC | G41: BU | H41: Profuturo | I41: 4.856457e+09 | J41: 3.4075 | K41: 15093.95 | M41: 46174 | N41: 5119 | O41: 1033.4953 | P41: 53155388 | AI41: rt | AJ41: rt | AK41: rt | AL41: rt | AM41: rt | AN41: rt | AO41: rt | AT41: rt | AU41: rt | AV41: rt | AW41: rt | AX41: rt | AZ41: NoCov | BA41: 0.58036121 | BB41: 0.33866066 | BC41: 0.032319378
B42: 1552782BAB48 | C42: USP1S81BAB48 | D42: 0.0032792162 | E42: F1 | F42: RFIC | G42: BU | H42: Profuturo | I42: 4.856457e+09 | J42: 3.4075 | K42: 4217.9 | M42: 46174 | N42: 5278 | O42: 1108.0451 | P42: 15925372 | AI42: rt | AJ42: rt | AK42: rt | AL42: rt | AM42: rt | AN42: rt | AO42: rt | AT42: rt | AU42: rt | AV42: rt | AW42: rt | AX42: rt | AZ42: NoCov | BA42: 0.58036121 | BB42: 0.33866066 | BC42: 0.0096828968
...

Sheet BD1_S
A1: SBS | B1: ISIN | C1: Weight | D1: Fondo | E1: assetclass | F1: Strategy | G1: Afp | H1: AUM | I1: Tipo | J1: Q | K1: Nombre | L1: Fecha | M1: codEmisor | N1: Precio | O1: Inversión | P1: Cov? | R1: NUEVA COBERTURA
A2: 15515123CH47 | B2: USP32133CH47 | C2: 0.0012602963 | D2: F1 | E2: RFIC | F2: BU | G2: Ex_Integra | H2: 1.3660104e+10 | I2: 3.6555 | J2: 4675.0074 | L2: 46174 | M2: 5151 | N2: 1080.7083 | O2: 18468754 | P2: =+IFERROR(IF(OR(B2="PEP795509FD5",B2="CVL79560FI39",B2="CVL79590GA30")=FALSE,IF(F2="SOB","Cov",INDEX('ANALISIS BD'!AZ:AZ,MATCH(BD1_S!B2,'ANALISIS BD'!C:C,0))),"NoCov"),"NoCov") -> NoCov | R2: Integra | V2: Ex_Integra
A3: 15515123CH47 | B3: USP32133CH47 | C3: 0.0032138989 | D3: F1 | E3: RFIC | F3: BU | G3: Integra | H3: 7.9289969e+09 | I3: 3.6555 | J3: 6920 | L3: 46174 | M3: 5151 | N3: 1080.7083 | O3: 27337663 | P3: =+IFERROR(IF(OR(B3="PEP795509FD5",B3="CVL79560FI39",B3="CVL79590GA30")=FALSE,IF(F3="SOB","Cov",INDEX('ANALISIS BD'!AZ:AZ,MATCH(BD1_S!B3,'ANALISIS BD'!C:C,0))),"NoCov"),"NoCov") -> NoCov | R3: F1 | V3: F1
A4: 15515123CH47 | B4: USP32133CH47 | C4: 3.9640842e-09 | D4: F1 | E4: RFIC | F4: BU | G4: Prima | H4: 6.909728e+09 | I4: 3.6555 | J4: 0.0074380562 | L4: 46174 | M4: 5151 | N4: 1080.7083 | O4: 29.384259 | P4: =+IFERROR(IF(OR(B4="PEP795509FD5",B4="CVL79560FI39",B4="CVL79590GA30")=FALSE,IF(F4="SOB","Cov",INDEX('ANALISIS BD'!AZ:AZ,MATCH(BD1_S!B4,'ANALISIS BD'!C:C,0))),"NoCov"),"NoCov") -> NoCov | S4: Cov | T4: =+SUMIFS($C:$C,$D:$D,$R$3,$G:$G,$R$2,$P:$P,S4) -> 0.7151317 | W4: Cov | X4: =+SUMIFS($C:$C,$D:$D,$R$3,$G:$G,$V$2,$P:$P,W4) -> 0.67478395
A5: 011000112B29 | B5: PEP01000C5F6 | C5: 0.00024750793 | D5: Multifondos | E5: RFLG | F5: SOB | G5: Ex_Integra | H5: 7.7424621e+10 | I5: 1 | J5: 17821 | K5: Gobierno Central | L5: 46174 | M5: 1000 | N5: 1075.3161 | O5: 19163208 | P5: =+IFERROR(IF(OR(B5="PEP795509FD5",B5="CVL79560FI39",B5="CVL79590GA30")=FALSE,IF(F5="SOB","Cov",INDEX('ANALISIS BD'!AZ:AZ,MATCH(BD1_S!B5,'ANALISIS BD'!C:C,0))),"NoCov"),"NoCov") -> Cov | S5: NoCov | T5: =+SUMIFS($C:$C,$D:$D,$R$3,$G:$G,$R$2,$P:$P,S5) -> 0.2702173 | W5: NoCov | X5: =+SUMIFS($C:$C,$D:$D,$R$3,$G:$G,$V$2,$P:$P,W5) -> 0.30151641
A6: 5270772F2269 | B6: LU0727122698 | C6: 0.0012256398 | D6: F1 | E6: RFIG | F6: TD | G6: Ex_Integra | H6: 1.3660104e+10 | I6: 3.6555 | J6: 144383.99 | K6: Franklin Templeton - Global Convertibles | L6: 46174 | M6: 7077 | N6: 34.03 | O6: 17960887 | P6: =+IFERROR(IF(OR(B6="PEP795509FD5",B6="CVL79560FI39",B6="CVL79590GA30")=FALSE,IF(F6="SOB","Cov",INDEX('ANALISIS BD'!AZ:AZ,MATCH(BD1_S!B6,'ANALISIS BD'!C:C,0))),"NoCov"),"NoCov") -> Cov | S6: Total | T6: =+T4+T5 -> 0.985349 | W6: Total | X6: =+X4+X5 -> 0.97630036
A7: 011000112B29 | B7: PEP01000C5F6 | C7: 0.00024550127 | D7: Multifondos | E7: RFLG | F7: SOB | G7: Profuturo | H7: 2.1900418e+10 | I7: 1 | J7: 5000 | K7: Gobierno Central | L7: 46174 | M7: 1000 | N7: 1075.3161 | O7: 5376580.4 | P7: =+IFERROR(IF(OR(B7="PEP795509FD5",B7="CVL79560FI39",B7="CVL79590GA30")=FALSE,IF(F7="SOB","Cov",INDEX('ANALISIS BD'!AZ:AZ,MATCH(BD1_S!B7,'ANALISIS BD'!C:C,0))),"NoCov"),"NoCov") -> Cov
A8: 011000112F42 | B8: PEP01000C4L7 | C8: 0.002826684 | D8: Multifondos | E8: RFLG | F8: SOB | G8: Ex_Integra | H8: 7.7424621e+10 | I8: 1 | J8: 208404 | K8: Gobierno Central | L8: 46174 | M8: 1000 | N8: 1050.1475 | O8: 2.1885493e+08 | P8: =+IFERROR(IF(OR(B8="PEP795509FD5",B8="CVL79560FI39",B8="CVL79590GA30")=FALSE,IF(F8="SOB","Cov",INDEX('ANALISIS BD'!AZ:AZ,MATCH(BD1_S!B8,'ANALISIS BD'!C:C,0))),"NoCov"),"NoCov") -> Cov | R8: F2 | V8: F2
A9: 011000112F42 | B9: PEP01000C4L7 | C9: 0.0041587425 | D9: Multifondos | E9: RFLG | F9: SOB | G9: Habitat | H9: 2.2785495e+10 | I9: 1 | J9: 90234 | K9: Gobierno Central | L9: 46174 | M9: 1000 | N9: 1050.1475 | O9: 94759007 | P9: =+IFERROR(IF(OR(B9="PEP795509FD5",B9="CVL79560FI39",B9="CVL79590GA30")=FALSE,IF(F9="SOB","Cov",INDEX('ANALISIS BD'!AZ:AZ,MATCH(BD1_S!B9,'ANALISIS BD'!C:C,0))),"NoCov"),"NoCov") -> Cov | S9: Cov | T9: =+SUMIFS($C:$C,$D:$D,$R$8,$G:$G,$R$2,$P:$P,S9) -> 0.70685114 | W9: Cov | X9: =+SUMIFS($C:$C,$D:$D,$R$8,$G:$G,$V$2,$P:$P,W9) -> 0.69051509
A10: 011000112F55 | B10: PEP01000C4S2 | C10: 0.0012107429 | D10: Multifondos | E10: RFLG | F10: SOB | G10: Ex_Integra | H10: 7.7424621e+10 | I10: 1 | J10: 88895 | K10: Gobierno Central | L10: 46174 | M10: 1000 | N10: 1054.5172 | O10: 93741307 | P10: =+IFERROR(IF(OR(B10="PEP795509FD5",B10="CVL79560FI39",B10="CVL79590GA30")=FALSE,IF(F10="SOB","Cov",INDEX('ANALISIS BD'!AZ:AZ,MATCH(BD1_S!B10,'ANALISIS BD'!C:C,0))),"NoCov"),"NoCov") -> Cov | S10: NoCov | T10: =+SUMIFS($C:$C,$D:$D,$R$8,$G:$G,$R$2,$P:$P,S10) -> 0.10561105 | W10: NoCov | X10: =+SUMIFS($C:$C,$D:$D,$R$8,$G:$G,$V$2,$P:$P,W10) -> 0.14204353
A11: 15515123CH47 | B11: USP32133CH47 | C11: 0.00354492 | D11: F1 | E11: RFIC | F11: BU | G11: Profuturo | H11: 4.856457e+09 | I11: 3.6555 | J11: 4675 | L11: 46174 | M11: 5151 | N11: 1080.7083 | O11: 18468725 | P11: =+IFERROR(IF(OR(B11="PEP795509FD5",B11="CVL79560FI39",B11="CVL79590GA30")=FALSE,IF(F11="SOB","Cov",INDEX('ANALISIS BD'!AZ:AZ,MATCH(BD1_S!B11,'ANALISIS BD'!C:C,0))),"NoCov"),"NoCov") -> NoCov | S11: Total | T11: =+T9+T10 -> 0.81246219 | W11: Total | X11: =+X9+X10 -> 0.83255862
A12: 0840002CNC19 | B12: US91282CNC19 | C12: 0.00065509686 | D12: F2 | E12: RFIG | F12: SOB | G12: Ex_Integra | H12: 5.0823903e+10 | I12: 3.6555 | J12: 98506.37 | K12: Gobierno de los Estados Unidos | L12: 46174 | M12: 4000 | N12: 99.191249 | O12: 35717780 | P12: =+IFERROR(IF(OR(B12="PEP795509FD5",B12="CVL79560FI39",B12="CVL79590GA30")=FALSE,IF(F12="SOB","Cov",INDEX('ANALISIS BD'!AZ:AZ,MATCH(BD1_S!B12,'ANALISIS BD'!C:C,0))),"NoCov"),"NoCov") -> Cov
A13: 0840038TF238 | B13: BRSTNCNTF238 | C13: 0.026580201 | D13: F1 | E13: RFIG | F13: SOB | G13: Habitat | H13: 1.8939189e+09 | I13: 0.6528844 | J13: 95257.93 | K13: Gobierno de Brasil | L13: 46174 | M13: 4003 | N13: 801.5185 | O13: 49848372 | P13: =+IFERROR(IF(OR(B13="PEP795509FD5",B13="CVL79560FI39",B13="CVL79590GA30")=FALSE,IF(F13="SOB","Cov",INDEX('ANALISIS BD'!AZ:AZ,MATCH(BD1_S!B13,'ANALISIS BD'!C:C,0))),"NoCov"),"NoCov") -> Cov | R13: F3 | V13: F3
A14: 5271112EG102 | B14: US46435G1022 | C14: 0.002125755 | D14: F1 | E14: RFIG | F14: TD | G14: Ex_Integra | H14: 1.3660104e+10 | I14: 3.6555 | J14: 70000 | K14: BlackRock - iShares Convertible Bond ETF | L14: 46174 | M14: 7111 | N14: 121.74 | O14: 31151440 | P14: =+IFERROR(IF(OR(B14="PEP795509FD5",B14="CVL79560FI39",B14="CVL79590GA30")=FALSE,IF(F14="SOB","Cov",INDEX('ANALISIS BD'!AZ:AZ,MATCH(BD1_S!B14,'ANALISIS BD'!C:C,0))),"NoCov"),"NoCov") -> Cov | S14: Cov | T14: =+SUMIFS($C:$C,$D:$D,$R$13,$G:$G,$R$2,$P:$P,S14) -> 0.77818039 | W14: Cov | X14: =+SUMIFS($C:$C,$D:$D,$R$13,$G:$G,$V$2,$P:$P,W14) -> 0.78545601
A15: 011000112B29 | B15: PEP01000C5F6 | C15: 0.00042111092 | D15: Multifondos | E15: RFLG | F15: SOB | G15: Prima | H15: 3.2738708e+10 | I15: 1 | J15: 12821 | K15: Gobierno Central | L15: 46174 | M15: 1000 | N15: 1075.3161 | O15: 13786627 | P15: =+IFERROR(IF(OR(B15="PEP795509FD5",B15="CVL79560FI39",B15="CVL79590GA30")=FALSE,IF(F15="SOB","Cov",INDEX('ANALISIS BD'!AZ:AZ,MATCH(BD1_S!B15,'ANALISIS BD'!C:C,0))),"NoCov"),"NoCov") -> Cov | S15: NoCov | T15: =+SUMIFS($C:$C,$D:$D,$R$13,$G:$G,$R$2,$P:$P,S15) -> 0.060288595 | W15: NoCov | X15: =+SUMIFS($C:$C,$D:$D,$R$13,$G:$G,$V$2,$P:$P,W15) -> 0.070219065
A16: 011000112G32 | B16: PEP01000C5E9 | C16: 0.0057924386 | D16: Multifondos | E16: RFLG | F16: SOB | G16: Ex_Integra | H16: 7.7424621e+10 | I16: 1 | J16: 405241.28 | K16: Gobierno Central | L16: 46174 | M16: 1000 | N16: 1106.6922 | O16: 4.4847736e+08 | P16: =+IFERROR(IF(OR(B16="PEP795509FD5",B16="CVL79560FI39",B16="CVL79590GA30")=FALSE,IF(F16="SOB","Cov",INDEX('ANALISIS BD'!AZ:AZ,MATCH(BD1_S!B16,'ANALISIS BD'!C:C,0))),"NoCov"),"NoCov") -> Cov | S16: Total | T16: =+T14+T15 -> 0.83846899 | W16: Total | X16: =+X14+X15 -> 0.85567508
A17: 011000112B29 | B17: PEP01000C5F6 | C17: 0.00024618363 | D17: Multifondos | E17: RFLG | F17: SOB | G17: Integra | H17: 3.9311487e+10 | I17: 1 | J17: 9000 | K17: Gobierno Central | L17: 46174 | M17: 1000 | N17: 1075.3161 | O17: 9677844.6 | P17: =+IFERROR(IF(OR(B17="PEP795509FD5",B17="CVL79560FI39",B17="CVL79590GA30")=FALSE,IF(F17="SOB","Cov",INDEX('ANALISIS BD'!AZ:AZ,MATCH(BD1_S!B17,'ANALISIS BD'!C:C,0))),"NoCov"),"NoCov") -> Cov
A18: 011000112G32 | B18: PEP01000C5E9 | C18: 0.0048649347 | D18: Multifondos | E18: RFLG | F18: SOB | G18: Profuturo | H18: 2.1900418e+10 | I18: 1 | J18: 96272.57 | K18: Gobierno Central | L18: 46174 | M18: 1000 | N18: 1106.6922 | O18: 1.065441e+08 | P18: =+IFERROR(IF(OR(B18="PEP795509FD5",B18="CVL79560FI39",B18="CVL79590GA30")=FALSE,IF(F18="SOB","Cov",INDEX('ANALISIS BD'!AZ:AZ,MATCH(BD1_S!B18,'ANALISIS BD'!C:C,0))),"NoCov"),"NoCov") -> Cov | R18: Multifondos | V18: Multifondos
A19: 084003411726 | B19: XS3344411726 | C19: 0.0033272413 | D19: F1 | E19: RFIG | F19: SOB | G19: Ex_Integra | H19: 1.3660104e+10 | I19: 4.4023187 | J19: 11425.27 | K19: Gobierno de Brasil | L19: 46174 | M19: 4003 | N19: 1022.28 | O19: 51418312 | P19: =+IFERROR(IF(OR(B19="PEP795509FD5",B19="CVL79560FI39",B19="CVL79590GA30")=FALSE,IF(F19="SOB","Cov",INDEX('ANALISIS BD'!AZ:AZ,MATCH(BD1_S!B19,'ANALISIS BD'!C:C,0))),"NoCov"),"NoCov") -> Cov | S19: Cov | T19: =+SUMIFS($C:$C,$D:$D,$R$18,$G:$G,$R$2,$P:$P,S19) -> 0.71491802 | W19: Cov | X19: =+SUMIFS($C:$C,$D:$D,$R$18,$G:$G,$V$2,$P:$P,W19) -> 0.70360789
A20: 011000112G33 | B20: PEP01000C5I0 | C20: 0.019381297 | D20: Multifondos | E20: RFLG | F20: SOB | G20: Ex_Integra | H20: 7.7424621e+10 | I20: 1 | J20: 1307394.5 | K20: Gobierno Central | L20: 46174 | M20: 1000 | N20: 1147.7711 | O20: 1.5005896e+09 | P20: =+IFERROR(IF(OR(B20="PEP795509FD5",B20="CVL79560FI39",B20="CVL79590GA30")=FALSE,IF(F20="SOB","Cov",INDEX('ANALISIS BD'!AZ:AZ,MATCH(BD1_S!B20,'ANALISIS BD'!C:C,0))),"NoCov"),"NoCov") -> Cov | S20: NoCov | T20: =+SUMIFS($C:$C,$D:$D,$R$18,$G:$G,$R$2,$P:$P,S20) -> 0.13474712 | W20: NoCov | X20: =+SUMIFS($C:$C,$D:$D,$R$18,$G:$G,$V$2,$P:$P,W20) -> 0.14542962
A21: 011000112F55 | B21: PEP01000C4S2 | C21: 0.0020174463 | D21: Multifondos | E21: RFLG | F21: SOB | G21: Habitat | H21: 2.2785495e+10 | I21: 1 | J21: 43592 | K21: Gobierno Central | L21: 46174 | M21: 1000 | N21: 1054.5172 | O21: 45968514 | P21: =+IFERROR(IF(OR(B21="PEP795509FD5",B21="CVL79560FI39",B21="CVL79590GA30")=FALSE,IF(F21="SOB","Cov",INDEX('ANALISIS BD'!AZ:AZ,MATCH(BD1_S!B21,'ANALISIS BD'!C:C,0))),"NoCov"),"NoCov") -> Cov | S21: Total | T21: =+T19+T20 -> 0.84966514 | W21: Total | X21: =+X19+X20 -> 0.84903751
A22: 5270772F2269 | B22: LU0727122698 | C22: 0.0088400657 | D22: F1 | E22: RFIG | F22: TD | G22: Habitat | H22: 1.8939189e+09 | I22: 3.6555 | J22: 144383.99 | K22: Franklin Templeton - Global Convertibles | L22: 46174 | M22: 7077 | N22: 34.03 | O22: 17960887 | P22: =+IFERROR(IF(OR(B22="PEP795509FD5",B22="CVL79560FI39",B22="CVL79590GA30")=FALSE,IF(F22="SOB","Cov",INDEX('ANALISIS BD'!AZ:AZ,MATCH(BD1_S!B22,'ANALISIS BD'!C:C,0))),"NoCov"),"NoCov") -> Cov
A23: 1551512PAC05 | B23: US05890PAC05 | C23: 0.0038776307 | D23: F1 | E23: RFIC | F23: BU | G23: Ex_Integra | H23: 1.3660104e+10 | I23: 3.6555 | J23: 14039 | L23: 46174 | M23: 5151 | N23: 1107.2569 | O23: 56823944 | P23: =+IFERROR(IF(OR(B23="PEP795509FD5",B23="CVL79560FI39",B23="CVL79590GA30")=FALSE,IF(F23="SOB","Cov",INDEX('ANALISIS BD'!AZ:AZ,MATCH(BD1_S!B23,'ANALISIS BD'!C:C,0))),"NoCov"),"NoCov") -> NoCov
A24: 011000112G34 | B24: PEP01000C5G4 | C24: 0.023844341 | D24: Multifondos | E24: RFLG | F24: SOB | G24: Ex_Integra | H24: 7.7424621e+10 | I24: 1 | J24: 1851516.5 | K24: Gobierno Central | L24: 46174 | M24: 1000 | N24: 997.09565 | O24: 1.8461391e+09 | P24: =+IFERROR(IF(OR(B24="PEP795509FD5",B24="CVL79560FI39",B24="CVL79590GA30")=FALSE,IF(F24="SOB","Cov",INDEX('ANALISIS BD'!AZ:AZ,MATCH(BD1_S!B24,'ANALISIS BD'!C:C,0))),"NoCov"),"NoCov") -> Cov
A25: 5271112EG102 | B25: US46435G1022 | C25: 0.005979263 | D25: F1 | E25: RFIG | F25: TD | G25: Profuturo | H25: 4.856457e+09 | I25: 3.6555 | J25: 70000 | K25: BlackRock - iShares Convertible Bond ETF | L25: 46174 | M25: 7111 | N25: 121.74 | O25: 31151440 | P25: =+IFERROR(IF(OR(B25="PEP795509FD5",B25="CVL79560FI39",B25="CVL79590GA30")=FALSE,IF(F25="SOB","Cov",INDEX('ANALISIS BD'!AZ:AZ,MATCH(BD1_S!B25,'ANALISIS BD'!C:C,0))),"NoCov"),"NoCov") -> Cov
A26: 011000112F42 | B26: PEP01000C4L7 | C26: 0.0037904956 | D26: Multifondos | E26: RFLG | F26: SOB | G26: Prima | H26: 3.2738708e+10 | I26: 1 | J26: 118170 | K26: Gobierno Central | L26: 46174 | M26: 1000 | N26: 1050.1475 | O26: 1.2409593e+08 | P26: =+IFERROR(IF(OR(B26="PEP795509FD5",B26="CVL79560FI39",B26="CVL79590GA30")=FALSE,IF(F26="SOB","Cov",INDEX('ANALISIS BD'!AZ:AZ,MATCH(BD1_S!B26,'ANALISIS BD'!C:C,0))),"NoCov"),"NoCov") -> Cov
A27: 5273932EA359 | B27: US78464A3591 | C27: 0.0091805964 | D27: F2 | E27: RFIG | F27: TD | G27: Ex_Integra | H27: 5.0823903e+10 | I27: 3.6555 | J27: 1270000 | K27: SSGA - Bloomberg Barclays Convertible Securities | L27: 46174 | M27: 7393 | N27: 107.82 | O27: 5.0055273e+08 | P27: =+IFERROR(IF(OR(B27="PEP795509FD5",B27="CVL79560FI39",B27="CVL79590GA30")=FALSE,IF(F27="SOB","Cov",INDEX('ANALISIS BD'!AZ:AZ,MATCH(BD1_S!B27,'ANALISIS BD'!C:C,0))),"NoCov"),"NoCov") -> Cov
A28: 0840002CNC19 | B28: US91282CNC19 | C28: 0.001470959 | D28: F2 | E28: RFIG | F28: SOB | G28: Prima | H28: 2.2634608e+10 | I28: 3.6555 | J28: 98506.37 | K28: Gobierno de los Estados Unidos | L28: 46174 | M28: 4000 | N28: 99.191249 | O28: 35717780 | P28: =+IFERROR(IF(OR(B28="PEP795509FD5",B28="CVL79560FI39",B28="CVL79590GA30")=FALSE,IF(F28="SOB","Cov",INDEX('ANALISIS BD'!AZ:AZ,MATCH(BD1_S!B28,'ANALISIS BD'!C:C,0))),"NoCov"),"NoCov") -> Cov
A29: 011000112G35 | B29: PEP01000C5K6 | C29: 0.029283838 | D29: Multifondos | E29: RFLG | F29: SOB | G29: Ex_Integra | H29: 7.7424621e+10 | I29: 1 | J29: 2102557.4 | K29: Gobierno Central | L29: 46174 | M29: 1000 | N29: 1078.3487 | O29: 2.26729e+09 | P29: =+IFERROR(IF(OR(B29="PEP795509FD5",B29="CVL79560FI39",B29="CVL79590GA30")=FALSE,IF(F29="SOB","Cov",INDEX('ANALISIS BD'!AZ:AZ,MATCH(BD1_S!B29,'ANALISIS BD'!C:C,0))),"NoCov"),"NoCov") -> Cov
A30: 011000112G37 | B30: PEP01000C2Z1 | C30: 0.042283942 | D30: Multifondos | E30: RFLG | F30: SOB | G30: Ex_Integra | H30: 7.7424621e+10 | I30: 1 | J30: 3116234.9 | K30: Gobierno Central | L30: 46174 | M30: 1000 | N30: 1050.5685 | O30: 3.2738182e+09 | P30: =+IFERROR(IF(OR(B30="PEP795509FD5",B30="CVL79560FI39",B30="CVL79590GA30")=FALSE,IF(F30="SOB","Cov",INDEX('ANALISIS BD'!AZ:AZ,MATCH(BD1_S!B30,'ANALISIS BD'!C:C,0))),"NoCov"),"NoCov") -> Cov
A31: 011000112G33 | B31: PEP01000C5I0 | C31: 0.020749837 | D31: Multifondos | E31: RFLG | F31: SOB | G31: Profuturo | H31: 2.1900418e+10 | I31: 1 | J31: 395923.98 | K31: Gobierno Central | L31: 46174 | M31: 1000 | N31: 1147.7711 | O31: 4.5443009e+08 | P31: =+IFERROR(IF(OR(B31="PEP795509FD5",B31="CVL79560FI39",B31="CVL79590GA30")=FALSE,IF(F31="SOB","Cov",INDEX('ANALISIS BD'!AZ:AZ,MATCH(BD1_S!B31,'ANALISIS BD'!C:C,0))),"NoCov"),"NoCov") -> Cov
A32: 1551192MAD04 | B32: USP1400MAD04 | C32: 0.0086965016 | D32: F1 | E32: RFIC | F32: BU | G32: Ex_Integra | H32: 1.3660104e+10 | I32: 3.6555 | J32: 33732.94 | L32: 46174 | M32: 5119 | N32: 1033.4953 | O32: 1.274411e+08 | P32: =+IFERROR(IF(OR(B32="PEP795509FD5",B32="CVL79560FI39",B32="CVL79590GA30")=FALSE,IF(F32="SOB","Cov",INDEX('ANALISIS BD'!AZ:AZ,MATCH(BD1_S!B32,'ANALISIS BD'!C:C,0))),"NoCov"),"NoCov") -> NoCov
A33: 011000112F55 | B33: PEP01000C4S2 | C33: 0.0041765993 | D33: Multifondos | E33: RFLG | F33: SOB | G33: Integra | H33: 3.9311487e+10 | I33: 1 | J33: 155700 | K33: Gobierno Central | L33: 46174 | M33: 1000 | N33: 1054.5172 | O33: 1.6418833e+08 | P33: =+IFERROR(IF(OR(B33="PEP795509FD5",B33="CVL79560FI39",B33="CVL79590GA30")=FALSE,IF(F33="SOB","Cov",INDEX('ANALISIS BD'!AZ:AZ,MATCH(BD1_S!B33,'ANALISIS BD'!C:C,0))),"NoCov"),"NoCov") -> Cov
A34: 084003411726 | B34: XS3344411726 | C34: 0.00089427335 | D34: F2 | E34: RFIG | F34: SOB | G34: Ex_Integra | H34: 5.0823903e+10 | I34: 4.4023187 | J34: 11425.27 | K34: Gobierno de Brasil | L34: 46174 | M34: 4003 | N34: 1022.28 | O34: 51418312 | P34: =+IFERROR(IF(OR(B34="PEP795509FD5",B34="CVL79560FI39",B34="CVL79590GA30")=FALSE,IF(F34="SOB","Cov",INDEX('ANALISIS BD'!AZ:AZ,MATCH(BD1_S!B34,'ANALISIS BD'!C:C,0))),"NoCov"),"NoCov") -> Cov
A35: 011000112G32 | B35: PEP01000C5E9 | C35: 0.014696076 | D35: Multifondos | E35: RFLG | F35: SOB | G35: Habitat | H35: 2.2785495e+10 | I35: 1 | J35: 302574.98 | K35: Gobierno Central | L35: 46174 | M35: 1000 | N35: 1106.6922 | O35: 3.3485737e+08 | P35: =+IFERROR(IF(OR(B35="PEP795509FD5",B35="CVL79560FI39",B35="CVL79590GA30")=FALSE,IF(F35="SOB","Cov",INDEX('ANALISIS BD'!AZ:AZ,MATCH(BD1_S!B35,'ANALISIS BD'!C:C,0))),"NoCov"),"NoCov") -> Cov
A36: 5273932EA359 | B36: US78464A3591 | C36: 0.0051941226 | D36: F2 | E36: RFIG | F36: TD | G36: Prima | H36: 2.2634608e+10 | I36: 3.6555 | J36: 320000 | K36: SSGA - Bloomberg Barclays Convertible Securities | L36: 46174 | M36: 7393 | N36: 107.82 | O36: 1.2612352e+08 | P36: =+IFERROR(IF(OR(B36="PEP795509FD5",B36="CVL79560FI39",B36="CVL79590GA30")=FALSE,IF(F36="SOB","Cov",INDEX('ANALISIS BD'!AZ:AZ,MATCH(BD1_S!B36,'ANALISIS BD'!C:C,0))),"NoCov"),"NoCov") -> Cov
A37: 011000112G39 | B37: PEP01000C5J8 | C37: 0.036737902 | D37: Multifondos | E37: RFLG | F37: SOB | G37: Ex_Integra | H37: 7.7424621e+10 | I37: 1 | J37: 2582158.4 | K37: Gobierno Central | L37: 46174 | M37: 1000 | N37: 1101.5661 | O37: 2.8444181e+09 | P37: =+IFERROR(IF(OR(B37="PEP795509FD5",B37="CVL79560FI39",B37="CVL79590GA30")=FALSE,IF(F37="SOB","Cov",INDEX('ANALISIS BD'!AZ:AZ,MATCH(BD1_S!B37,'ANALISIS BD'!C:C,0))),"NoCov"),"NoCov") -> Cov
A38: 011000112F55 | B38: PEP01000C4S2 | C38: 0.0014592144 | D38: Multifondos | E38: RFLG | F38: SOB | G38: Prima | H38: 3.2738708e+10 | I38: 1 | J38: 45303 | K38: Gobierno Central | L38: 46174 | M38: 1000 | N38: 1054.5172 | O38: 47772793 | P38: =+IFERROR(IF(OR(B38="PEP795509FD5",B38="CVL79560FI39",B38="CVL79590GA30")=FALSE,IF(F38="SOB","Cov",INDEX('ANALISIS BD'!AZ:AZ,MATCH(BD1_S!B38,'ANALISIS BD'!C:C,0))),"NoCov"),"NoCov") -> Cov
A39: 011000112G40 | B39: PEP01000C5H2 | C39: 0.022941055 | D39: Multifondos | E39: RFLG | F39: SOB | G39: Ex_Integra | H39: 7.7424621e+10 | I39: 1 | J39: 1992704.5 | K39: Gobierno Central | L39: 46174 | M39: 1000 | N39: 891.35269 | O39: 1.7762025e+09 | P39: =+IFERROR(IF(OR(B39="PEP795509FD5",B39="CVL79560FI39",B39="CVL79590GA30")=FALSE,IF(F39="SOB","Cov",INDEX('ANALISIS BD'!AZ:AZ,MATCH(BD1_S!B39,'ANALISIS BD'!C:C,0))),"NoCov"),"NoCov") -> Cov
A40: 0840038TF238 | B40: BRSTNCNTF238 | C40: 0.053773139 | D40: F1 | E40: RFIG | F40: SOB | G40: Profuturo | H40: 4.856457e+09 | I40: 0.6528844 | J40: 494158.69 | K40: Gobierno de Brasil | L40: 46174 | M40: 4003 | N40: 801.5185 | O40: 2.5859271e+08 | P40: =+IFERROR(IF(OR(B40="PEP795509FD5",B40="CVL79560FI39",B40="CVL79590GA30")=FALSE,IF(F40="SOB","Cov",INDEX('ANALISIS BD'!AZ:AZ,MATCH(BD1_S!B40,'ANALISIS BD'!C:C,0))),"NoCov"),"NoCov") -> Cov
...
