Workbook

Sheet BD
A1: Corte | B1: AFP | C1: Fondo | D1: Portafolio | E1: SBS | F1: ISIN | G1: Estrategia | H1: Universo | I1: Categoria | J1: Tipo_Dato | K1: Pais | L1: Nombre_Original | M1: Emisor | N1: PERDIO_HUELLA | O1: CO2-H | P1: Weight | Q1: Inv_MM_USD | R1: Huella | S1: Intensidad | T1: Huella_Verif | U1: Intensidad_Verif
A2: 202606 | B2: Ex_Integra | C2: F2 | D2: IN-FONDO2 | E2: 0840002CNC19 | F2: US91282CNC19 | G2: SOB | H2: Soberanos | I2: GOB | K2: EEUU | L2: Gobierno de los Estados Unidos | M2: Gobierno de los Estados Unidos | N2: FALSE | O2: 202.59174 | P2: 0.00067661643 | Q2: 9.4581485 | R2: 1916.1428 | S2: 0.1370769 | T2: =O2*Q2 | U2: =O2*P2
A3: 202606 | B3: Ex_Integra | C3: F1 | D3: IN-FONDO1 | E3: 084003411726 | F3: XS3344411726 | G3: SOB | H3: Soberanos | I3: GOB | K3: Brasil | L3: Gobierno de Brasil | M3: Gobierno de Brasil | N3: FALSE | O3: 274.39828 | P3: 0.0033728351 | Q3: 12.498937 | R3: 3429.6869 | S3: 0.92550015 | T3: =O3*Q3 | U3: =O3*P3
A4: 202606 | B4: Ex_Integra | C4: F2 | D4: IN-FONDO2 | E4: 084003411726 | F4: XS3344411726 | G4: SOB | H4: Soberanos | I4: GOB | K4: Brasil | L4: Gobierno de Brasil | M4: Gobierno de Brasil | N4: FALSE | O4: 274.39828 | P4: 0.00090969042 | Q4: 12.716196 | R4: 3489.3023 | S4: 0.24961749 | T4: =O4*Q4 | U4: =O4*P4
A5: 202606 | B5: Ex_Integra | C5: F1 | D5: IN-FONDO1 | E5: 0840052BAZ31 | F5: US91087BAZ31 | G5: SOB | H5: Soberanos | I5: GOB | K5: México | L5: Gobierno de Mexico | M5: Gobierno de México | N5: FALSE | O5: 204.30315 | P5: 0.0032830534 | Q5: 12.166227 | R5: 2485.5985 | S5: 0.67073815 | T5: =O5*Q5 | U5: =O5*P5
A6: 202606 | B6: Ex_Integra | C6: F2 | D6: IN-FONDO2 | E6: 0840052BAZ31 | F6: US91087BAZ31 | G6: SOB | H6: Soberanos | I6: GOB | K6: México | L6: Gobierno de Mexico | M6: Gobierno de México | N6: FALSE | O6: 204.30315 | P6: 0.001611959 | Q6: 22.532925 | R6: 4603.5475 | S6: 0.32932829 | T6: =O6*Q6 | U6: =O6*P6
A7: 202606 | B7: Ex_Integra | C7: F2 | D7: IN-FONDO2 | E7: 0840052QBB32 | F7: US91086QBB32 | G7: SOB | H7: Soberanos | I7: GOB | K7: México | L7: Gobierno de México | M7: Gobierno de México | N7: FALSE | O7: 204.30315 | P7: 0.0004994821 | Q7: 6.9820591 | R7: 1426.4567 | S7: 0.10204577 | T7: =O7*Q7 | U7: =O7*P7
A8: 202606 | B8: Ex_Integra | C8: F1 | D8: IN-FONDO1 | E8: 0840052QBB32 | F8: US91086QBB32 | G8: SOB | H8: Soberanos | I8: GOB | K8: México | L8: Gobierno de México | M8: Gobierno de México | N8: FALSE | O8: 204.30315 | P8: 0.0018519166 | Q8: 6.8627692 | R8: 1402.0854 | S8: 0.37835238 | T8: =O8*Q8 | U8: =O8*P8
A9: 202606 | B9: Ex_Integra | C9: F2 | D9: IN-FONDO2 | E9: 01100028DQ26 | F9: US715638DQ26 | G9: SOB | H9: Soberanos | I9: GOB | K9: Perú | L9: Gobierno Central | M9: Gobierno Central | N9: FALSE | O9: 170.41984 | P9: 6.0940321e-07 | Q9: 0.008518602 | R9: 1.4517388 | S9: 0.0001038544 | T9: =O9*Q9 | U9: =O9*P9
A10: 202606 | B10: Ex_Integra | C10: F1 | D10: IN-FONDO1 | E10: 01100028DR09 | F10: US715638DR09 | G10: SOB | H10: Soberanos | I10: GOB | K10: Perú | L10: Gobierno Central | M10: Gobierno Central | N10: FALSE | O10: 170.41984 | P10: 5.8572117e-07 | Q10: 0.0021705455 | R10: 0.36990402 | S10: 9.9818508e-05 | T10: =O10*Q10 | U10: =O10*P10
A11: 202606 | B11: Ex_Integra | C11: F1 | D11: IN-FONDO1 | E11: 0840038TF238 | F11: BRSTNCNTF238 | G11: SOB | H11: Soberanos | I11: GOB | K11: Brasil | L11: Gobierno de Brasil | M11: Gobierno de Brasil | N11: FALSE | O11: 274.39828 | P11: 0.046997124 | Q11: 174.16034 | R11: 47789.298 | S11: 12.89593 | T11: =O11*Q11 | U11: =O11*P11
A12: 202606 | B12: Ex_Integra | C12: F1 | D12: IN-FONDO1 | E12: 0840038TF2K7 | F12: BRSTNCNTF2K7 | G12: SOB | H12: Soberanos | I12: GOB | K12: Brasil | L12: Gobierno de Brasil | M12: Gobierno de Brasil | N12: FALSE | O12: 274.39828 | P12: 0.0032273003 | Q12: 11.959619 | R12: 3281.699 | S12: 0.88556565 | T12: =O12*Q12 | U12: =O12*P12
A13: 202606 | B13: Ex_Integra | C13: F1 | D13: IN-FONDO1 | E13: 0840038TF212 | F13: BRSTNCNTF212 | G13: SOB | H13: Soberanos | I13: GOB | K13: Brasil | L13: Gobierno de Brasil | M13: Gobierno de Brasil | N13: FALSE | O13: 274.39828 | P13: 0.012042696 | Q13: 44.627413 | R13: 12245.685 | S13: 3.3044951 | T13: =O13*Q13 | U13: =O13*P13
... A63: 202606 | B63: Ex_Integra | C63: F2 | D63: IN-FONDO2 | E63: 011000312F54 | F63: PEP01000C4T0 | G63: SOB | H63: Soberanos | I63: GOB | K63: Perú | L63: Gobierno Central | M63: Gobierno Central | N63: FALSE | O63: 170.41984 | P63: 0.00036317378 | Q63: 5.07666 | R63: 865.16358 | S63: 0.061892018 | T63: =O63*Q63 | U63: =O63*P63
A64: 202606 | B64: Ex_Integra | C64: F3 | D64: IN-FONDO3 | E64: 2220082PAB78 | F64: USP6680PAB78 | G64: BU | H64: Sector | I64: Materials | J64: MSCI | M64: nan | N64: FALSE | O64: 32.13 | P64: 0.00058775142 | Q64: 2.0937595 | R64: 67.272492 | S64: 0.018884453 | T64: =O64*Q64 | U64: =O64*P64
A65: 202606 | B65: Ex_Integra | C65: F1 | D65: IN-FONDO1 | E65: 2220082PAB78 | F65: USP6680PAB78 | G65: BU | H65: Sector | I65: Materials | J65: MSCI | M65: nan | N65: FALSE | O65: 32.13 | P65: 0.010670635 | Q65: 39.542876 | R65: 1270.5126 | S65: 0.34284751 | T65: =O65*Q65 | U65: =O65*P65
A66: 202606 | B66: Ex_Integra | C66: F2 | D66: IN-FONDO2 | E66: 2220082PAB78 | F66: USP6680PAB78 | G66: BU | H66: Sector | I66: Materials | J66: MSCI | M66: nan | N66: FALSE | O66: 32.13 | P66: 0.0022021118 | Q66: 30.782434 | R66: 989.0396 | S66: 0.070753852 | T66: =O66*Q66 | U66: =O66*P66
A67: 202606 | B67: Ex_Integra | C67: F3 | D67: IN-FONDO3 | E67: 2259582AAA36 | F67: USP6432AAA36 | G67: BU | H67: Sector | I67: Materials | J67: MSCI | M67: nan | N67: FALSE | O67: 116.89 | P67: 0.00028132429 | Q67: 1.0021675 | R67: 117.14336 | S67: 0.032883996 | T67: =O67*Q67 | U67: =O67*P67
A68: 202606 | B68: Ex_Integra | C68: F1 | D68: IN-FONDO1 | E68: 2259582AAA36 | F68: USP6432AAA36 | G68: BU | H68: Sector | I68: Materials | J68: MSCI | M68: nan | N68: FALSE | O68: 116.89 | P68: 0.0019779426 | Q68: 7.3297924 | R68: 856.77943 | S68: 0.23120172 | T68: =O68*Q68 | U68: =O68*P68
A69: 202606 | B69: Ex_Integra | C69: F2 | D69: IN-FONDO2 | E69: 2259582AAA36 | F69: USP6432AAA36 | G69: BU | H69: Sector | I69: Materials | J69: MSCI | M69: nan | N69: FALSE | O69: 116.89 | P69: 0.00097475393 | Q69: 13.625693 | R69: 1592.7072 | S69: 0.11393899 | T69: =O69*Q69 | U69: =O69*P69
A70: 202606 | B70: Ex_Integra | C70: F2 | D70: IN-FONDO2 | E70: 22204327AE63 | F70: USP98047AE63 | G70: BU | H70: Sector | I70: Materials | J70: MSCI | M70: nan | N70: FALSE | O70: 113.85 | P70: 0.0046521504 | Q70: 65.030537 | R70: 7403.7266 | S70: 0.52964733 | T70: =O70*Q70 | U70: =O70*P70
A71: 202606 | B71: Ex_Integra | C71: F1 | D71: IN-FONDO1 | E71: 22204327AE63 | F71: USP98047AE63 | G71: BU | H71: Sector | I71: Materials | J71: MSCI | M71: nan | N71: FALSE | O71: 113.85 | P71: 0.008378714 | Q71: 31.049553 | R71: 3534.9916 | S71: 0.95391659 | T71: =O71*Q71 | U71: =O71*P71
A72: 202606 | B72: Ex_Integra | C72: F3 | D72: IN-FONDO3 | E72: 395953O13172 | F72: HK1208013172 | G72: BU | H72: Sector | I72: Materials | J72: MSCI | M72: nan | N72: FALSE | O72: 46.98 | P72: 0.00012567153 | Q72: 0.44768239 | R72: 21.032119 | S72: 0.0059040486 | T72: =O72*Q72 | U72: =O72*P72
A73: 202606 | B73: Ex_Integra | C73: F2 | D73: IN-FONDO2 | E73: 302043100001 | F73: PEP648011109 | G73: BU | H73: Sector | I73: Materials | J73: MSCI | L73: Volcan* | M73: Volcan | N73: FALSE | O73: 113.85 | P73: 2.3743506e-08 | Q73: 0.00033190091 | R73: 0.037786919 | S73: 2.7031982e-06 | T73: =O73*Q73 | U73: =O73*P73
A74: 202606 | B74: Ex_Integra | C74: F2 | D74: IN-FONDO2 | E74: 302043100002 | F74: PEP648014202 | G74: BU | H74: Sector | I74: Materials | J74: MSCI | L74: Volcan* | M74: Volcan | N74: FALSE | O74: 113.85 | P74: 0.001278807 | Q74: 17.875927 | R74: 2035.1743 | S74: 0.14559217 | T74: =O74*Q74 | U74: =O74*P74
A75: 202606 | B75: Ex_Integra | C75: F1 | D75: IN-FONDO1 | E75: 302043100002 | F75: PEP648014202 | G75: BU | H75: Sector | I75: Materials | J75: MSCI | L75: Volcan* | M75: Volcan | N75: FALSE | O75: 113.85 | P75: 0.0012103985 | Q75: 4.4854533 | R75: 510.66886 | S75: 0.13780386 | T75: =O75*Q75 | U75: =O75*P75
A76: 202606 | B76: Ex_Integra | C76: F3 | D76: IN-FONDO3 | E76: 302043100002 | F76: PEP648014202 | G76: BU | H76: Sector | I76: Materials | J76: MSCI | L76: Volcan* | M76: Volcan | N76: FALSE | O76: 113.85 | P76: 0.007065566 | Q76: 25.169817 | R76: 2865.5837 | S76: 0.80441469 | T76: =O76*Q76 | U76: =O76*P76
A77: 202606 | B77: Ex_Integra | C77: F3 | D77: IN-FONDO3 | E77: 302845100002 | F77: PEP620001003 | G77: BU | H77: Sector | I77: Materials | J77: MSCI | L77: Nexa Resources Perú | M77: Nexa Resources Perú | N77: FALSE | O77: 167.61 | P77: 0.0028773301 | Q77: 10.249975 | R77: 1717.9982 | S77: 0.48226929 | T77: =O77*Q77 | U77: =O77*P77
A78: 202606 | B78: Ex_Integra | C78: F1 | D78: IN-FONDO1 | E78: 302845100002 | F78: PEP620001003 | G78: BU | H78: Sector | I78: Materials | J78: MSCI | L78: Nexa Resources Perú | M78: Nexa Resources Perú | N78: FALSE | O78: 167.61 | P78: 5.6109197e-06 | Q78: 0.020792755 | R78: 3.4850737 | S78: 0.00094044626 | T78: =O78*Q78 | U78: =O78*P78
A79: 202606 | B79: Ex_Integra | C79: F2 | D79: IN-FONDO2 | E79: 302845100002 | F79: PEP620001003 | G79: BU | H79: Sector | I79: Materials | J79: MSCI | L79: Nexa Resources Perú | M79: Nexa Resources Perú | N79: FALSE | O79: 167.61 | P79: 0.00040533812 | Q79: 5.6660583 | R79: 949.68802 | S79: 0.067938722 | T79: =O79*Q79 | U79: =O79*P79
A80: 202606 | B80: Ex_Integra | C80: F2 | D80: IN-FONDO2 | E80: 312039100001 | F80: PEP622005002 | G80: BU | H80: Sector | I80: Materials | J80: MSCI | L80: Minsur | M80: Minsur | N80: FALSE | O80: 116.89 | P80: 0.030090232 | Q80: 420.61923 | R80: 49166.182 | S80: 3.5172472 | T80: =O80*Q80 | U80: =O80*P80
A81: 202606 | B81: Ex_Integra | C81: F3 | D81: IN-FONDO3 | E81: 312039100001 | F81: PEP622005002 | G81: BU | H81: Sector | I81: Materials | J81: MSCI | L81: Minsur | M81: Minsur | N81: FALSE | O81: 116.89 | P81: 0.054646863 | Q81: 194.66969 | R81: 22754.94 | S81: 6.3876718 | T81: =O81*Q81 | U81: =O81*P81
A82: 202606 | B82: Ex_Integra | C82: F1 | D82: IN-FONDO1 | E82: 312039100001 | F82: PEP622005002 | G82: BU | H82: Sector | I82: Materials | J82: MSCI | L82: Minsur | M82: Minsur | N82: FALSE | O82: 116.89 | P82: 0.009829985 | Q82: 36.427623 | R82: 4258.0249 | S82: 1.1490269 | T82: =O82*Q82 | U82: =O82*P82
A83: 202606 | B83: Ex_Integra | C83: F1 | D83: IN-FONDO1 | E83: 395833228291 | F83: LU1701428291 | G83: BU | H83: Sector | I83: Materials | J83: MSCI | L83: Nexa Resources | M83: Nexa Resources | N83: FALSE | O83: 206.9 | P83: 0.00021937034 | Q83: 0.81293511 | R83: 168.19627 | S83: 0.045387722 | T83: =O83*Q83 | U83: =O83*P83
A84: 202606 | B84: Ex_Integra | C84: F3 | D84: IN-FONDO3 | E84: 395833228291 | F84: LU1701428291 | G84: BU | H84: Sector | I84: Materials | J84: MSCI | L84: Nexa Resources | M84: Nexa Resources | N84: FALSE | O84: 206.9 | P84: 0.0088783088 | Q84: 31.62739 | R84: 6543.7069 | S84: 1.8369221 | T84: =O84*Q84 | U84: =O84*P84
A85: 202606 | B85: Ex_Integra | C85: F2 | D85: IN-FONDO2 | E85: 395833228291 | F85: LU1701428291 | G85: BU | H85: Sector | I85: Materials | J85: MSCI | L85: Nexa Resources | M85: Nexa Resources | N85: FALSE | O85: 206.9 | P85: 0.0032966427 | Q85: 46.08244 | R85: 9534.4569 | S85: 0.68207537 | T85: =O85*Q85 | U85: =O85*P85
A86: 202606 | B86: Ex_Integra | C86: F2 | D86: IN-FONDO2 | E86: 3920836W5029 | F86: GB00B1FW5029 | G86: BU | H86: Sector | I86: Materials | J86: MSCI | M86: nan | N86: FALSE | O86: 31.79 | P86: 0.0073822023 | Q86: 103.19283 | R86: 3280.5002 | S86: 0.23468021 | T86: =O86*Q86 | U86: =O86*P86
A87: 202606 | B87: Ex_Integra | C87: F1 | D87: IN-FONDO1 | E87: 3920836W5029 | F87: GB00B1FW5029 | G87: BU | H87: Sector | I87: Materials | J87: MSCI | M87: nan | N87: FALSE | O87: 31.79 | P87: 0.0014060737 | Q87: 5.2105798 | R87: 165.64433 | S87: 0.044699082 | T87: =O87*Q87 | U87: =O87*P87
A88: 202606 | B88: Ex_Integra | C88: F3 | D88: IN-FONDO3 | E88: 3920836W5029 | F88: GB00B1FW5029 | G88: BU | H88: Sector | I88: Materials | J88: MSCI | M88: nan | N88: FALSE | O88: 31.79 | P88: 0.015761449 | Q88: 56.147349 | R88: 1784.9242 | S88: 0.50105648 | T88: =O88*Q88 | U88: =O88*P88
A89: 202606 | B89: Ex_Integra | C89: F1 | D89: IN-FONDO1 | E89: 3220082A1040 | F89: US2044481040 | G89: BU | H89: Sector | I89: Materials | J89: MSCI | L89: Buenaventura* | M89: Buenaventura | N89: FALSE | O89: 32.13 | P89: 0.0038732375 | Q89: 14.353311 | R89: 461.1719 | S89: 0.12444712 | T89: =O89*Q89 | U89: =O89*P89
...

Sheet Huella Soberanos
C1: Corte | D1: Perú | E1: Brasil | F1: Colombia | G1: México | H1: Chile | I1: Sudáfrica | J1: Total | K1: Variación %
C2: Dic25 | D2: =SUMIFS('BD'!$R$2:$R$6977,'BD'!$H$2:$H$6977,"Soberanos",'BD'!$B$2:$B$6977,"Integra",'BD'!$K$2:$K$6977,D$1,'BD'!$A$2:$A$6977,"202512") | E2: =SUMIFS('BD'!$R$2:$R$6977,'BD'!$H$2:$H$6977,"Soberanos",'BD'!$B$2:$B$6977,"Integra",'BD'!$K$2:$K$6977,E$1,'BD'!$A$2:$A$6977,"202512") | F2: =SUMIFS('BD'!$R$2:$R$6977,'BD'!$H$2:$H$6977,"Soberanos",'BD'!$B$2:$B$6977,"Integra",'BD'!$K$2:$K$6977,F$1,'BD'!$A$2:$A$6977,"202512") | G2: =SUMIFS('BD'!$R$2:$R$6977,'BD'!$H$2:$H$6977,"Soberanos",'BD'!$B$2:$B$6977,"Integra",'BD'!$K$2:$K$6977,G$1,'BD'!$A$2:$A$6977,"202512") | H2: =SUMIFS('BD'!$R$2:$R$6977,'BD'!$H$2:$H$6977,"Soberanos",'BD'!$B$2:$B$6977,"Integra",'BD'!$K$2:$K$6977,H$1,'BD'!$A$2:$A$6977,"202512") | I2: =SUMIFS('BD'!$R$2:$R$6977,'BD'!$H$2:$H$6977,"Soberanos",'BD'!$B$2:$B$6977,"Integra",'BD'!$K$2:$K$6977,I$1,'BD'!$A$2:$A$6977,"202512") | J2: =SUM(D2:I2)
C3: Jun26 | D3: =SUMIFS('BD'!$R$2:$R$6977,'BD'!$H$2:$H$6977,"Soberanos",'BD'!$B$2:$B$6977,"Integra",'BD'!$K$2:$K$6977,D$1,'BD'!$A$2:$A$6977,"202606") | E3: =SUMIFS('BD'!$R$2:$R$6977,'BD'!$H$2:$H$6977,"Soberanos",'BD'!$B$2:$B$6977,"Integra",'BD'!$K$2:$K$6977,E$1,'BD'!$A$2:$A$6977,"202606") | F3: =SUMIFS('BD'!$R$2:$R$6977,'BD'!$H$2:$H$6977,"Soberanos",'BD'!$B$2:$B$6977,"Integra",'BD'!$K$2:$K$6977,F$1,'BD'!$A$2:$A$6977,"202606") | G3: =SUMIFS('BD'!$R$2:$R$6977,'BD'!$H$2:$H$6977,"Soberanos",'BD'!$B$2:$B$6977,"Integra",'BD'!$K$2:$K$6977,G$1,'BD'!$A$2:$A$6977,"202606") | H3: =SUMIFS('BD'!$R$2:$R$6977,'BD'!$H$2:$H$6977,"Soberanos",'BD'!$B$2:$B$6977,"Integra",'BD'!$K$2:$K$6977,H$1,'BD'!$A$2:$A$6977,"202606") | I3: =SUMIFS('BD'!$R$2:$R$6977,'BD'!$H$2:$H$6977,"Soberanos",'BD'!$B$2:$B$6977,"Integra",'BD'!$K$2:$K$6977,I$1,'BD'!$A$2:$A$6977,"202606") | J3: =SUM(D3:I3) | K3: =IFERROR(J3/J2-1,"")

Sheet Intensidad Soberanos
C1: Corte | D1: Perú | E1: Brasil | F1: Colombia | G1: México | H1: Chile | I1: Sudáfrica | J1: Total | K1: Variación %
C2: Dic25 | D2: =SUMIFS('BD'!$S$2:$S$6977,'BD'!$H$2:$H$6977,"Soberanos",'BD'!$B$2:$B$6977,"Integra",'BD'!$K$2:$K$6977,D$1,'BD'!$A$2:$A$6977,"202512") | E2: =SUMIFS('BD'!$S$2:$S$6977,'BD'!$H$2:$H$6977,"Soberanos",'BD'!$B$2:$B$6977,"Integra",'BD'!$K$2:$K$6977,E$1,'BD'!$A$2:$A$6977,"202512") | F2: =SUMIFS('BD'!$S$2:$S$6977,'BD'!$H$2:$H$6977,"Soberanos",'BD'!$B$2:$B$6977,"Integra",'BD'!$K$2:$K$6977,F$1,'BD'!$A$2:$A$6977,"202512") | G2: =SUMIFS('BD'!$S$2:$S$6977,'BD'!$H$2:$H$6977,"Soberanos",'BD'!$B$2:$B$6977,"Integra",'BD'!$K$2:$K$6977,G$1,'BD'!$A$2:$A$6977,"202512") | H2: =SUMIFS('BD'!$S$2:$S$6977,'BD'!$H$2:$H$6977,"Soberanos",'BD'!$B$2:$B$6977,"Integra",'BD'!$K$2:$K$6977,H$1,'BD'!$A$2:$A$6977,"202512") | I2: =SUMIFS('BD'!$S$2:$S$6977,'BD'!$H$2:$H$6977,"Soberanos",'BD'!$B$2:$B$6977,"Integra",'BD'!$K$2:$K$6977,I$1,'BD'!$A$2:$A$6977,"202512") | J2: =SUM(D2:I2)
C3: Jun26 | D3: =SUMIFS('BD'!$S$2:$S$6977,'BD'!$H$2:$H$6977,"Soberanos",'BD'!$B$2:$B$6977,"Integra",'BD'!$K$2:$K$6977,D$1,'BD'!$A$2:$A$6977,"202606") | E3: =SUMIFS('BD'!$S$2:$S$6977,'BD'!$H$2:$H$6977,"Soberanos",'BD'!$B$2:$B$6977,"Integra",'BD'!$K$2:$K$6977,E$1,'BD'!$A$2:$A$6977,"202606") | F3: =SUMIFS('BD'!$S$2:$S$6977,'BD'!$H$2:$H$6977,"Soberanos",'BD'!$B$2:$B$6977,"Integra",'BD'!$K$2:$K$6977,F$1,'BD'!$A$2:$A$6977,"202606") | G3: =SUMIFS('BD'!$S$2:$S$6977,'BD'!$H$2:$H$6977,"Soberanos",'BD'!$B$2:$B$6977,"Integra",'BD'!$K$2:$K$6977,G$1,'BD'!$A$2:$A$6977,"202606") | H3: =SUMIFS('BD'!$S$2:$S$6977,'BD'!$H$2:$H$6977,"Soberanos",'BD'!$B$2:$B$6977,"Integra",'BD'!$K$2:$K$6977,H$1,'BD'!$A$2:$A$6977,"202606") | I3: =SUMIFS('BD'!$S$2:$S$6977,'BD'!$H$2:$H$6977,"Soberanos",'BD'!$B$2:$B$6977,"Integra",'BD'!$K$2:$K$6977,I$1,'BD'!$A$2:$A$6977,"202606") | J3: =SUM(D3:I3) | K3: =IFERROR(J3/J2-1,"")

Sheet Huella por Sector
C1: Corte | D1: Materials | E1: Utilities | F1: Otros | G1: RF | H1: RV | I1: Proxies | J1: Alts | K1: Total | L1: Variación %
C2: Dic25 | D2: =SUMIFS('BD'!$R$2:$R$6977,'BD'!$H$2:$H$6977,"Sector",'BD'!$B$2:$B$6977,"Integra",'BD'!$I$2:$I$6977,D$1,'BD'!$J$2:$J$6977,"MSCI",'BD'!$A$2:$A$6977,"202512") | E2: =SUMIFS('BD'!$R$2:$R$6977,'BD'!$H$2:$H$6977,"Sector",'BD'!$B$2:$B$6977,"Integra",'BD'!$I$2:$I$6977,E$1,'BD'!$J$2:$J$6977,"MSCI",'BD'!$A$2:$A$6977,"202512") | F2: =SUMIFS('BD'!$R$2:$R$6977,'BD'!$H$2:$H$6977,"Sector",'BD'!$B$2:$B$6977,"Integra",'BD'!$I$2:$I$6977,F$1,'BD'!$J$2:$J$6977,"MSCI",'BD'!$A$2:$A$6977,"202512") | G2: =SUMIFS('BD'!$R$2:$R$6977,'BD'!$H$2:$H$6977,"Sector",'BD'!$B$2:$B$6977,"Integra",'BD'!$I$2:$I$6977,G$1,'BD'!$J$2:$J$6977,"MSCI",'BD'!$A$2:$A$6977,"202512") | H2: =SUMIFS('BD'!$R$2:$R$6977,'BD'!$H$2:$H$6977,"Sector",'BD'!$B$2:$B$6977,"Integra",'BD'!$I$2:$I$6977,H$1,'BD'!$J$2:$J$6977,"MSCI",'BD'!$A$2:$A$6977,"202512") | I2: =SUMIFS('BD'!$R$2:$R$6977,'BD'!$H$2:$H$6977,"Sector",'BD'!$B$2:$B$6977,"Integra",'BD'!$I$2:$I$6977,I$1,'BD'!$J$2:$J$6977,"Proxies",'BD'!$A$2:$A$6977,"202512") | J2: =SUMIFS('BD'!$R$2:$R$6977,'BD'!$H$2:$H$6977,"Sector",'BD'!$B$2:$B$6977,"Integra",'BD'!$I$2:$I$6977,J$1,'BD'!$J$2:$J$6977,"Proxies",'BD'!$A$2:$A$6977,"202512") | K2: =SUM(D2:J2)
C3: Jun26 | D3: =SUMIFS('BD'!$R$2:$R$6977,'BD'!$H$2:$H$6977,"Sector",'BD'!$B$2:$B$6977,"Integra",'BD'!$I$2:$I$6977,D$1,'BD'!$J$2:$J$6977,"MSCI",'BD'!$A$2:$A$6977,"202606") | E3: =SUMIFS('BD'!$R$2:$R$6977,'BD'!$H$2:$H$6977,"Sector",'BD'!$B$2:$B$6977,"Integra",'BD'!$I$2:$I$6977,E$1,'BD'!$J$2:$J$6977,"MSCI",'BD'!$A$2:$A$6977,"202606") | F3: =SUMIFS('BD'!$R$2:$R$6977,'BD'!$H$2:$H$6977,"Sector",'BD'!$B$2:$B$6977,"Integra",'BD'!$I$2:$I$6977,F$1,'BD'!$J$2:$J$6977,"MSCI",'BD'!$A$2:$A$6977,"202606") | G3: =SUMIFS('BD'!$R$2:$R$6977,'BD'!$H$2:$H$6977,"Sector",'BD'!$B$2:$B$6977,"Integra",'BD'!$I$2:$I$6977,G$1,'BD'!$J$2:$J$6977,"MSCI",'BD'!$A$2:$A$6977,"202606") | H3: =SUMIFS('BD'!$R$2:$R$6977,'BD'!$H$2:$H$6977,"Sector",'BD'!$B$2:$B$6977,"Integra",'BD'!$I$2:$I$6977,H$1,'BD'!$J$2:$J$6977,"MSCI",'BD'!$A$2:$A$6977,"202606") | I3: =SUMIFS('BD'!$R$2:$R$6977,'BD'!$H$2:$H$6977,"Sector",'BD'!$B$2:$B$6977,"Integra",'BD'!$I$2:$I$6977,I$1,'BD'!$J$2:$J$6977,"Proxies",'BD'!$A$2:$A$6977,"202606") | J3: =SUMIFS('BD'!$R$2:$R$6977,'BD'!$H$2:$H$6977,"Sector",'BD'!$B$2:$B$6977,"Integra",'BD'!$I$2:$I$6977,J$1,'BD'!$J$2:$J$6977,"Proxies",'BD'!$A$2:$A$6977,"202606") | K3: =SUM(D3:J3) | L3: =IFERROR(K3/K2-1,"")

Sheet Intensidad por Sector
C1: Corte | D1: Materials | E1: Utilities | F1: Otros | G1: RF | H1: RV | I1: Proxies | J1: Alts | K1: Total | L1: Variación %
C2: Dic25 | D2: =SUMIFS('BD'!$S$2:$S$6977,'BD'!$H$2:$H$6977,"Sector",'BD'!$B$2:$B$6977,"Integra",'BD'!$I$2:$I$6977,D$1,'BD'!$J$2:$J$6977,"MSCI",'BD'!$A$2:$A$6977,"202512") | E2: =SUMIFS('BD'!$S$2:$S$6977,'BD'!$H$2:$H$6977,"Sector",'BD'!$B$2:$B$6977,"Integra",'BD'!$I$2:$I$6977,E$1,'BD'!$J$2:$J$6977,"MSCI",'BD'!$A$2:$A$6977,"202512") | F2: =SUMIFS('BD'!$S$2:$S$6977,'BD'!$H$2:$H$6977,"Sector",'BD'!$B$2:$B$6977,"Integra",'BD'!$I$2:$I$6977,F$1,'BD'!$J$2:$J$6977,"MSCI",'BD'!$A$2:$A$6977,"202512") | G2: =SUMIFS('BD'!$S$2:$S$6977,'BD'!$H$2:$H$6977,"Sector",'BD'!$B$2:$B$6977,"Integra",'BD'!$I$2:$I$6977,G$1,'BD'!$J$2:$J$6977,"MSCI",'BD'!$A$2:$A$6977,"202512") | H2: =SUMIFS('BD'!$S$2:$S$6977,'BD'!$H$2:$H$6977,"Sector",'BD'!$B$2:$B$6977,"Integra",'BD'!$I$2:$I$6977,H$1,'BD'!$J$2:$J$6977,"MSCI",'BD'!$A$2:$A$6977,"202512") | I2: =SUMIFS('BD'!$S$2:$S$6977,'BD'!$H$2:$H$6977,"Sector",'BD'!$B$2:$B$6977,"Integra",'BD'!$I$2:$I$6977,I$1,'BD'!$J$2:$J$6977,"Proxies",'BD'!$A$2:$A$6977,"202512") | J2: =SUMIFS('BD'!$S$2:$S$6977,'BD'!$H$2:$H$6977,"Sector",'BD'!$B$2:$B$6977,"Integra",'BD'!$I$2:$I$6977,J$1,'BD'!$J$2:$J$6977,"Proxies",'BD'!$A$2:$A$6977,"202512") | K2: =SUM(D2:J2)
C3: Jun26 | D3: =SUMIFS('BD'!$S$2:$S$6977,'BD'!$H$2:$H$6977,"Sector",'BD'!$B$2:$B$6977,"Integra",'BD'!$I$2:$I$6977,D$1,'BD'!$J$2:$J$6977,"MSCI",'BD'!$A$2:$A$6977,"202606") | E3: =SUMIFS('BD'!$S$2:$S$6977,'BD'!$H$2:$H$6977,"Sector",'BD'!$B$2:$B$6977,"Integra",'BD'!$I$2:$I$6977,E$1,'BD'!$J$2:$J$6977,"MSCI",'BD'!$A$2:$A$6977,"202606") | F3: =SUMIFS('BD'!$S$2:$S$6977,'BD'!$H$2:$H$6977,"Sector",'BD'!$B$2:$B$6977,"Integra",'BD'!$I$2:$I$6977,F$1,'BD'!$J$2:$J$6977,"MSCI",'BD'!$A$2:$A$6977,"202606") | G3: =SUMIFS('BD'!$S$2:$S$6977,'BD'!$H$2:$H$6977,"Sector",'BD'!$B$2:$B$6977,"Integra",'BD'!$I$2:$I$6977,G$1,'BD'!$J$2:$J$6977,"MSCI",'BD'!$A$2:$A$6977,"202606") | H3: =SUMIFS('BD'!$S$2:$S$6977,'BD'!$H$2:$H$6977,"Sector",'BD'!$B$2:$B$6977,"Integra",'BD'!$I$2:$I$6977,H$1,'BD'!$J$2:$J$6977,"MSCI",'BD'!$A$2:$A$6977,"202606") | I3: =SUMIFS('BD'!$S$2:$S$6977,'BD'!$H$2:$H$6977,"Sector",'BD'!$B$2:$B$6977,"Integra",'BD'!$I$2:$I$6977,I$1,'BD'!$J$2:$J$6977,"Proxies",'BD'!$A$2:$A$6977,"202606") | J3: =SUMIFS('BD'!$S$2:$S$6977,'BD'!$H$2:$H$6977,"Sector",'BD'!$B$2:$B$6977,"Integra",'BD'!$I$2:$I$6977,J$1,'BD'!$J$2:$J$6977,"Proxies",'BD'!$A$2:$A$6977,"202606") | K3: =SUM(D3:J3) | L3: =IFERROR(K3/K2-1,"")

Sheet Intensidad FFMM
A1: Corte | B1: Corte_Rol | C1: AFP | D1: Tipo_Fila | E1: Bloque | F1: Gestion | G1: Instrumento | H1: SubCategoria | I1: Benchmark_Tipo | J1: Benchmark_Nombre | K1: Metrica | L1: Valor | N1: Instrumento | O1: Intensidad | P1: Benchmark
A2: 202512 | B2: Comparación | C2: Ex_Integra | D2: Benchmark | I2: Escalar_Portafolio | J2: Total_Integra | K2: Intensidad | L2: 75.896051 | N2: BlackRock - iShares Korea (Equities) | O2: =SUMIFS($L$2:$L$426,$G$2:$G$426,"BlackRock - iShares Korea",$E$2:$E$426,"Equities",$D$2:$D$426,"Instrumento",$C$2:$C$426,"Integra",$A$2:$A$426,"202606") | P2: 50.676744
A3: 202512 | B3: Comparación | C3: Ex_Integra | D3: Benchmark | I3: Escalar_Portafolio | J3: F1_Integra | K3: Intensidad | L3: 37.747666 | N3: Global X - Copper Miners ETF (Equities) | O3: =SUMIFS($L$2:$L$426,$G$2:$G$426,"Global X - Copper Miners ETF",$E$2:$E$426,"Equities",$D$2:$D$426,"Instrumento",$C$2:$C$426,"Integra",$A$2:$A$426,"202606") | P3: 50.676744
A4: 202512 | B4: Comparación | C4: Ex_Integra | D4: Benchmark | I4: Escalar_Portafolio | J4: F2_Integra | K4: Intensidad | L4: 16.583562 | N4: BNP Paribas - Japan Small Caps (Equities) | O4: =SUMIFS($L$2:$L$426,$G$2:$G$426,"BNP Paribas - Japan Small Caps",$E$2:$E$426,"Equities",$D$2:$D$426,"Instrumento",$C$2:$C$426,"Integra",$A$2:$A$426,"202606") | P4: 50.676744
A5: 202512 | B5: Comparación | C5: Ex_Integra | D5: Benchmark | I5: Escalar_Portafolio | J5: F3_Integra | K5: Intensidad | L5: 21.564823 | N5: JP Morgan - Korea Equity Fund (Equities) | O5: =SUMIFS($L$2:$L$426,$G$2:$G$426,"JP Morgan - Korea Equity Fund",$E$2:$E$426,"Equities",$D$2:$D$426,"Instrumento",$C$2:$C$426,"Integra",$A$2:$A$426,"202606") | P5: 50.676744
A6: 202512 | B6: Comparación | C6: Habitat | D6: Benchmark | I6: Escalar_Portafolio | J6: Total_Integra | K6: Intensidad | L6: 63.150033 | N6: BlackRock - iShares PHLX Semiconductor ETF (Equities) | O6: =SUMIFS($L$2:$L$426,$G$2:$G$426,"BlackRock - iShares PHLX Semiconductor ETF",$E$2:$E$426,"Equities",$D$2:$D$426,"Instrumento",$C$2:$C$426,"Integra",$A$2:$A$426,"202606") | P6: 50.676744
A7: 202512 | B7: Comparación | C7: Habitat | D7: Benchmark | I7: Escalar_Portafolio | J7: F1_Integra | K7: Intensidad | L7: 27.245936 | N7: BlackRock - iShares PHLX Semiconductor ETF (Equities) | O7: =SUMIFS($L$2:$L$426,$G$2:$G$426,"BlackRock - iShares PHLX Semiconductor ETF",$E$2:$E$426,"Equities",$D$2:$D$426,"Instrumento",$C$2:$C$426,"Integra",$A$2:$A$426,"202606") | P7: 50.676744
A8: 202512 | B8: Comparación | C8: Habitat | D8: Benchmark | I8: Escalar_Portafolio | J8: F2_Integra | K8: Intensidad | L8: 13.075085 | N8: BlackRock - iShares Korea (Equities) | O8: =SUMIFS($L$2:$L$426,$G$2:$G$426,"BlackRock - iShares Korea",$E$2:$E$426,"Equities",$D$2:$D$426,"Instrumento",$C$2:$C$426,"Integra",$A$2:$A$426,"202606") | P8: 50.676744
A9: 202512 | B9: Comparación | C9: Habitat | D9: Benchmark | I9: Escalar_Portafolio | J9: F3_Integra | K9: Intensidad | L9: 22.829012 | N9: Global X - Copper Miners ETF (Equities) | O9: =SUMIFS($L$2:$L$426,$G$2:$G$426,"Global X - Copper Miners ETF",$E$2:$E$426,"Equities",$D$2:$D$426,"Instrumento",$C$2:$C$426,"Integra",$A$2:$A$426,"202606") | P9: 50.676744
A10: 202512 | B10: Comparación | C10: Integra | D10: Benchmark | I10: Escalar_Portafolio | J10: Total_Integra | K10: Intensidad | L10: 65.224844 | N10: BNP Paribas - Japan Small Caps (Equities) | O10: =SUMIFS($L$2:$L$426,$G$2:$G$426,"BNP Paribas - Japan Small Caps",$E$2:$E$426,"Equities",$D$2:$D$426,"Instrumento",$C$2:$C$426,"Integra",$A$2:$A$426,"202606") | P10: 50.676744
A11: 202512 | B11: Comparación | C11: Integra | D11: Benchmark | I11: Escalar_Portafolio | J11: F1_Integra | K11: Intensidad | L11: 28.069357 | N11: JP Morgan - Korea Equity Fund (Equities) | O11: =SUMIFS($L$2:$L$426,$G$2:$G$426,"JP Morgan - Korea Equity Fund",$E$2:$E$426,"Equities",$D$2:$D$426,"Instrumento",$C$2:$C$426,"Integra",$A$2:$A$426,"202606") | P11: 50.676744
A12: 202512 | B12: Comparación | C12: Integra | D12: Benchmark | I12: Escalar_Portafolio | J12: F2_Integra | K12: Intensidad | L12: 14.076505 | N12: Moneda - Latam High Yield (Fixed Income) | O12: =SUMIFS($L$2:$L$426,$G$2:$G$426,"Moneda - Latam High Yield",$E$2:$E$426,"Fixed Income",$D$2:$D$426,"Instrumento",$C$2:$C$426,"Integra",$A$2:$A$426,"202606") | P12: 50.676744
A13: 202512 | B13: Comparación | C13: Integra | D13: Benchmark | I13: Escalar_Portafolio | J13: F3_Integra | K13: Intensidad | L13: 23.078982 | N13: Vontobel - Emerging Markets Debt (Fixed Income) | O13: =SUMIFS($L$2:$L$426,$G$2:$G$426,"Vontobel - Emerging Markets Debt",$E$2:$E$426,"Fixed Income",$D$2:$D$426,"Instrumento",$C$2:$C$426,"Integra",$A$2:$A$426,"202606") | P13: 50.676744
A14: 202512 | B14: Comparación | C14: Prima | D14: Benchmark | I14: Escalar_Portafolio | J14: Total_Integra | K14: Intensidad | L14: 79.277836 | N14: Pimco - Emerging Markets Local Bond Fund (Fixed Income) | O14: =SUMIFS($L$2:$L$426,$G$2:$G$426,"Pimco - Emerging Markets Local Bond Fund",$E$2:$E$426,"Fixed Income",$D$2:$D$426,"Instrumento",$C$2:$C$426,"Integra",$A$2:$A$426,"202606") | P14: 50.676744
A15: 202512 | B15: Comparación | C15: Prima | D15: Benchmark | I15: Escalar_Portafolio | J15: F1_Integra | K15: Intensidad | L15: 43.397454 | N15: Moneda - Deuda Latam LCC (Fixed Income) | O15: =SUMIFS($L$2:$L$426,$G$2:$G$426,"Moneda - Deuda Latam LCC",$E$2:$E$426,"Fixed Income",$D$2:$D$426,"Instrumento",$C$2:$C$426,"Integra",$A$2:$A$426,"202606") | P15: 50.676744
A16: 202512 | B16: Comparación | C16: Prima | D16: Benchmark | I16: Escalar_Portafolio | J16: F2_Integra | K16: Intensidad | L16: 16.71005 | N16: Vontobel - Credit Opportunities (Fixed Income) | O16: =SUMIFS($L$2:$L$426,$G$2:$G$426,"Vontobel - Credit Opportunities",$E$2:$E$426,"Fixed Income",$D$2:$D$426,"Instrumento",$C$2:$C$426,"Integra",$A$2:$A$426,"202606") | P16: 50.676744
A17: 202512 | B17: Comparación | C17: Prima | D17: Benchmark | I17: Escalar_Portafolio | J17: F3_Integra | K17: Intensidad | L17: 19.170332 | N17: Vontobel - Credit Opportunities (Fixed Income) | O17: =SUMIFS($L$2:$L$426,$G$2:$G$426,"Vontobel - Credit Opportunities",$E$2:$E$426,"Fixed Income",$D$2:$D$426,"Instrumento",$C$2:$C$426,"Integra",$A$2:$A$426,"202606") | P17: 50.676744
A18: 202512 | B18: Comparación | C18: Profuturo | D18: Benchmark | I18: Escalar_Portafolio | J18: Total_Integra | K18: Intensidad | L18: 75.984063 | N18: Moneda - Latam High Yield (Fixed Income) | O18: =SUMIFS($L$2:$L$426,$G$2:$G$426,"Moneda - Latam High Yield",$E$2:$E$426,"Fixed Income",$D$2:$D$426,"Instrumento",$C$2:$C$426,"Integra",$A$2:$A$426,"202606") | P18: 50.676744
A19: 202512 | B19: Comparación | C19: Profuturo | D19: Benchmark | I19: Escalar_Portafolio | J19: F1_Integra | K19: Intensidad | L19: 34.14988 | N19: Pimco - Emerging Markets Local Bond Fund (Fixed Income) | O19: =SUMIFS($L$2:$L$426,$G$2:$G$426,"Pimco - Emerging Markets Local Bond Fund",$E$2:$E$426,"Fixed Income",$D$2:$D$426,"Instrumento",$C$2:$C$426,"Integra",$A$2:$A$426,"202606") | P19: 50.676744
A20: 202512 | B20: Comparación | C20: Profuturo | D20: Benchmark | I20: Escalar_Portafolio | J20: F2_Integra | K20: Intensidad | L20: 19.999563 | N20: Moneda - Deuda Latam LCC (Fixed Income) | O20: =SUMIFS($L$2:$L$426,$G$2:$G$426,"Moneda - Deuda Latam LCC",$E$2:$E$426,"Fixed Income",$D$2:$D$426,"Instrumento",$C$2:$C$426,"Integra",$A$2:$A$426,"202606") | P20: 50.676744
A21: 202512 | B21: Comparación | C21: Profuturo | D21: Benchmark | I21: Escalar_Portafolio | J21: F3_Integra | K21: Intensidad | L21: 21.83462 | N21: Vontobel - Emerging Markets Debt (Fixed Income) | O21: =SUMIFS($L$2:$L$426,$G$2:$G$426,"Vontobel - Emerging Markets Debt",$E$2:$E$426,"Fixed Income",$D$2:$D$426,"Instrumento",$C$2:$C$426,"Integra",$A$2:$A$426,"202606") | P21: 50.676744
A22: 202512 | B22: Comparación | C22: Ex_Integra | D22: Benchmark | E22: Equities | H22: DM | I22: Comparables_Subcat_Ajustado (x Weight del instrumento) | K22: Intensidad | L22: 63.45775
A23: 202512 | B23: Comparación | C23: Ex_Integra | D23: Benchmark | E23: Equities | H23: EM | I23: Comparables_Subcat_Ajustado (x Weight del instrumento) | K23: Intensidad | L23: 71.066596
A24: 202512 | B24: Comparación | C24: Ex_Integra | D24: Benchmark | E24: Equities | H24: Metales Preciosos | I24: Comparables_Subcat_Ajustado (x Weight del instrumento) | K24: Intensidad | L24: 78.727754
A25: 202512 | B25: Comparación | C25: Ex_Integra | D25: Benchmark | E25: Equities | H25: Peru | I25: Comparables_Subcat_Ajustado (x Weight del instrumento) | K25: Intensidad | L25: 31.332475
A26: 202512 | B26: Comparación | C26: Ex_Integra | D26: Benchmark | E26: Equities | H26: DM | I26: Comparables_Subcat_SinAjustar | K26: Intensidad | L26: 1.095698
A27: 202512 | B27: Comparación | C27: Ex_Integra | D27: Benchmark | E27: Equities | H27: EM | I27: Comparables_Subcat_SinAjustar | K27: Intensidad | L27: 0.861977
A28: 202512 | B28: Comparación | C28: Ex_Integra | D28: Benchmark | E28: Equities | H28: Metales Preciosos | I28: Comparables_Subcat_SinAjustar | K28: Intensidad | L28: 11.295997
A29: 202512 | B29: Comparación | C29: Ex_Integra | D29: Benchmark | E29: Equities | H29: Peru | I29: Comparables_Subcat_SinAjustar | K29: Intensidad | L29: 1.337515
A30: 202512 | B30: Comparación | C30: Habitat | D30: Benchmark | E30: Equities | H30: DM | I30: Comparables_Subcat_Ajustado (x Weight del instrumento) | K30: Intensidad | L30: 63.45775
A31: 202512 | B31: Comparación | C31: Habitat | D31: Benchmark | E31: Equities | H31: EM | I31: Comparables_Subcat_Ajustado (x Weight del instrumento) | K31: Intensidad | L31: 71.066596
A32: 202512 | B32: Comparación | C32: Habitat | D32: Benchmark | E32: Equities | H32: Metales Preciosos | I32: Comparables_Subcat_Ajustado (x Weight del instrumento) | K32: Intensidad | L32: 78.727754
A33: 202512 | B33: Comparación | C33: Habitat | D33: Benchmark | E33: Equities | H33: Peru | I33: Comparables_Subcat_Ajustado (x Weight del instrumento) | K33: Intensidad | L33: 31.332475
... A101: 202512 | B101: Comparación | C101: Profuturo | D101: Benchmark | E101: Fixed Income | H101: IG | I101: Comparables_Subcat_SinAjustar | K101: Intensidad | L101: 0.187061
A102: 202512 | B102: Comparación | C102: Ex_Integra | D102: Instrumento | E102: Equities | F102: Active | G102: BNP Paribas - Japan Small Caps | H102: DM | K102: Intensidad | L102: 1.621033
A103: 202512 | B103: Comparación | C103: Ex_Integra | D103: Instrumento | E103: Equities | F103: Active | G103: BNP Paribas - Japan Small Caps | H103: DM | K103: Weight | L103: 0.013354
A104: 202512 | B104: Comparación | C104: Habitat | D104: Instrumento | E104: Equities | F104: Active | G104: BNP Paribas - Japan Small Caps | H104: DM | K104: Intensidad | L104: 4.450315
A105: 202512 | B105: Comparación | C105: Habitat | D105: Instrumento | E105: Equities | F105: Active | G105: BNP Paribas - Japan Small Caps | H105: DM | K105: Weight | L105: 0.036662
A106: 202512 | B106: Comparación | C106: Integra | D106: Instrumento | E106: Equities | F106: Active | G106: BNP Paribas - Japan Small Caps | H106: DM | K106: Intensidad | L106: 3.044707
A107: 202512 | B107: Comparación | C107: Integra | D107: Instrumento | E107: Equities | F107: Active | G107: BNP Paribas - Japan Small Caps | H107: DM | K107: Weight | L107: 0.025083
...

Sheet Intensidad y Benchmarks
A1: Corte | B1: Corte_Rol | C1: AFP | D1: Segmento | E1: Categoria | F1: Tipo_Dato | G1: Pais | H1: Emisor | I1: Benchmark_Nombre | J1: Metrica | K1: Valor | M1: Serie | N1: Intensidad
A2: 202512 | B2: Comparación | C2: Habitat | D2: AFP_Categoria | E2: Materials | F2: MSCI | J2: Intensidad | K2: 21.110172 | M2: Integra | N2: =SUMIFS($K$2:$K$77,$D$2:$D$77,"AFP_Categoria",$C$2:$C$77,"Integra",$A$2:$A$77,"202606")
A3: 202512 | B3: Comparación | C3: Habitat | D3: AFP_Categoria | E3: Utilities | F3: MSCI | J3: Intensidad | K3: 0.592175 | M3: Prima | N3: =SUMIFS($K$2:$K$77,$D$2:$D$77,"AFP_Categoria",$C$2:$C$77,"Prima",$A$2:$A$77,"202606")
A4: 202512 | B4: Comparación | C4: Habitat | D4: AFP_Categoria | E4: Otros | F4: MSCI | J4: Intensidad | K4: 14.30549 | M4: Profuturo | N4: =SUMIFS($K$2:$K$77,$D$2:$D$77,"AFP_Categoria",$C$2:$C$77,"Profuturo",$A$2:$A$77,"202606")
A5: 202512 | B5: Comparación | C5: Habitat | D5: AFP_Categoria | E5: RF | F5: MSCI | J5: Intensidad | K5: 21.719801 | M5: Habitat | N5: =SUMIFS($K$2:$K$77,$D$2:$D$77,"AFP_Categoria",$C$2:$C$77,"Habitat",$A$2:$A$77,"202606")
A6: 202512 | B6: Comparación | C6: Habitat | D6: AFP_Categoria | E6: RV | F6: MSCI | J6: Intensidad | K6: 27.500445 | M6: ACWI | N6: =SUMIFS($K$2:$K$77,$D$2:$D$77,"Benchmark_Mercado",$I$2:$I$77,"ACWI",$A$2:$A$77,"202606")
A7: 202512 | B7: Comparación | C7: Habitat | D7: AFP_Categoria | E7: Proxies | F7: Proxies | J7: Intensidad | K7: 58.113863 | M7: ILF | N7: =SUMIFS($K$2:$K$77,$D$2:$D$77,"Benchmark_Mercado",$I$2:$I$77,"ILF",$A$2:$A$77,"202606")
A8: 202512 | B8: Comparación | C8: Habitat | D8: AFP_Categoria | E8: Alts | F8: Proxies | J8: Intensidad | K8: 18.714894 | M8: CEMB | N8: =SUMIFS($K$2:$K$77,$D$2:$D$77,"Benchmark_Mercado",$I$2:$I$77,"CEMB",$A$2:$A$77,"202606")
A9: 202512 | B9: Comparación | C9: Integra | D9: AFP_Categoria | E9: Materials | F9: MSCI | J9: Intensidad | K9: 27.233583 | M9: EMB | N9: =SUMIFS($K$2:$K$77,$D$2:$D$77,"Benchmark_Mercado",$I$2:$I$77,"EMB",$A$2:$A$77,"202606")
A10: 202512 | B10: Comparación | C10: Integra | D10: AFP_Categoria | E10: Utilities | F10: MSCI | J10: Intensidad | K10: 0.360136 | M10: Gobierno Central | N10: =SUMIFS($K$2:$K$77,$D$2:$D$77,"Soberano_GOB",$H$2:$H$77,"Gobierno Central",$A$2:$A$77,"202606")
A11: 202512 | B11: Comparación | C11: Integra | D11: AFP_Categoria | E11: Otros | F11: MSCI | J11: Intensidad | K11: 14.065582 | M11: Gobierno de Brasil | N11: =SUMIFS($K$2:$K$77,$D$2:$D$77,"Soberano_GOB",$H$2:$H$77,"Gobierno de Brasil",$A$2:$A$77,"202606")
A12: 202512 | B12: Comparación | C12: Integra | D12: AFP_Categoria | E12: RF | F12: MSCI | J12: Intensidad | K12: 23.202345 | M12: Gobierno de Colombia | N12: =SUMIFS($K$2:$K$77,$D$2:$D$77,"Soberano_GOB",$H$2:$H$77,"Gobierno de Colombia",$A$2:$A$77,"202606")
A13: 202512 | B13: Comparación | C13: Integra | D13: AFP_Categoria | E13: RV | F13: MSCI | J13: Intensidad | K13: 36.157902 | M13: Gobierno de Sudáfrica | N13: =SUMIFS($K$2:$K$77,$D$2:$D$77,"Soberano_GOB",$H$2:$H$77,"Gobierno de Sudáfrica",$A$2:$A$77,"202606")
A14: 202512 | B14: Comparación | C14: Integra | D14: AFP_Categoria | E14: Proxies | F14: Proxies | J14: Intensidad | K14: 40.601161 | M14: Gobierno de Mexico | N14: =SUMIFS($K$2:$K$77,$D$2:$D$77,"Soberano_GOB",$H$2:$H$77,"Gobierno de Mexico",$A$2:$A$77,"202606")
A15: 202512 | B15: Comparación | C15: Integra | D15: AFP_Categoria | E15: Alts | F15: Proxies | J15: Intensidad | K15: 17.58301 | M15: Gobierno de México | N15: =SUMIFS($K$2:$K$77,$D$2:$D$77,"Soberano_GOB",$H$2:$H$77,"Gobierno de México",$A$2:$A$77,"202606")
A16: 202512 | B16: Comparación | C16: Prima | D16: AFP_Categoria | E16: Materials | F16: MSCI | J16: Intensidad | K16: 36.738399 | M16: Gobierno de Chile | N16: =SUMIFS($K$2:$K$77,$D$2:$D$77,"Soberano_GOB",$H$2:$H$77,"Gobierno de Chile",$A$2:$A$77,"202606")
A17: 202512 | B17: Comparación | C17: Prima | D17: AFP_Categoria | E17: Utilities | F17: MSCI | J17: Intensidad | K17: 1.083011
A18: 202512 | B18: Comparación | C18: Prima | D18: AFP_Categoria | E18: Otros | F18: MSCI | J18: Intensidad | K18: 19.918916
A19: 202512 | B19: Comparación | C19: Prima | D19: AFP_Categoria | E19: RF | F19: MSCI | J19: Intensidad | K19: 40.486087
A20: 202512 | B20: Comparación | C20: Prima | D20: AFP_Categoria | E20: RV | F20: MSCI | J20: Intensidad | K20: 30.214588
A21: 202512 | B21: Comparación | C21: Prima | D21: AFP_Categoria | E21: Proxies | F21: Proxies | J21: Intensidad | K21: 43.735007
A22: 202512 | B22: Comparación | C22: Prima | D22: AFP_Categoria | E22: Alts | F22: Proxies | J22: Intensidad | K22: 10.062701
A23: 202512 | B23: Comparación | C23: Profuturo | D23: AFP_Categoria | E23: Materials | F23: MSCI | J23: Intensidad | K23: 17.533109
A24: 202512 | B24: Comparación | C24: Profuturo | D24: AFP_Categoria | E24: Utilities | F24: MSCI | J24: Intensidad | K24: 0.292189
A25: 202512 | B25: Comparación | C25: Profuturo | D25: AFP_Categoria | E25: Otros | F25: MSCI | J25: Intensidad | K25: 8.948961
A26: 202512 | B26: Comparación | C26: Profuturo | D26: AFP_Categoria | E26: RF | F26: MSCI | J26: Intensidad | K26: 28.365067
A27: 202512 | B27: Comparación | C27: Profuturo | D27: AFP_Categoria | E27: RV | F27: MSCI | J27: Intensidad | K27: 31.010547
A28: 202512 | B28: Comparación | C28: Profuturo | D28: AFP_Categoria | E28: Proxies | F28: Proxies | J28: Intensidad | K28: 48.881664
A29: 202512 | B29: Comparación | C29: Profuturo | D29: AFP_Categoria | E29: Alts | F29: Proxies | J29: Intensidad | K29: 13.582613
A30: 202512 | B30: Comparación | D30: Benchmark_Mercado | I30: ACWI | J30: Intensidad | K30: 39.567477
A31: 202512 | B31: Comparación | D31: Benchmark_Mercado | I31: ILF | J31: Intensidad | K31: 145.75332
A32: 202512 | B32: Comparación | D32: Benchmark_Mercado | I32: CEMB | J32: Intensidad | K32: 202.57506
A33: 202512 | B33: Comparación | D33: Benchmark_Mercado | I33: EMB | J33: Intensidad | K33: 388.10196
A34: 202512 | B34: Comparación | C34: Integra | D34: Soberano_GOB | G34: Perú | H34: Gobierno Central | J34: Intensidad | K34: 97.22459
A35: 202512 | B35: Comparación | C35: Integra | D35: Soberano_GOB | G35: Brasil | H35: Gobierno de Brasil | J35: Intensidad | K35: 14.223795
A36: 202512 | B36: Comparación | C36: Integra | D36: Soberano_GOB | G36: México | H36: Gobierno de México | J36: Intensidad | K36: 3.037226
A37: 202512 | B37: Comparación | C37: Integra | D37: Soberano_GOB | G37: Chile | H37: Gobierno de Chile | J37: Intensidad | K37: 4.951348
A38: 202512 | B38: Comparación | C38: Integra | D38: Soberano_GOB | G38: Colombia | H38: Gobierno de Colombia | J38: Intensidad | K38: 4.696621
A39: 202606 | B39: Actual | C39: Habitat | D39: AFP_Categoria | E39: Materials | F39: MSCI | J39: Intensidad | K39: 20.38687
A40: 202606 | B40: Actual | C40: Habitat | D40: AFP_Categoria | E40: Utilities | F40: MSCI | J40: Intensidad | K40: 0.638379
...

Sheet Mayores contribuyentes
A1: Corte | B1: Corte_Rol | C1: AFP | D1: Emisor | E1: Metrica | F1: Valor | H1: Emisor | I1: Intensidad | J1: Huella
A2: 202512 | B2: Comparación | C2: Ex_Integra | D2: AXA - World Funds Framligton Digital Economy | E2: Huella | F2: 0.096157 | H2: Minsur | I2: =SUMIFS('BD'!$S$2:$S$6977,'BD'!$H$2:$H$6977,"Mayores",'BD'!$B$2:$B$6977,"Integra",'BD'!$M$2:$M$6977,"Minsur",'BD'!$A$2:$A$6977,"202606") | J2: =SUMIFS('BD'!$R$2:$R$6977,'BD'!$H$2:$H$6977,"Mayores",'BD'!$B$2:$B$6977,"Integra",'BD'!$M$2:$M$6977,"Minsur",'BD'!$A$2:$A$6977,"202606")
A3: 202512 | B3: Comparación | C3: Ex_Integra | D3: AXA - World Funds Framligton Digital Economy | E3: Intensidad | F3: 2.7e-05 | H3: BlackRock - iShares Korea | I3: =SUMIFS('BD'!$S$2:$S$6977,'BD'!$H$2:$H$6977,"Mayores",'BD'!$B$2:$B$6977,"Integra",'BD'!$M$2:$M$6977,"BlackRock - iShares Korea",'BD'!$A$2:$A$6977,"202606") | J3: =SUMIFS('BD'!$R$2:$R$6977,'BD'!$H$2:$H$6977,"Mayores",'BD'!$B$2:$B$6977,"Integra",'BD'!$M$2:$M$6977,"BlackRock - iShares Korea",'BD'!$A$2:$A$6977,"202606")
A4: 202512 | B4: Comparación | C4: Ex_Integra | D4: AXA - World Funds Framligton Digital Economy | E4: Inv MM$ | F4: 0.070143 | H4: Vontobel - Emerging Markets Debt | I4: =SUMIFS('BD'!$S$2:$S$6977,'BD'!$H$2:$H$6977,"Mayores",'BD'!$B$2:$B$6977,"Integra",'BD'!$M$2:$M$6977,"Vontobel - Emerging Markets Debt",'BD'!$A$2:$A$6977,"202606") | J4: =SUMIFS('BD'!$R$2:$R$6977,'BD'!$H$2:$H$6977,"Mayores",'BD'!$B$2:$B$6977,"Integra",'BD'!$M$2:$M$6977,"Vontobel - Emerging Markets Debt",'BD'!$A$2:$A$6977,"202606")
A5: 202512 | B5: Comparación | C5: Ex_Integra | D5: AXA World Funds - US Dynamic High Yield | E5: Huella | F5: 0.117442 | H5: Nexa Resources Perú | I5: =SUMIFS('BD'!$S$2:$S$6977,'BD'!$H$2:$H$6977,"Mayores",'BD'!$B$2:$B$6977,"Integra",'BD'!$M$2:$M$6977,"Nexa Resources Perú",'BD'!$A$2:$A$6977,"202606") | J5: =SUMIFS('BD'!$R$2:$R$6977,'BD'!$H$2:$H$6977,"Mayores",'BD'!$B$2:$B$6977,"Integra",'BD'!$M$2:$M$6977,"Nexa Resources Perú",'BD'!$A$2:$A$6977,"202606")
A6: 202512 | B6: Comparación | C6: Ex_Integra | D6: AXA World Funds - US Dynamic High Yield | E6: Intensidad | F6: 3.2e-05 | H6: Ecopetrol | I6: =SUMIFS('BD'!$S$2:$S$6977,'BD'!$H$2:$H$6977,"Mayores",'BD'!$B$2:$B$6977,"Integra",'BD'!$M$2:$M$6977,"Ecopetrol",'BD'!$A$2:$A$6977,"202606") | J6: =SUMIFS('BD'!$R$2:$R$6977,'BD'!$H$2:$H$6977,"Mayores",'BD'!$B$2:$B$6977,"Integra",'BD'!$M$2:$M$6977,"Ecopetrol",'BD'!$A$2:$A$6977,"202606")
A7: 202512 | B7: Comparación | C7: Ex_Integra | D7: AXA World Funds - US Dynamic High Yield | E7: Inv MM$ | F7: 0.001041 | H7: Global X - Copper Miners ETF | I7: =SUMIFS('BD'!$S$2:$S$6977,'BD'!$H$2:$H$6977,"Mayores",'BD'!$B$2:$B$6977,"Integra",'BD'!$M$2:$M$6977,"Global X - Copper Miners ETF",'BD'!$A$2:$A$6977,"202606") | J7: =SUMIFS('BD'!$R$2:$R$6977,'BD'!$H$2:$H$6977,"Mayores",'BD'!$B$2:$B$6977,"Integra",'BD'!$M$2:$M$6977,"Global X - Copper Miners ETF",'BD'!$A$2:$A$6977,"202606")
A8: 202512 | B8: Comparación | C8: Ex_Integra | D8: Aberdeen - Select Emerging Markets Bond | E8: Huella | F8: 2.6e-05 | H8: Pimco - Emerging Markets Local Bond Fund | I8: =SUMIFS('BD'!$S$2:$S$6977,'BD'!$H$2:$H$6977,"Mayores",'BD'!$B$2:$B$6977,"Integra",'BD'!$M$2:$M$6977,"Pimco - Emerging Markets Local Bond Fund",'BD'!$A$2:$A$6977,"202606") | J8: =SUMIFS('BD'!$R$2:$R$6977,'BD'!$H$2:$H$6977,"Mayores",'BD'!$B$2:$B$6977,"Integra",'BD'!$M$2:$M$6977,"Pimco - Emerging Markets Local Bond Fund",'BD'!$A$2:$A$6977,"202606")
A9: 202512 | B9: Comparación | C9: Ex_Integra | D9: Aberdeen - Select Emerging Markets Bond | E9: Intensidad | F9: 0 | H9: BNP Paribas - Japan Small Caps | I9: =SUMIFS('BD'!$S$2:$S$6977,'BD'!$H$2:$H$6977,"Mayores",'BD'!$B$2:$B$6977,"Integra",'BD'!$M$2:$M$6977,"BNP Paribas - Japan Small Caps",'BD'!$A$2:$A$6977,"202606") | J9: =SUMIFS('BD'!$R$2:$R$6977,'BD'!$H$2:$H$6977,"Mayores",'BD'!$B$2:$B$6977,"Integra",'BD'!$M$2:$M$6977,"BNP Paribas - Japan Small Caps",'BD'!$A$2:$A$6977,"202606")
A10: 202512 | B10: Comparación | C10: Ex_Integra | D10: Aberdeen - Select Emerging Markets Bond | E10: Inv MM$ | F10: 0 | H10: Buenaventura | I10: =SUMIFS('BD'!$S$2:$S$6977,'BD'!$H$2:$H$6977,"Mayores",'BD'!$B$2:$B$6977,"Integra",'BD'!$M$2:$M$6977,"Buenaventura",'BD'!$A$2:$A$6977,"202606") | J10: =SUMIFS('BD'!$R$2:$R$6977,'BD'!$H$2:$H$6977,"Mayores",'BD'!$B$2:$B$6977,"Integra",'BD'!$M$2:$M$6977,"Buenaventura",'BD'!$A$2:$A$6977,"202606")
A11: 202512 | B11: Comparación | C11: Ex_Integra | D11: Aegon High Yield Global Bond Fund | E11: Huella | F11: 2598.6648 | H11: nan | I11: =SUMIFS('BD'!$S$2:$S$6977,'BD'!$H$2:$H$6977,"Mayores",'BD'!$B$2:$B$6977,"Integra",'BD'!$M$2:$M$6977,"nan",'BD'!$A$2:$A$6977,"202606") | J11: =SUMIFS('BD'!$R$2:$R$6977,'BD'!$H$2:$H$6977,"Mayores",'BD'!$B$2:$B$6977,"Integra",'BD'!$M$2:$M$6977,"nan",'BD'!$A$2:$A$6977,"202606")
A12: 202512 | B12: Comparación | C12: Ex_Integra | D12: Aegon High Yield Global Bond Fund | E12: Intensidad | F12: 0.461637 | H12: Vontobel - Credit Opportunities | I12: =SUMIFS('BD'!$S$2:$S$6977,'BD'!$H$2:$H$6977,"Mayores",'BD'!$B$2:$B$6977,"Integra",'BD'!$M$2:$M$6977,"Vontobel - Credit Opportunities",'BD'!$A$2:$A$6977,"202606") | J12: =SUMIFS('BD'!$R$2:$R$6977,'BD'!$H$2:$H$6977,"Mayores",'BD'!$B$2:$B$6977,"Integra",'BD'!$M$2:$M$6977,"Vontobel - Credit Opportunities",'BD'!$A$2:$A$6977,"202606")
A13: 202512 | B13: Comparación | C13: Ex_Integra | D13: Aegon High Yield Global Bond Fund | E13: Inv MM$ | F13: 38.74936 | H13: Aenza | I13: =SUMIFS('BD'!$S$2:$S$6977,'BD'!$H$2:$H$6977,"Mayores",'BD'!$B$2:$B$6977,"Integra",'BD'!$M$2:$M$6977,"Aenza",'BD'!$A$2:$A$6977,"202606") | J13: =SUMIFS('BD'!$R$2:$R$6977,'BD'!$H$2:$H$6977,"Mayores",'BD'!$B$2:$B$6977,"Integra",'BD'!$M$2:$M$6977,"Aenza",'BD'!$A$2:$A$6977,"202606")
A14: 202512 | B14: Comparación | C14: Ex_Integra | D14: Aenza | E14: Huella | F14: 7988.2834 | H14: JP Morgan - Korea Equity Fund | I14: =SUMIFS('BD'!$S$2:$S$6977,'BD'!$H$2:$H$6977,"Mayores",'BD'!$B$2:$B$6977,"Integra",'BD'!$M$2:$M$6977,"JP Morgan - Korea Equity Fund",'BD'!$A$2:$A$6977,"202606") | J14: =SUMIFS('BD'!$R$2:$R$6977,'BD'!$H$2:$H$6977,"Mayores",'BD'!$B$2:$B$6977,"Integra",'BD'!$M$2:$M$6977,"JP Morgan - Korea Equity Fund",'BD'!$A$2:$A$6977,"202606")
A15: 202512 | B15: Comparación | C15: Ex_Integra | D15: Aenza | E15: Intensidad | F15: 1.651909 | H15: BlackRock - iShares PHLX Semiconductor ETF | I15: =SUMIFS('BD'!$S$2:$S$6977,'BD'!$H$2:$H$6977,"Mayores",'BD'!$B$2:$B$6977,"Integra",'BD'!$M$2:$M$6977,"BlackRock - iShares PHLX Semiconductor ETF",'BD'!$A$2:$A$6977,"202606") | J15: =SUMIFS('BD'!$R$2:$R$6977,'BD'!$H$2:$H$6977,"Mayores",'BD'!$B$2:$B$6977,"Integra",'BD'!$M$2:$M$6977,"BlackRock - iShares PHLX Semiconductor ETF",'BD'!$A$2:$A$6977,"202606")
A16: 202512 | B16: Comparación | C16: Ex_Integra | D16: Aenza | E16: Inv MM$ | F16: 62.281954 | H16: WisdomTree - Japan Hedged Equity | I16: =SUMIFS('BD'!$S$2:$S$6977,'BD'!$H$2:$H$6977,"Mayores",'BD'!$B$2:$B$6977,"Integra",'BD'!$M$2:$M$6977,"WisdomTree - Japan Hedged Equity",'BD'!$A$2:$A$6977,"202606") | J16: =SUMIFS('BD'!$R$2:$R$6977,'BD'!$H$2:$H$6977,"Mayores",'BD'!$B$2:$B$6977,"Integra",'BD'!$M$2:$M$6977,"WisdomTree - Japan Hedged Equity",'BD'!$A$2:$A$6977,"202606")
A17: 202512 | B17: Comparación | C17: Ex_Integra | D17: Alicorp | E17: Huella | F17: 74.450437
A18: 202512 | B18: Comparación | C18: Ex_Integra | D18: Alicorp | E18: Intensidad | F18: 0.018426
A19: 202512 | B19: Comparación | C19: Ex_Integra | D19: Alicorp | E19: Inv MM$ | F19: 2.034165
A20: 202512 | B20: Comparación | C20: Ex_Integra | D20: Alliance Bernstein - Emerging Markets Growth | E20: Huella | F20: 348.61454
A21: 202512 | B21: Comparación | C21: Ex_Integra | D21: Alliance Bernstein - Emerging Markets Growth | E21: Intensidad | F21: 0.091332
A22: 202512 | B22: Comparación | C22: Ex_Integra | D22: Alliance Bernstein - Emerging Markets Growth | E22: Inv MM$ | F22: 3.849484
A23: 202512 | B23: Comparación | C23: Ex_Integra | D23: Allianz - Artificial Intelligence | E23: Huella | F23: 34.740787
A24: 202512 | B24: Comparación | C24: Ex_Integra | D24: Allianz - Artificial Intelligence | E24: Intensidad | F24: 0.009767
A25: 202512 | B25: Comparación | C25: Ex_Integra | D25: Allianz - Artificial Intelligence | E25: Inv MM$ | F25: 4.297153
A26: 202512 | B26: Comparación | C26: Ex_Integra | D26: Allianz - China-A | E26: Huella | F26: 59.193733
A27: 202512 | B27: Comparación | C27: Ex_Integra | D27: Allianz - China-A | E27: Intensidad | F27: 0.014008
A28: 202512 | B28: Comparación | C28: Ex_Integra | D28: Allianz - China-A | E28: Inv MM$ | F28: 1.652254
... A2719: 202606 | B2719: Actual | C2719: Profuturo | D2719: WisdomTree - Cloud Computing | E2719: Inv MM$ | F2719: 30.863486

Sheet Auditoría
A1: Hoja | B1: Objeto(s) en HISTORICO | C1: Metrica(s) | D1: Corte Actual (default) | E1: Corte Comparación (default) | F1: AFP default dashboard | G1: Nota / fórmula
A2: Huella Soberanos | B2: Soberanos | C2: Huella | D2: 202606 | E2: 202512 | F2: Integra | G2: País se obtiene mapeando Emisor con PAIS_POR_EMISOR_SOBERANO. También existen en HISTORICO '% Huella', '% AUM' e 'Intensidad implícita' para este objeto, no incluidas aquí.
A3: Intensidad Soberanos | B3: Soberanos | C3: Intensidad | D3: 202606 | E3: 202512 | F3: Integra | G3: Intensidad = CO2-H x Weight (no Huella x Weight).
A4: Huella por Sector | B4: Sector_MSCI_Proxies | C4: Huella | D4: 202606 | E4: 202512 | F4: Integra | G4: Tipo_Dato distingue MSCI (dato directo) vs Proxies. 'Proxies' consolida RF+RV+BU proxy sin distinguir origen.
A5: Intensidad por Sector | B5: Sector_MSCI_Proxies | C5: Intensidad | D5: 202606 | E5: 202512 | F5: Integra | G5: Igual a la hoja anterior, métrica Intensidad.
A6: Intensidad FFMM | B6: TopSubCat_Asset | C6: Intensidad, Weight | D6: 202606 | E6: No aplica (el chart solo usa el corte actual) | F6: Integra | G6: Los benchmarks 'Comparables_Subcat_Ajustado' y 'FFMM' son valores base que el dashboard multiplica por el Weight PROPIO de cada instrumento antes de graficar; esa multiplicación no viene precalculada aquí. Los benchmarks FFMM reflejan solo el corte actual (misma limitación que el dashboard).
A7: Intensidad y Benchmarks | B7: Sector_MSCI_Proxies, Comparables, Soberanos | C7: Intensidad | D7: 202606 | E7: No aplica (el chart solo usa el corte actual) | F7: Integra, Prima, Profuturo, Habitat (según segmento) | G7: Combina 3 fuentes distintas identificadas por la columna Segmento.
A8: Mayores contribuyentes | B8: Contrib_Variacion_Intensidad | C8: Huella, Intensidad, Inv MM$, PERDIO_HUELLA | D8: 202606 | E8: No aplica (el chart solo usa el corte actual) | F8: Integra | G8: El dashboard muestra solo el Top 15 por Intensidad; aquí va el universo BU+TD sin Proxy completo. PERDIO_HUELLA=1 marca emisores con dato de respaldo de la hoja 'Perdieron Huella' (símbolo ◇ en el dashboard).
