Workbook
Name IQ_CH: 110000
Name IQ_CQ: 5000
Name IQ_CY: 10000
Name IQ_DAILY: 500000
Name IQ_FH: 100000
Name IQ_FQ: 500
Name IQ_FY: 1000
Name IQ_LTM: 2000
Name IQ_MONTH: 15000
Name IQ_NTM: 6000
Name IQ_WEEK: 50000
Name IQ_YTD: 3000

Sheet IS
B2: PEN 000 | C2: 2019 | D2: 2020 | E2: 2021 | F2: 2022 | G2: 2023 | H2: 2024 | I2: 2025
B3: Ingresos de actividades ordinarias
B4: Ingresos por distribución de energía | C4: 369257 | D4: 372967 | E4: 425246 | F4: 480828 | G4: 531848 | H4: 562856 | I4: 573857
B5: Otros ingresos operativos | C5: 3866 | D5: 4731 | E5: 6017 | F5: 7755 | G5: 8905 | H5: 7667 | I5: 7564
B6: Total ingresos | C6: =SUM(C4:C5) -> 373123 | D6: =SUM(D4:D5) -> 377698 | E6: =SUM(E4:E5) -> 431263 | F6: =SUM(F4:F5) -> 488583 | G6: =SUM(G4:G5) -> 540753 | H6: =SUM(H4:H5) -> 570523 | I6: =SUM(I4:I5) -> 581421
B7: Costos de actividades ordinarias
B8: Costo de distribución de energía | C8: -247680 | D8: -246064 | E8: -273225 | F8: -322814 | G8: -361629 | H8: -386573 | I8: -398594
B9: Otros costos operativos | C9: -173 | D9: -83 | E9: -200 | F9: -235 | G9: -158 | H9: -200 | I9: -247
B10: Total costos | C10: =SUM(C8:C9) -> -247853 | D10: =SUM(D8:D9) -> -246147 | E10: =SUM(E8:E9) -> -273425 | F10: =SUM(F8:F9) -> -323049 | G10: =SUM(G8:G9) -> -361787 | H10: =SUM(H8:H9) -> -386773 | I10: =SUM(I8:I9) -> -398841
B12: Ganancia bruta | C12: =C6+C10 -> 125270 | D12: =D6+D10 -> 131551 | E12: =E6+E10 -> 157838 | F12: =F6+F10 -> 165534 | G12: =G6+G10 -> 178966 | H12: =H6+H10 -> 183750 | I12: =I6+I10 -> 182580
B14: Gastos operativos
B15: Gastos de comercialización | C15: -33370 | D15: -31513 | E15: -38236 | F15: -36038 | G15: -35653 | H15: -30427 | I15: -30840
B16: Gastos de administración | C16: -40609 | D16: -27281 | E16: -30651 | F16: -34720 | G16: -35719 | H16: -38860 | I16: -44184
B17: Pérdida por deterioro de CxC | C17: -2782 | D17: -4713 | E17: -2107 | F17: -1807 | G17: -4600 | H17: -2437 | I17: -1392
B18: Otros ingresos | C18: 4049 | D18: 3654 | E18: 7504 | F18: 9405 | G18: 6393 | H18: 7928 | I18: 7959
B19: Otros gastos | C19: -3396 | D19: -3983 | E19: -6504 | F19: -5170 | G19: -4744 | H19: -5912 | I19: -4015
B20: Total gastos operativos | C20: =SUM(C15:C19) -> -76108 | D20: =SUM(D15:D19) -> -63836 | E20: =SUM(E15:E19) -> -69994 | F20: =SUM(F15:F19) -> -68330 | G20: =SUM(G15:G19) -> -74323 | H20: =SUM(H15:H19) -> -69708 | I20: =SUM(I15:I19) -> -72472
B22: Resultado operativo | C22: =C12+C20 -> 49162 | D22: =D12+D20 -> 67715 | E22: =E12+E20 -> 87844 | F22: =F12+F20 -> 97204 | G22: =G12+G20 -> 104643 | H22: =H12+H20 -> 114042 | I22: =I12+I20 -> 110108
B24: Resultado financiero
B25: Ingresos financieros | C25: 3957 | D25: 7003 | E25: 3685 | F25: 5557 | G25: 5630 | H25: 4622 | I25: 4824
B26: Costos financieros | C26: -33988 | D26: -26572 | E26: -28061 | F26: -26463 | G26: -26995 | H26: -28692 | I26: -31380
B27: Diferencia de cambio, neta | C27: 3616 | D27: -1358 | E27: -1777 | F27: 1268 | G27: -154 | H27: -1124 | I27: 6977
B28: Costo financiero neto | C28: =SUM(C25:C27) -> -26415 | D28: =SUM(D25:D27) -> -20927 | E28: =SUM(E25:E27) -> -26153 | F28: =SUM(F25:F27) -> -19638 | G28: =SUM(G25:G27) -> -21519 | H28: =SUM(H25:H27) -> -25194 | I28: =SUM(I25:I27) -> -19579
B29: Ganancia antes de impuestos | C29: =C22+C28 -> 22747 | D29: =D22+D28 -> 46788 | E29: =E22+E28 -> 61691 | F29: =F22+F28 -> 77566 | G29: =G22+G28 -> 83124 | H29: =H22+H28 -> 88848 | I29: =I22+I28 -> 90529
B30: Gasto por impuesto a las ganancias | C30: -11369 | D30: -15026 | E30: -19614 | F30: -23928 | G30: -25479 | H30: -27190 | I30: -27170
B32: Ganancia del ejercicio | C32: =C29+C30 -> 11378 | D32: =D29+D30 -> 31762 | E32: =E29+E30 -> 42077 | F32: =F29+F30 -> 53638 | G32: =G29+G30 -> 57645 | H32: =H29+H30 -> 61658 | I32: =I29+I30 -> 63359
B34: Depreciación
B35: Amortización
B36: Intereses sobre CxC
B37: EBITDA | C37: =+C22+SUM(C34:C36) -> 49162 | D37: =+D22+SUM(D34:D36) -> 67715 | E37: =+E22+SUM(E34:E36) -> 87844 | F37: =+F22+SUM(F34:F36) -> 97204 | G37: =+G22+SUM(G34:G36) -> 104643 | H37: =+H22+SUM(H34:H36) -> 114042 | I37: =+I22+SUM(I34:I36) -> 110108
B39: Márgenes
B40: Margen bruto | C40: =C12/C$6 -> 0.33573379 | D40: =D12/D$6 -> 0.34829679 | E40: =E12/E$6 -> 0.36599013 | F40: =F12/F$6 -> 0.33880426 | G40: =G12/G$6 -> 0.33095702 | H40: =H12/H$6 -> 0.32207291 | I40: =I12/I$6 -> 0.31402375
B41: Margen operativo | C41: =C22/C$6 -> 0.13175816 | D41: =D22/D$6 -> 0.17928345 | E41: =E22/E$6 -> 0.20369009 | F41: =F22/F$6 -> 0.19895084 | G41: =G22/G$6 -> 0.19351349 | H41: =H22/H$6 -> 0.19989028 | I41: =I22/I$6 -> 0.1893774
B42: Margen neto | C42: =C32/C$6 -> 0.030493966 | D42: =D32/D$6 -> 0.084093641 | E42: =E32/E$6 -> 0.097566914 | F42: =F32/F$6 -> 0.10978278 | G42: =G32/G$6 -> 0.10660135 | H42: =H32/H$6 -> 0.10807277 | I42: =I32/I$6 -> 0.10897267
B43: Margen EBITDA
B45: Crecimiento
B46: Ingresos | C46: - | D46: =D6/C6-1 -> 0.012261372 | E46: =E6/D6-1 -> 0.14181965 | F46: =F6/E6-1 -> 0.13291194 | G46: =G6/F6-1 -> 0.10677817 | H46: =H6/G6-1 -> 0.055052861 | I46: =I6/H6-1 -> 0.019101772
B47: Ganancia bruta | C47: - | D47: =D12/C12-1 -> 0.050139698 | E47: =E12/D12-1 -> 0.19982364 | F47: =F12/E12-1 -> 0.048758854 | G47: =G12/F12-1 -> 0.081143451 | H47: =H12/G12-1 -> 0.026731334 | I47: =I12/H12-1 -> -0.0063673469
B48: Ganancia neta | C48: - | D48: =D32/C32-1 -> 1.7915275 | E48: =E32/D32-1 -> 0.32475915 | F48: =F32/E32-1 -> 0.27475818 | G48: =G32/F32-1 -> 0.074704501 | H48: =H32/G32-1 -> 0.069615752 | I48: =I32/H32-1 -> 0.027587661
B50: Tasa efectiva de impuesto | C50: =-C30/C29 -> 0.49980217 | D50: =-D30/D29 -> 0.32115072 | E50: =-E30/E29 -> 0.31793941 | F50: =-F30/F29 -> 0.30848568 | G50: =-G30/G29 -> 0.30651797 | H50: =-H30/H29 -> 0.30602827 | I50: =-I30/I29 -> 0.30012482

Sheet Energía distribuida
B2: PEN 000 | C2: 2019 | D2: 2020 | E2: 2021 | F2: 2022 | G2: 2023 | H2: 2024 | I2: 2025
B3: Ingresos por servicios de distribución de energía
B4: Clientes de baja tensión | C4: - | D4: - | E4: 282613 | F4: 308741 | G4: 317805 | H4: 334150 | I4: 347903
B5: Clientes de media tensión | C5: - | D5: - | E5: 91363 | F5: 100468 | G5: 104362 | H5: 107332 | I5: 110296
B6: Clientes libres | C6: - | D6: - | E6: 45119 | F6: 68650 | G6: 100499 | H6: 113517 | I6: 106027
B7: Peaje de transmisión y distribución | C7: - | D7: - | E7: 13569 | F7: 10877 | G7: 8336 | H7: 3469 | I7: 13299
B8: Servicios complementarios, conexión y corte/reconexión | C8: - | D8: - | E8: 12555 | F8: 13981 | G8: 15355 | H8: 17923 | I8: 16278
B9: Energía entregada y no facturada | C9: - | D9: - | E9: -644 | F9: 386 | G9: 1235 | H9: 7532 | I9: -1609
B10: Clientes - entidades relacionadas | C10: - | D10: - | E10: 294 | F10: 324 | G10: 346 | H10: 360 | I10: 318
B11: FOSE y mecanismo de compensación | C11: - | D11: - | E11: -19623 | F11: -22599 | G11: -16090 | H11: -21427 | I11: -18655
B12: Total servicios de distribución de energía | C12: =IS!C4 -> 369257 | D12: =IS!D4 -> 372967 | E12: =SUM(E4:E11) -> 425246 | F12: =SUM(F4:F11) -> 480828 | G12: =SUM(G4:G11) -> 531848 | H12: =SUM(H4:H11) -> 562856 | I12: =SUM(I4:I11) -> 573857
B14: Otros ingresos operativos
B15: Alquiler por uso de infraestructura | C15: - | D15: - | E15: - | F15: - | G15: 5821 | H15: 5829 | I15: 6374
B16: Servicios de ingeniería | C16: - | D16: - | E16: - | F16: - | G16: 2549 | H16: 1245 | I16: 375
B17: Mantenimiento en redes de terceros | C17: - | D17: - | E17: - | F17: - | G17: 235 | H17: 213 | I17: 491
B18: Otros ingresos operativos con relacionadas | C18: - | D18: - | E18: - | F18: - | G18: 300 | H18: 380 | I18: 324
B19: Total otros ingresos operativos | C19: =IS!C5 -> 3866 | D19: =IS!D5 -> 4731 | E19: =IS!E5 -> 6017 | F19: =IS!F5 -> 7755 | G19: =SUM(G15:G18) -> 8905 | H19: =SUM(H15:H18) -> 7667 | I19: =SUM(I15:I18) -> 7564
B21: Total ingresos de actividades ordinarias | C21: =C12+C19 -> 373123 | D21: =D12+D19 -> 377698 | E21: =E12+E19 -> 431263 | F21: =F12+F19 -> 488583 | G21: =G12+G19 -> 540753 | H21: =H12+H19 -> 570523 | I21: =I12+I19 -> 581421
B23: % servicios
B24: % baja tensión sobre distribución | C24: - | D24: - | E24: =E4/E12 -> 0.66458709 | F24: =F4/F12 -> 0.64210279 | G24: =G4/G12 -> 0.59754855 | H24: =H4/H12 -> 0.59366872 | I24: =I4/I12 -> 0.60625382
B25: % media tensión | C25: - | D25: - | E25: =E5/E12 -> 0.21484741 | F25: =F5/F12 -> 0.2089479 | G25: =G5/G12 -> 0.19622524 | H25: =H5/H12 -> 0.19069176 | I25: =I5/I12 -> 0.19220119
B26: % clientes libres | C26: - | D26: - | E26: =E6/E12 -> 0.10610094 | F26: =F6/F12 -> 0.14277455 | G26: =G6/G12 -> 0.18896188 | H26: =H6/H12 -> 0.20168036 | I26: =I6/I12 -> 0.18476206
B28: Crecimiento
B29: Crecimiento servicios de distribución (a/a) | C29: - | D29: =D12/C12-1 -> 0.010047203 | E29: =E12/D12-1 -> 0.14017058 | F29: =F12/E12-1 -> 0.13070552 | G29: =G12/F12-1 -> 0.10610863 | H29: =H12/G12-1 -> 0.058302372 | I29: =I12/H12-1 -> 0.019544964
B30: Crecimiento baja tensión (a/a) | C30: - | D30: - | E30: - | F30: =F4/E4-1 -> 0.092451515 | G30: =G4/F4-1 -> 0.029357941 | H30: =H4/G4-1 -> 0.051430909 | I30: =I4/H4-1 -> 0.041158163
B31: Crecimiento media tensión (a/a) | C31: - | D31: - | E31: - | F31: =F5/E5-1 -> 0.099657411 | G31: =G5/F5-1 -> 0.03875861 | H31: =H5/G5-1 -> 0.028458634 | I31: =I5/H5-1 -> 0.02761525
B32: Crecimiento clientes libres (a/a) | C32: - | D32: - | E32: - | F32: =F6/E6-1 -> 0.52153195 | G32: =G6/F6-1 -> 0.46393299 | H32: =H6/G6-1 -> 0.12953363 | I32: =I6/H6-1 -> -0.065981307
B34: Información operativa
B35: Energía distribuída | C35: =+SUM(C36:C37) -> 1068138 | D35: =+SUM(D36:D37) -> 1051543 | E35: =+SUM(E36:E37) -> 1136860 | F35: =+SUM(F36:F37) -> 1205140 | G35: =+SUM(G36:G37) -> 1269420 | H35: =+SUM(H36:H37) -> 1326147 | I35: =+SUM(I36:I37) -> 1400651
B36: Clientes propios ELD | C36: 725068 | D36: 700844 | E36: 750634 | F36: 829966 | G36: 940457 | H36: 1000161 | I36: 1016004
B37: Terceros que usan redes de ELD | C37: 343070 | D37: 350699 | E37: 386226 | F37: 375174 | G37: 328963 | H37: 325986 | I37: 384647
B38: Compra de energía y generación propia | C38: 847468 | D38: 822710 | E38: 895124 | F38: 990736 | G38: 1101855 | H38: 1147616 | I38: 1174419
B40: Clientes
B41: Redes (km)
B42: Pérdida de energía
B61: (1) Homologado: suma de servicios complementarios + venta de medidores/conexión + corte y reconexión. Hasta 2023 (EEFF 2023) se presentaba como un solo rubro; desde el EEFF 2024 se abre en 3.

Sheet Costos
B2: PEN 000 | C2: 2019 | D2: 2020 | E2: 2021 | F2: 2022 | G2: 2023 | H2: 2024 | I2: 2025
B3: Costo de servicio de distribución de energía
B4: Compra de energía | C4: 150389 | D4: 147275 | E4: 168635 | F4: 207229 | G4: 235874 | H4: 243210 | I4: 241681
B5: Compra de gas | C5: 28335 | D5: 32301 | E5: 35452 | F5: 38155 | G5: 39811 | H5: 45814 | I5: 52158
B6: Depreciación | C6: 42280 | D6: 41338 | E6: 43281 | F6: 44374 | G6: 45725 | H6: 49372 | I6: 55524
B7: Servicios prestados por relacionadas | C7: 8478 | D7: 8474 | E7: 9204 | F7: 9620 | G7: 14048 | H7: 19275 | I7: 19095
B8: Gastos de personal | C8: 6413 | D8: 7830 | E8: 7728 | F8: 7365 | G8: 9379 | H8: 9958 | I8: 9547
B9: Servicios prestados por terceros | C9: 2314 | D9: 2817 | E9: 2407 | F9: 2853 | G9: 2324 | H9: 2792 | I9: 3429
B10: Suministros diversos | C10: 1790 | D10: 2515 | E10: 2619 | F10: 3474 | G10: 3901 | H10: 5230 | I10: 6481
B11: Cargas diversas de gestión | C11: 2353 | D11: 2222 | E11: 2608 | F11: 3551 | G11: 4432 | H11: 4693 | I11: 3859
B12: Amortización | C12: 1275 | D12: 1226 | E12: 1216 | F12: 1208 | G12: 1118 | H12: 396 | I12: 924
B13: Tributos | C13: 70 | D13: 66 | E13: 75 | F13: 4985 | G13: 5017 | H13: 5833 | I13: 5896
B14: Arrendamientos | C14: 3983 | D14: 0 | E14: 0 | F14: 0 | G14: 0 | H14: 0 | I14: 0
B15: Total costo de servicio de distribución | C15: =SUM(C4:C14) -> 247680 | D15: =SUM(D4:D14) -> 246064 | E15: =SUM(E4:E14) -> 273225 | F15: =SUM(F4:F14) -> 322814 | G15: =SUM(G4:G14) -> 361629 | H15: =SUM(H4:H14) -> 386573 | I15: =SUM(I4:I14) -> 398594
B17: Otros costos operativos (remoción y reubicación de redes)
B18: Total otros costos operativos | C18: 173 | D18: 83 | E18: 200 | F18: 235 | G18: 158 | H18: 200 | I18: 247
B19: Del cual: amortización | C19: 6 | D19: 6 | E19: 6 | F19: 6 | G19: 9 | H19: 8 | I19: 13
B20: Total costos de actividades ordinarias | C20: =C15+C18 -> 247853 | D20: =D15+D18 -> 246147 | E20: =E15+E18 -> 273425 | F20: =F15+F18 -> 323049 | G20: =G15+G18 -> 361787 | H20: =H15+H18 -> 386773 | I20: =I15+I18 -> 398841
B22: Análisis
B23: Costos pass-through (compra de energía + gas) / ingresos | C23: =(C4+C5)/IS!C6 -> 0.47899486 | D23: =(D4+D5)/IS!D6 -> 0.47544864 | E23: =(E4+E5)/IS!E6 -> 0.47323095 | F23: =(F4+F5)/IS!F6 -> 0.50223606 | G23: =(G4+G5)/IS!G6 -> 0.50981687 | H23: =(H4+H5)/IS!H6 -> 0.50659483 | I23: =(I4+I5)/IS!I6 -> 0.50538078
B24: Compra de energía + gas / total costo de distribución | C24: =(C4+C5)/C15 -> 0.72159238 | D24: =(D4+D5)/D15 -> 0.72979387 | E24: =(E4+E5)/E15 -> 0.74695581 | F24: =(F4+F5)/F15 -> 0.76014051 | G24: =(G4+G5)/G15 -> 0.76234207 | H24: =(H4+H5)/H15 -> 0.74765698 | I24: =(I4+I5)/I15 -> 0.73718872
B25: Costo total / ingresos | C25: =C20/IS!C6 -> 0.66426621 | D25: =D20/IS!D6 -> 0.65170321 | E25: =E20/IS!E6 -> 0.63400987 | F25: =F20/IS!F6 -> 0.66119574 | G25: =G20/IS!G6 -> 0.66904298 | H25: =H20/IS!H6 -> 0.67792709 | I25: =I20/IS!I6 -> 0.68597625
B26: Costos "propios" excl. energía, gas, depreciación y amortización | C26: =C15-C4-C5-C6-C12 -> 25401 | D26: =D15-D4-D5-D6-D12 -> 23924 | E26: =E15-E4-E5-E6-E12 -> 24641 | F26: =F15-F4-F5-F6-F12 -> 31848 | G26: =G15-G4-G5-G6-G12 -> 39101 | H26: =H15-H4-H5-H6-H12 -> 47781 | I26: =I15-I4-I5-I6-I12 -> 48307

Sheet Gastos Operativos
B2: PEN 000 | C2: 2019 | D2: 2020 | E2: 2021 | F2: 2022 | G2: 2023 | H2: 2024 | I2: 2025
B3: Gastos de comercialización
B4: Servicios prestados por relacionadas | C4: 10791 | D4: 9640 | E4: 13168 | F4: 14300 | G4: 14791 | H4: 12979 | I4: 12426
B5: Gastos de personal | C5: 5995 | D5: 6633 | E5: 7038 | F5: 7417 | G5: 6599 | H5: 7268 | I5: 7427
B6: Servicios prestados por terceros | C6: 6378 | D6: 5221 | E6: 5891 | F6: 6271 | G6: 5166 | H6: 4893 | I6: 5446
B7: Suministros diversos | C7: 4599 | D7: 4283 | E7: 5843 | F7: 5990 | G7: 6944 | H7: 3970 | I7: 3757
B8: Tributos | C8: 4346 | D8: 4511 | E8: 4875 | F8: 564 | G8: 1056 | H8: 143 | I8: 301
B9: Amortización | C9: 691 | D9: 690 | E9: 692 | F9: 719 | G9: 565 | H9: 513 | I9: 542
B10: Depreciación | C10: 363 | D10: 343 | E10: 498 | F10: 593 | G10: 450 | H10: 533 | I10: 564
B11: Cargas diversas de gestión | C11: 207 | D11: 192 | E11: 231 | F11: 184 | G11: 82 | H11: 128 | I11: 377
B12: Total gastos de comercialización | C12: =SUM(C4:C11) -> 33370 | D12: =SUM(D4:D11) -> 31513 | E12: =SUM(E4:E11) -> 38236 | F12: =SUM(F4:F11) -> 36038 | G12: =SUM(G4:G11) -> 35653 | H12: =SUM(H4:H11) -> 30427 | I12: =SUM(I4:I11) -> 30840
B14: Gastos de administración
B15: Gastos de personal | C15: 28352 | D15: 15195 | E15: 17065 | F15: 17941 | G15: 16636 | H15: 18347 | I15: 20092
B16: Servicios prestados por terceros | C16: 7080 | D16: 5859 | E16: 7142 | F16: 9639 | G16: 12420 | H16: 14015 | I16: 17094
B17: Depreciación | C17: 2278 | D17: 2775 | E17: 2839 | F17: 3127 | G17: 3394 | H17: 3462 | I17: 3240
B18: Cargas diversas de gestión | C18: 1158 | D18: 2295 | E18: 2452 | F18: 2883 | G18: 1849 | H18: 1665 | I18: 2202
B19: Suministros diversos | C19: 386 | D19: 413 | E19: 496 | F19: 434 | G19: 569 | H19: 527 | I19: 645
B20: Amortización | C20: 329 | D20: 333 | E20: 386 | F20: 407 | G20: 364 | H20: 361 | I20: 356
B21: Tributos | C21: 190 | D21: 149 | E21: 96 | F21: 140 | G21: 347 | H21: 258 | I21: 258
B22: Servicios prestados por relacionadas | C22: 836 | D22: 262 | E22: 175 | F22: 149 | G22: 140 | H22: 225 | I22: 297
B23: Total gastos de administración | C23: =SUM(C15:C22) -> 40609 | D23: =SUM(D15:D22) -> 27281 | E23: =SUM(E15:E22) -> 30651 | F23: =SUM(F15:F22) -> 34720 | G23: =SUM(G15:G22) -> 35719 | H23: =SUM(H15:H22) -> 38860 | I23: =SUM(I15:I22) -> 44184
B25: Pérdida por deterioro de cuentas por cobrar comerciales
B26: Deterioro de cuentas por cobrar comerciales | C26: =-IS!C17 -> 2782 | D26: =-IS!D17 -> 4713 | E26: =-IS!E17 -> 2107 | F26: =-IS!F17 -> 1807 | G26: =-IS!G17 -> 4600 | H26: =-IS!H17 -> 2437 | I26: =-IS!I17 -> 1392
B28: Otros ingresos (Nota Otros Ingresos y Gastos)
B29: Servicios prestados a partes relacionadas | C29: 2022 | D29: 2688 | E29: 2889 | F29: 3415 | G29: 3543 | H29: 4647 | I29: 5663
B30: Venta de materiales a partes relacionadas | C30: 0 | D30: 0 | E30: 625 | F30: 1131 | G30: 241 | H30: 642 | I30: 255
B31: Recuperación de incobrables / castigo y condonación de deudas | C31: 942 | D31: 618 | E31: 3278 | F31: 2235 | G31: 1737 | H31: 1343 | I31: 1283
B32: Venta de chatarra y de propiedad, planta y equipo | C32: 224 | D32: 93 | E32: 183 | F32: 952 | G32: 309 | H32: 472 | I32: 207
B33: Reversión de provisiones y recupero de desvalorización de inventarios | C33: 69 | D33: 62 | E33: 182 | F33: 937 | G33: 2 | H33: 0 | I33: 25
B34: Indemnizaciones, penalidades, alquileres e intereses por devolución de impuestos | C34: 342 | D34: 49 | E34: 239 | F34: 566 | G34: 453 | H34: 575 | I34: 236
B35: Otros menores | C35: 450 | D35: 144 | E35: 108 | F35: 169 | G35: 108 | H35: 249 | I35: 290
B36: Total otros ingresos | C36: =SUM(C29:C35) -> 4049 | D36: =SUM(D29:D35) -> 3654 | E36: =SUM(E29:E35) -> 7504 | F36: =SUM(F29:F35) -> 9405 | G36: =SUM(G29:G35) -> 6393 | H36: =SUM(H29:H35) -> 7928 | I36: =SUM(I29:I35) -> 7959
B38: Otros gastos (Nota Otros Ingresos y Gastos)
B39: Provisiones, desvalorización de inventarios y deterioro de otras cuentas por cobrar / castigos | C39: 1064 | D39: 1467 | E39: 3593 | F39: 1511 | G39: 2013 | H39: 2137 | I39: 488
B40: Costo de baja de activo fijo e intangibles | C40: 1240 | D40: 1301 | E40: 588 | F40: 740 | G40: 1058 | H40: 1093 | I40: 840
B41: Gerenciamiento, sinergias corporativas, backoffice y gestión de recaudo | C41: 0 | D41: 160 | E41: 751 | F41: 854 | G41: 1007 | H41: 1470 | I41: 2069
B42: Costo por venta de materiales | C42: 557 | D42: 416 | E42: 719 | F42: 1125 | G42: 260 | H42: 631 | I42: 165
B43: Gastos de personal y servicios a relacionadas | C43: 110 | D43: 115 | E43: 149 | F43: 151 | G43: 115 | H43: 236 | I43: 185
B44: Indemnizaciones, sanciones y gastos de ejercicios anteriores | C44: 361 | D44: 54 | E44: 523 | F44: 715 | G44: 263 | H44: 298 | I44: 58
B45: Gastos asociados al COVID-19 | C45: 0 | D45: 426 | E45: 119 | F45: 32 | G45: 0 | H45: 0 | I45: 0
...

Sheet Costos y Gastos x Naturaleza
A1: Costos y gastos operativos consolidados por naturaleza + EBITDA simple
A2: Suma de costo de servicio + comercialización + administración (sin otros costos/ingresos/gastos). EBITDA simple = resultado de operación + depreciación + amortización.
A4: En miles de soles (S/ 000) | B4: Nota | C4: 2019 | D4: 2020 | E4: 2021 | F4: 2022 | G4: 2023 | H4: 2024 | I4: 2025
A5: Por naturaleza (costo de servicio + comercialización + administración)
A6: Compra de energía | C6: =Costos!C4 -> 150389 | D6: =Costos!D4 -> 147275 | E6: =Costos!E4 -> 168635 | F6: =Costos!F4 -> 207229 | G6: =Costos!G4 -> 235874 | H6: =Costos!H4 -> 243210 | I6: =Costos!I4 -> 241681
A7: Compra de gas | C7: =Costos!C5 -> 28335 | D7: =Costos!D5 -> 32301 | E7: =Costos!E5 -> 35452 | F7: =Costos!F5 -> 38155 | G7: =Costos!G5 -> 39811 | H7: =Costos!H5 -> 45814 | I7: =Costos!I5 -> 52158
A8: Gastos de personal | C8: =Costos!C8+'Gastos Operativos'!C5+'Gastos Operativos'!C15 -> 40760 | D8: =Costos!D8+'Gastos Operativos'!D5+'Gastos Operativos'!D15 -> 29658 | E8: =Costos!E8+'Gastos Operativos'!E5+'Gastos Operativos'!E15 -> 31831 | F8: =Costos!F8+'Gastos Operativos'!F5+'Gastos Operativos'!F15 -> 32723 | G8: =Costos!G8+'Gastos Operativos'!G5+'Gastos Operativos'!G15 -> 32614 | H8: =Costos!H8+'Gastos Operativos'!H5+'Gastos Operativos'!H15 -> 35573 | I8: =Costos!I8+'Gastos Operativos'!I5+'Gastos Operativos'!I15 -> 37066
A9: Servicios prestados por relacionadas | C9: =Costos!C7+'Gastos Operativos'!C4+'Gastos Operativos'!C22 -> 20105 | D9: =Costos!D7+'Gastos Operativos'!D4+'Gastos Operativos'!D22 -> 18376 | E9: =Costos!E7+'Gastos Operativos'!E4+'Gastos Operativos'!E22 -> 22547 | F9: =Costos!F7+'Gastos Operativos'!F4+'Gastos Operativos'!F22 -> 24069 | G9: =Costos!G7+'Gastos Operativos'!G4+'Gastos Operativos'!G22 -> 28979 | H9: =Costos!H7+'Gastos Operativos'!H4+'Gastos Operativos'!H22 -> 32479 | I9: =Costos!I7+'Gastos Operativos'!I4+'Gastos Operativos'!I22 -> 31818
A10: Servicios prestados por terceros | C10: =Costos!C9+'Gastos Operativos'!C6+'Gastos Operativos'!C16 -> 15772 | D10: =Costos!D9+'Gastos Operativos'!D6+'Gastos Operativos'!D16 -> 13897 | E10: =Costos!E9+'Gastos Operativos'!E6+'Gastos Operativos'!E16 -> 15440 | F10: =Costos!F9+'Gastos Operativos'!F6+'Gastos Operativos'!F16 -> 18763 | G10: =Costos!G9+'Gastos Operativos'!G6+'Gastos Operativos'!G16 -> 19910 | H10: =Costos!H9+'Gastos Operativos'!H6+'Gastos Operativos'!H16 -> 21700 | I10: =Costos!I9+'Gastos Operativos'!I6+'Gastos Operativos'!I16 -> 25969
A11: Depreciación | C11: =Costos!C6+'Gastos Operativos'!C10+'Gastos Operativos'!C17 -> 44921 | D11: =Costos!D6+'Gastos Operativos'!D10+'Gastos Operativos'!D17 -> 44456 | E11: =Costos!E6+'Gastos Operativos'!E10+'Gastos Operativos'!E17 -> 46618 | F11: =Costos!F6+'Gastos Operativos'!F10+'Gastos Operativos'!F17 -> 48094 | G11: =Costos!G6+'Gastos Operativos'!G10+'Gastos Operativos'!G17 -> 49569 | H11: =Costos!H6+'Gastos Operativos'!H10+'Gastos Operativos'!H17 -> 53367 | I11: =Costos!I6+'Gastos Operativos'!I10+'Gastos Operativos'!I17 -> 59328
A12: Amortización | C12: =Costos!C12+'Gastos Operativos'!C9+'Gastos Operativos'!C20 -> 2295 | D12: =Costos!D12+'Gastos Operativos'!D9+'Gastos Operativos'!D20 -> 2249 | E12: =Costos!E12+'Gastos Operativos'!E9+'Gastos Operativos'!E20 -> 2294 | F12: =Costos!F12+'Gastos Operativos'!F9+'Gastos Operativos'!F20 -> 2334 | G12: =Costos!G12+'Gastos Operativos'!G9+'Gastos Operativos'!G20 -> 2047 | H12: =Costos!H12+'Gastos Operativos'!H9+'Gastos Operativos'!H20 -> 1270 | I12: =Costos!I12+'Gastos Operativos'!I9+'Gastos Operativos'!I20 -> 1822
A13: Tributos | C13: =Costos!C13+'Gastos Operativos'!C8+'Gastos Operativos'!C21 -> 4606 | D13: =Costos!D13+'Gastos Operativos'!D8+'Gastos Operativos'!D21 -> 4726 | E13: =Costos!E13+'Gastos Operativos'!E8+'Gastos Operativos'!E21 -> 5046 | F13: =Costos!F13+'Gastos Operativos'!F8+'Gastos Operativos'!F21 -> 5689 | G13: =Costos!G13+'Gastos Operativos'!G8+'Gastos Operativos'!G21 -> 6420 | H13: =Costos!H13+'Gastos Operativos'!H8+'Gastos Operativos'!H21 -> 6234 | I13: =Costos!I13+'Gastos Operativos'!I8+'Gastos Operativos'!I21 -> 6455
A14: Suministros diversos | C14: =Costos!C10+'Gastos Operativos'!C7+'Gastos Operativos'!C19 -> 6775 | D14: =Costos!D10+'Gastos Operativos'!D7+'Gastos Operativos'!D19 -> 7211 | E14: =Costos!E10+'Gastos Operativos'!E7+'Gastos Operativos'!E19 -> 8958 | F14: =Costos!F10+'Gastos Operativos'!F7+'Gastos Operativos'!F19 -> 9898 | G14: =Costos!G10+'Gastos Operativos'!G7+'Gastos Operativos'!G19 -> 11414 | H14: =Costos!H10+'Gastos Operativos'!H7+'Gastos Operativos'!H19 -> 9727 | I14: =Costos!I10+'Gastos Operativos'!I7+'Gastos Operativos'!I19 -> 10883
A15: Cargas diversas de gestión | C15: =Costos!C11+'Gastos Operativos'!C11+'Gastos Operativos'!C18 -> 3718 | D15: =Costos!D11+'Gastos Operativos'!D11+'Gastos Operativos'!D18 -> 4709 | E15: =Costos!E11+'Gastos Operativos'!E11+'Gastos Operativos'!E18 -> 5291 | F15: =Costos!F11+'Gastos Operativos'!F11+'Gastos Operativos'!F18 -> 6618 | G15: =Costos!G11+'Gastos Operativos'!G11+'Gastos Operativos'!G18 -> 6363 | H15: =Costos!H11+'Gastos Operativos'!H11+'Gastos Operativos'!H18 -> 6486 | I15: =Costos!I11+'Gastos Operativos'!I11+'Gastos Operativos'!I18 -> 6438
A16: Arrendamientos | C16: =Costos!C14 -> 3983 | D16: =Costos!D14 -> 0 | E16: =Costos!E14 -> 0 | F16: =Costos!F14 -> 0 | G16: =Costos!G14 -> 0 | H16: =Costos!H14 -> 0 | I16: =Costos!I14 -> 0
A17: Total | C17: =SUM(C6:C16) -> 321659 | D17: =SUM(D6:D16) -> 304858 | E17: =SUM(E6:E16) -> 342112 | F17: =SUM(F6:F16) -> 393572 | G17: =SUM(G6:G16) -> 433001 | H17: =SUM(H6:H16) -> 455860 | I17: =SUM(I6:I16) -> 473618
A18: Verificación vs. costo de servicio + comercialización + administración (debe ser 0) | C18: =C17+IS!C8+IS!C15+IS!C16 -> 0 | D18: =D17+IS!D8+IS!D15+IS!D16 -> 0 | E18: =E17+IS!E8+IS!E15+IS!E16 -> 0 | F18: =F17+IS!F8+IS!F15+IS!F16 -> 0 | G18: =G17+IS!G8+IS!G15+IS!G16 -> 0 | H18: =H17+IS!H8+IS!H15+IS!H16 -> 0 | I18: =I17+IS!I8+IS!I15+IS!I16 -> 0
A20: EBITDA simple
A21: Resultado de actividades de operación | C21: =IS!C22 -> 49162 | D21: =IS!D22 -> 67715 | E21: =IS!E22 -> 87844 | F21: =IS!F22 -> 97204 | G21: =IS!G22 -> 104643 | H21: =IS!H22 -> 114042 | I21: =IS!I22 -> 110108
A22: (+) Depreciación | C22: =C11 -> 44921 | D22: =D11 -> 44456 | E22: =E11 -> 46618 | F22: =F11 -> 48094 | G22: =G11 -> 49569 | H22: =H11 -> 53367 | I22: =I11 -> 59328
A23: (+) Amortización (incl. otros costos operativos) | C23: =C12+Costos!C19 -> 2301 | D23: =D12+Costos!D19 -> 2255 | E23: =E12+Costos!E19 -> 2300 | F23: =F12+Costos!F19 -> 2340 | G23: =G12+Costos!G19 -> 2056 | H23: =H12+Costos!H19 -> 1278 | I23: =I12+Costos!I19 -> 1835
A24: EBITDA simple | C24: =SUM(C21:C23) -> 96384 | D24: =SUM(D21:D23) -> 114426 | E24: =SUM(E21:E23) -> 136762 | F24: =SUM(F21:F23) -> 147638 | G24: =SUM(G21:G23) -> 156268 | H24: =SUM(H21:H23) -> 168687 | I24: =SUM(I21:I23) -> 171271
A25: Margen EBITDA simple | C25: =C24/IS!C6 -> 0.25831696 | D25: =D24/IS!D6 -> 0.30295633 | E25: =E24/IS!E6 -> 0.31711972 | F25: =F24/IS!F6 -> 0.30217588 | G25: =G24/IS!G6 -> 0.28898222 | H25: =H24/IS!H6 -> 0.29567081 | I25: =I24/IS!I6 -> 0.29457312
A26: Memo: ingresos menos compra de energía y gas (margen propio de distribución) | C26: =IS!C6-C6-C7 -> 194399 | D26: =IS!D6-D6-D7 -> 198122 | E26: =IS!E6-E6-E7 -> 227176 | F26: =IS!F6-F6-F7 -> 243199 | G26: =IS!G6-G6-G7 -> 265068 | H26: =IS!H6-H6-H7 -> 281499 | I26: =IS!I6-I6-I7 -> 287582
A28: Nota: el roadshow define un EBITDA ajustado distinto (suma otros ingresos/gastos e intereses de cuentas por cobrar comerciales); no es comparable con este EBITDA simple.
A29: Sobre 2022: depreciación y amortización idénticas a las notas; la reexpresión de tributos no altera el total consolidado.
