Workbook
Name IQ_CH: 110000
Name IQ_CQ: 5000
Name IQ_CY: 10000
Name IQ_DAILY: 500000
Name IQ_FH: 100000
Name IQ_FQ: 500
Name IQ_FY: 1000
Name IQ_LTM: 2000
Name IQ_MONTH: 15000
Name IQ_NTM: 6000
Name IQ_WEEK: 50000
Name IQ_YTD: 3000

Sheet guia
A1: Fecha Reporte
A2: =TEXT(EDATE(TODAY(),1),"yyyymm") -> 202608 | B2: =TEXT(EDATE(TODAY(),0),"yyyymm") -> 202607

Sheet 202606
A1: FUND_SHARE_CLASS_ID | B1: FUND_NAME | C1: Client_ID | D1: Security_Status | E1: FUND_ISIN | F1: FUND_TICKER | G1: FUND_FINANCED_CARBON_EMISSIONS | H1: FUND_CARBON_EMISSIONS_SCOPE_3_TOT_EVIC_INTEN | I1: FUND_ISIN
A2: 40056077 | B2: iShares Core S&P 500 ETF | C2: US4642872000 | D2: Matched | E2: US4642872000 | F2: IVV | G2: 22.272457 | H2: 177.58506 | I2: US4642872000
A3: 40056109 | B3: iShares US Real Estate ETF | C3: US4642877397 | D3: Matched | E3: US4642877397 | F3: IYR | G3: 6.7584659 | H3: 39.940379 | I3: US4642877397
A4: 40056868 | B4: iShares MSCI Eurozone ETF | C4: US4642866085 | D4: Matched | E4: US4642866085 | F4: EZU | G4: 43.232015 | H4: 396.91306 | I4: US4642866085
A5: 40068873 | B5: iShares Latin America 40 ETF | C5: US4642873909 | D5: Matched | E5: US4642873909 | F5: ILF | G5: 109.30923 | H5: 743.38134 | I5: US4642873909
A6: 40073950 | B6: iShares Global Energy ETF | C6: US4642873412 | D6: Matched | E6: US4642873412 | F6: IXC | G6: 208.759 | H6: 2220.5207 | I6: US4642873412
A7: 40073951 | B7: iShares Global Financials ETF | C7: US4642873339 | D7: Matched | E7: US4642873339 | F7: IXG | G7: 3.533892 | H7: 54.296142 | I7: US4642873339
A8: 40073952 | B8: iShares Global Healthcare ETF | C8: US4642873255 | D8: Matched | E8: US4642873255 | F8: IXJ | G8: 2.7511171 | H8: 89.510659 | I8: US4642873255
A9: 40073953 | B9: iShares Global Tech ETF | C9: US4642872919 | D9: Matched | E9: US4642872919 | F9: IXN | G9: 7.9125586 | H9: 72.088831 | I9: US4642872919
A10: 40073954 | B10: iShares Global Comm Services ETF | C10: US4642872752 | D10: Matched | E10: US4642872752 | F10: IXP | G10: 3.9668277 | H10: 36.215903 | I10: US4642872752
A11: 40111267 | B11: iShares Global Consumer Discretionary ETF | C11: US4642887453 | D11: Matched | E11: US4642887453 | F11: RXI | G11: 11.680975 | H11: 322.22907 | I11: US4642887453
A12: 40111270 | B12: iShares Global Consumer Staples ETF | C12: US4642887370 | D12: Matched | E12: US4642887370 | F12: KXI | G12: 20.599526 | H12: 283.85097 | I12: US4642887370
A13: 40111272 | B13: iShares Global Industrials ETF | C13: US4642887297 | D13: Matched | E13: US4642887297 | F13: EXI | G13: 29.22582 | H13: 600.13717 | I13: US4642887297
... A26: 68060932 | B26: iShares ? High Yield Corp Bond UCITS ETF EUR D | C26: IE00B66F4759 | D26: Matched | E26: IE00B66F4759 | F26: IHYG | G26: 99.280223 | H26: 741.44553 | I26: IE00B66F4759

Sheet 202607
A1: FUND_SHARE_CLASS_ID | B1: FUND_NAME | C1: Client_ID | D1: Security_Status | E1: FUND_ISIN | F1: FUND_TICKER | G1: FUND_FINANCED_CARBON_EMISSIONS | H1: FUND_CARBON_EMISSIONS_SCOPE_3_TOT_EVIC_INTEN | I1: FUND_ISIN
A2: 40056077 | B2: iShares Core S&P 500 ETF | C2: US4642872000 | D2: Matched | E2: US4642872000 | F2: IVV | G2: 22.272457 | H2: 177.58506 | I2: US4642872000
A3: 40056109 | B3: iShares US Real Estate ETF | C3: US4642877397 | D3: Matched | E3: US4642877397 | F3: IYR | G3: 6.7584659 | H3: 39.940379 | I3: US4642877397
A4: 40056868 | B4: iShares MSCI Eurozone ETF | C4: US4642866085 | D4: Matched | E4: US4642866085 | F4: EZU | G4: 43.232015 | H4: 396.91306 | I4: US4642866085
A5: 40068873 | B5: iShares Latin America 40 ETF | C5: US4642873909 | D5: Matched | E5: US4642873909 | F5: ILF | G5: 109.30923 | H5: 743.38134 | I5: US4642873909
A6: 40073950 | B6: iShares Global Energy ETF | C6: US4642873412 | D6: Matched | E6: US4642873412 | F6: IXC | G6: 208.759 | H6: 2220.5207 | I6: US4642873412
A7: 40073951 | B7: iShares Global Financials ETF | C7: US4642873339 | D7: Matched | E7: US4642873339 | F7: IXG | G7: 3.533892 | H7: 54.296142 | I7: US4642873339
A8: 40073952 | B8: iShares Global Healthcare ETF | C8: US4642873255 | D8: Matched | E8: US4642873255 | F8: IXJ | G8: 2.7511171 | H8: 89.510659 | I8: US4642873255
A9: 40073953 | B9: iShares Global Tech ETF | C9: US4642872919 | D9: Matched | E9: US4642872919 | F9: IXN | G9: 7.9125586 | H9: 72.088831 | I9: US4642872919
A10: 40073954 | B10: iShares Global Comm Services ETF | C10: US4642872752 | D10: Matched | E10: US4642872752 | F10: IXP | G10: 3.9668277 | H10: 36.215903 | I10: US4642872752
A11: 40111267 | B11: iShares Global Consumer Discretionary ETF | C11: US4642887453 | D11: Matched | E11: US4642887453 | F11: RXI | G11: 11.680975 | H11: 322.22907 | I11: US4642887453
A12: 40111270 | B12: iShares Global Consumer Staples ETF | C12: US4642887370 | D12: Matched | E12: US4642887370 | F12: KXI | G12: 20.599526 | H12: 283.85097 | I12: US4642887370
A13: 40111272 | B13: iShares Global Industrials ETF | C13: US4642887297 | D13: Matched | E13: US4642887297 | F13: EXI | G13: 29.22582 | H13: 600.13717 | I13: US4642887297
... A26: 68060932 | B26: iShares ? High Yield Corp Bond UCITS ETF EUR D | C26: IE00B66F4759 | D26: Matched | E26: IE00B66F4759 | F26: IHYG | G26: 99.280223 | H26: 741.44553 | I26: IE00B66F4759

Sheet Reporte ASG Mensual
A1: SBS | B1: ISIN | C1: Fondo | D1: Afp | E1: Emisor | F1: Cobertura | G1: Nombre | H1: Proxy | I1: Proxy
A2: 12535622BA92 | B2: USP58072BA92 | C2: Multifondos | D2: Ex_Integra | E2: Inversiones CMPC | F2: NoCov | G2: iShares Global Materials ETF | H2: US4642886950 | I2: 46174
A3: 15515123CH47 | B3: USP32133CH47 | C3: F1 | D3: Ex_Integra | E3: Banco de Crédito e Inversiones | F3: NoCov | G3: iShares Global Financials ETF | H3: US4642873339 | I3: 46174
A4: 2100022V2H78 | B4: US05971V2H78 | C4: Multifondos | D4: Habitat | E4: Banco de Crédito del Perú | F4: NoCov | G4: iShares Global Financials ETF | H4: US4642873339 | I4: 46174
A5: 1254342KAB22 | B5: USP4R21KAB22 | C5: Multifondos | D5: Ex_Integra | E5: Grupo Nutresa S.A. | F5: NoCov | G5: iShares Global Consumer Discretionary ETF | H5: US4642887453 | I5: 46174
A6: 12535622BA92 | B6: USP58072BA92 | C6: Multifondos | D6: Prima | E6: Inversiones CMPC | F6: NoCov | G6: iShares Global Materials ETF | H6: US4642886950 | I6: 46174
A7: 1551192MAD04 | B7: USP1400MAD04 | C7: Multifondos | D7: Profuturo | E7: Grupo Financiero Banorte | F7: NoCov | G7: iShares Global Financials ETF | H7: US4642873339 | I7: 46174
A8: 1551112LAN29 | B8: US05968LAN29 | C8: Multifondos | D8: Ex_Integra | E8: Banco de Colombia | F8: NoCov | G8: iShares Global Financials ETF | H8: US4642873339 | I8: 46174
A9: 15515123CH47 | B9: USP32133CH47 | C9: F1 | D9: Profuturo | E9: Banco de Crédito e Inversiones | F9: NoCov | G9: iShares Global Financials ETF | H9: US4642873339 | I9: 46174
A10: 1551512PAC05 | B10: US05890PAC05 | C10: F1 | D10: Ex_Integra | E10: Banco de Crédito e Inversiones | F10: NoCov | G10: iShares Global Financials ETF | H10: US4642873339 | I10: 46174
A11: 15515123CH47 | B11: USP32133CH47 | C11: F1 | D11: Prima | E11: Banco de Crédito e Inversiones | F11: NoCov | G11: iShares Global Financials ETF | H11: US4642873339 | I11: 46174
A12: 2100022V2J35 | B12: US05971V2J35 | C12: Multifondos | D12: Habitat | E12: Banco de Crédito del Perú | F12: NoCov | G12: iShares Global Financials ETF | H12: US4642873339 | I12: 46174
A13: 1551192MAD04 | B13: USP1400MAD04 | C13: Multifondos | D13: Ex_Integra | E13: Grupo Financiero Banorte | F13: NoCov | G13: iShares Global Financials ETF | H13: US4642873339 | I13: 46174
... A914: 5277012F9LZQ | B914: IE000NG9LZQX | C914: F1 | D914: Prima | E914: Moneda - Latam High Yield | F914: NoCov | G914: iShares Latin America 40 ETF | H914: US4642873909 | I914: 46174
A915: 4974252S2BDC | C915: F2 | D915: Profuturo | E915: BD Capital - Senior Loans 2 | F915: NoCov | G915: iShares iBoxx $ High Yield Corporate Bond ETF | H915: US4642885135 | I915: 46174
A916: 4974252S2BDC | C916: F1 | D916: Profuturo | E916: BD Capital - Senior Loans 2 | F916: NoCov | G916: iShares iBoxx $ High Yield Corporate Bond ETF | H916: US4642885135 | I916: 46174
A917: 5270582R1157 | B917: KYG6201R1157 | C917: Multifondos | D917: Ex_Integra | E917: Moneda - CLOs | F917: NoCov | G917: iShares iBoxx $ High Yield Corporate Bond ETF | H917: US4642885135 | I917: 46174
A918: 4974252SCBDC | B918: CVL79590GA30 | C918: F1 | D918: Profuturo | E918: BD Capital - Senior Loans C | F918: NoCov | G918: iShares MSCI Peru and Global Exposure ETF | H918: US4642898427 | I918: 46174
A919: 4974252SCBDC | B919: CVL79590GA30 | C919: F2 | D919: Profuturo | E919: BD Capital - Senior Loans C | F919: NoCov | G919: iShares MSCI Peru and Global Exposure ETF | H919: US4642898427 | I919: 46174
A920: 5275262COMP2 | B920: CL0002633205 | C920: F2 | D920: Habitat | E920: FIGLHYI CI - Compass Latam HY | F920: NoCov | G920: iShares Latin America 40 ETF | H920: US4642873909 | I920: 46174
A921: 5275262COMP2 | B921: CL0002633205 | C921: F1 | D921: Habitat | E921: FIGLHYI CI - Compass Latam HY | F921: NoCov | G921: iShares Latin America 40 ETF | H921: US4642873909 | I921: 46174
A922: 4911102LINAE | C922: F2 | D922: Profuturo | E922: Fond. de Inversión Activa Financiamiento Estructurado Peru II | F922: NoCov | G922: iShares MSCI Peru and Global Exposure ETF | H922: US4642898427 | I922: 46174
A923: 5272092MACSM | B923: LU0721876877 | C923: Multifondos | D923: Ex_Integra | E923: Matthews Asia Funds - China Innov Fd I Acc USD | F923: NoCov | G923: iShares MSCI ACWI ETF | H923: US4642882579 | I923: 46174
A924: 4911102LINAE | C924: F1 | D924: Profuturo | E924: Fond. de Inversión Activa Financiamiento Estructurado Peru II | F924: NoCov | G924: iShares MSCI Peru and Global Exposure ETF | H924: US4642898427 | I924: 46174
A925: 5273662CORP1 | B925: LU1569037366 | C925: Multifondos | D925: Ex_Integra | E925: Credicorp Capital Latin American Corporate Debt S | F925: NoCov | G925: iShares Latin America 40 ETF | H925: US4642873909 | I925: 46174
A926: 4974252S2BDC | C926: F2 | D926: Ex_Integra | E926: BD Capital - Senior Loans 2 | F926: NoCov | G926: iShares iBoxx $ High Yield Corporate Bond ETF | H926: US4642885135 | I926: 46174
A927: 4975141HMCPS | C927: F1 | D927: Profuturo | E927: Fondo HMC II (PEN) | F927: NoCov | G927: iShares MSCI Peru and Global Exposure ETF | H927: US4642898427 | I927: 46174
A928: 5273982F6385 | B928: LU1883863851 | C928: Multifondos | D928: Ex_Integra | E928: Amundi Funds US High Yield Bond - I2 U C | F928: NoCov | G928: iShares iBoxx $ High Yield Corporate Bond ETF | H928: US4642885135 | I928: 46174
A929: 4974252S2BDC | C929: F1 | D929: Ex_Integra | E929: BD Capital - Senior Loans 2 | F929: NoCov | G929: iShares iBoxx $ High Yield Corporate Bond ETF | H929: US4642885135 | I929: 46174
A930: 4975141HMCPS | C930: F2 | D930: Profuturo | E930: Fondo HMC II (PEN) | F930: NoCov | G930: iShares MSCI Peru and Global Exposure ETF | H930: US4642898427 | I930: 46174
A931: 4974252SCBDC | B931: CVL79590GA30 | C931: F2 | D931: Ex_Integra | E931: BD Capital - Senior Loans C | F931: NoCov | G931: iShares MSCI Peru and Global Exposure ETF | H931: US4642898427 | I931: 46174
A932: 4974252S2BDC | C932: F2 | D932: Prima | E932: BD Capital - Senior Loans 2 | F932: NoCov | G932: iShares iBoxx $ High Yield Corporate Bond ETF | H932: US4642885135 | I932: 46174
A933: 5277192F9LZQ | B933: IE000NG9LZQ6 | C933: F2 | D933: Habitat | E933: Moneda - Latam High Yield | F933: NoCov | G933: iShares Latin America 40 ETF | H933: US4642873909 | I933: 46174
A934: 4974252S2BDC | C934: F1 | D934: Prima | E934: BD Capital - Senior Loans 2 | F934: NoCov | G934: iShares iBoxx $ High Yield Corporate Bond ETF | H934: US4642885135 | I934: 46174
A935: 5274302F65N6 | B935: IE00BD065N65 | C935: Multifondos | D935: Ex_Integra | E935: Veritas Asian C USD | F935: NoCov | G935: iShares MSCI All Country Asia ex Japan ETF | H935: US4642881829 | I935: 46174
A936: 5277192F9LZQ | B936: IE000NG9LZQ6 | C936: F1 | D936: Habitat | E936: Moneda - Latam High Yield | F936: NoCov | G936: iShares Latin America 40 ETF | H936: US4642873909 | I936: 46174
A937: 5274542F8758 | B937: LU1617687584 | C937: Multifondos | D937: Ex_Integra | E937: Oaktree (Lux.) III - Global Credit Fund I USD acc | F937: NoCov | G937: iShares US & Intl High Yield Corp Bond ETF | H937: US4642861789 | I937: 46174
A938: 491105206SI1 | B938: PEP795509FD5 | C938: F2 | D938: Profuturo | E938: Sigma - Leasing Operativo | F938: NoCov | G938: iShares MSCI Peru and Global Exposure ETF | H938: US4642898427 | I938: 46174
A939: 5274742F1585 | B939: LU0648315850 | C939: Multifondos | D939: Ex_Integra | E939: LarrainVial AM SICAV - Latin American Corp Dbt I | F939: NoCov | G939: iShares Latin America 40 ETF | H939: US4642873909 | I939: 46174
A940: 5274742F8681 | B940: LU2600586817 | C940: Multifondos | D940: Ex_Integra | E940: LarrainVial AM SICAV - Gavekal Latam LC Debt I | F940: NoCov | G940: iShares Latin America 40 ETF | H940: US4642873909 | I940: 46174
...

Sheet 202608
A1: FUND_SHARE_CLASS_ID | B1: FUND_NAME | C1: Client_ID | D1: Security_Status | E1: FUND_ISIN | F1: FUND_ID | G1: FUND_TICKER | H1: FUND_FINANCED_CARBON_EMISSIONS | I1: FUND_FINANCED_CARBON_EMISSIONS_COVERAGE | J1: FUND_CARBON_EMISSIONS_SCOPE_3_DOWN_EVIC_INTEN | K1: FUND_CARBON_EMISSIONS_SCOPE_3_DOWN_EVIC_INTEN_COV | L1: FUND_CARBON_EMISSIONS_SCOPE_3_TOT_EVIC_INTEN | M1: FUND_CARBON_EMISSIONS_SCOPE_3_TOT_EVIC_INTEN_COV | N1: FUND_CARBON_EMISSIONS_SCOPE_3_UPST_EVIC_INTEN | O1: FUND_CARBON_EMISSIONS_SCOPE_3_UPST_EVIC_INTEN_COV | P1: FUND_FOSS_FUEL_SECT_EXP_PCT | Q1: FUND_FOSSIL_FUEL_REVENUES_PCT | R1: FUND_GREEN_REVENUES_PCT | S1: FUND_GREEN_FFB_REV_RATIO | T1: FUND_OIL_GAS_ANY_TIE | U1: FUND_EXP_TO_OG_REV_REFINING | V1: FUND_THERMAL_COAL_ANY_TIE | W1: FUND_WEIGHTED_AVG_CARBON_INTEN | X1: FUND_WEIGHTED_AVG_CARBON_INTEN_COVERAGE | Y1: FUND_CARBON_EMISSIONS_SCOPE_3_DOWN_SALES_INTEN | Z1: FUND_CARBON_EMISSIONS_SCOPE_3_DOWN_SALES_INTEN_COV | AA1: FUND_CARBON_EMISSIONS_SCOPE_3_TOTAL_SALES_INTEN | AB1: FUND_CARBON_EMISSIONS_SCOPE_3_TOTAL_SALES_INTEN_COV | AC1: FUND_CARBON_EMISSIONS_SCOPE_3_UPST_INTEN_PROF | AD1: FUND_CARBON_EMISSIONS_SCOPE_3_UPST_INTEN_PROF_COV | AE1: FUND_WEIGHTED_AVG_SOV_CARBON_INTEN | AF1: FUND_WEIGHTED_AVG_SOV_CARBON_INTEN_COVERAGE | AG1: FUND_OVERSHOOT_GLOBAL_BUDGET_TCRE | AH1: FUND_IMPLIED_TEMP_RISE_OVERSHOOT | AI1: FUND_IMPLIED_TEMP_RISE_BUDGET | AJ1: FUND_ITR_1.5_ALIGN_PCT | AK1: FUND_ITR_2.0_ALIGN_PCT | AL1: FUND_ITR_BAND | AM1: FUND_IMPLIED_TEMP_RISE_COVERAGE | AN1: FUND_ITR_MISALIGN_PCT | AO1: FUND_ITR_STRONG_MISALIGN_PCT | AP1: FUND_IMPLIED_TEMP_RISE | AQ1: FUND_PERC_LOW_CARB_VALUE_COV | AR1: FUND_CBN_LCT_MGMT_SCORE_QUART_1 | AS1: FUND_CARBON_EMISSIONS_CLEANER_ENERGY_SOURCES | AT1: FUND_PERC_LOW_CARB_VALUE | AU1: FUND_HAS_SBTI_APPROVED_TARGET | AV1: FUND_HAS_SBTI_APPROVED_TARGET_COV | AW1: FUND_AFFORD_HOUSING_INVOLV_PCT | AX1: FUND_ALT_ENERGY_INVOLV_PCT | AY1: FUND_CONNECTIVITY_MAX_REV_INVOLV_PCT | AZ1: FUND_EDU_SERVICES_INVOLV_PCT | BA1: FUND_ENERGY_EFF_INVOLV_PCT | BB1: FUND_CLEAN_TECH_INVOLV_PCT | BC1: FUND_GREEN_BLDG_INVOLV_PCT | BD1: FUND_HEALTHCARE_INVOLV_PCT | BE1: FUND_NUTRI_FOOD_INVOLV_PCT | BF1: FUND_POLL_PREV_INVOLV_PCT | BG1: FUND_AFFORD_HOUSING_PCT | BH1: FUND_ALT_ENERGY_PCT | BI1: FUND_CONNECTIVITY_MAX_REV_PCT | BJ1: FUND_EDU_SERVICES_PCT | BK1: FUND_ENERGY_EFF_PCT | BL1: FUND_CLEAN_TECH_PCT | BM1: FUND_GREEN_BLDG_PCT | BN1: FUND_HEALTHCARE_PCT | BO1: FUND_NUTRI_FOOD_PCT | BP1: FUND_POLL_PREV_PCT | BQ1: FUND_SOCIAL_FIN_PCT | BR1: FUND_SANITARY_PROD_PCT | BS1: FUND_SOCIAL_IMPACT_PCT | BT1: FUND_SUST_AG_MAX_REV_PCT | BU1: FUND_SUSTAINABLE_IMPACT_PCT | BV1: FUND_SUST_WATER_PCT | BW1: FUND_SOCIAL_FIN_INVOLV_PCT | BX1: FUND_SANITARY_PROD_INVOLV_PCT | BY1: FUND_SOCIAL_IMPACT_INVOLV_PCT | BZ1: FUND_SUST_AG_MAX_REV_INVOLV_PCT | CA1: FUND_SUSTAINABLE_IMPACT_INVOLV_PCT | CB1: FUND_SUST_WATER_INVOLV_PCT | CC1: FUND_EXP_TO_POLLUT_PREVEN_PCT | CD1: FUND_CT_SUST_AG_MAX_REV | CE1: FUND_EXP_TO_SUST_WATER_PCT | CF1: FUND_OVERSHOOT_GLOBAL_BUDGET_TCRE_SIMULATED | CG1: FUND_CARBON_SCOPE_12_INTEN_3Y_TREND_M_IMPROV | CH1: FUND_WATER_FRESH_WD_INTEN_3Y_TREND_M_IMPROV | CI1: FUND_CARBON_SCOPE_12_INTEN_3Y_TREND_M_NON_DETER | CJ1: FUND_WATER_FRESH_WD_INTEN_3Y_TREND_M_NON_DETER | CK1: FUND_CARBON_SCOPE_12_INTEN_3Y_TREND_M_STABLE | CL1: FUND_WATER_FRESH_WD_INTEN_3Y_TREND_M_STABLE | CM1: FUND_CARBON_SCOPE_12_INTEN_3Y_TREND_M_WORSE | CN1: FUND_WATER_FRESH_WD_INTEN_3Y_TREND_M_WORSE | CO1: FUND_ACCOUNTING_FLAG_PCT | CP1: FUND_BOARD_FLAG_PCT | CQ1: FUND_BOARD_INDEP_0_25PCT | CR1: FUND_BOARD_INDEP_25_50PCT | CS1: FUND_BOARD_INDEP_50_75PCT | CT1: FUND_BOARD_INDEP_75_100PCT | CU1: FUND_CONTROLLING_SHAREHOLDER_PCT | CV1: FUND_CONTROLLING_SHAREHOLDER_CONCERNS_PCT | CW1: FUND_CROSS_SHAREHOLDINGS_PCT | CX1: FUND_MAJORITY_VOTING_PCT | CY1: FUND_ENTRENCHED_BOARD_PCT | CZ1: FUND_EXEC_PAY_NONDISCLOSURE_PCT | DA1: FUND_FEMALE_DIRECTORS_30_PCT | DB1: FUND_GOV_GLOBAL_AVERAGE_PCT | DC1: FUND_GOV_GLOBAL_LAGGARDS_PCT | DD1: FUND_GOV_GLOBAL_LEADERS_PCT | DE1: FUND_GM_EVENT_EVENT_TYPE | DF1: FUND_GOV_METRICS_RESEARCHED_COVERAGE | DG1: FUND_HUMAN_CAPITAL_DEV_MGMT_SCORE | DH1: FUND_HUMAN_CAPITAL_DEV_MGMT_SCORE_COVERAGE | DI1: FUND_INDEPENDENT_BOARD_MAJORITY | DJ1: FUND_LACK_INDEP_MAJORITY_PCT | DK1: FUND_LACK_INTERNAL_PAY_EQUITY_PCT | DL1: FUND_LCT_CAT_ASSET_STRAND_PCT | DM1: FUND_LCT_CAT_NEUTRAL_PCT | DN1: FUND_LCT_CAT_OPERAT_TRANSITION_PCT | DO1: FUND_LCT_CAT_PRODUCT_TRANSITION_PCT | DP1: FUND_LCT_CAT_SOLUTIONS_PCT | DQ1: FUND_LOW_CARBON_TRANSITION | DR1: FUND_LOW_CARBON_TRANS_SCORE_COVERAGE | DS1: FUND_NEGATIVE_DIRECTOR_VOTES_PCT | DT1: FUND_CLASSIFIED_BOARD_PCT | DU1: FUND_NO_FEMALE_DIRECTORS_PCT | DV1: FUND_NO_PAY_PERF_LINK_PCT | DW1: FUND_ONE_SHARE_ONE_VOTE_PCT | DX1: FUND_OVERBOARDING_PCT | DY1: FUND_OWNERSHIP_FLAG_PCT | DZ1: FUND_PAY_FLAG_PCT | EA1: FUND_PAY_LINKED_TO_SUSTAINABILITY | EB1: FUND_POISON_PILL_PCT | EC1: FUND_WASTE_MGMT_THEME_WEIGHT | ED1: FUND_PROD_CARB_FTPRNT_MGMT_SCORE | EE1: FUND_PROD_CARB_FTPRNT_MGMT_SCORE_COVERAGE | EF1: FUND_VOTE_AGAINST_PAY_PRACTICES_PCT | EG1: FUND_THREE_FEMALE_DIRECTORS_PCT | EH1: FUND_TOXIC_EMISS_WSTE_MGMT_SCORE | EI1: FUND_TOXIC_EMISS_WSTE_MGMT_SCORE_COVERAGE | EJ1: FUND_WATER_STRESS_EXP_SCORE_HIGH_PCT | EK1: FUND_WATER_STRESS_EXP_SCORE_LOW_PCT | EL1: FUND_WATER_STRESS_EXP_SCORE_MODERATE_PCT | EM1: FUND_WATER_STRESS_HIGH_RISK_BUS_PCT | EN1: FUND_WATER_STRESS_HIGH_RISK_GEO_PCT | EO1: FUND_WEIGHTED_AVG_WATER_FRESH_WD_INTEN | EP1: FUND_WEIGHTED_AVG_WATER_FRESH_WD_INTEN_COVERAGE | EQ1: FUND_WEIGHTED_AVG_WATER_WD_INTEN | ER1: FUND_WEIGHTED_AVG_WATER_WD_INTEN_COVERAGE | ES1: FUND_COMBINED_CEO_CHAIR | ET1: FUND_DIVERSITY_WORKF_POLICY_M | EU1: FUND_HUMAN_RIGHT_POLICY_M_YES | EV1: FUND_MONITOR_EMP_SATISFACTION_M | EW1: FUND_MONITOR_HUMAN_RIGHTS_POLICY_M | EX1: FUND_NON_COMP_BENEFITS_M | EY1: FUND_PAY_CONTROVERSY | EZ1: FUND_PHILANTHROPIC_INVEST_ALIGN_M | FA1: FUND_LABOR_POLICY_INTL_RECOG_M | FB1: FUND_PRIV_DATA_SECURITY_PROCESS_M | FC1: FUND_DIVERSITY_PROGRAMS_M | FD1: FUND_CBN_RENEW_ENER_USE_M | FE1: FUND_SDG01_ACHIEVE_SIGNAL | FF1: FUND_SDG01_ALIGN_PCT | FG1: FUND_SDG01_ANY_ALIGN_PCT | FH1: FUND_SDG01_ANY_MISALIGN_PCT | FI1: FUND_SDG01_MISALIGN_PCT | FJ1: FUND_SDG01_NEUTRAL_PCT | FK1: FUND_SDG01_STRONG_ALIGN_PCT | FL1: FUND_SDG01_STRONG_MISALIGN_PCT | FM1: FUND_SDG02_ACHIEVE_SIGNAL | FN1: FUND_SDG02_ALIGN_PCT | FO1: FUND_SDG02_ANY_ALIGN_PCT | FP1: FUND_SDG02_ANY_MISALIGN_PCT | FQ1: FUND_SDG02_MISALIGN_PCT | FR1: FUND_SDG02_NEUTRAL_PCT | FS1: FUND_SDG02_STRONG_ALIGN_PCT | FT1: FUND_SDG02_STRONG_MISALIGN_PCT | FU1: FUND_SDG03_ACHIEVE_SIGNAL | FV1: FUND_SDG03_ALIGN_PCT | FW1: FUND_SDG03_ANY_ALIGN_PCT | FX1: FUND_SDG03_ANY_MISALIGN_PCT | FY1: FUND_SDG03_MISALIGN_PCT | FZ1: FUND_SDG03_NEUTRAL_PCT | GA1: FUND_SDG03_STRONG_ALIGN_PCT | GB1: FUND_SDG03_STRONG_MISALIGN_PCT | GC1: FUND_SDG04_ACHIEVE_SIGNAL | GD1: FUND_SDG04_ALIGN_PCT | GE1: FUND_SDG04_ANY_ALIGN_PCT | GF1: FUND_SDG04_ANY_MISALIGN_PCT | GG1: FUND_SDG04_MISALIGN_PCT | GH1: FUND_SDG04_NEUTRAL_PCT | GI1: FUND_SDG04_STRONG_ALIGN_PCT | GJ1: FUND_SDG04_STRONG_MISALIGN_PCT | GK1: FUND_SDG05_ACHIEVE_SIGNAL | GL1: FUND_SDG05_ALIGN_PCT | GM1: FUND_SDG05_ANY_ALIGN_PCT | GN1: FUND_SDG05_ANY_MISALIGN_PCT | GO1: FUND_SDG05_MISALIGN_PCT | GP1: FUND_SDG05_NEUTRAL_PCT | GQ1: FUND_SDG05_STRONG_ALIGN_PCT | GR1: FUND_SDG05_STRONG_MISALIGN_PCT | GS1: FUND_SDG06_ACHIEVE_SIGNAL | GT1: FUND_SDG06_ALIGN_PCT | GU1: FUND_SDG06_ANY_ALIGN_PCT | GV1: FUND_SDG06_ANY_MISALIGN_PCT | GW1: FUND_SDG06_MISALIGN_PCT | GX1: FUND_SDG06_NEUTRAL_PCT | GY1: FUND_SDG06_STRONG_ALIGN_PCT | GZ1: FUND_SDG06_STRONG_MISALIGN_PCT | HA1: FUND_SDG07_ACHIEVE_SIGNAL | HB1: FUND_SDG07_ALIGN_PCT | HC1: FUND_SDG07_ANY_ALIGN_PCT | HD1: FUND_SDG07_ANY_MISALIGN_PCT | HE1: FUND_SDG07_MISALIGN_PCT | HF1: FUND_SDG07_NEUTRAL_PCT | HG1: FUND_SDG07_STRONG_ALIGN_PCT | HH1: FUND_SDG07_STRONG_MISALIGN_PCT | HI1: FUND_SDG08_ACHIEVE_SIGNAL | HJ1: FUND_SDG08_ALIGN_PCT | HK1: FUND_SDG08_ANY_ALIGN_PCT | HL1: FUND_SDG08_ANY_MISALIGN_PCT | HM1: FUND_SDG08_MISALIGN_PCT | HN1: FUND_SDG08_NEUTRAL_PCT | HO1: FUND_SDG08_STRONG_ALIGN_PCT | HP1: FUND_SDG08_STRONG_MISALIGN_PCT | HQ1: FUND_SDG09_ACHIEVE_SIGNAL | HR1: FUND_SDG09_ALIGN_PCT | HS1: FUND_SDG09_ANY_ALIGN_PCT | HT1: FUND_SDG09_ANY_MISALIGN_PCT | HU1: FUND_SDG09_MISALIGN_PCT | HV1: FUND_SDG09_NEUTRAL_PCT | HW1: FUND_SDG09_STRONG_ALIGN_PCT | HX1: FUND_SDG09_STRONG_MISALIGN_PCT | HY1: FUND_SDG10_ACHIEVE_SIGNAL | HZ1: FUND_SDG10_ALIGN_PCT | IA1: FUND_SDG10_ANY_ALIGN_PCT | IB1: FUND_SDG10_ANY_MISALIGN_PCT | IC1: FUND_SDG10_MISALIGN_PCT | ID1: FUND_SDG10_NEUTRAL_PCT | IE1: FUND_SDG10_STRONG_ALIGN_PCT | IF1: FUND_SDG10_STRONG_MISALIGN_PCT | IG1: FUND_SDG11_ACHIEVE_SIGNAL | IH1: FUND_SDG11_ALIGN_PCT | II1: FUND_SDG11_ANY_ALIGN_PCT | IJ1: FUND_SDG11_ANY_MISALIGN_PCT | IK1: FUND_SDG11_MISALIGN_PCT | IL1: FUND_SDG11_NEUTRAL_PCT | IM1: FUND_SDG11_STRONG_ALIGN_PCT | IN1: FUND_SDG11_STRONG_MISALIGN_PCT | IO1: FUND_SDG12_ACHIEVE_SIGNAL | IP1: FUND_SDG12_ALIGN_PCT | IQ1: FUND_SDG12_ANY_ALIGN_PCT | IR1: FUND_SDG12_ANY_MISALIGN_PCT | IS1: FUND_SDG12_MISALIGN_PCT | IT1: FUND_SDG12_NEUTRAL_PCT | IU1: FUND_SDG12_STRONG_ALIGN_PCT | IV1: FUND_SDG12_STRONG_MISALIGN_PCT | IW1: FUND_SDG13_ACHIEVE_SIGNAL | IX1: FUND_SDG13_ALIGN_PCT | IY1: FUND_SDG13_ANY_ALIGN_PCT | IZ1: FUND_SDG13_ANY_MISALIGN_PCT | JA1: FUND_SDG13_MISALIGN_PCT | JB1: FUND_SDG13_NEUTRAL_PCT | JC1: FUND_SDG13_STRONG_ALIGN_PCT | JD1: FUND_SDG13_STRONG_MISALIGN_PCT | JE1: FUND_SDG14_ACHIEVE_SIGNAL | JF1: FUND_SDG14_ALIGN_PCT | JG1: FUND_SDG14_ANY_ALIGN_PCT | JH1: FUND_SDG14_ANY_MISALIGN_PCT | JI1: FUND_SDG14_MISALIGN_PCT | JJ1: FUND_SDG14_NEUTRAL_PCT | JK1: FUND_SDG14_STRONG_ALIGN_PCT | JL1: FUND_SDG14_STRONG_MISALIGN_PCT | JM1: FUND_SDG15_ACHIEVE_SIGNAL | JN1: FUND_SDG15_ALIGN_PCT | JO1: FUND_SDG15_ANY_ALIGN_PCT | JP1: FUND_SDG15_ANY_MISALIGN_PCT | JQ1: FUND_SDG15_MISALIGN_PCT | JR1: FUND_SDG15_NEUTRAL_PCT | JS1: FUND_SDG15_STRONG_ALIGN_PCT | JT1: FUND_SDG15_STRONG_MISALIGN_PCT | JU1: FUND_SDG16_ACHIEVE_SIGNAL | JV1: FUND_SDG16_ALIGN_PCT | JW1: FUND_SDG16_ANY_ALIGN_PCT | JX1: FUND_SDG16_ANY_MISALIGN_PCT | JY1: FUND_SDG16_MISALIGN_PCT | JZ1: FUND_SDG16_NEUTRAL_PCT | KA1: FUND_SDG16_STRONG_ALIGN_PCT | KB1: FUND_SDG16_STRONG_MISALIGN_PCT | KC1: FUND_SDG17_ACHIEVE_SIGNAL | KD1: FUND_SDG17_ALIGN_PCT | KE1: FUND_SDG17_ANY_ALIGN_PCT | KF1: FUND_SDG17_ANY_MISALIGN_PCT | KG1: FUND_SDG17_MISALIGN_PCT | KH1: FUND_SDG17_NEUTRAL_PCT | KI1: FUND_SDG17_STRONG_ALIGN_PCT | KJ1: FUND_SDG17_STRONG_MISALIGN_PCT | KK1: FUND_SDG_COVERAGE | KL1: FUND_ESG_SCORE_ADJUSTMENT | KM1: FUND_ESG_SCORE_ADJUSTMENT_PCT | KN1: FUND_ESG_TREND_NEGATIVE_PCT | KO1: FUND_ASSET_CLASS | KP1: FUND_ASSET_UNIVERSE | KQ1: FUND_DOMICILE | KR1: FUND_ESG_AVERAGE_PCT | KS1: FUND_ESG_COVERAGE | KT1: FUND_ESG_COVERAGE_OVERALL | KU1: FUND_ESG_ENV_SCORE_AVG_PEER | KV1: FUND_ESG_GOV_SCORE_AVG_PEER | KW1: FUND_ESG_LAGGARDS_PCT | KX1: FUND_ESG_LEADERS_PCT | KY1: FUND_ESG_POLICY | KZ1: FUND_ESG_QUALITY_SCORE | LA1: FUND_ESG_QUALITY_SCORE_PCTL_GLOBAL | LB1: FUND_ESG_QUALITY_SCORE_AVG_PEER | LC1: FUND_ESG_QUALITY_SCORE_PCTL_PEER | LD1: FUND_ESG_RATING | LE1: ESG_RATING_A | LF1: ESG_RATING_AA | LG1: ESG_RATING_AAA | LH1: ESG_RATING_B | LI1: ESG_RATING_BB | LJ1: ESG_RATING_BBB | LK1: ESG_RATING_CCC | LL1: ESG_RATING_NoValue | LM1: FUND_ESG_SOCIAL_SCORE_AVG_PEER | LN1: FUND_ESG_TREND_NONE_PCT | LO1: FUND_ESG_TREND_POSITIVE_PCT | LP1: FUND_ESG_TREND_STABLE_PCT | LQ1: ESG_ENVIRONMENTAL_SCORE | LR1: FUND_ENVIRONMENTAL_WEIGHT | LS1: FUND_GEO_FOCUS | LT1: ESG_GOVERNANCE_SCORE | LU1: FUND_GOVERNANCE_WEIGHT | LV1: FUND_HOLDINGS_COUNT | LW1: FUND_HOLDING_FUNDS_COUNT | LX1: FUND_HOLDINGS_MATCHED | LY1: FUND_IN_UNIVERSE | LZ1: FUND_INVESTMENT_STRATEGY | MA1: FUND_LATEST_HOLDINGS_DATE | MB1: FUND_LIPPER_GLOBAL_CLASS | MC1: FUND_LIPPER_GLOBAL_CLASS_SIZE | MD1: FUND_MANAGER | ME1: FUND_OVERVIEW_NAME | MF1: ESG_SOCIAL_SCORE | MG1: FUND_SOCIAL_WEIGHT | MH1: FUND_NAV_USD | MI1: FUND_WEIGHTED_AVG_ESG_SCORE | MJ1: FUND_WEIGHTED_AVG_SCORE_PCTL_GLOBAL | MK1: FUND_WEIGHTED_AVG_SCORE_PCTL_PEER | ML1: FUND_WEIGHTED_AVG_KEY_ISSUE_SCORE | MM1: FUND_OF_FUNDS | MN1: FUND_AE_TIE_PCT | MO1: FUND_AE_HIGH_RESTRICT_PCT | MP1: FUND_AE_LEAST_RESTRICT_PCT | MQ1: FUND_AE_MODER_RESTRICT_PCT | MR1: FUND_ALC_TIE_PCT | MS1: FUND_ALC_HIGH_RESTRICT_PCT | MT1: FUND_ALC_LEAST_RESTRICT_PCT | MU1: FUND_ALC_MODER_RESTRICT_PCT | MV1: FUND_ANI_TIE_PCT | MW1: FUND_ANI_HIGH_RESTRICT_PCT | MX1: FUND_ANI_MODER_RESTRICT_PCT | MY1: FUND_WEAP_BIO_CHEM_TIE_PCT | MZ1: FUND_CANNA_TIE_PCT | NA1: FUND_CANNA_HIGH_RESTRICT_PCT | NB1: FUND_CANNA_MODER_RESTRICT_PCT | NC1: FUND_CATHOLIC_VALUES_FAIL_PCT | ND1: FUND_PROD_CIV_ARMS_AUTO_PCT | NE1: FUND_FIREARM_REV_PCT10_PCT | NF1: FUND_FIREARM_TIE_PCT | NG1: FUND_FIREARM_HIGH_RESTRICT_PCT | NH1: FUND_FIREARM_MODER_RESTRICT_PCT | NI1: FUND_PROD_CIV_ARMS_PCT | NJ1: FUND_PROD_CIV_ARMS_AMMO_PCT | NK1: FUND_PROD_CIV_ARMS_SEMI_PCT | NL1: FUND_FIREARM_RETAILER_PCT | NM1: FUND_CM_TIE_PCT | NN1: FUND_CM_HIGH_RESTRICT_PCT | NO1: FUND_CM_MODER_RESTRICT_PCT | NP1: FUND_CONTR_WEAP_TIE_PCT | NQ1: FUND_CONTR_CONTROVERSIAL_WORKPLACE_M | NR1: FUND_CONTR_CONV_WEAP_TIE_PCT | NS1: FUND_CONV_WEAP_HIGH_RESTRICT_PCT | NT1: FUND_CONV_WEAP_LEAST_RESTRICT_PCT | NU1: FUND_CONV_WEAP_MODER_RESTRICT_PCT | NV1: FUND_PRED_LEND_DIRECT_PCT | NW1: FUND_FIREARM_LEAST_RESTRICT_PCT | NX1: FUND_FOSSIL_FUEL_RESERVES_PCT | NY1: FUND_GAM_TIE_PCT | NZ1: FUND_GAM_HIGH_RESTRICT_PCT | OA1: FUND_GAM_LEAST_RESTRICT_PCT | OB1: FUND_GAM_MODER_RESTRICT_PCT | OC1: FUND_GMO_TIE_PCT | OD1: FUND_GMO_HIGH_RESTRICT_PCT | OE1: FUND_GMO_LEAST_RESTRICT_PCT | OF1: FUND_GMO_MODER_RESTRICT_PCT | OG1: FUND_UNGC_COMPLIANCE_VIOLATION_PCT | OH1: FUND_UNGC_COMPLIANCE_VIOLATION_WATCH_LIST_PCT | OI1: FUND_CONTR_HEALTH_SAFETY_M | OJ1: FUND_HIGH_IMPACT_FOSSIL_FUEL_RESERVES_PCT | OK1: FUND_HR_COMPLIANCE_VIOLATION_PCT | OL1: FUND_HR_NORMS_VIOLATION_WATCH_LIST_PCT | OM1: FUND_ISLAMIC_NON_COMPLIANT_PCT | ON1: FUND_LABOR_COMPLIANCE_VIOLATION_PCT | OO1: FUND_LABOR_NORMS_VIOLATION_WATCH_LIST_PCT | OP1: FUND_LM_TIE_PCT | OQ1: FUND_LM_HIGH_RESTRICT_PCT | OR1: FUND_LM_MODER_RESTRICT_PCT | OS1: FUND_NATURAL_GAS_RESERVES | OT1: FUND_NUC_TIE_PCT | OU1: FUND_NUC_HIGH_RESTRICT_PCT | OV1: FUND_NUC_LEAST_RESTRICT_PCT | OW1: FUND_NUC_MODER_RESTRICT_PCT | OX1: FUND_WEAP_NUC_TIE_PCT | OY1: FUND_WEAP_NUC_HIGH_RESTRICT_PCT | OZ1: FUND_WEAP_NUC_LEAST_RESTRICT_PCT | PA1: FUND_WEAP_NUC_MODER_RESTRICT_PCT | PB1: FUND_PALM_TIE_PCT | PC1: FUND_PALM_HIGH_RESTRICT_PCT | PD1: FUND_PALM_MODER_RESTRICT_PCT | PE1: FUND_CONTR_PRODUCT_SAFE_M | PF1: FUND_VERY_SEVERE_CONTROVERSY_PCT | PG1: FUND_VERY_SEVERE_CUST_CONTROVERSY_PCT | PH1: FUND_VERY_SEVERE_ENV_CONTROVERSY_PCT | PI1: FUND_VERY_SEVERE_GOV_CONTROVERSY_PCT | PJ1: FUND_VERY_SEVERE_HR_CONTROVERSY_PCT | PK1: FUND_VERY_SEVERE_LR_CONTROVERSY_PCT | PL1: FUND_CHILD_LABOR_CONTROVERSY_PCT | PM1: FUND_SEVERE_CONTROVERSY_PCT | PN1: FUND_CUSTOMER_CONTROVERSY_PCT | PO1: FUND_ENVIRONMENT_CONTROVERSY_PCT | PP1: FUND_GOVERNANCE_CONTROVERSY_PCT | PQ1: FUND_HUMAN_RIGHTS_CONTROVERSY_PCT | PR1: FUND_LABOR_RIGHTS_CONTROVERSY_PCT | PS1: FUND_REV_EXP_AE | PT1: FUND_REV_EXP_ALC | PU1: FUND_REV_EXP_CONV_WEAP | PV1: FUND_REV_EXP_FIREARM | PW1: FUND_REV_EXP_GAM | PX1: FUND_REV_EXP_GMO | PY1: FUND_REV_EXP_NUC | PZ1: FUND_REV_EXP_TOB | QA1: FUND_SRI_EXCLUSION_CRITERIA_PCT | QB1: FUND_THERMAL_COAL_TIE_PCT | QC1: FUND_THERMAL_COAL_HIGH_RESTRICT_PCT | QD1: FUND_THERMAL_COAL_LEAST_RESTRICT_PCT | QE1: FUND_THERMAL_COAL_MODER_RESTRICT_PCT | QF1: FUND_THERMAL_COAL_RESERVES | QG1: FUND_TOB_TIE_PCT | QH1: FUND_TOB_HIGH_RESTRICT_PCT | QI1: FUND_TOB_LEAST_RESTRICT_PCT | QJ1: FUND_TOB_MODER_RESTRICT_PCT | QK1: FUND_WEAP_GTIE_PCT
A2: 40056077 | B2: iShares Core S&P 500 ETF | C2: US4642872000 | D2: Matched | E2: US4642872000 | F2: 35557136 | G2: IVV | H2: 22.262271 | I2: 99.540277 | J2: 124.59092 | K2: 99.540277 | L2: 178.49342 | M2: 99.540277 | N2: 53.902503 | O2: 99.540277 | P2: 11.5163 | Q2: 2.9126284 | R2: 13.262482 | S2: 4.553441 | T2: 11.42105 | U2: 1.6185507 | V2: 3.5443457 | W2: 91.559741 | X2: 99.651031 | Y2: 401.63503 | Z2: 99.651031 | AA2: 649.75138 | AB2: 99.651031 | AC2: 248.1162 | AD2: 99.651031 | AE2: 202.59174 | AF2: 0.04533778 | AG2: 2006.2231 | AH2: 5004.9451 | AI2: 1467.4775 | AJ2: 29.361012 | AK2: 19.647897 | AL2: Misaligned | AM2: 99.540277 | AN2: 30.349614 | AO2: 20.18398 | AP2: 3 | AQ2: 93.363195 | AR2: 63.006747 | AS2: 97.40707 | AT2: 5.3719495 | AU2: 58.404463 | AV2: 99.651031 | AW2: 0.83228747 | AX2: 4.6116199 | AY2: 1.1348104 | AZ2: 0 | BA2: 22.154424 | BB2: 25.719233 | BC2: 1.3940016 | BD2: 1.8498827 | BE2: 1.1811373 | BF2: 1.9954151 | BG2: 0.08031326 | BH2: 0.3022154 | BI2: 0.00248368 | BJ2: 0 | BK2: 9.048343 | BL2: 9.649701 | BM2: 0.15104092 | BN2: 0.75797205 | BO2: 0.11900751 | BP2: 0.07289786 | BQ2: 0.01661208 | BR2: 0.0910415 | BS2: 1.0674301 | BT2: 0.02537893 | BU2: 10.716943 | BV2: 0.04982493 | BW2: 1.3642226 | BX2: 1.7123996 | BY2: 7.0243966 | BZ2: 0.14846587 | CA2: 29.442336 | CB2: 2.4576861 | CC2: 0.1565869 | CD2: 0.03093161 | CE2: 0.05441826 | CG2: 60.150693 | CH2: 9.369657 | CI2: 2.527135 | CJ2: 74.289303 | CK2: 24.54936 | CL2: 10.636609 | CM2: 12.449204 | CN2: 3.7570639 | CO2: 24.452926 | CP2: 17.510465 | CQ2: 0 | CR2: 2.075361 | CS2: 18.29978 | CT2: 79.139878 | CU2: 13.25255 | CV2: 10.339601 | CW2: 0.00249868 | CX2: 96.321925 | CY2: 37.110499 | CZ2: 0.88565437 | DA2: 74.972256 | DB2: 67.95532 | DC2: 14.389952 | DD2: 17.215523 | DE2: 59.133978 | DF2: 99.567862 | DG2: 6.0266269 | DH2: 99.542502 | DI2: 97.600179 | DJ2: 2.0762128 | DK2: 42.814634 | DL2: 2.3079087 | DM2: 64.535322 | DN2: 3.4020655 | DO2: 12.587792 | DP2: 16.70895 | DQ2: 6.2655873 | DR2: 99.542037 | DS2: 41.847165 | DT2: 8.7063544 | DU2: 0 | DV2: 2.2246617 | DW2: 17.519226 | DX2: 59.766137 | DY2: 18.349265 | DZ2: 4.197354 | EA2: 54.630049 | EB2: 0.00090404 | EC2: 3.3415771 | ED2: 6.0104202 | EE2: 12.300468 | EF2: 23.537997 | EG2: 83.441485 | EH2: 4.1759165 | EI2: 17.341882 | EJ2: 5.9723861 | EK2: 57.233529 | EL2: 36.086382 | EM2: 5.010186 | EN2: 1.4397442 | EO2: 14517.367 | EP2: 42.499425 | EQ2: 11650.364 | ER2: 79.714661 | ES2: 41.393955 | ET2: 22.034211 | EU2: 3.8223222 | EV2: 54.722224 | EW2: 2.7616949 | EX2: 56.063876 | EY2: 2.1322092 | EZ2: 3.5897889 | FA2: 86.440979 | FB2: 99.006649 | FC2: 19.865094 | FD2: 95.431218 | FE2: Not Aligned | FF2: 4.5348937 | FG2: 4.5348937 | FH2: 22.379252 | FI2: 22.366971 | FJ2: 72.628357 | FK2: 0 | FL2: 0.01228063 | FM2: Aligned | FN2: 0.74422636 | FO2: 0.75550857 | FP2: 0.70448902 | FQ2: 0.70448902 | FR2: 98.082505 | FS2: 0.01128221 | FT2: 0 | FU2: Not Aligned | FV2: 7.0016584 | FW2: 7.0016584 | FX2: 8.2896599 | FY2: 7.6555599 | FZ2: 84.251184 | GA2: 0 | GB2: 0.63410002 | GC2: Not Aligned | GD2: 0 | GE2: 0 | GF2: 4.7488111 | GG2: 4.7488111 | GH2: 94.793691 | GI2: 0 | GJ2: 0 | GK2: Aligned | GL2: 40.464802 | GM2: 40.464802 | GN2: 0 | GO2: 0 | GP2: 59.0777 | GQ2: 0 | GR2: 0 | GS2: Aligned | GT2: 6.1748387 | GU2: 6.3402778 | GV2: 1.5505548 | GW2: 1.5505548 | GX2: 91.65167 | GY2: 0.16543911 | GZ2: 0 | HA2: Not Aligned | HB2: 34.220229 | HC2: 34.220229 | HD2: 3.9003752 | HE2: 0.20695611 | HF2: 61.421898 | HG2: 0 | HH2: 3.693419 | HI2: Not Aligned | HJ2: 10.505439 | HK2: 10.505439 | HL2: 11.456134 | HM2: 11.456134 | HN2: 77.58093 | HO2: 0 | HP2: 0 | HQ2: Not Aligned | HR2: 12.649946 | HS2: 12.966646 | HT2: 24.447247 | HU2: 24.434966 | HV2: 62.128609 | HW2: 0.31670057 | HX2: 0.01228063 | HY2: Aligned | HZ2: 14.155453 | IA2: 14.155453 | IB2: 12.457654 | IC2: 12.457654 | ID2: 72.929395 | IE2: 0 | IF2: 0 | IG2: Not Aligned | IH2: 3.3361389 | II2: 3.3361389 | IJ2: 16.968877 | IK2: 16.968877 | IL2: 79.237486 | IM2: 0 | IN2: 0 | IO2: Not Aligned | IP2: 19.210096 | IQ2: 29.247867 | IR2: 5.9704107 | IS2: 2.2769917 | IT2: 64.324225 | IU2: 10.03777 | IV2: 3.693419 | IW2: Not Aligned | IX2: 41.621683 | IY2: 41.621683 | IZ2: 3.9146701 | JA2: 0.22125109 | JB2: 54.00615 | JC2: 0 | JD2: 3.693419 | JE2: Not Aligned | JF2: 0.04343151 | JG2: 0.04343151 | JH2: 5.8108689 | JI2: 5.730296 | JJ2: 93.688202 | JK2: 0 | JL2: 0.08057294 | JM2: Not Aligned | JN2: 0 | JO2: 0 | JP2: 6.8104924 | JQ2: 6.8104924 | JR2: 92.73201 | JS2: 0 | JT2: 0 | JU2: Aligned | JV2: 10.32258 | JW2: 10.32258 | JX2: 9.6991626 | JY2: 9.6991626 | JZ2: 79.52076 | KA2: 0 | KB2: 0 | KC2: Not Aligned | KD2: 0.89998073 | KE2: 0.89998073 | KF2: 23.661159 | KG2: 23.661159 | KH2: 74.981363 | KI2: 0 | KJ2: 0 | KK2: 99.542502 | KL2: 0.17699742 | KM2: 2.7240137 | KN2: 6.0527457 | KO2: Equity | KP2: Exchange Traded Funds | KQ2: USA | KR2: 54.468621 | KS2: 99.710181 | KT2: 99.58784 | KU2: 5.7830404 | KV2: 5.6110777 | KW2: 2.9448919 | KX2: 42.174328 | KZ2: 6.49767 | LA2: 48.106397 | LB2: 6.5045186 | LC2: 53.241343 | LD2: A | LE2: 19.508835 | LF2: 33.389758 | LG2: 8.7845694 | LH2: 2.9130421 | LI2: 6.1195495 | LJ2: 28.840237 | LK2: 0.03184977 | LL2: 0.41215977 | LM2: 4.7866754 | LN2: 0.41215977 | LO2: 11.721651 | LP2: 81.813443 | LQ2: 5.817533 | LR2: 19.249343 | LS2: United States of America | LT2: 5.4837464 | LU2: 38.021967 | LV2: 507 | LW2: 2 | LX2: 505 | LY2: T | LZ2: The Fund seeks investment results that correspond generally to the price and yield performance of the S&P 500 Index which is composed of large-capitalization U.S. equities. The underlying Index included approximately 86.44% of the market capitalization of all publicly traded U.S. equity securities. | MA2: 46203 | MB2: Equity US | MC2: 3841 | MD2: BlackRock Fund Advisors | ME2: iShares Core S&P 500 ETF | MF2: 4.7459526 | MG2: 42.316531 | MH2: 888128937468 | MI2: 6.49767 | MJ2: 48.106397 | MK2: 53.241343 | ML2: 5.2347632 | MM2: T | MN2: 4.6608215 | MO2: 0.08157136 | MP2: 0 | MQ2: 0 | MR2: 10.733805 | MS2: 4.4327096 | MT2: 0.04652663 | MU2: 0.04652663 | MV2: 13.77476 | MW2: 13.750798 | MX2: 12.799997 | MY2: 0 | MZ2: 0.18580698 | NA2: 0 | NB2: 0 | NC2: 10.360527 | ND2: 0 | NE2: 0 | NF2: 0.7677892 | NG2: 0 | NH2: 0 | NI2: 0 | NJ2: 0 | NK2: 0 | NL2: 0.7677892 | NM2: 0.42373178 | NN2: 0.42373178 | NO2: 0 | NP2: 0.56281245 | NQ2: 0.51309086 | NR2: 7.884528 | NS2: 3.9146884 | NT2: 1.1047578 | NU2: 1.1884259 | NV2: 0.00310939 | NW2: 0 | NX2: 4.6880442 | NY2: 1.9112859 | NZ2: 0.54803574 | OA2: 0.0481241 | OB2: 0.0929534 | OC2: 0.2740503 | OD2: 0.2740503 | OE2: 0.08756191 | OF2: 0.08756191 | OG2: 0 | OH2: 18.314384 | OI2: 13.00933 | OJ2: 4.5482646 | OK2: 0 | OL2: 10.298796 | OM2: 67.853558 | ON2: 0 | OO2: 5.7706043 | OP2: 0 | OQ2: 0 | OR2: 0 | OS2: 2.1063156 | OT2: 4.4648894 | OU2: 2.9017545 | OV2: 1.4830917 | OW2: 1.4830917 | OX2: 1.92137 | OY2: 1.3184209 | OZ2: 1.054537 | PA2: 1.054537 | PB2: 0.07937483 | PC2: 0.02236473 | PD2: 0 | PE2: 22.25739 | PF2: 0.01228063 | PG2: 0.01228063 | PH2: 0 | PI2: 0 | PJ2: 0 | PK2: 0 | PL2: 0 | PM2: 30.868916 | PN2: 14.497737 | PO2: 3.3491184 | PP2: 8.6543611 | PQ2: 4.6159579 | PR2: 5.7706043 | PS2: 0.04524958 | PT2: 0.21778455 | PU2: 0.82108312 | PV2: 0.00760111 | PW2: 0.08792909 | PX2: 0.04817268 | PY2: 0.37316327 | PZ2: 0.67112148 | QA2: 11.681092 | QB2: 0.00020424 | QC2: 0 | QD2: 0 | QE2: 0 | QF2: 1.8377065 | QG2: 5.4285893 | QH2: 0.66714791 | QI2: 0.62181939 | QJ2: 0.62181939 | QK2: 7.884528
A3: 40056109 | B3: iShares US Real Estate ETF | C3: US4642877397 | D3: Matched | E3: US4642877397 | F3: 35557182 | G3: IYR | H3: 6.7813414 | I3: 99.464999 | J3: 10.78743 | K3: 99.464999 | L3: 40.1148 | M3: 99.464999 | N3: 29.32737 | O3: 99.464999 | P3: 2.3917048 | Q3: 0.02296265 | R3: 15.262255 | S3: 664.65566 | T3: 2.3917048 | U3: 0 | V3: 1.2757026 | W3: 70.969563 | X3: 99.464999 | Y3: 26.371452 | Z3: 99.464999 | AA3: 255.32308 | AB3: 99.464999 | AC3: 228.9528 | AD3: 99.464999 | AE3: 202.59174 | AF3: 0.05487671 | AG3: 249.27856 | AH3: 622.06956 | AI3: 239.61816 | AJ3: 11.501023 | AK3: 23.333947 | AL3: Misaligned | AM3: 99.464999 | AN3: 37.693075 | AO3: 26.936954 | AP3: 2.6 | AQ3: 52.444705 | AR3: 69.042538 | AS3: 96.161092 | AT3: 0.8770182 | AU3: 64.536829 | AV3: 99.464999 | AW3: 34.239168 | AX3: 8.7238175 | AY3: 3.8540077 | AZ3: 0 | BA3: 28.297057 | BB3: 75.293151 | BC3: 65.610131 | BD3: 0 | BE3: 0.18200036 | BF3: 0 | BG3: 4.2651555 | BH3: 0.01221334 | BI3: 0.0489459 | BJ3: 0 | BK3: 6.5359206 | BL3: 15.249325 | BM3: 7.6640448 | BN3: 0 | BO3: 0.0001092 | BP3: 0 | BQ3: 0 | BR3: 0 | BS3: 4.3142106 | BT3: 1.0371462 | BU3: 19.554551 | BV3: 0 | BW3: 0 | BX3: 0 | BY3: 38.275177 | BZ3: 1.2757026 | CA3: 77.309955 | CB3: 0 | CC3: 0 | CD3: 1.0371462 | CE3: 0 | CG3: 59.85162 | CH3: 2.0614041 | CI3: 2.3341047 | CJ3: 80.12486 | CK3: 33.855668 | CL3: 0 | CM3: 3.4236068 | CN3: 2.5391051 | CO3: 21.453443 | CP3: 3.492807 | CQ3: 0 | CR3: 0 | CS3: 13.165426 | CT3: 86.299573 | CU3: 2.020504 | CV3: 1.6780034 | CW3: 0 | CX3: 94.218688 | CY3: 38.326877 | CZ3: 5.6197112 | DA3: 89.028978 | DB3: 74.022148 | DC3: 2.1369043 | DD3: 23.305947 | DE3: 67.049134 | DF3: 99.464999 | DG3: 5.8858399 | DH3: 99.464999 | DI3: 99.464999 | DJ3: 0 | DK3: 59.599919 | DL3: 0 | DM3: 93.635987 | DN3: 0 | DO3: 1.2757026 | DP3: 4.5533091 | DQ3: 6.3988804 | DR3: 99.464999 | DS3: 37.911976 | DT3: 2.9342059 | DU3: 0 | DV3: 11.132222 | DW3: 87.848176 | DX3: 28.432457 | DY3: 14.184328 | DZ3: 0.85460171 | EA3: 77.922256 | EB3: 0 | EC3: 0 | EE3: 0 | EF3: 41.584483 | EG3: 92.693485 | EI3: 0 | EJ3: 1.2757026 | EK3: 24.267649 | EL3: 73.921648 | EM3: 1.2757026 | EN3: 0 | EO3: 1347.3211 | EP3: 20.10614 | EQ3: 33683.612 | ER3: 77.312555 | ES3: 10.267921 | ET3: 27.385855 | EU3: 0 | EV3: 70.255941 | EW3: 0 | EX3: 45.870092 | EY3: 0 | EZ3: 0 | FA3: 80.556861 | FB3: 91.055482 | FC3: 26.696353 | FD3: 90.18878 | FE3: Aligned | FF3: 18.285837 | FG3: 18.285837 | FH3: 0 | FI3: 0 | FJ3: 81.179162 | FK3: 0 | FL3: 0 | FM3: Aligned | FN3: 1.2757026 | FO3: 1.2757026 | FP3: 0 | FQ3: 0 | FR3: 98.189296 | FS3: 0 | FT3: 0 | FU3: Not Aligned | FV3: 0 | FW3: 0 | FX3: 0 | FY3: 0 | FZ3: 99.464999 | GA3: 0 | GB3: 0 | GC3: Not Aligned | GD3: 0 | GE3: 0 | GF3: 0 | GG3: 0 | GH3: 99.464999 | GI3: 0 | GJ3: 0 | GK3: Aligned | GL3: 48.202096 | GM3: 48.202096 | GN3: 0 | GO3: 0 | GP3: 51.262903 | GQ3: 0 | GR3: 0 | GS3: Aligned | GT3: 1.2757026 | GU3: 1.2757026 | GV3: 0 | GW3: 0 | GX3: 98.189296 | GY3: 0 | GZ3: 0 | HA3: Aligned | HB3: 26.901454 | HC3: 26.901454 | HD3: 0 | HE3: 0 | HF3: 72.563545 | HG3: 0 | HH3: 0 | HI3: Aligned | HJ3: 22.191044 | HK3: 22.191044 | HL3: 0 | HM3: 0 | HN3: 77.273955 | HO3: 0 | HP3: 0 | HQ3: Aligned | HR3: 17.611935 | HS3: 17.611935 | HT3: 0 | HU3: 0 | HV3: 81.853064 | HW3: 0 | HX3: 0 | HY3: Aligned | HZ3: 38.624877 | IA3: 38.624877 | IB3: 0 | IC3: 0 | ID3: 60.840122 | IE3: 0 | IF3: 0 | IG3: Aligned | IH3: 44.203788 | II3: 44.203788 | IJ3: 0 | IK3: 0 | IL3: 55.261211 | IM3: 0 | IN3: 0 | IO3: Aligned | IP3: 53.960008 | IQ3: 64.082828 | IR3: 0 | IS3: 0 | IT3: 35.382171 | IU3: 10.12282 | IV3: 0 | IW3: Aligned | IX3: 9.9347199 | IY3: 9.9347199 | IZ3: 0 | JA3: 0 | JB3: 89.530279 | JC3: 0 | JD3: 0 | JE3: Not Aligned | JF3: 0 | JG3: 0 | JH3: 0 | JI3: 0 | JJ3: 99.464999 | JK3: 0 | JL3: 0 | JM3: Not Aligned | JN3: 0 | JO3: 0 | JP3: 0 | JQ3: 0 | JR3: 99.464999 | JS3: 0 | JT3: 0 | JU3: Aligned | JV3: 18.927638 | JW3: 18.927638 | JX3: 0 | JY3: 0 | JZ3: 80.537361 | KA3: 0 | KB3: 0 | KC3: Not Aligned | KD3: 0 | KE3: 0 | KF3: 0 | KG3: 0 | KH3: 99.464999 | KI3: 0 | KJ3: 0 | KK3: 99.464999 | KL3: -0.87668178 | KM3: -13.559527 | KN3: 20.922042 | KO3: Equity | KP3: Exchange Traded Funds | KQ3: USA | KR3: 56.037189 | KS3: 99.626625 | KT3: 99.519876 | KU3: 5.558891 | KV3: 6.6866488 | KW3: 4.001908 | KX3: 39.480779 | KZ3: 6.4654303 | LA3: 46.637606 | LB3: 6.1489286 | LC3: 67.857143 | LD3: A | LE3: 18.858714 | LF3: 18.886638 | LG3: 20.594141 | LH3: 3.2720065 | LI3: 13.018426 | LJ3: 24.160048 | LK3: 0.72990146 | LL3: 0.48012436 | LM3: 4.6302256 | LN3: 0.48012436 | LO3: 11.364423 | LP3: 67.233411 | LQ3: 5.6982897 | LR3: 26.040201 | LS3: United States of America | LT3: 6.693641 | LU3: 44.456618 | LV3: 64 | LW3: 1 | LX3: 62 | LY3: T | LZ3: The Fund seeks investment results that correspond generally to the price and yield performance, before fees and expenses, of the Dow Jones US Real Estate Index. Uses a representative sampling strategy. Component firms include hotel and resort firms and REIT's. | MA3: 46203 | MB3: Equity Sector Real Estate US | MC3: 168 | MD3: BlackRock Fund Advisors | ME3: iShares US Real Estate ETF | MF3: 4.8140946 | MG3: 29.023056 | MH3: 4672414947 | MI3: 6.4654303 | MJ3: 46.637606 | MK3: 67.857143 | ML3: 5.8850655 | MM3: T | MN3: 0 | MO3: 0 | MP3: 0 | MQ3: 0 | MR3: 5.01351 | MS3: 1.1160022 | MT3: 0 | MU3: 0 | MV3: 0 | MW3: 0 | MX3: 0 | MY3: 0 | MZ3: 0 | NA3: 0 | NB3: 0 | NC3: 3.0762061 | ND3: 0 | NE3: 0 | NF3: 0 | NG3: 0 | NH3: 0 | NI3: 0 | NJ3: 0 | NK3: 0 | NL3: 0 | NM3: 0 | NN3: 0 | NO3: 0 | NP3: 0 | NQ3: 0 | NR3: 0 | NS3: 0 | NT3: 0 | NU3: 0 | NV3: 0 | NW3: 0 | NX3: 1.2757026 | NY3: 3.0762061 | NZ3: 3.0762061 | OA3: 0 | OB3: 3.0762061 | OC3: 0 | OD3: 0 | OE3: 0 | OF3: 0 | OG3: 0 | OH3: 0 | OI3: 0 | OJ3: 1.2757026 | OK3: 0 | OL3: 0 | OM3: 73.345847 | ON3: 0 | OO3: 0 | OP3: 0 | OQ3: 0 | OR3: 0 | OS3: 1.2757026 | OT3: 0 | OU3: 0 | OV3: 0 | OW3: 0 | OX3: 0 | OY3: 0 | OZ3: 0 | PA3: 0 | PB3: 0 | PC3: 0 | PD3: 0 | PE3: 0 | PF3: 0 | PG3: 0 | PH3: 0 | PI3: 0 | PJ3: 0 | PK3: 0 | PL3: 0 | PM3: 0 | PN3: 0 | PO3: 0 | PP3: 0 | PQ3: 0 | PR3: 0 | PS3: 0 | PT3: 0.08521012 | PU3: 0 | PV3: 0 | PW3: 2.1881978 | PX3: 0 | PY3: 0 | PZ3: 0.00021442 | QA3: 3.0762061 | QB3: 0 | QC3: 0 | QD3: 0 | QE3: 0 | QF3: 1.2757026 | QG3: 2.1442043 | QH3: 0 | QI3: 0 | QJ3: 0 | QK3: 0
A4: 40056868 | B4: iShares MSCI Eurozone ETF | C4: US4642866085 | D4: Matched | E4: US4642866085 | F4: 35557352 | G4: EZU | H4: 42.848172 | I4: 99.647304 | J4: 298.24568 | K4: 99.647304 | L4: 397.03327 | M4: 99.647304 | N4: 98.787583 | O4: 99.647304 | P4: 21.899381 | Q4: 2.1173363 | R4: 6.4311664 | S4: 3.0373854 | T4: 21.444886 | U4: 1.3309691 | V4: 5.2234478 | W4: 84.282305 | X4: 99.766802 | Y4: 683.14659 | Z4: 99.675603 | AA4: 942.54645 | AB4: 99.675603 | AC4: 259.39973 | AD4: 99.675603 | AE4: 202.59174 | AF4: 0.01331267 | AG4: 2137.7545 | AH4: 5333.3472 | AI4: 3353.2954 | AJ4: 41.664383 | AK4: 27.647824 | AL4: Misaligned | AM4: 98.858811 | AN4: 15.701743 | AO4: 13.873161 | AP4: 2.2 | AQ4: 86.078239 | AR4: 66.083939 | AS4: 97.828922 | AT4: 10.367572 | AU4: 67.499925 | AV4: 99.766802 | AW4: 0.61169388 | AX4: 10.854791 | AY4: 0.64809352 | AZ4: 0.18909811 | BA4: 21.290387 | BB4: 24.102959 | BC4: 1.9204808 | BD4: 7.1670283 | BE4: 0.79769202 | BF4: 1.9847802 | BG4: 0.22925807 | BH4: 1.4127848 | BI4: 0.02519383 | BJ4: 0.01058949 | BK4: 2.0260011 | BL4: 4.0458346 | BM4: 0.4905564 | BN4: 1.4608867 | BO4: 0.09167867 | BP4: 0.04703539 | BQ4: 0.3307702 | BR4: 0.08323256 | BS4: 2.2316095 | BT4: 0.05543273 | BU4: 6.2583726 | BV4: 0.01402411 | BW4: 7.8395216 | BX4: 2.597674 | BY4: 17.611824 | BZ4: 0.18079819 | CA4: 37.223128 | CB4: 1.5445846 | CC4: 0.14295428 | CD4: 0.06238681 | CE4: 0.11061227 | CG4: 74.758652 | CH4: 22.842372 | CI4: 0.15779842 | CJ4: 66.550434 | CK4: 15.97014 | CL4: 5.0442496 | CM4: 8.8802112 | CN4: 2.9122709 | CO4: 0.52459475 | CP4: 11.164188 | CQ4: 0.11819882 | CR4: 4.3640564 | CS4: 48.280417 | CT4: 47.00413 | CU4: 20.384596 | CV4: 11.00929 | CW4: 0.57619424 | CX4: 20.383196 | CY4: 6.2904371 | CZ4: 2.9945701 | DA4: 95.464745 | DB4: 36.213238 | DC4: 5.6416436 | DD4: 57.911921 | DE4: 41.349387 | DF4: 99.766802 | DG4: 6.4506214 | DH4: 99.647304 | DI4: 97.103729 | DJ4: 2.6630734 | DK4: 8.1159189 | DL4: 0.11499885 | DM4: 62.636874 | DN4: 2.9380706 | DO4: 26.542735 | DP4: 7.4146258 | DQ4: 5.8332665 | DR4: 99.647304 | DS4: 30.072199 | DT4: 92.219478 | DU4: 0 | DV4: 0.69779303 | DW4: 31.198188 | DX4: 24.470355 | DY4: 9.9726003 | DZ4: 1.5483845 | EA4: 97.803722 | EB4: 15.086249 | EC4: 3.8722673 | ED4: 6.503237 | EE4: 13.628964 | EF4: 38.873011 | EG4: 97.596224 | EH4: 5.46402 | EI4: 25.109349 | EJ4: 9.1444086 | EK4: 67.140929 | EL4: 23.481465 | EM4: 11.156488 | EN4: 9.9711003 | EO4: 4670.1918 | EP4: 48.738413 | EQ4: 6712.1554 | ER4: 92.826472 | ES4: 7.5725243 | ET4: 69.348406 | EU4: 5.8073419 | EV4: 79.9513 | EW4: 29.831802 | EX4: 42.570474 | EY4: 0.2298977 | EZ4: 3.7113629 | FA4: 99.344607 | FB4: 99.592104 | FC4: 83.376666 | FD4: 98.494215 | FE4: Aligned | FF4: 12.678273 | FG4: 12.678273 | FH4: 1.6879831 | FI4: 1.6879831 | FJ4: 85.309347 | FK4: 0 | FL4: 0 | FM4: Aligned | FN4: 1.3764862 | FO4: 1.3764862 | FP4: 0.42659573 | FQ4: 0.42659573 | FR4: 97.872521 | FS4: 0 | FT4: 0 | FU4: Not Aligned | FV4: 2.4747753 | FW4: 2.4747753 | FX4: 3.3828662 | FY4: 3.3828662 | FZ4: 93.817962 | GA4: 0 | GB4: 0 | GC4: Not Aligned | GD4: 0 | GE4: 0 | GF4: 0 | GG4: 0 | GH4: 99.675603 | GI4: 0 | GJ4: 0 | GK4: Aligned | GL4: 86.97283 | GM4: 86.97283 | GN4: 0 | GO4: 0 | GP4: 12.702773 | GQ4: 0 | GR4: 0 | GS4: Aligned | GT4: 26.199738 | GU4: 26.199738 | GV4: 0.4497955 | GW4: 0.4497955 | GX4: 73.02607 | GY4: 0 | GZ4: 0 | HA4: Not Aligned | HB4: 62.460275 | HC4: 62.562474 | HD4: 5.0415496 | HE4: 0.61649384 | HF4: 32.071579 | HG4: 0.10219898 | HH4: 4.4250558 | HI4: Aligned | HJ4: 36.645933 | HK4: 36.645933 | HL4: 0 | HM4: 0 | HN4: 63.02967 | HO4: 0 | HP4: 0 | HQ4: Aligned | HR4: 38.496415 | HS4: 44.636654 | HT4: 0.34839651 | HU4: 0.34839651 | HV4: 54.690553 | HW4: 6.1402386 | HX4: 0 | HY4: Aligned | HZ4: 79.285407 | IA4: 79.285407 | IB4: 0 | IC4: 0 | ID4: 20.390196 | IE4: 0 | IF4: 0 | IG4: Not Aligned | IH4: 5.9913401 | II4: 5.9913401 | IJ4: 6.602234 | IK4: 6.602234 | IL4: 87.082029 | IM4: 0 | IN4: 0 | IO4: Not Aligned | IP4: 38.066919 | IQ4: 39.02681 | IR4: 5.1592484 | IS4: 0.73419266 | IT4: 55.489545 | IU4: 0.95989042 | IV4: 4.4250558 | IW4: Not Aligned | IX4: 58.288717 | IY4: 58.547115 | IZ4: 4.4250558 | JA4: 0 | JB4: 36.703433 | JC4: 0.25839742 | JD4: 4.4250558 | JE4: Not Aligned | JF4: 0 | JG4: 0 | JH4: 3.5429646 | JI4: 3.4751652 | JJ4: 96.132639 | JK4: 0 | JL4: 0.06779932 | JM4: Not Aligned | JN4: 0 | JO4: 0 | JP4: 4.5876541 | JQ4: 4.5876541 | JR4: 95.087949 | JS4: 0 | JT4: 0 | JU4: Aligned | JV4: 12.135879 | JW4: 12.135879 | JX4: 0 | JY4: 0 | JZ4: 87.539725 | KA4: 0 | KB4: 0 | KC4: Aligned | KD4: 1.8931811 | KE4: 1.8931811 | KF4: 0 | KG4: 0 | KH4: 97.782422 | KI4: 0 | KJ4: 0 | KK4: 99.675603 | KL4: 0.54264146 | KM4: 6.7790323 | KN4: 7.9404206 | KO4: Equity | KP4: Exchange Traded Funds | KQ4: USA | KR4: 24.037972 | KS4: 99.866292 | KT4: 99.688916 | KU4: 6.3939449 | KV4: 6.8008484 | KW4: 0.82619173 | KX4: 74.824752 | KZ4: 8.004704 | LA4: 95.14799 | LB4: 7.9772285 | LC4: 46.996198 | LD4: AA | LE4: 14.075572 | LF4: 35.383846 | LG4: 39.440906 | LH4: 0.7595924 | LI4: 2.2087779 | LJ4: 7.7536225 | LK4: 0.06659933 | LL4: 0.3110841 | LM4: 5.2600118 | LN4: 0.3110841 | LO4: 15.545645 | LP4: 76.202851 | LQ4: 6.5050272 | LR4: 22.079665 | LS4: Europe | LT4: 6.7027449 | LU4: 39.521177 | LV4: 225 | LW4: 1 | LX4: 223 | LY4: T | LZ4: The Fund seeks to track the investment results of an index composed of large- and mid-capitalization equities from developed market countries that use the euro as their official currency. The Fund invests at least 95% of its assets in the securities of its Underlying Index and in depositary receipts in its index. | MA4: 46203 | MB4: Equity Europe | MC4: 1315 | MD4: BlackRock Fund Advisors | ME4: iShares MSCI Eurozone ETF | MF4: 5.4517977 | MG4: 38.088073 | MH4: 9595189883 | MI4: 8.004704 | MJ4: 95.14799 | MK4: 46.996198 | ML4: 6.1810048 | MM4: T | MN4: 3.8285617 | MO4: 0 | MP4: 0 | MQ4: 0 | MR4: 9.8743013 | MS4: 4.2125579 | MT4: 1.6227838 | MU4: 3.402566 | MV4: 17.317527 | MW4: 16.99033 | MX4: 15.448646 | MY4: 0 | MZ4: 0.4306957 | NA4: 0.4306957 | NB4: 0 | NC4: 12.750673 | ND4: 0 | NE4: 0.02829972 | NF4: 0.02829972 | NG4: 0.02829972 | NH4: 0.02829972 | NI4: 0.02829972 | NJ4: 0.02829972 | NK4: 0 | NL4: 0 | NM4: 0 | NN4: 0 | NO4: 0 | NP4: 0 | NQ4: 0.49199508 | NR4: 9.5168048 | NS4: 7.902121 | NT4: 0.78539215 | NU4: 1.3739863 | NV4: 3.2148679 | NW4: 0 | NX4: 6.1719383 | NY4: 2.500675 | NZ4: 0.76409235 | OA4: 0 | OB4: 0 | OC4: 1.3555865 | OD4: 1.3185868 | OE4: 0.70209298 | OF4: 0.70209298 | OG4: 0 | OH4: 11.633884 | OI4: 1.4932851 | OJ4: 4.5107549 | OK4: 0 | OL4: 7.8171218 | OM4: 63.847362 | ON4: 0 | OO4: 3.596264 | OP4: 0 | OQ4: 0 | OR4: 0 | OS4: 6.1719383 | OT4: 11.784682 | OU4: 5.0355496 | OV4: 4.1311587 | OW4: 4.298957 | OX4: 5.0553494 | OY4: 4.3708563 | OZ4: 3.4685653 | PA4: 3.4685653 | PB4: 0.03699963 | PC4: 0 | PD4: 0 | PE4: 5.0496495 | PF4: 0 | PG4: 0 | PH4: 0 | PI4: 0 | PJ4: 0 | PK4: 0 | PL4: 0 | PM4: 17.122929 | PN4: 5.2160478 | PO4: 2.6844732 | PP4: 2.1073789 | PQ4: 6.5224348 | PR4: 3.596264 | PS4: 0.01894125 | PT4: 1.7297724 | PU4: 1.3742556 | PV4: 0.00424213 | PW4: 0.02325527 | PX4: 0.15267826 | PY4: 0.20001918 | PZ4: 0.04384657 | QA4: 19.494305 | QB4: 0.99229007 | QC4: 0 | QD4: 0 | QE4: 0 | QF4: 1.4805852 | QG4: 4.7569524 | QH4: 0 | QI4: 0 | QJ4: 0 | QK4: 10.218898
A5: 40068873 | B5: iShares Latin America 40 ETF | C5: US4642873909 | D5: Matched | E5: US4642873909 | F5: 35560680 | G5: ILF | H5: 111.51934 | I5: 98.928005 | J5: 635.90783 | K5: 98.928005 | L5: 747.51033 | M5: 98.928005 | N5: 111.6025 | O5: 98.928005 | P5: 33.393733 | Q5: 9.6972177 | R5: 1.6430035 | S5: 0.16943041 | T5: 33.393733 | U5: 9.3261997 | V5: 0 | W5: 222.02592 | X5: 98.928005 | Y5: 1639.3641 | Z5: 98.928005 | AA5: 1901.9427 | AB5: 98.928005 | AC5: 262.57919 | AD5: 98.928005 | AE5: 202.59174 | AF5: 0.08614577 | AG5: 8101.2884 | AH5: 20244.44 | AI5: 3403.8604 | AJ5: 16.265519 | AK5: 25.678972 | AL5: Strongly Misaligned | AM5: 98.179209 | AN5: 26.476968 | AO5: 29.757751 | AP5: 4 | AQ5: 43.99278 | AR5: 50.145949 | AS5: 85.829671 | AT5: 8.355491 | AU5: 24.494778 | AV5: 98.928005 | AW5: 0 | AX5: 1.6849916 | AY5: 0 | AZ5: 0 | BA5: 7.2398638 | BB5: 14.232229 | BC5: 0.74879626 | BD5: 0 | BE5: 8.9578552 | BF5: 3.7128814 | BG5: 0 | BH5: 0.00690847 | BI5: 0 | BJ5: 0 | BK5: 0.16030581 | BL5: 1.2972207 | BM5: 0.15552498 | BN5: 0 | BO5: 0.59564748 | BP5: 0.17360305 | BQ5: 0.88784436 | BR5: 0.01314095 | BS5: 1.4966328 | BT5: 0.08462238 | BU5: 2.7938535 | BV5: 0.71625601 | BW5: 23.041685 | BX5: 6.9370653 | BY5: 31.99954 | BZ5: 0.36349818 | CA5: 43.606982 | CB5: 2.1671891 | CC5: 0.17551752 | CD5: 0.08462238 | CE5: 0.72976524 | CG5: 84.756276 | CH5: 19.108604 | CI5: 0 | CJ5: 53.738531 | CK5: 13.348133 | CL5: 14.963425 | CM5: 0.82359588 | CN5: 9.1533542 | CO5: 0.60929695 | CP5: 25.278574 | CQ5: 1.6437918 | CR5: 38.774106 | CS5: 23.088085 | CT5: 35.422023 | CU5: 69.296854 | CV5: 36.641317 | CW5: 4.2184789 | CX5: 17.089015 | CY5: 35.752621 | CZ5: 96.611317 | DA5: 21.689592 | DB5: 59.502202 | DC5: 39.425803 | DD5: 0 | DE5: 41.231694 | DF5: 98.928005 | DG5: 4.8276059 | DH5: 98.928005 | DI5: 58.510107 | DJ5: 40.417898 | DK5: 2.3166884 | DL5: 10.495548 | DM5: 56.586817 | DN5: 10.508547 | DO5: 21.337093 | DP5: 0 | DQ5: 5.0220344 | DR5: 98.928005 | DS5: 24.466978 | DT5: 61.739591 | DU5: 7.9416603 | DV5: 0 | DW5: 68.985155 | DX5: 18.467508 | DY5: 33.794931 | DZ5: 38.149009 | EA5: 65.853171 | EB5: 1.8824906 | EC5: 5.2422048 | ED5: 5.5617253 | EE5: 10.723946 | EF5: 1.8824906 | EG5: 55.301424 | EH5: 4.4562765 | EI5: 37.222114 | EJ5: 16.938815 | EK5: 46.385968 | EL5: 35.603222 | EM5: 29.94415 | EN5: 30.517947 | EO5: 2250558.2 | EP5: 62.163289 | EQ5: 1579847.4 | ER5: 88.790956 | ES5: 13.797931 | ET5: 41.555292 | EU5: 31.384343 | EV5: 72.00354 | EW5: 24.758376 | EX5: 26.380868 | EY5: 0 | EZ5: 29.738351 | FA5: 98.928005 | FB5: 97.243014 | FC5: 62.324088 | FD5: 88.753656 | FE5: Aligned | FF5: 17.178614 | FG5: 17.178614 | FH5: 1.8824906 | FI5: 1.8824906 | FJ5: 79.866901 | FK5: 0 | FL5: 0 | FM5: Not Aligned | FN5: 1.0802946 | FO5: 1.0802946 | FP5: 8.404558 | FQ5: 8.404558 | FR5: 89.443153 | FS5: 0 | FT5: 0 | FU5: Not Aligned | FV5: 0 | FW5: 0 | FX5: 8.404558 | FY5: 0 | FZ5: 90.523447 | GA5: 0 | GB5: 8.404558 | GC5: Not Aligned | GD5: 0 | GE5: 0 | GF5: 0 | GG5: 0 | GH5: 98.928005 | GI5: 0 | GJ5: 0 | GK5: Aligned | GL5: 46.848066 | GM5: 46.848066 | GN5: 0 | GO5: 0 | GP5: 52.07994 | GQ5: 0 | GR5: 0 | GS5: Not Aligned | GT5: 9.0888546 | GU5: 11.256044 | GV5: 8.404558 | GW5: 0 | GX5: 79.267404 | GY5: 2.1671891 | GZ5: 8.404558 | HA5: Not Aligned | HB5: 39.436003 | HC5: 41.318493 | HD5: 10.859046 | HE5: 0 | HF5: 46.750466 | HG5: 1.8824906 | HH5: 10.859046 | HI5: Not Aligned | HJ5: 24.838476 | HK5: 24.838476 | HL5: 8.404558 | HM5: 0 | HN5: 65.684972 | HO5: 0 | HP5: 8.404558 | HQ5: Aligned | HR5: 36.628017 | HS5: 36.628017 | HT5: 8.404558 | HU5: 8.404558 | HV5: 53.895431 | HW5: 0 | HX5: 0 | HY5: Aligned | HZ5: 68.06826 | IA5: 68.06826 | IB5: 0 | IC5: 0 | ID5: 30.859746 | IE5: 0 | IF5: 0 | IG5: Not Aligned | IH5: 1.5650922 | II5: 1.5650922 | IJ5: 10.287049 | IK5: 1.8824906 | IL5: 87.075865 | IM5: 0 | IN5: 8.404558 | IO5: Not Aligned | IP5: 12.425838 | IQ5: 14.593027 | IR5: 19.263604 | IS5: 0 | IT5: 65.071375 | IU5: 2.1671891 | IV5: 19.263604 | IW5: Not Aligned | IX5: 39.671602 | IY5: 41.554092 | IZ5: 10.859046 | JA5: 0 | JB5: 46.514867 | JC5: 1.8824906 | JD5: 10.859046 | JE5: Not Aligned | JF5: 2.1671891 | JG5: 2.1671891 | JH5: 8.9633552 | JI5: 0.55879721 | JJ5: 87.797461 | JK5: 0 | JL5: 8.404558 | JM5: Not Aligned | JN5: 0 | JO5: 0 | JP5: 10.845846 | JQ5: 2.4412878 | JR5: 88.08216 | JS5: 0 | JT5: 8.404558 | JU5: Aligned | JV5: 15.98572 | JW5: 15.98572 | JX5: 0 | JY5: 0 | JZ5: 82.942285 | KA5: 0 | KB5: 0 | KC5: Aligned | KD5: 13.043035 | KE5: 13.043035 | KF5: 0 | KG5: 0 | KH5: 85.884971 | KI5: 0 | KJ5: 0 | KK5: 98.928005 | KL5: 0.09522928 | KM5: 1.6211919 | KN5: 13.752431 | KO5: Equity | KP5: Exchange Traded Funds | KQ5: USA | KR5: 74.818172 | KS5: 99.406974 | KT5: 99.014151 | KU5: 5.4686989 | KV5: 4.9980013 | KW5: 2.7704861 | KX5: 21.425493 | KZ5: 5.8740288 | LA5: 30.522546 | LB5: 5.8035852 | LC5: 70 | LD5: A | LE5: 33.103681 | LF5: 16.265519 | LG5: 5.1599742 | LH5: 2.1271894 | LI5: 15.519722 | LJ5: 26.194769 | LK5: 0.64329678 | LL5: 0.98584887 | LM5: 5.0878726 | LN5: 0.98584887 | LO5: 18.144109 | LP5: 67.117611 | LQ5: 5.6611884 | LR5: 24.280716 | LS5: Latin America | LT5: 4.8199497 | LU5: 34.758041 | LV5: 44 | LW5: 1 | LX5: 42 | LY5: T | LZ5: The Fund seeks to track the investment results of the S&P Latin America 40 composed of 40 of the largest Latin American equities. The Fund invests, under normal circumstances, at least 90% of its assets in securities of the Underlying Index and in depositary receipts representing securities of the Underlying Index. | MA5: 46203 | MB5: Equity Emerging Markets Latin America | MC5: 70 | MD5: BlackRock Fund Advisors | ME5: iShares Latin America 40 ETF | MF5: 5.0512137 | MG5: 39.975394 | MH5: 3739343853 | MI5: 5.8740288 | MJ5: 30.522546 | MK5: 70 | ML5: 5.1196114 | MM5: T | MN5: 9.3024535 | MO5: 0 | MP5: 0 | MQ5: 0 | MR5: 13.96933 | MS5: 4.390878 | MT5: 2.1295893 | MU5: 2.1295893 | MV5: 0 | MW5: 0 | MX5: 0 | MY5: 0 | MZ5: 0 | NA5: 0 | NB5: 0 | NC5: 13.702231 | ND5: 0 | NE5: 0 | NF5: 0 | NG5: 0 | NH5: 0 | NI5: 0 | NJ5: 0 | NK5: 0 | NL5: 0 | NM5: 0 | NN5: 0 | NO5: 0 | NP5: 0 | NQ5: 8.404558 | NR5: 0 | NS5: 0 | NT5: 0 | NU5: 0 | NV5: 8.802856 | NW5: 0 | NX5: 11.138844 | NY5: 0 | NZ5: 0 | OA5: 0 | OB5: 0 | OC5: 0 | OD5: 0 | OE5: 0 | OF5: 0 | OG5: 8.404558 | OH5: 28.724256 | OI5: 0 | OJ5: 0.55879721 | OK5: 8.404558 | OL5: 18.228709 | OM5: 64.01488 | ON5: 0 | OO5: 16.346218 | OP5: 0 | OQ5: 0 | OR5: 0 | OS5: 11.138844 | OT5: 1.8824906 | OU5: 1.8824906 | OV5: 0 | OW5: 1.8824906 | OX5: 0 | OY5: 0 | OZ5: 0 | PA5: 0 | PB5: 0 | PC5: 0 | PD5: 0 | PE5: 0 | PF5: 8.404558 | PG5: 0 | PH5: 0 | PI5: 0 | PJ5: 8.404558 | PK5: 0 | PL5: 0 | PM5: 28.724256 | PN5: 0 | PO5: 10.845846 | PP5: 9.9367503 | PQ5: 10.287049 | PR5: 16.346218 | PS5: 0.02347452 | PT5: 1.8208565 | PU5: 0 | PV5: 0 | PW5: 0 | PX5: 0 | PY5: 0 | PZ5: 0.06327383 | QA5: 4.0120799 | QB5: 0 | QC5: 0 | QD5: 0 | QE5: 0 | QF5: 0 | QG5: 7.1202644 | QH5: 0 | QI5: 0 | QJ5: 0 | QK5: 0
