Workbook
Name IQ_CH: 110000
Name IQ_CQ: 5000
Name IQ_CY: 10000
Name IQ_DAILY: 500000
Name IQ_FH: 100000
Name IQ_FQ: 500
Name IQ_FY: 1000
Name IQ_LTM: 2000
Name IQ_MONTH: 15000
Name IQ_NTM: 6000
Name IQ_WEEK: 50000
Name IQ_YTD: 3000

Sheet Filtros FI

Sheet Port Bloomberg
A1: Name | B1: Company Name | C1: Short Name | D1: Issuer | E1: ISIN | F1: Ticker | G1: Eqty Ticker | H1: Group | I1: Sector | J1: Subgroup | K1: Cnty of Dom | L1: Cntry (Risk) | M1: Crncy | N1: Amt Iss (P) | O1: Cpn Type | P1: Cpn (P) | Q1: BB Comp (P) | R1: Mty
A2: ABENGO 6 ⅞ 04/30/43 | B2: Atlantica Transmision Sur SA | C2: ATL TRANS SUR | D2: ATL TRANSMISION SUR | E2: USP00173AA51 | F2: ABENGO | G2: AY US | H2: Electric | I2: UTL | J2: Electric-Transmission | K2: PE | L2: PE | M2: USD | N2: 432000 | O2: SINGLE | P2: 6.875 | Q2: BBB- | R2: 04/30/2043
A3: ABRAGF 14 10/22/29 | B3: ABRA Global Finance | C3: ABRA GLOBAL FIN | D3: ABRA GLOBAL FINANCE | E3: USG00912AC21 | F3: ABRAGF | G3: 2058922D LN | H3: Airlines | I3: IND | J3: Airlines | K3: KY | L3: CO | M3: USD | N3: 560672.64 | O3: PIK | P3: 14 | Q3: NR | R3: 10/22/2029
A4: ACUPET 7 ½ 01/13/32 | B4: Acu Petroleo Luxembourg Sarl | C4: ACU PETROLEO LUX | D4: ACU PETROLEO LUXEMBOURG | E4: USL0R80QAA10 | F4: ACUPET | G4: 1469040D BZ | H4: Pipelines | I4: IND | J4: Pipelines | K4: LU | L4: BR | M4: USD | N4: 600000 | O4: SINGLE | P4: 7.5 | Q4: BB+ | R4: 01/13/2032
A5: AEGEBZ 6 ¾ 05/20/29 | B5: Aegea Finance Sarl | C5: AEGEA FINANCE | D5: AEGEA FINANCE SARL | E5: USL01343AA79 | F5: AEGEBZ | G5: 0596570D BZ | H5: Water | I5: UTL | J5: Water | K5: LU | L5: BR | M5: USD | N5: 500000 | O5: SINGLE | P5: 6.75 | Q5: B | R5: 05/20/2029
A6: AEGEBZ 7 ⅝ 01/20/36 | B6: Aegea Finance Sarl | C6: AEGEA FINANCE | D6: AEGEA FINANCE SARL | E6: USL01343AE91 | F6: AEGEBZ | G6: 0596570D BZ | H6: Water | I6: UTL | J6: Water | K6: LU | L6: BR | M6: USD | N6: 750000 | O6: SINGLE | P6: 7.625 | Q6: B | R6: 01/20/2036
A7: AEGEBZ 9 01/20/31 | B7: Aegea Finance Sarl | C7: AEGEA FINANCE | D7: AEGEA FINANCE SARL | E7: USL01343AB52 | F7: AEGEBZ | G7: 0596570D BZ | H7: Water | I7: UTL | J7: Water | K7: LU | L7: BR | M7: USD | N7: 800000 | O7: SINGLE | P7: 9 | Q7: B | R7: 01/20/2031
A8: AEROMX 8 ¼ 11/15/29 | B8: Grupo Aeromexico SAB de CV | C8: GRUPO AEROMEXICO | D8: GRUPO AEROMEXICO SAB | E8: USP4955JAB46 | F8: AEROMX | G8: AERO* MM | H8: Airlines | I8: IND | J8: Airlines | K8: MX | L8: MX | M8: USD | N8: 500000 | O8: SINGLE | P8: 8.25 | Q8: BB- | R8: 11/15/2029
A9: AEROMX 8 ⅝ 11/15/31 | B9: Grupo Aeromexico SAB de CV | C9: GRUPO AEROMEXICO | D9: GRUPO AEROMEXICO SAB | E9: USP4955JAC29 | F9: AEROMX | G9: AERO* MM | H9: Airlines | I9: IND | J9: Airlines | K9: MX | L9: MX | M9: USD | N9: 610000 | O9: SINGLE | P9: 8.625 | Q9: BB- | R9: 11/15/2031
A10: AES 4.72 06/30/40 | B10: Alto Maipo SpA | C10: ALTO MAIPO SPA | D10: ALTO MAIPO SPA | E10: USP0243BAA37 | F10: AES | G10: AESANDES CI | H10: Energy-Alternate Sources | I10: UTL | J10: Energy-Alternate Sources | K10: CL | L10: CL | M10: USD | O10: STEPUP1 | P10: 4 | R10: 06/30/2040
A11: AES 6 ¼ 03/14/32 | B11: AES Andes SA | C11: AES ANDES SA | D11: AES ANDES SA | E11: USP0091LAD84 | F11: AES | G11: AESANDES CI | H11: Electric | I11: UTL | J11: Electric-Generation | K11: CL | L11: CL | M11: USD | N11: 400000 | O11: SINGLE | P11: 6.25 | Q11: BBB- | R11: 03/14/2032
A12: AES 6 ¼ 11/14/34 | B12: AES Andes SA | C12: AES ANDES SA | D12: AES ANDES SA | E12: USP0091LAE67 | F12: AES | G12: AESANDES CI | H12: Electric | I12: UTL | J12: Electric-Generation | K12: CL | L12: CL | M12: USD | N12: 485000 | O12: SINGLE | P12: 6.25 | Q12: BBB- | R12: 11/14/2034
A13: AES 6.3 03/15/29 | B13: AES Andes SA | C13: AES ANDES SA | D13: AES ANDES SA | E13: USP0091LAA46 | F13: AES | G13: AESANDES CI | H13: Electric | I13: UTL | J13: Electric-Generation | K13: CL | L13: CL | M13: USD | N13: 500000 | O13: SINGLE | P13: 6.3 | Q13: BBB- | R13: 03/15/2029
A14: AES 8.15 06/10/55 | B14: AES Andes SA | C14: AES ANDES SA | D14: AES ANDES SA | E14: USP0091LAC02 | F14: AES | G14: AESANDES CI | H14: Electric | I14: UTL | J14: Electric-Generation | K14: CL | L14: CL | M14: USD | N14: 530000 | O14: SINGLE | P14: 8.15 | Q14: BB | R14: 06/10/2055
A15: AGRO 7 ½ 07/29/32 | B15: Adecoagro SA | C15: ADECOAGRO SA | D15: ADECOAGRO SA | E15: USL00849AB20 | F15: AGRO | G15: AGRO US | H15: Agriculture | I15: IND | J15: Agricultural Operations | K15: AR | L15: BR | M15: USD | N15: 500000 | O15: SINGLE | P15: 7.5 | Q15: B+ | R15: 07/29/2032
A16: AGROSU 4.6 01/20/32 | B16: Agrosuper SA | C16: AGROSUPER | D16: AGROSUPER SA | E16: USP01020AK52 | F16: AGROSU | G16: 4627222Z CI | H16: Food | I16: IND | J16: Food-Meat Products | K16: CL | L16: CL | M16: USD | N16: 500000 | O16: SINGLE | P16: 4.6 | Q16: BBB- | R16: 01/20/2032
A17: AICNRA 5 ¾ 06/15/33 | B17: AI Candelaria -spain- SA | C17: AI CANDELARIA | D17: AI CANDELARIA -SPAIN- SA | E17: USE0R75RAB28 | F17: AICNRA | G17: 1666958D SM | H17: Pipelines | I17: IND | J17: Pipelines | K17: ES | L17: CO | M17: USD | N17: 600000 | O17: SINGLE | P17: 5.75 | Q17: B | R17: 06/15/2033
A18: ALFACL 4.55 09/27/51 | B18: Alfa Desarrollo SpA | C18: ALFA DESARROLLO | D18: ALFA DESARROLLO SPA | E18: USP0R60QAA15 | F18: ALFACL | G18: COLBUN CI | H18: Electric | I18: UTL | J18: Electric-Transmission | K18: CL | L18: CL | M18: USD | N18: 1098618 | O18: SINGLE | P18: 4.55 | Q18: BBB- | R18: 09/27/2051
A19: ALPEKA 3 ¼ 02/25/31 | B19: Alpek SAB de CV | C19: ALPEK SA DE CV | D19: ALPEK SA DE CV | E19: USP01703AD22 | F19: ALPEKA | G19: ALPEKA MM | H19: Chemicals | I19: IND | J19: Petrochemicals | K19: MX | L19: MX | M19: USD | N19: 600000 | O19: SINGLE | P19: 3.25 | Q19: BB+ | R19: 02/25/2031
A20: ALPEKA 4 ¼ 09/18/29 | B20: Alpek SAB de CV | C20: ALPEK SA DE CV | D20: ALPEK SA DE CV | E20: USP01703AC49 | F20: ALPEKA | G20: ALPEKA MM | H20: Chemicals | I20: IND | J20: Petrochemicals | K20: MX | L20: MX | M20: USD | N20: 500000 | O20: SINGLE | P20: 4.25 | Q20: BB+ | R20: 09/18/2029
A21: AMXLMM 2 ⅞ 05/07/30 | B21: America Movil SAB de CV | C21: AMERICA MOVIL SA | D21: AMERICA MOVIL SAB DE CV | E21: US02364WBJ36 | F21: AMXLMM | G21: AMXB MM | H21: Telecommunications | I21: IND | J21: Cellular Telecom | K21: MX | L21: MX | M21: USD | N21: 1000000 | O21: SINGLE | P21: 2.875 | Q21: BBB+ | R21: 05/07/2030
A22: AMXLMM 3 ⅝ 04/22/29 | B22: America Movil SAB de CV | C22: AMERICA MOVIL SA | D22: AMERICA MOVIL SAB DE CV | E22: US02364WBH79 | F22: AMXLMM | G22: AMXB MM | H22: Telecommunications | I22: IND | J22: Cellular Telecom | K22: MX | L22: MX | M22: USD | N22: 1000000 | O22: SINGLE | P22: 3.625 | Q22: BBB+ | R22: 04/22/2029
... A36: ARISCN 8 10/31/29 | B36: Aris Mining Corp | C36: ARIS MINING | D36: ARIS MINING CORP | E36: USC04492AA97 | F36: ARISCN | G36: ARIS CN | H36: Mining | I36: IND | J36: Gold Mining | K36: CA | L36: CO | M36: USD | N36: 450000 | O36: SINGLE | P36: 8 | Q36: B+ | R36: 10/31/2029
A37: ATPTOW 7 ⅞ 02/03/30 | B37: ATP Tower Holdings / Andean Telecom Partners Chile SpA / Andean Tower Partners C | C37: ATP TOW/ANDEAN | D37: ATP TOW/ANDEAN TELECOM | E37: USU0489EAA48 | F37: ATPTOW | H37: Engineering&Construction | I37: IND | J37: Building-Heavy Construct | K37: US | L37: CL | M37: USD | N37: 500000 | O37: SINGLE | P37: 7.875 | Q37: BB- | R37: 02/03/2030
A38: AUNA 8 ¾ 11/06/32 | B38: Auna SA / Oncosalud SAC | C38: AUNA SA/ONCOSALU | D38: AUNA SA / ONCOSALUD SAC | E38: USL04168AA59 | F38: AUNA | G38: AUNA US | H38: Healthcare-Services | I38: IND | J38: Medical-Hospitals | K38: LU | L38: PE | M38: USD | N38: 365000 | O38: SINGLE | P38: 8.75 | Q38: B+ | R38: 11/06/2032
A39: AVALCB 4 ⅜ 02/04/30 | B39: Grupo Aval Ltd | C39: GRUPO AVAL LTD | D39: GRUPO AVAL LTD | E39: USG42045AC15 | F39: AVALCB | G39: AVAL CB | H39: Banks | I39: FIN | J39: Commer Banks Non-US | K39: KY | L39: CO | M39: USD | N39: 1000000 | O39: SINGLE | P39: 4.375 | Q39: BB | R39: 02/04/2030
A40: AZUBBZ 9 ⅞ 02/15/31 | B40: Azul Secured Finance LLP | C40: AZUL SECURED FIN | D40: AZUL SECURED FINANCE LLP | E40: USU0551YAK11 | F40: AZUBBZ | G40: 2870534Z BZ | H40: Airlines | I40: IND | J40: Airlines | K40: US | L40: BR | M40: USD | N40: 1375000 | O40: SINGLE | P40: 9.875 | Q40: B- | R40: 02/15/2031
A41: BANBRA 4 ⅞ 01/11/29 | B41: Banco do Brasil SA/Cayman | C41: BANCO BRASL (CI) | D41: BANCO DO BRASIL (CAYMAN) | E41: USP3772WAK82 | F41: BANBRA | G41: BBAS3 BZ | H41: Banks | I41: FOA | J41: Commer Banks Non-US | K41: KY | L41: BR | M41: USD | N41: 500000 | O41: SINGLE | P41: 4.875 | Q41: BB | R41: 01/11/2029
A42: BANBRA 5 ⅝ 10/23/31 | B42: Banco do Brasil SA/Cayman | C42: BANCO BRASL (CI) | D42: BANCO DO BRASIL (CAYMAN) | E42: USP3772WAL65 | F42: BANBRA | G42: BBAS3 BZ | H42: Banks | I42: FOA | J42: Commer Banks Non-US | K42: KY | L42: BR | M42: USD | N42: 500000 | O42: SINGLE | P42: 5.625 | Q42: BB | R42: 10/23/2031
A43: BANBRA 6 03/18/31 | B43: Banco do Brasil SA/Cayman | C43: BANCO BRASL (CI) | D43: BANCO DO BRASIL (CAYMAN) | E43: USP2000TAE57 | F43: BANBRA | G43: BBAS3 BZ | H43: Banks | I43: FOA | J43: Commer Banks Non-US | K43: KY | L43: BR | M43: USD | N43: 750000 | O43: SINGLE | P43: 6 | Q43: BB | R43: 03/18/2031
A44: BANBRA 6 ¼ 04/18/30 | B44: Banco do Brasil SA/Cayman | C44: BANCO BRASL (CI) | D44: BANCO DO BRASIL (CAYMAN) | E44: USP2000TAB19 | F44: BANBRA | G44: BBAS3 BZ | H44: Banks | I44: FOA | J44: Commer Banks Non-US | K44: KY | L44: BR | M44: USD | N44: 750000 | O44: SINGLE | P44: 6.25 | Q44: BB | R44: 04/18/2030
A45: BANCO 7.95 PERP | B45: Banco del Estado de Chile | C45: BANCO DEL ESTADO | D45: BANCO DEL ESTADO -CHILE | E45: USP1027DHQ71 | F45: BANCO | G45: 167579Z CI | H45: Banks | I45: FOA | J45: Regional Banks-Non US | K45: CL | L45: CL | M45: USD | N45: 600000 | O45: SINGLE | P45: 7.95 | Q45: BBB-
A46: BANMEX 6.697 08/07/36 | B46: Banco Nacional de Mexico SA | C46: BANCO NAC DE MEX | D46: BANCO NAC DE MEXICO SA | E46: USP1S8TDFJ81 | F46: BANMEX | G46: BANAMEX MM | H46: Banks | I46: FIN | J46: Commer Banks Non-US | K46: MX | L46: MX | M46: USD | N46: 1300000 | O46: SINGLE | P46: 6.697 | Q46: BB+ | R46: 08/07/2036
A47: BANORT 6 ⅝ PERP | B47: Banco Mercantil del Norte SA/Grand Cayman | C47: BANCO MERC NORTE | D47: BANCO MERCANTIL DE NORTE | E47: USP1401KAB72 | F47: BANORT | G47: BMNA MM | H47: Banks | I47: FIN | J47: Commer Banks Non-US | K47: KY | L47: MX | M47: USD | N47: 550000 | O47: SINGLE | P47: 6.625 | Q47: BB-
A48: BANORT 7 ½ PERP | B48: Banco Mercantil del Norte SA/Grand Cayman | C48: BANCO MERC NORTE | D48: BANCO MERCANTIL DE NORTE | E48: USP1400MAB48 | F48: BANORT | G48: BMNA MM | H48: Banks | I48: FIN | J48: Commer Banks Non-US | K48: KY | L48: MX | M48: USD | N48: 500000 | O48: SINGLE | P48: 7.5 | Q48: BB-
A49: BANORT 8 PERP | B49: Banco Mercantil del Norte SA/Grand Cayman | C49: BANCO MERC NORTE | D49: BANCO MERCANTIL DE NORTE | E49: USP1400MAF51 | F49: BANORT | G49: BMNA MM | H49: Banks | I49: FIN | J49: Commer Banks Non-US | K49: KY | L49: MX | M49: USD | N49: 600000 | O49: SINGLE | P49: 8 | Q49: BB-
A50: BANORT 8 ¾ PERP | B50: Banco Mercantil del Norte SA/Grand Cayman | C50: BANCO MERC NORTE | D50: BANCO MERCANTIL DE NORTE | E50: USP1400MAE86 | F50: BANORT | G50: BMNA MM | H50: Banks | I50: FIN | J50: Commer Banks Non-US | K50: KY | L50: MX | M50: USD | N50: 750000 | O50: SINGLE | P50: 8.75 | Q50: BB-
A51: BANORT 8 ⅜ PERP | B51: Banco Mercantil del Norte SA/Grand Cayman | C51: BANCO MERC NORTE | D51: BANCO MERCANTIL DE NORTE | E51: USP1400MAD04 | F51: BANORT | G51: BMNA MM | H51: Banks | I51: FIN | J51: Commer Banks Non-US | K51: KY | L51: MX | M51: USD | N51: 750000 | O51: SINGLE | P51: 8.375 | Q51: BB-
A52: BANORT 8 ⅜ PERP | B52: Banco Mercantil del Norte SA/Grand Cayman | C52: BANCO MERC NORTE | D52: BANCO MERCANTIL DE NORTE | E52: USP1400MAC21 | F52: BANORT | G52: BMNA MM | H52: Banks | I52: FIN | J52: Commer Banks Non-US | K52: KY | L52: MX | M52: USD | N52: 500000 | O52: SINGLE | P52: 8.375 | Q52: BB-
A53: BANORT 8.45 PERP | B53: Banco Mercantil del Norte SA/Grand Cayman | C53: BANCO MERC NORTE | D53: BANCO MERCANTIL DE NORTE | E53: USP1400MAG35 | F53: BANORT | G53: BMNA MM | H53: Banks | I53: FIN | J53: Commer Banks Non-US | K53: KY | L53: MX | M53: USD | N53: 750000 | O53: SINGLE | P53: 8.45 | Q53: BB-
...

Sheet Port Filtrado
A1: Name | B1: Company Name | C1: Short Name | D1: Issuer | E1: ISIN | F1: Ticker | G1: Eqty Ticker | H1: Group | I1: Sector | J1: Subgroup | K1: Cnty of Dom | L1: Cntry (Risk) | M1: Crncy | N1: Amt Iss (P) | O1: Cpn Type | P1: Cpn (P) | Q1: BB Comp (P) | R1: Mty | S1: EN BD_MATLAB | T1: EN LISTA | U1: AGREGAR
A2: =IF('Port Bloomberg'!A2="","",'Port Bloomberg'!A2) -> ABENGO 6 ⅞ 04/30/43 | B2: =IF('Port Bloomberg'!B2="","",'Port Bloomberg'!B2) -> Atlantica Transmision Sur SA | C2: =IF('Port Bloomberg'!C2="","",'Port Bloomberg'!C2) -> ATL TRANS SUR | D2: =IF('Port Bloomberg'!D2="","",'Port Bloomberg'!D2) -> ATL TRANSMISION SUR | E2: =IF('Port Bloomberg'!E2="","",'Port Bloomberg'!E2) -> USP00173AA51 | F2: =IF('Port Bloomberg'!F2="","",'Port Bloomberg'!F2) -> ABENGO | G2: =IF('Port Bloomberg'!G2="","",'Port Bloomberg'!G2) -> AY US | H2: =IF('Port Bloomberg'!H2="","",'Port Bloomberg'!H2) -> Electric | ... R2: =IF('Port Bloomberg'!R2="","",'Port Bloomberg'!R2) -> 04/30/2043 | S2: =IF(E2="","",IFERROR(IF(MATCH(E2,[1]Instrumentos!$D:$D,0)>0,1,0),0)) -> 1 | T2: =IF(E2="","",IFERROR(IF(MATCH(E2,'Lista de excepciones'!$E:$E,0)>0,1,0),0)) -> 0 | U2: =IF(E2="","",IF(S2+T2=0,"AGREGAR/REVISAR","NO")) -> NO
A3: =IF('Port Bloomberg'!A3="","",'Port Bloomberg'!A3) -> ABRAGF 14 10/22/29 | B3: =IF('Port Bloomberg'!B3="","",'Port Bloomberg'!B3) -> ABRA Global Finance | C3: =IF('Port Bloomberg'!C3="","",'Port Bloomberg'!C3) -> ABRA GLOBAL FIN | D3: =IF('Port Bloomberg'!D3="","",'Port Bloomberg'!D3) -> ABRA GLOBAL FINANCE | E3: =IF('Port Bloomberg'!E3="","",'Port Bloomberg'!E3) -> USG00912AC21 | F3: =IF('Port Bloomberg'!F3="","",'Port Bloomberg'!F3) -> ABRAGF | G3: =IF('Port Bloomberg'!G3="","",'Port Bloomberg'!G3) -> 2058922D LN | H3: =IF('Port Bloomberg'!H3="","",'Port Bloomberg'!H3) -> Airlines | ... R3: =IF('Port Bloomberg'!R3="","",'Port Bloomberg'!R3) -> 10/22/2029 | S3: =IF(E3="","",IFERROR(IF(MATCH(E3,[1]Instrumentos!$D:$D,0)>0,1,0),0)) -> 0 | T3: =IF(E3="","",IFERROR(IF(MATCH(E3,'Lista de excepciones'!$E:$E,0)>0,1,0),0)) -> 1 | U3: =IF(E3="","",IF(S3+T3=0,"AGREGAR/REVISAR","NO")) -> NO
A4: =IF('Port Bloomberg'!A4="","",'Port Bloomberg'!A4) -> ACUPET 7 ½ 01/13/32 | B4: =IF('Port Bloomberg'!B4="","",'Port Bloomberg'!B4) -> Acu Petroleo Luxembourg Sarl | C4: =IF('Port Bloomberg'!C4="","",'Port Bloomberg'!C4) -> ACU PETROLEO LUX | D4: =IF('Port Bloomberg'!D4="","",'Port Bloomberg'!D4) -> ACU PETROLEO LUXEMBOURG | E4: =IF('Port Bloomberg'!E4="","",'Port Bloomberg'!E4) -> USL0R80QAA10 | F4: =IF('Port Bloomberg'!F4="","",'Port Bloomberg'!F4) -> ACUPET | G4: =IF('Port Bloomberg'!G4="","",'Port Bloomberg'!G4) -> 1469040D BZ | H4: =IF('Port Bloomberg'!H4="","",'Port Bloomberg'!H4) -> Pipelines | ... R4: =IF('Port Bloomberg'!R4="","",'Port Bloomberg'!R4) -> 01/13/2032 | S4: =IF(E4="","",IFERROR(IF(MATCH(E4,[1]Instrumentos!$D:$D,0)>0,1,0),0)) -> 0 | T4: =IF(E4="","",IFERROR(IF(MATCH(E4,'Lista de excepciones'!$E:$E,0)>0,1,0),0)) -> 1 | U4: =IF(E4="","",IF(S4+T4=0,"AGREGAR/REVISAR","NO")) -> NO
A5: =IF('Port Bloomberg'!A5="","",'Port Bloomberg'!A5) -> AEGEBZ 6 ¾ 05/20/29 | B5: =IF('Port Bloomberg'!B5="","",'Port Bloomberg'!B5) -> Aegea Finance Sarl | C5: =IF('Port Bloomberg'!C5="","",'Port Bloomberg'!C5) -> AEGEA FINANCE | D5: =IF('Port Bloomberg'!D5="","",'Port Bloomberg'!D5) -> AEGEA FINANCE SARL | E5: =IF('Port Bloomberg'!E5="","",'Port Bloomberg'!E5) -> USL01343AA79 | F5: =IF('Port Bloomberg'!F5="","",'Port Bloomberg'!F5) -> AEGEBZ | G5: =IF('Port Bloomberg'!G5="","",'Port Bloomberg'!G5) -> 0596570D BZ | H5: =IF('Port Bloomberg'!H5="","",'Port Bloomberg'!H5) -> Water | ... R5: =IF('Port Bloomberg'!R5="","",'Port Bloomberg'!R5) -> 05/20/2029 | S5: =IF(E5="","",IFERROR(IF(MATCH(E5,[1]Instrumentos!$D:$D,0)>0,1,0),0)) -> 1 | T5: =IF(E5="","",IFERROR(IF(MATCH(E5,'Lista de excepciones'!$E:$E,0)>0,1,0),0)) -> 0 | U5: =IF(E5="","",IF(S5+T5=0,"AGREGAR/REVISAR","NO")) -> NO
A6: =IF('Port Bloomberg'!A6="","",'Port Bloomberg'!A6) -> AEGEBZ 7 ⅝ 01/20/36 | B6: =IF('Port Bloomberg'!B6="","",'Port Bloomberg'!B6) -> Aegea Finance Sarl | C6: =IF('Port Bloomberg'!C6="","",'Port Bloomberg'!C6) -> AEGEA FINANCE | D6: =IF('Port Bloomberg'!D6="","",'Port Bloomberg'!D6) -> AEGEA FINANCE SARL | E6: =IF('Port Bloomberg'!E6="","",'Port Bloomberg'!E6) -> USL01343AE91 | F6: =IF('Port Bloomberg'!F6="","",'Port Bloomberg'!F6) -> AEGEBZ | G6: =IF('Port Bloomberg'!G6="","",'Port Bloomberg'!G6) -> 0596570D BZ | H6: =IF('Port Bloomberg'!H6="","",'Port Bloomberg'!H6) -> Water | ... R6: =IF('Port Bloomberg'!R6="","",'Port Bloomberg'!R6) -> 01/20/2036 | S6: =IF(E6="","",IFERROR(IF(MATCH(E6,[1]Instrumentos!$D:$D,0)>0,1,0),0)) -> 1 | T6: =IF(E6="","",IFERROR(IF(MATCH(E6,'Lista de excepciones'!$E:$E,0)>0,1,0),0)) -> 0 | U6: =IF(E6="","",IF(S6+T6=0,"AGREGAR/REVISAR","NO")) -> NO
A7: =IF('Port Bloomberg'!A7="","",'Port Bloomberg'!A7) -> AEGEBZ 9 01/20/31 | B7: =IF('Port Bloomberg'!B7="","",'Port Bloomberg'!B7) -> Aegea Finance Sarl | C7: =IF('Port Bloomberg'!C7="","",'Port Bloomberg'!C7) -> AEGEA FINANCE | D7: =IF('Port Bloomberg'!D7="","",'Port Bloomberg'!D7) -> AEGEA FINANCE SARL | E7: =IF('Port Bloomberg'!E7="","",'Port Bloomberg'!E7) -> USL01343AB52 | F7: =IF('Port Bloomberg'!F7="","",'Port Bloomberg'!F7) -> AEGEBZ | G7: =IF('Port Bloomberg'!G7="","",'Port Bloomberg'!G7) -> 0596570D BZ | H7: =IF('Port Bloomberg'!H7="","",'Port Bloomberg'!H7) -> Water | ... R7: =IF('Port Bloomberg'!R7="","",'Port Bloomberg'!R7) -> 01/20/2031 | S7: =IF(E7="","",IFERROR(IF(MATCH(E7,[1]Instrumentos!$D:$D,0)>0,1,0),0)) -> 1 | T7: =IF(E7="","",IFERROR(IF(MATCH(E7,'Lista de excepciones'!$E:$E,0)>0,1,0),0)) -> 0 | U7: =IF(E7="","",IF(S7+T7=0,"AGREGAR/REVISAR","NO")) -> NO
A8: =IF('Port Bloomberg'!A8="","",'Port Bloomberg'!A8) -> AEROMX 8 ¼ 11/15/29 | B8: =IF('Port Bloomberg'!B8="","",'Port Bloomberg'!B8) -> Grupo Aeromexico SAB de CV | C8: =IF('Port Bloomberg'!C8="","",'Port Bloomberg'!C8) -> GRUPO AEROMEXICO | D8: =IF('Port Bloomberg'!D8="","",'Port Bloomberg'!D8) -> GRUPO AEROMEXICO SAB | E8: =IF('Port Bloomberg'!E8="","",'Port Bloomberg'!E8) -> USP4955JAB46 | F8: =IF('Port Bloomberg'!F8="","",'Port Bloomberg'!F8) -> AEROMX | G8: =IF('Port Bloomberg'!G8="","",'Port Bloomberg'!G8) -> AERO* MM | H8: =IF('Port Bloomberg'!H8="","",'Port Bloomberg'!H8) -> Airlines | ... R8: =IF('Port Bloomberg'!R8="","",'Port Bloomberg'!R8) -> 11/15/2029 | S8: =IF(E8="","",IFERROR(IF(MATCH(E8,[1]Instrumentos!$D:$D,0)>0,1,0),0)) -> 0 | T8: =IF(E8="","",IFERROR(IF(MATCH(E8,'Lista de excepciones'!$E:$E,0)>0,1,0),0)) -> 1 | U8: =IF(E8="","",IF(S8+T8=0,"AGREGAR/REVISAR","NO")) -> NO
A9: =IF('Port Bloomberg'!A9="","",'Port Bloomberg'!A9) -> AEROMX 8 ⅝ 11/15/31 | B9: =IF('Port Bloomberg'!B9="","",'Port Bloomberg'!B9) -> Grupo Aeromexico SAB de CV | C9: =IF('Port Bloomberg'!C9="","",'Port Bloomberg'!C9) -> GRUPO AEROMEXICO | D9: =IF('Port Bloomberg'!D9="","",'Port Bloomberg'!D9) -> GRUPO AEROMEXICO SAB | E9: =IF('Port Bloomberg'!E9="","",'Port Bloomberg'!E9) -> USP4955JAC29 | F9: =IF('Port Bloomberg'!F9="","",'Port Bloomberg'!F9) -> AEROMX | G9: =IF('Port Bloomberg'!G9="","",'Port Bloomberg'!G9) -> AERO* MM | H9: =IF('Port Bloomberg'!H9="","",'Port Bloomberg'!H9) -> Airlines | ... R9: =IF('Port Bloomberg'!R9="","",'Port Bloomberg'!R9) -> 11/15/2031 | S9: =IF(E9="","",IFERROR(IF(MATCH(E9,[1]Instrumentos!$D:$D,0)>0,1,0),0)) -> 0 | T9: =IF(E9="","",IFERROR(IF(MATCH(E9,'Lista de excepciones'!$E:$E,0)>0,1,0),0)) -> 1 | U9: =IF(E9="","",IF(S9+T9=0,"AGREGAR/REVISAR","NO")) -> NO
A10: =IF('Port Bloomberg'!A10="","",'Port Bloomberg'!A10) -> AES 4.72 06/30/40 | B10: =IF('Port Bloomberg'!B10="","",'Port Bloomberg'!B10) -> Alto Maipo SpA | C10: =IF('Port Bloomberg'!C10="","",'Port Bloomberg'!C10) -> ALTO MAIPO SPA | D10: =IF('Port Bloomberg'!D10="","",'Port Bloomberg'!D10) -> ALTO MAIPO SPA | E10: =IF('Port Bloomberg'!E10="","",'Port Bloomberg'!E10) -> USP0243BAA37 | F10: =IF('Port Bloomberg'!F10="","",'Port Bloomberg'!F10) -> AES | G10: =IF('Port Bloomberg'!G10="","",'Port Bloomberg'!G10) -> AESANDES CI | H10: =IF('Port Bloomberg'!H10="","",'Port Bloomberg'!H10) -> Energy-Alternate Sources | ... R10: =IF('Port Bloomberg'!R10="","",'Port Bloomberg'!R10) -> 06/30/2040 | S10: =IF(E10="","",IFERROR(IF(MATCH(E10,[1]Instrumentos!$D:$D,0)>0,1,0),0)) -> 0 | T10: =IF(E10="","",IFERROR(IF(MATCH(E10,'Lista de excepciones'!$E:$E,0)>0,1,0),0)) -> 1 | U10: =IF(E10="","",IF(S10+T10=0,"AGREGAR/REVISAR","NO")) -> NO
A11: =IF('Port Bloomberg'!A11="","",'Port Bloomberg'!A11) -> AES 6 ¼ 03/14/32 | B11: =IF('Port Bloomberg'!B11="","",'Port Bloomberg'!B11) -> AES Andes SA | C11: =IF('Port Bloomberg'!C11="","",'Port Bloomberg'!C11) -> AES ANDES SA | D11: =IF('Port Bloomberg'!D11="","",'Port Bloomberg'!D11) -> AES ANDES SA | E11: =IF('Port Bloomberg'!E11="","",'Port Bloomberg'!E11) -> USP0091LAD84 | F11: =IF('Port Bloomberg'!F11="","",'Port Bloomberg'!F11) -> AES | G11: =IF('Port Bloomberg'!G11="","",'Port Bloomberg'!G11) -> AESANDES CI | H11: =IF('Port Bloomberg'!H11="","",'Port Bloomberg'!H11) -> Electric | ... R11: =IF('Port Bloomberg'!R11="","",'Port Bloomberg'!R11) -> 03/14/2032 | S11: =IF(E11="","",IFERROR(IF(MATCH(E11,[1]Instrumentos!$D:$D,0)>0,1,0),0)) -> 1 | T11: =IF(E11="","",IFERROR(IF(MATCH(E11,'Lista de excepciones'!$E:$E,0)>0,1,0),0)) -> 0 | U11: =IF(E11="","",IF(S11+T11=0,"AGREGAR/REVISAR","NO")) -> NO
A12: =IF('Port Bloomberg'!A12="","",'Port Bloomberg'!A12) -> AES 6 ¼ 11/14/34 | B12: =IF('Port Bloomberg'!B12="","",'Port Bloomberg'!B12) -> AES Andes SA | C12: =IF('Port Bloomberg'!C12="","",'Port Bloomberg'!C12) -> AES ANDES SA | D12: =IF('Port Bloomberg'!D12="","",'Port Bloomberg'!D12) -> AES ANDES SA | E12: =IF('Port Bloomberg'!E12="","",'Port Bloomberg'!E12) -> USP0091LAE67 | F12: =IF('Port Bloomberg'!F12="","",'Port Bloomberg'!F12) -> AES | G12: =IF('Port Bloomberg'!G12="","",'Port Bloomberg'!G12) -> AESANDES CI | H12: =IF('Port Bloomberg'!H12="","",'Port Bloomberg'!H12) -> Electric | ... R12: =IF('Port Bloomberg'!R12="","",'Port Bloomberg'!R12) -> 11/14/2034 | S12: =IF(E12="","",IFERROR(IF(MATCH(E12,[1]Instrumentos!$D:$D,0)>0,1,0),0)) -> 1 | T12: =IF(E12="","",IFERROR(IF(MATCH(E12,'Lista de excepciones'!$E:$E,0)>0,1,0),0)) -> 0 | U12: =IF(E12="","",IF(S12+T12=0,"AGREGAR/REVISAR","NO")) -> NO
A13: =IF('Port Bloomberg'!A13="","",'Port Bloomberg'!A13) -> AES 6.3 03/15/29 | B13: =IF('Port Bloomberg'!B13="","",'Port Bloomberg'!B13) -> AES Andes SA | C13: =IF('Port Bloomberg'!C13="","",'Port Bloomberg'!C13) -> AES ANDES SA | D13: =IF('Port Bloomberg'!D13="","",'Port Bloomberg'!D13) -> AES ANDES SA | E13: =IF('Port Bloomberg'!E13="","",'Port Bloomberg'!E13) -> USP0091LAA46 | F13: =IF('Port Bloomberg'!F13="","",'Port Bloomberg'!F13) -> AES | G13: =IF('Port Bloomberg'!G13="","",'Port Bloomberg'!G13) -> AESANDES CI | H13: =IF('Port Bloomberg'!H13="","",'Port Bloomberg'!H13) -> Electric | ... R13: =IF('Port Bloomberg'!R13="","",'Port Bloomberg'!R13) -> 03/15/2029 | S13: =IF(E13="","",IFERROR(IF(MATCH(E13,[1]Instrumentos!$D:$D,0)>0,1,0),0)) -> 1 | T13: =IF(E13="","",IFERROR(IF(MATCH(E13,'Lista de excepciones'!$E:$E,0)>0,1,0),0)) -> 0 | U13: =IF(E13="","",IF(S13+T13=0,"AGREGAR/REVISAR","NO")) -> NO
... A1250: =IF('Port Bloomberg'!A1250="","",'Port Bloomberg'!A1250) | B1250: =IF('Port Bloomberg'!B1250="","",'Port Bloomberg'!B1250) | C1250: =IF('Port Bloomberg'!C1250="","",'Port Bloomberg'!C1250) | D1250: =IF('Port Bloomberg'!D1250="","",'Port Bloomberg'!D1250) | E1250: =IF('Port Bloomberg'!E1250="","",'Port Bloomberg'!E1250) | F1250: =IF('Port Bloomberg'!F1250="","",'Port Bloomberg'!F1250) | G1250: =IF('Port Bloomberg'!G1250="","",'Port Bloomberg'!G1250) | H1250: =IF('Port Bloomberg'!H1250="","",'Port Bloomberg'!H1250) | ... R1250: =IF('Port Bloomberg'!R1250="","",'Port Bloomberg'!R1250) | S1250: =IF(E1250="","",IFERROR(IF(MATCH(E1250,[1]Instrumentos!$D:$D,0)>0,1,0),0)) | T1250: =IF(E1250="","",IFERROR(IF(MATCH(E1250,'Lista de excepciones'!$E:$E,0)>0,1,0),0)) | U1250: =IF(E1250="","",IF(S1250+T1250=0,"AGREGAR/REVISAR","NO"))

Sheet Lista de excepciones
A1: Name | B1: Long Name | C1: Short Name | D1: Issuer | E1: ISIN | F1: Ticker | G1: Eqty Ticker | H1: Group | I1: Subgroup | J1: Sector | K1: Cntry | L1: Cntry (Risk) | M1: Crncy | N1: BB Comp | O1: Comentario
A2: ABRAGF 14 10/22/29 | B2: ABRA Global Finance | C2: ABRA GLOBAL FIN | D2: ABRA GLOBAL FINANCE | E2: USG00912AC21 | F2: ABRAGF | H2: Airlines | I2: IND | J2: Airlines | K2: KY | L2: CO | M2: USD | N2: NR | O2: CCC+
A3: ABRAGF 5 03/02/28 | B3: ABRA Global Finance | C3: ABRA GLOBAL FIN | D3: ABRA GLOBAL FINANCE | E3: USG00912AA64 | F3: ABRAGF | H3: Airlines | I3: IND | J3: Airlines | K3: KY | L3: CO | M3: USD | N3: NR | O3: CCC+
A4: ACUPET 7 ½ 01/13/32 | B4: ACUPET 7 ½ 01/13/32 | C4: ACU PETROLEO LUX | D4: ACU PETROLEO LUXEMBOURG | E4: USL0R80QAA10 | F4: ACUPET | G4: 1469040D BZ | H4: Pipelines | I4: Energy | J4: Pipelines | K4: BR | L4: BR | M4: USD | N4: BB | O4: NO APLICA
A5: AEGEBZ 9 01/20/31 | B5: Aegea Finance Sarl | C5: AEGEA FINANCE | D5: AEGEA FINANCE SARL | E5: USL01343AD19 | F5: AEGEBZ | G5: AEGEBZ | H5: Water | I5: Utilities | J5: Water | K5: LU | L5: BR | M5: USD | N5: BB- | O5: NO APLICA
A6: AEROMX 8 ¼ 11/15/29 | B6: Grupo Aeromexico SAB de CV | C6: GRUPO AEROMEXICO | D6: GRUPO AEROMEXICO SAB | E6: USP4955JAB46 | F6: AEROMX | G6: AEROMX | H6: Airlines | I6: Consumer, Cyclical | J6: Airlines | K6: MX | L6: MX | M6: USD | N6: BB- | O6: HICIERON CALL
A7: AEROMX 8 ⅝ 11/15/31 | B7: Grupo Aeromexico SAB de CV | C7: GRUPO AEROMEXICO | D7: GRUPO AEROMEXICO SAB | E7: USP4955JAC29 | F7: AEROMX | G7: AEROMX | H7: Airlines | I7: Consumer, Cyclical | J7: Airlines | K7: MX | L7: MX | M7: USD | N7: BB- | O7: HICIERON CALL
A8: AES 4.72 06/30/40 | B8: Alto Maipo SpA | C8: ALTO MAIPO SPA | D8: ALTO MAIPO SPA | E8: USP0243BAA37 | F8: AES | G8: AESANDES CI | H8: Energy-Alternate Sources | I8: UTL | J8: Energy-Alternate Sources | K8: CL | L8: CL | M8: USD | O8: CCC+
A9: AMAGGI 5 ¼ 01/28/28 | B9: AMAGGI 5 ¼ 01/28/28 | C9: AMAGGI LUX INT | D9: AMAGGI LUX INTL SARL | E9: USL0183BAA90 | F9: AMAGGI | H9: Agriculture | I9: Agricultural Operations | J9: Consumer, Non-cyclical | K9: BR | L9: BR | M9: USD | N9: BB- | O9: NO APLICA
A10: AMBIBZ 10 ⅞ 02/05/33 | B10: Ambipar Lux Sarl | C10: AMBIPAR LUX SARL | D10: AMBIPAR LUX SARL | E10: USL0183EAB13 | F10: AMBIBZ | H10: Environmental Control | I10: IND | J10: Non-hazardous Waste Disp | K10: LU | L10: BR | M10: USD | N10: BB- | O10: NO APLICA
A11: ANDRGI 9 12/28/29 | B11: Andrade Gutierrez International SA | C11: ANDRADE GUT INT | D11: ANDRADE GUTIER INT SA | E11: USL01795AG50 | F11: ANDRGI | H11: Engineering&Construction | I11: IND | J11: Building-Heavy Construct | K11: LU | L11: BR | M11: USD | N11: NR | O11: NR
A12: ATPTOW 7 ⅞ 02/03/30 | B12: ATP Tower Holdings / Andean Telecom Partners Chile SpA / Andean Tower Partners C | C12: ATP TOW/ANDEAN | D12: ATP TOW/ANDEAN TELECOM | E12: USU0489EAA48 | F12: ATPTOW | H12: Engineering&Construction | I12: IND | J12: Building-Heavy Construct | K12: US | L12: CL | M12: USD | N12: BB- | O12: NO APLICA
A13: AUNA 10 12/18/29 | B13: Auna SA | C13: AUNA SA | D13: AUNA SA | E13: USL0415AAA18 | F13: AUNA | H13: Healthcare-Services | I13: IND | J13: Medical-Hospitals | K13: LU | L13: PE | M13: USD | N13: B+ | O13: NO APLICA - SE REFINANCIÓ
A14: AZUBBZ 9 ⅞ 02/15/31 | B14: Azul Secured Finance LLP | C14: AZUL SECURED FIN | D14: AZUL SECURED FINANCE LLP | E14: USU0551YAK11 | F14: AZUBBZ | G14: 2870534Z BZ | H14: Airlines | I14: IND | J14: Airlines | K14: US | L14: BR | M14: USD | N14: NR | O14: NR
A15: BANVOR 5 ⅞ 04/08/28 | B15: Banco Votorantim SA/Luxembourg | C15: Banco Votorantim SA/Luxembourg | D15: BANCO VOTORANTIM | E15: XS3046422542 | F15: BANVOR | G15: 1009Z BZ | H15: Banks | I15: FIN | J15: Commer Banks Non-US | K15: LU | L15: BR | M15: USD | N15: BB | O15: NO APLICA
A16: BORLTD 9 ½ 08/07/32 | B16: Boroo Investments Pte Ltd | C16: BOROO INV PT LTD | D16: BOROO INVESTMENTS | E16: USY00601AA55 | F16: BORLTD | H16: Mining | I16: IND | J16: Gold Mining | K16: SG | L16: PE | M16: USD | N16: B+ | O16: NO APLICA
A17: BORRNO 10 ⅜ 11/15/30 | B17: Borr IHC Ltd / Borr Finance LLC | C17: BORR IHC/BORR FI | D17: BORR IHC LTD / BORR FIN | E17: USG1467FAB97 | F17: BORRNO | G17: BORR NO | H17: Oil&Gas | I17: Energy | J17: Oil&Gas Drilling | K17: US | L17: MX | M17: USD | N17: B | O17: NO APLICA
A18: BORRNO 10 11/15/28 | B18: Borr IHC Ltd / Borr Finance LLC | C18: BORR IHC/BORR FI | D18: BORR IHC LTD / BORR FIN | E18: USG1467FAA15 | F18: BORRNO | G18: BORR NO | H18: Oil&Gas | I18: Energy | J18: Oil&Gas Drilling | K18: US | L18: MX | M18: USD | N18: B | O18: NO APLICA
A19: BORRNO 8 ¾ 01/15/32 | B19: Borr IHC Ltd / Borr Finance LLC | C19: BORR IHC/BORR FI | D19: BORR IHC LTD / BORR FIN | E19: USG1467FAH67 | F19: BORRNO | G19: BORR US | H19: Oil&Gas | I19: IND | J19: Oil&Gas Drilling | K19: US | L19: MX | M19: USD | N19: B | O19: NO APLICA
A20: BRASKM 12.06 01/23/2081 | B20: Braskem Netherlands Finance BV | C20: BRASKEM NL | D20: BRASKEM NETHERLANDS | E20: USN15516AF97 | F20: BRASKM | G20: BRKM3 BZ | H20: Chemicals | I20: IND | J20: Chemicals-Diversified | K20: NL | L20: BR | M20: USD | N20: C | O20: C
A21: BRASKM 4 ½ 01/31/30 | B21: Braskem Netherlands Finance BV | C21: BRASKEM NL | D21: BRASKEM NETHERLANDS | E21: USN15516AD40 | F21: BRASKM | G21: BRKM3 BZ | H21: Chemicals | I21: IND | J21: Chemicals-Diversified | K21: NL | L21: BR | M21: USD | N21: CC+ | O21: CC+
A22: BRASKM 5 ⅞ 01/31/50 | B22: Braskem Netherlands Finance BV | C22: BRASKEM NL | D22: BRASKEM NETHERLANDS | E22: USN15516AE23 | F22: BRASKM | G22: BRKM3 BZ | H22: Chemicals | I22: IND | J22: Chemicals-Diversified | K22: NL | L22: BR | M22: USD | N22: CC+ | O22: CC+
A23: BRASKM 7 ⅛ 07/22/41 | B23: Braskem America Finance Co | C23: BRASKEM AMERICA | D23: BRASKEM AMERICA FINANCE | E23: USU1065PAA94 | F23: BRASKM | G23: BRKM3 BZ | H23: Chemicals | I23: IND | J23: Petrochemicals | K23: US | L23: BR | M23: USD | N23: CC+ | O23: CC+
A24: BRASKM 7 ¼ 02/13/33 | B24: Braskem Netherlands Finance BV | C24: BRASKEM NL | D24: BRASKEM NETHERLANDS | E24: USN15516AG70 | F24: BRASKM | G24: BRKM3 BZ | H24: Chemicals | I24: IND | J24: Chemicals-Diversified | K24: NL | L24: BR | M24: USD | N24: CC+ | O24: CC+
A25: BRASKM 8 ½ 01/12/31 | B25: Braskem Netherlands Finance BV | C25: BRASKEM NL | D25: BRASKEM NETHERLANDS | E25: USN15516AH53 | F25: BRASKM | G25: BRKM3 BZ | H25: Chemicals | I25: IND | J25: Chemicals-Diversified | K25: NL | L25: BR | M25: USD | N25: CC+ | O25: CC+
A26: BRASKM 8 10/15/34 | B26: Braskem Netherlands Finance BV | C26: BRASKEM NL | D26: BRASKEM NETHERLANDS | E26: USN15516AJ10 | F26: BRASKM | G26: BRKM3 BZ | H26: Chemicals | I26: IND | J26: Chemicals-Diversified | K26: NL | L26: BR | M26: USD | N26: CC+ | O26: CC+
A27: BSMXB 7.525 10/01/28 | B27: Banco Santander Mexico SA Institucion de Banca Multiple Grupo Financiero Santand | C27: SANTANDER MEXICO | D27: BANCO SANTANDER MEXICO | E27: USP1507SAG23 | F27: BSMXB | G27: BSMXB MM | H27: Banks | I27: Financial | J27: Commer Banks Non-US | K27: MX | L27: MX | M27: USD | N27: BBB- | O27: VENCIMIENTO <= 2028
A28: CDEL 4.85 05/18/48 | B28: Corp Nacional del Cobre de Chile | C28: CODELCO INC | D28: CODELCO INC | E28: XS1798294523 | F28: CDEL | G28: 1006Z CI | H28: Mining | I28: FOA | J28: Non-Ferrous Metals | K28: CL | L28: CL | M28: USD | N28: NR | O28: NO RATING
A29: CHIPEC 0 01/25/28 | B29: CHIPEC 0 01/25/28 | C29: CHILE ELEC PEC | D29: CHILE ELEC PEC SPA | E29: USP2550MAA29 | F29: CHIPEC | H29: Electric | I29: Utilities | J29: Electric-Distribution | K29: CL | L29: CL | M29: USD | N29: BBB- | O29: NO APLICA
A30: CHLELC 6.01 01/20/33 | B30: Chile Electricity Lux MPC Sarl | C30: CHILE ELECTR LUX | D30: CHILE ELECTRICITY LUX | E30: USL15669AA91 | F30: CHLELC | H30: Electric | I30: Utilities | J30: Electric-Distribution | K30: LU | L30: CL | M30: USD | N30: A | O30: NO APLICA
A31: CHLMPC 5.58 10/20/35 | B31: Chile Electricity Lux Mpc II Sarl | C31: CL ELECTRICITY | D31: CHILE ELECTRICITY LUX | E31: USL1567LAA19 | F31: CHLMPC | G31: CHLMPC | H31: Electric | I31: Utilities | J31: Electric-Distribution | K31: LU | L31: CL | M31: USD | N31: A- | O31: NO APLICA
A32: CHLMPC 5.672 10/20/35 | B32: Chile Electricity Lux Mpc II Sarl | C32: Chile Electricity Lux Mpc II Sarl | D32: CL ELECTRICITY | E32: USL1567LAB91 | F32: CHLMPC | H32: Electric | I32: FOA | J32: Electric-Distribution | K32: LU | L32: CL | M32: USD | N32: A- | O32: NO APLICA
A33: COSHSA 9 ⅜ 11/07/29 | B33: NewCo Holding USD 20 Sarl | C33: NEWCOL HLDG SARL | D33: NEWCO HOLDING USD SARL | E33: USL67356AA09 | F33: COSHSA | H33: Oil&Gas | I33: Energy | J33: Oil&Gas Drilling | K33: LU | L33: BR | M33: USD | N33: B | O33: NO APLICA
A34: COXMEX 7 ⅛ 01/08/32 | B34: COX Asset Mexico SA de CV | C34: COX ASSET MEX CV | D34: COX ASSET MEXICO SA CV | E34: USP3172AAA45 | F34: COXMEX | G34: COXG SM | H34: Electric | I34: UTL | J34: Electric-Generation | K34: MX | L34: MX | M34: USD | N34: NR | O34: NO APLICA
A35: COXMEX 7 ¾ 05/08/36 | B35: COX Asset Mexico SA de CV | C35: COX ASSET MEX CV | D35: COX ASSET MEXICO SA CV | E35: USP3172AAB28 | F35: COXMEX | G35: COXG SM | H35: Electric | I35: UTL | J35: Electric-Generation | K35: MX | L35: MX | M35: USD | N35: NR | O35: NO APLICA
A36: CSANBZ 8 ¼ PERP | B36: Cosan Overseas Ltd | C36: COSAN OVERSEAS | D36: COSAN OVERSEAS LTD | E36: XS0556373347 | F36: CSANBZ | G36: CSAN3 BZ | H36: Oil&Gas | I36: IND | J36: Oil Refining&Marketing | K36: KY | L36: BR | M36: USD | N36: BB | O36: NO APLICA
A37: CSNABZ 6 ¾ 01/28/28 | B37: CSN Inova Ventures | C37: CSN ISLANDS XI | D37: CSN ISLANDS XI CORP | E37: USG2583XAB76 | F37: CSNABZ | G37: CSNA3 BZ | H37: Iron/Steel | I37: Basic Materials | J37: Steel-Producers | K37: KY | L37: BR | M37: USD | N37: BB- | O37: VENCIMIENTO <= 2028
A38: ECELUP 8 ½ 12/01/32 | B38: Eldorado Intl. Finance GmbH | C38: ELDORADO INTL FI | D38: ELDORADO INTL FIN GMBH | E38: USA18007AC71 | F38: ECELUP | G38: 0113756D BZ | H38: Forest Products&Paper | I38: IND | J38: Paper&Related Products | K38: AT | L38: BR | M38: USD | N38: BB- | O38: NO APLICA
A39: EKT 12 ½ 10/15/31 | B39: Mexico Remittances Funding Fiduciary Estate Management Sarl | C39: MX REMIT FUND | D39: MX REMIT FUND FIDUC EST | E39: USL6364EAB94 | F39: EKT | G39: EKT | H39: Diversified Finan Serv | I39: Financial | J39: Finance-Other Services | K39: LU | L39: MX | M39: USD | N39: BB | O39: NO APLICA
A40: ENELCH 4 ⅞ 06/12/28 | B40: Enel Chile SA | C40: ENEL CHILE SA | D40: ENEL CHILE SA | E40: US29278DAA37 | F40: ENELCH | G40: ENELCHIL CI | H40: Electric | I40: Utilities | J40: Electric-Integrated | K40: CL | L40: CL | M40: USD | N40: BBB | O40: VENCIMIENTO <= 2028
...
